Workbook

Sheet المدخلات
A1: 📋 جدول المدخلات الشهرية
B2: المبيعات والتشغيل | F2: 🏦 الصندوق (الكاش الفعلي) | H2: الديون التي لنا | J2: الديون التي علينا
A3: الشهر | B3: المبيعات (ل.س) | C3: المشتريات (ل.س) | D3: المصاريف (ل.س) | E3: الربح/الخسارة (آلي) | F3: صندوق (ل.س) | G3: صندوق (دولار) | H3: دين لنا (ل.س) | I3: دين لنا ($) | J3: دين علينا (ل.س) | K3: دين علينا ($) | L3: مفتاح الشهر (YYYYMM) | M3: سعر الصرف (1$ = ؟ ل.س)
A4: يناير | B4: 118926000 | C4: 74709000 | D4: 38000000 | E4: =IF(B4="","",B4-C4-D4) -> 6217000 | F4: 1000000 | G4: 0 | H4: 70767000 | I4: 6080 | J4: 4123000 | K4: 14534 | L4: 202601
A5: فبراير | B5: 87859000 | C5: 41296000 | D5: 36215000 | E5: =IF(B5="","",B5-C5-D5) -> 10348000 | F5: 2489000 | G5: 325 | H5: 58684000 | I5: 5052 | J5: 3838000 | K5: 12974 | L5: 202602
A6: مارس | B6: 105443000 | C6: 45155000 | D6: 37203000 | E6: =IF(B6="","",B6-C6-D6) -> 23085000 | F6: 1684000 | G6: 270 | H6: 66327000 | I6: 5156 | J6: 4536000 | K6: 12826 | L6: 202603
A7: أبريل | B7: 166691000 | C7: 91555000 | D7: 38371000 | E7: =IF(B7="","",B7-C7-D7) -> 36765000 | F7: 1436000 | G7: 295 | H7: 70574000 | I7: 7360 | J7: 5924000 | K7: 11459 | L7: 202604
A8: مايو | B8: 163334000 | C8: 91196000 | D8: 26000000 | E8: =IF(B8="","",B8-C8-D8) -> 46138000 | F8: 1500000 | G8: 50 | H8: 35913000 | I8: 6270 | J8: 8730000 | K8: 5679 | L8: 202605
A9: يونيو | B9: 197424000 | C9: 61619000 | D9: 32391000 | E9: =IF(B9="","",B9-C9-D9) -> 103414000 | F9: 584000 | G9: 686 | H9: 35652000 | I9: 11283 | J9: 6647000 | K9: 5101 | L9: 202606 | M9: 13300
A10: يوليو | B10: 191042000 | C10: 140673000 | D10: 29190000 | E10: =IF(B10="","",B10-C10-D10) -> 21179000 | F10: 4287000 | G10: 330 | H10: 46227000 | I10: 10118 | J10: 8341000 | K10: 7147 | L10: 202607 | M10: 13200
A11: أغسطس | E11: =IF(B11="","",B11-C11-D11)
A12: سبتمبر | E12: =IF(B12="","",B12-C12-D12)
A13: أكتوبر | E13: =IF(B13="","",B13-C13-D13)
A14: نوفمبر | E14: =IF(B14="","",B14-C14-D14)
A15: ديسمبر | E15: =IF(B15="","",B15-C15-D15)
A17: 💡 الأزرق = أرقام يدوية | الأسود = محسوب تلقائياً | الصندوق: أدخل الكاش الموجود فعلاً بالليرة السورية والدولار
A18: 🆕 عمود "سعر الصرف" ضروري لأن أصناف المخزون مسعّرة في برنامج المحاسبة بعملتين (دولار وليرة سورية). عبّئه شهرياً بمتوسط سعر الصرف خلال الشهر ليتم توحيد قيمة المخزون وتكلفة الاستهلاك بالليرة السورية في صفحة "أرشيف المخزون".

Sheet الحسابات
A1: 📊 الحسابات الشهرية
A2: الشهر | B2: الربح/الخسارة | C2: هامش الربح % | D2: نمو المبيعات % | E2: نسبة المصاريف % | F2: صندوق (ل.س) | G2: صندوق ($) | H2: صافي الدين (ل.س) | I2: صافي الدين ($) | J2: الحالة | K2: مفتاح الشهر | L2: قيمة المخزون | M2: تكلفة المواد المستهلكة | N2: صافي الربح الحقيقي | O2: هامش الربح الحقيقي % | P2: تغير قيمة المخزون % | Q2: تغير تكلفة الاستهلاك % | R2: تغير الربح الحقيقي %
A3: =المدخلات!A4 -> يناير | B3: =IF(المدخلات!B4="","",المدخلات!B4-المدخلات!C4-المدخلات!D4) -> 6217000 | C3: =IF(المدخلات!B4=0,"",B3/المدخلات!B4) -> 0.052276205 | E3: =IF(المدخلات!B4=0,"",المدخلات!D4/المدخلات!B4) -> 0.31952643 | F3: =IF(المدخلات!F4="","",المدخلات!F4) -> 1000000 | G3: =IF(المدخلات!G4="","",المدخلات!G4) -> 0 | H3: =IF(OR(المدخلات!H4="",المدخلات!J4=""),"",المدخلات!H4-المدخلات!J4) -> 66644000 | I3: =IF(OR(المدخلات!I4="",المدخلات!K4=""),"",المدخلات!I4-المدخلات!K4) -> -8454 | J3: =IF(B3="","",IF(B3>0,"✅ ربح","🔴 خسارة")) -> ✅ ربح | K3: =IF(المدخلات!L4="","",المدخلات!L4) -> 202601 | L3: =IF(K3="","",SUMIFS('أرشيف المخزون'!$N$5:$N$2004,'أرشيف المخزون'!$A$5:$A$2004,K3)) -> 0 | M3: =IF(K3="","",SUMIFS('أرشيف المخزون'!$O$5:$O$2004,'أرشيف المخزون'!$A$5:$A$2004,K3)) -> 0 | N3: =IF(OR(المدخلات!B4="",M3=""),"",المدخلات!B4-M3-المدخلات!D4) -> 80926000 | O3: =IF(OR(المدخلات!B4="",المدخلات!B4=0,N3=""),"",N3/المدخلات!B4) -> 0.68047357
A4: =المدخلات!A5 -> فبراير | B4: =IF(المدخلات!B5="","",المدخلات!B5-المدخلات!C5-المدخلات!D5) -> 10348000 | C4: =IF(المدخلات!B5=0,"",B4/المدخلات!B5) -> 0.11777962 | D4: =IF(OR(المدخلات!B4=0,المدخلات!B5=""),"",(المدخلات!B5-المدخلات!B4)/المدخلات!B4) -> -0.26122967 | E4: =IF(المدخلات!B5=0,"",المدخلات!D5/المدخلات!B5) -> 0.41219454 | F4: =IF(المدخلات!F5="","",المدخلات!F5) -> 2489000 | G4: =IF(المدخلات!G5="","",المدخلات!G5) -> 325 | H4: =IF(OR(المدخلات!H5="",المدخلات!J5=""),"",المدخلات!H5-المدخلات!J5) -> 54846000 | I4: =IF(OR(المدخلات!I5="",المدخلات!K5=""),"",المدخلات!I5-المدخلات!K5) -> -7922 | J4: =IF(B4="","",IF(B4>0,"✅ ربح","🔴 خسارة")) -> ✅ ربح | K4: =IF(المدخلات!L5="","",المدخلات!L5) -> 202602 | L4: =IF(K4="","",SUMIFS('أرشيف المخزون'!$N$5:$N$2004,'أرشيف المخزون'!$A$5:$A$2004,K4)) -> 0 | M4: =IF(K4="","",SUMIFS('أرشيف المخزون'!$O$5:$O$2004,'أرشيف المخزون'!$A$5:$A$2004,K4)) -> 0 | N4: =IF(OR(المدخلات!B5="",M4=""),"",المدخلات!B5-M4-المدخلات!D5) -> 51644000 | O4: =IF(OR(المدخلات!B5="",المدخلات!B5=0,N4=""),"",N4/المدخلات!B5) -> 0.58780546 | P4: =IF(OR(L3="",L3=0,L4=""),"",(L4-L3)/L3) | Q4: =IF(OR(M3="",M3=0,M4=""),"",(M4-M3)/M3) | R4: =IF(OR(N3="",N3=0,N4=""),"",(N4-N3)/N3) -> -0.36183674
A5: =المدخلات!A6 -> مارس | B5: =IF(المدخلات!B6="","",المدخلات!B6-المدخلات!C6-المدخلات!D6) -> 23085000 | C5: =IF(المدخلات!B6=0,"",B5/المدخلات!B6) -> 0.21893345 | D5: =IF(OR(المدخلات!B5=0,المدخلات!B6=""),"",(المدخلات!B6-المدخلات!B5)/المدخلات!B5) -> 0.20013886 | E5: =IF(المدخلات!B6=0,"",المدخلات!D6/المدخلات!B6) -> 0.3528257 | F5: =IF(المدخلات!F6="","",المدخلات!F6) -> 1684000 | G5: =IF(المدخلات!G6="","",المدخلات!G6) -> 270 | H5: =IF(OR(المدخلات!H6="",المدخلات!J6=""),"",المدخلات!H6-المدخلات!J6) -> 61791000 | I5: =IF(OR(المدخلات!I6="",المدخلات!K6=""),"",المدخلات!I6-المدخلات!K6) -> -7670 | J5: =IF(B5="","",IF(B5>0,"✅ ربح","🔴 خسارة")) -> ✅ ربح | K5: =IF(المدخلات!L6="","",المدخلات!L6) -> 202603 | L5: =IF(K5="","",SUMIFS('أرشيف المخزون'!$N$5:$N$2004,'أرشيف المخزون'!$A$5:$A$2004,K5)) -> 0 | M5: =IF(K5="","",SUMIFS('أرشيف المخزون'!$O$5:$O$2004,'أرشيف المخزون'!$A$5:$A$2004,K5)) -> 0 | N5: =IF(OR(المدخلات!B6="",M5=""),"",المدخلات!B6-M5-المدخلات!D6) -> 68240000 | O5: =IF(OR(المدخلات!B6="",المدخلات!B6=0,N5=""),"",N5/المدخلات!B6) -> 0.6471743 | P5: =IF(OR(L4="",L4=0,L5=""),"",(L5-L4)/L4) | Q5: =IF(OR(M4="",M4=0,M5=""),"",(M5-M4)/M4) | R5: =IF(OR(N4="",N4=0,N5=""),"",(N5-N4)/N4) -> 0.32135388
A6: =المدخلات!A7 -> أبريل | B6: =IF(المدخلات!B7="","",المدخلات!B7-المدخلات!C7-المدخلات!D7) -> 36765000 | C6: =IF(المدخلات!B7=0,"",B6/المدخلات!B7) -> 0.2205578 | D6: =IF(OR(المدخلات!B6=0,المدخلات!B7=""),"",(المدخلات!B7-المدخلات!B6)/المدخلات!B6) -> 0.58086359 | E6: =IF(المدخلات!B7=0,"",المدخلات!D7/المدخلات!B7) -> 0.23019239 | F6: =IF(المدخلات!F7="","",المدخلات!F7) -> 1436000 | G6: =IF(المدخلات!G7="","",المدخلات!G7) -> 295 | H6: =IF(OR(المدخلات!H7="",المدخلات!J7=""),"",المدخلات!H7-المدخلات!J7) -> 64650000 | I6: =IF(OR(المدخلات!I7="",المدخلات!K7=""),"",المدخلات!I7-المدخلات!K7) -> -4099 | J6: =IF(B6="","",IF(B6>0,"✅ ربح","🔴 خسارة")) -> ✅ ربح | K6: =IF(المدخلات!L7="","",المدخلات!L7) -> 202604 | L6: =IF(K6="","",SUMIFS('أرشيف المخزون'!$N$5:$N$2004,'أرشيف المخزون'!$A$5:$A$2004,K6)) -> 0 | M6: =IF(K6="","",SUMIFS('أرشيف المخزون'!$O$5:$O$2004,'أرشيف المخزون'!$A$5:$A$2004,K6)) -> 0 | N6: =IF(OR(المدخلات!B7="",M6=""),"",المدخلات!B7-M6-المدخلات!D7) -> 128320000 | O6: =IF(OR(المدخلات!B7="",المدخلات!B7=0,N6=""),"",N6/المدخلات!B7) -> 0.76980761 | P6: =IF(OR(L5="",L5=0,L6=""),"",(L6-L5)/L5) | Q6: =IF(OR(M5="",M5=0,M6=""),"",(M6-M5)/M5) | R6: =IF(OR(N5="",N5=0,N6=""),"",(N6-N5)/N5) -> 0.88042204
A7: =المدخلات!A8 -> مايو | B7: =IF(المدخلات!B8="","",المدخلات!B8-المدخلات!C8-المدخلات!D8) -> 46138000 | C7: =IF(المدخلات!B8=0,"",B7/المدخلات!B8) -> 0.2824764 | D7: =IF(OR(المدخلات!B7=0,المدخلات!B8=""),"",(المدخلات!B8-المدخلات!B7)/المدخلات!B7) -> -0.02013906 | E7: =IF(المدخلات!B8=0,"",المدخلات!D8/المدخلات!B8) -> 0.15918302 | F7: =IF(المدخلات!F8="","",المدخلات!F8) -> 1500000 | G7: =IF(المدخلات!G8="","",المدخلات!G8) -> 50 | H7: =IF(OR(المدخلات!H8="",المدخلات!J8=""),"",المدخلات!H8-المدخلات!J8) -> 27183000 | I7: =IF(OR(المدخلات!I8="",المدخلات!K8=""),"",المدخلات!I8-المدخلات!K8) -> 591 | J7: =IF(B7="","",IF(B7>0,"✅ ربح","🔴 خسارة")) -> ✅ ربح | K7: =IF(المدخلات!L8="","",المدخلات!L8) -> 202605 | L7: =IF(K7="","",SUMIFS('أرشيف المخزون'!$N$5:$N$2004,'أرشيف المخزون'!$A$5:$A$2004,K7)) -> 0 | M7: =IF(K7="","",SUMIFS('أرشيف المخزون'!$O$5:$O$2004,'أرشيف المخزون'!$A$5:$A$2004,K7)) -> 0 | N7: =IF(OR(المدخلات!B8="",M7=""),"",المدخلات!B8-M7-المدخلات!D8) -> 137334000 | O7: =IF(OR(المدخلات!B8="",المدخلات!B8=0,N7=""),"",N7/المدخلات!B8) -> 0.84081698 | P7: =IF(OR(L6="",L6=0,L7=""),"",(L7-L6)/L6) | Q7: =IF(OR(M6="",M6=0,M7=""),"",(M7-M6)/M6) | R7: =IF(OR(N6="",N6=0,N7=""),"",(N7-N6)/N6) -> 0.070246259
A8: =المدخلات!A9 -> يونيو | B8: =IF(المدخلات!B9="","",المدخلات!B9-المدخلات!C9-المدخلات!D9) -> 103414000 | C8: =IF(المدخلات!B9=0,"",B8/المدخلات!B9) -> 0.52381676 | D8: =IF(OR(المدخلات!B8=0,المدخلات!B9=""),"",(المدخلات!B9-المدخلات!B8)/المدخلات!B8) -> 0.20871343 | E8: =IF(المدخلات!B9=0,"",المدخلات!D9/المدخلات!B9) -> 0.1640682 | F8: =IF(المدخلات!F9="","",المدخلات!F9) -> 584000 | G8: =IF(المدخلات!G9="","",المدخلات!G9) -> 686 | H8: =IF(OR(المدخلات!H9="",المدخلات!J9=""),"",المدخلات!H9-المدخلات!J9) -> 29005000 | I8: =IF(OR(المدخلات!I9="",المدخلات!K9=""),"",المدخلات!I9-المدخلات!K9) -> 6182 | J8: =IF(B8="","",IF(B8>0,"✅ ربح","🔴 خسارة")) -> ✅ ربح | K8: =IF(المدخلات!L9="","",المدخلات!L9) -> 202606 | L8: =IF(K8="","",SUMIFS('أرشيف المخزون'!$N$5:$N$2004,'أرشيف المخزون'!$A$5:$A$2004,K8)) -> 4.7082131e+08 | M8: =IF(K8="","",SUMIFS('أرشيف المخزون'!$O$5:$O$2004,'أرشيف المخزون'!$A$5:$A$2004,K8)) -> 0 | N8: =IF(OR(المدخلات!B9="",M8=""),"",المدخلات!B9-M8-المدخلات!D9) -> 165033000 | O8: =IF(OR(المدخلات!B9="",المدخلات!B9=0,N8=""),"",N8/المدخلات!B9) -> 0.8359318 | P8: =IF(OR(L7="",L7=0,L8=""),"",(L8-L7)/L7) | Q8: =IF(OR(M7="",M7=0,M8=""),"",(M8-M7)/M7) | R8: =IF(OR(N7="",N7=0,N8=""),"",(N8-N7)/N7) -> 0.20169077
A9: =المدخلات!A10 -> يوليو | B9: =IF(المدخلات!B10="","",المدخلات!B10-المدخلات!C10-المدخلات!D10) -> 21179000 | C9: =IF(المدخلات!B10=0,"",B9/المدخلات!B10) -> 0.11086044 | D9: =IF(OR(المدخلات!B9=0,المدخلات!B10=""),"",(المدخلات!B10-المدخلات!B9)/المدخلات!B9) -> -0.032326364 | E9: =IF(المدخلات!B10=0,"",المدخلات!D10/المدخلات!B10) -> 0.15279363 | F9: =IF(المدخلات!F10="","",المدخلات!F10) -> 4287000 | G9: =IF(المدخلات!G10="","",المدخلات!G10) -> 330 | H9: =IF(OR(المدخلات!H10="",المدخلات!J10=""),"",المدخلات!H10-المدخلات!J10) -> 37886000 | I9: =IF(OR(المدخلات!I10="",المدخلات!K10=""),"",المدخلات!I10-المدخلات!K10) -> 2971 | J9: =IF(B9="","",IF(B9>0,"✅ ربح","🔴 خسارة")) -> ✅ ربح | K9: =IF(المدخلات!L10="","",المدخلات!L10) -> 202607 | L9: =IF(K9="","",SUMIFS('أرشيف المخزون'!$N$5:$N$2004,'أرشيف المخزون'!$A$5:$A$2004,K9)) -> 5.3775681e+08 | M9: =IF(K9="","",SUMIFS('أرشيف المخزون'!$O$5:$O$2004,'أرشيف المخزون'!$A$5:$A$2004,K9)) -> 25442362 | N9: =IF(OR(المدخلات!B10="",M9=""),"",المدخلات!B10-M9-المدخلات!D10) -> 1.3640964e+08 | O9: =IF(OR(المدخلات!B10="",المدخلات!B10=0,N9=""),"",N9/المدخلات!B10) -> 0.71402957 | P9: =IF(OR(L8="",L8=0,L9=""),"",(L9-L8)/L8) -> 0.14216752 | Q9: =IF(OR(M8="",M8=0,M9=""),"",(M9-M8)/M8) | R9: =IF(OR(N8="",N8=0,N9=""),"",(N9-N8)/N8) -> -0.17344023
A10: =المدخلات!A11 -> أغسطس | B10: =IF(المدخلات!B11="","",المدخلات!B11-المدخلات!C11-المدخلات!D11) | C10: =IF(المدخلات!B11=0,"",B10/المدخلات!B11) | D10: =IF(OR(المدخلات!B10=0,المدخلات!B11=""),"",(المدخلات!B11-المدخلات!B10)/المدخلات!B10) | E10: =IF(المدخلات!B11=0,"",المدخلات!D11/المدخلات!B11) | F10: =IF(المدخلات!F11="","",المدخلات!F11) | G10: =IF(المدخلات!G11="","",المدخلات!G11) | H10: =IF(OR(المدخلات!H11="",المدخلات!J11=""),"",المدخلات!H11-المدخلات!J11) | I10: =IF(OR(المدخلات!I11="",المدخلات!K11=""),"",المدخلات!I11-المدخلات!K11) | J10: =IF(B10="","",IF(B10>0,"✅ ربح","🔴 خسارة")) | K10: =IF(المدخلات!L11="","",المدخلات!L11) | L10: =IF(K10="","",SUMIFS('أرشيف المخزون'!$N$5:$N$2004,'أرشيف المخزون'!$A$5:$A$2004,K10)) | M10: =IF(K10="","",SUMIFS('أرشيف المخزون'!$O$5:$O$2004,'أرشيف المخزون'!$A$5:$A$2004,K10)) | N10: =IF(OR(المدخلات!B11="",M10=""),"",المدخلات!B11-M10-المدخلات!D11) | O10: =IF(OR(المدخلات!B11="",المدخلات!B11=0,N10=""),"",N10/المدخلات!B11) | P10: =IF(OR(L9="",L9=0,L10=""),"",(L10-L9)/L9) | Q10: =IF(OR(M9="",M9=0,M10=""),"",(M10-M9)/M9) | R10: =IF(OR(N9="",N9=0,N10=""),"",(N10-N9)/N9)
A11: =المدخلات!A12 -> سبتمبر | B11: =IF(المدخلات!B12="","",المدخلات!B12-المدخلات!C12-المدخلات!D12) | C11: =IF(المدخلات!B12=0,"",B11/المدخلات!B12) | D11: =IF(OR(المدخلات!B11=0,المدخلات!B12=""),"",(المدخلات!B12-المدخلات!B11)/المدخلات!B11) | E11: =IF(المدخلات!B12=0,"",المدخلات!D12/المدخلات!B12) | F11: =IF(المدخلات!F12="","",المدخلات!F12) | G11: =IF(المدخلات!G12="","",المدخلات!G12) | H11: =IF(OR(المدخلات!H12="",المدخلات!J12=""),"",المدخلات!H12-المدخلات!J12) | I11: =IF(OR(المدخلات!I12="",المدخلات!K12=""),"",المدخلات!I12-المدخلات!K12) | J11: =IF(B11="","",IF(B11>0,"✅ ربح","🔴 خسارة")) | K11: =IF(المدخلات!L12="","",المدخلات!L12) | L11: =IF(K11="","",SUMIFS('أرشيف المخزون'!$N$5:$N$2004,'أرشيف المخزون'!$A$5:$A$2004,K11)) | M11: =IF(K11="","",SUMIFS('أرشيف المخزون'!$O$5:$O$2004,'أرشيف المخزون'!$A$5:$A$2004,K11)) | N11: =IF(OR(المدخلات!B12="",M11=""),"",المدخلات!B12-M11-المدخلات!D12) | O11: =IF(OR(المدخلات!B12="",المدخلات!B12=0,N11=""),"",N11/المدخلات!B12) | P11: =IF(OR(L10="",L10=0,L11=""),"",(L11-L10)/L10) | Q11: =IF(OR(M10="",M10=0,M11=""),"",(M11-M10)/M10) | R11: =IF(OR(N10="",N10=0,N11=""),"",(N11-N10)/N10)
A12: =المدخلات!A13 -> أكتوبر | B12: =IF(المدخلات!B13="","",المدخلات!B13-المدخلات!C13-المدخلات!D13) | C12: =IF(المدخلات!B13=0,"",B12/المدخلات!B13) | D12: =IF(OR(المدخلات!B12=0,المدخلات!B13=""),"",(المدخلات!B13-المدخلات!B12)/المدخلات!B12) | E12: =IF(المدخلات!B13=0,"",المدخلات!D13/المدخلات!B13) | F12: =IF(المدخلات!F13="","",المدخلات!F13) | G12: =IF(المدخلات!G13="","",المدخلات!G13) | H12: =IF(OR(المدخلات!H13="",المدخلات!J13=""),"",المدخلات!H13-المدخلات!J13) | I12: =IF(OR(المدخلات!I13="",المدخلات!K13=""),"",المدخلات!I13-المدخلات!K13) | J12: =IF(B12="","",IF(B12>0,"✅ ربح","🔴 خسارة")) | K12: =IF(المدخلات!L13="","",المدخلات!L13) | L12: =IF(K12="","",SUMIFS('أرشيف المخزون'!$N$5:$N$2004,'أرشيف المخزون'!$A$5:$A$2004,K12)) | M12: =IF(K12="","",SUMIFS('أرشيف المخزون'!$O$5:$O$2004,'أرشيف المخزون'!$A$5:$A$2004,K12)) | N12: =IF(OR(المدخلات!B13="",M12=""),"",المدخلات!B13-M12-المدخلات!D13) | O12: =IF(OR(المدخلات!B13="",المدخلات!B13=0,N12=""),"",N12/المدخلات!B13) | P12: =IF(OR(L11="",L11=0,L12=""),"",(L12-L11)/L11) | Q12: =IF(OR(M11="",M11=0,M12=""),"",(M12-M11)/M11) | R12: =IF(OR(N11="",N11=0,N12=""),"",(N12-N11)/N11)
A13: =المدخلات!A14 -> نوفمبر | B13: =IF(المدخلات!B14="","",المدخلات!B14-المدخلات!C14-المدخلات!D14) | C13: =IF(المدخلات!B14=0,"",B13/المدخلات!B14) | D13: =IF(OR(المدخلات!B13=0,المدخلات!B14=""),"",(المدخلات!B14-المدخلات!B13)/المدخلات!B13) | E13: =IF(المدخلات!B14=0,"",المدخلات!D14/المدخلات!B14) | F13: =IF(المدخلات!F14="","",المدخلات!F14) | G13: =IF(المدخلات!G14="","",المدخلات!G14) | H13: =IF(OR(المدخلات!H14="",المدخلات!J14=""),"",المدخلات!H14-المدخلات!J14) | I13: =IF(OR(المدخلات!I14="",المدخلات!K14=""),"",المدخلات!I14-المدخلات!K14) | J13: =IF(B13="","",IF(B13>0,"✅ ربح","🔴 خسارة")) | K13: =IF(المدخلات!L14="","",المدخلات!L14) | L13: =IF(K13="","",SUMIFS('أرشيف المخزون'!$N$5:$N$2004,'أرشيف المخزون'!$A$5:$A$2004,K13)) | M13: =IF(K13="","",SUMIFS('أرشيف المخزون'!$O$5:$O$2004,'أرشيف المخزون'!$A$5:$A$2004,K13)) | N13: =IF(OR(المدخلات!B14="",M13=""),"",المدخلات!B14-M13-المدخلات!D14) | O13: =IF(OR(المدخلات!B14="",المدخلات!B14=0,N13=""),"",N13/المدخلات!B14) | P13: =IF(OR(L12="",L12=0,L13=""),"",(L13-L12)/L12) | Q13: =IF(OR(M12="",M12=0,M13=""),"",(M13-M12)/M12) | R13: =IF(OR(N12="",N12=0,N13=""),"",(N13-N12)/N12)
A14: =المدخلات!A15 -> ديسمبر | B14: =IF(المدخلات!B15="","",المدخلات!B15-المدخلات!C15-المدخلات!D15) | C14: =IF(المدخلات!B15=0,"",B14/المدخلات!B15) | D14: =IF(OR(المدخلات!B14=0,المدخلات!B15=""),"",(المدخلات!B15-المدخلات!B14)/المدخلات!B14) | E14: =IF(المدخلات!B15=0,"",المدخلات!D15/المدخلات!B15) | F14: =IF(المدخلات!F15="","",المدخلات!F15) | G14: =IF(المدخلات!G15="","",المدخلات!G15) | H14: =IF(OR(المدخلات!H15="",المدخلات!J15=""),"",المدخلات!H15-المدخلات!J15) | I14: =IF(OR(المدخلات!I15="",المدخلات!K15=""),"",المدخلات!I15-المدخلات!K15) | J14: =IF(B14="","",IF(B14>0,"✅ ربح","🔴 خسارة")) | K14: =IF(المدخلات!L15="","",المدخلات!L15) | L14: =IF(K14="","",SUMIFS('أرشيف المخزون'!$N$5:$N$2004,'أرشيف المخزون'!$A$5:$A$2004,K14)) | M14: =IF(K14="","",SUMIFS('أرشيف المخزون'!$O$5:$O$2004,'أرشيف المخزون'!$A$5:$A$2004,K14)) | N14: =IF(OR(المدخلات!B15="",M14=""),"",المدخلات!B15-M14-المدخلات!D15) | O14: =IF(OR(المدخلات!B15="",المدخلات!B15=0,N14=""),"",N14/المدخلات!B15) | P14: =IF(OR(L13="",L13=0,L14=""),"",(L14-L13)/L13) | Q14: =IF(OR(M13="",M13=0,M14=""),"",(M14-M13)/M13) | R14: =IF(OR(N13="",N13=0,N14=""),"",(N14-N13)/N13)

Sheet لوحة التحكم
A1: 🏢 لوحة التحكم المالية الذكية
A2: ="📅 آخر شهر تم إدخاله: "&IFERROR(LOOKUP(2,1/(المدخلات!B4:B15<>""),المدخلات!A4:A15),"") -> 📅 آخر شهر تم إدخاله: يوليو
A4: 💰 المبيعات | B4: آخر شهر | C4: الشهر السابق | D4: التغير % | E4: 📈 | F4: الوضع
B5: =IFERROR(LOOKUP(2,1/(المدخلات!B4:B15<>""),المدخلات!B4:B15),"") -> 191042000 | C5: =IFERROR(INDEX(المدخلات!B4:B15,COUNTA(المدخلات!B4:B15)-1),"") -> 197424000 | D5: =IF(OR(C5=0,C5=""),"",(B5-C5)/C5) -> -0.032326364 | E5: =IF(D5="","",IF(D5>0,"▲ ","▼ ")) -> ▼ | F5: =IF(D5="","",IF(D5>0,"✅","🔴")) -> 🔴
A7: 📈 الربح/الخسارة (تقديري - على أساس المشتريات) | B7: آخر شهر | C7: الشهر السابق | D7: التغير % | E7: 📈 | F7: الوضع
B8: =IFERROR(LOOKUP(2,1/(المدخلات!B4:B15<>""),الحسابات!B3:B14),"") -> 21179000 | C8: =IFERROR(INDEX(الحسابات!B3:B14,COUNTA(المدخلات!B4:B15)-1),"") -> 103414000 | D8: =IF(OR(C8=0,C8=""),"",(B8-C8)/C8) -> -0.79520181 | E8: =IF(D8="","",IF(D8>0,"▲ ","▼ ")) -> ▼ | F8: =IF(D8="","",IF(D8>0,"✅","🔴")) -> 🔴
A10: 💸 المصاريف | B10: آخر شهر | C10: الشهر السابق | D10: التغير % | E10: 📈 | F10: الوضع
B11: =IFERROR(LOOKUP(2,1/(المدخلات!B4:B15<>""),المدخلات!D4:D15),"") -> 29190000 | C11: =IFERROR(INDEX(المدخلات!D4:D15,COUNTA(المدخلات!B4:B15)-1),"") -> 32391000 | D11: =IF(OR(C11=0,C11=""),"",(B11-C11)/C11) -> -0.098823747 | E11: =IF(D11="","",IF(D11>0,"▲ ","▼ ")) -> ▼ | F11: =IF(D11="","",IF(D11>0,"✅","🔴")) -> 🔴
A13: 🏦 صافي الدين (ل.س) | B13: آخر شهر | C13: الشهر السابق | D13: التغير % | E13: 📈 | F13: الوضع
B14: =IFERROR(LOOKUP(2,1/(المدخلات!B4:B15<>""),الحسابات!H3:H14),"") -> 37886000 | C14: =IFERROR(INDEX(الحسابات!H3:H14,COUNTA(المدخلات!B4:B15)-1),"") -> 29005000 | D14: =IF(OR(C14=0,C14=""),"",(B14-C14)/C14) -> 0.30618859 | E14: =IF(D14="","",IF(D14>0,"▲ ","▼ ")) -> ▲ | F14: =IF(D14="","",IF(D14>0,"✅","🔴")) -> ✅
A16: 💵 صافي الدين ($) | B16: آخر شهر | C16: الشهر السابق | D16: التغير % | E16: 📈 | F16: الوضع
B17: =IFERROR(LOOKUP(2,1/(المدخلات!B4:B15<>""),الحسابات!I3:I14),"") -> 2971 | C17: =IFERROR(INDEX(الحسابات!I3:I14,COUNTA(المدخلات!B4:B15)-1),"") -> 6182 | D17: =IF(OR(C17=0,C17=""),"",(B17-C17)/C17) -> -0.51941119 | E17: =IF(D17="","",IF(D17>0,"▲ ","▼ ")) -> ▼ | F17: =IF(D17="","",IF(D17>0,"✅","🔴")) -> 🔴
A19: 🏦 الكاش المتاح في الصندوق
A20: كاش الصندوق | B20: =IFERROR(LOOKUP(2,1/(المدخلات!B4:B15<>""),المدخلات!F4:F15),"") -> 4287000 | C20: ليرة سورية
A21: كاش الصندوق | B21: =IFERROR(LOOKUP(2,1/(المدخلات!B4:B15<>""),المدخلات!G4:G15),"") -> 330 | C21: دولار أمريكي
A23: 📋 تفصيل الديون بالعملتين
A24: البيان | B24: ليرة سورية | C24: دولار
A25: ديون لنا 🟢 | B25: =IFERROR(LOOKUP(2,1/(المدخلات!B4:B15<>""),المدخلات!H4:H15),"") -> 46227000 | C25: =IFERROR(LOOKUP(2,1/(المدخلات!B4:B15<>""),المدخلات!I4:I15),"") -> 10118
A26: ديون علينا 🔴 | B26: =IFERROR(LOOKUP(2,1/(المدخلات!B4:B15<>""),المدخلات!J4:J15),"") -> 8341000 | C26: =IFERROR(LOOKUP(2,1/(المدخلات!B4:B15<>""),المدخلات!K4:K15),"") -> 7147
A27: صافي الدين | B27: =IFERROR(LOOKUP(2,1/(المدخلات!B4:B15<>""),الحسابات!H3:H14),"") -> 37886000 | C27: =IFERROR(LOOKUP(2,1/(المدخلات!B4:B15<>""),الحسابات!I3:I14),"") -> 2971
A29: 📦 قيمة المخزون | B29: آخر شهر | C29: الشهر السابق | D29: التغير % | E29: 📈 | F29: الوضع
B30: =IFERROR(LOOKUP(2,1/(المدخلات!B4:B15<>""),الحسابات!L3:L14),"") -> 5.3775681e+08 | C30: =IFERROR(INDEX(الحسابات!L3:L14,COUNTA(المدخلات!B4:B15)-1),"") -> 4.7082131e+08 | D30: =IF(OR(C30=0,C30=""),"",(B30-C30)/C30) -> 0.14216752 | E30: =IF(D30="","",IF(D30>0,"▲ ","▼ ")) -> ▲ | F30: =IF(D30="","",IF(D30>0,"✅","🔴")) -> ✅
A32: 🧾 تكلفة المواد المستهلكة | B32: آخر شهر | C32: الشهر السابق | D32: التغير % | E32: 📈 | F32: الوضع
B33: =IFERROR(LOOKUP(2,1/(المدخلات!B4:B15<>""),الحسابات!M3:M14),"") -> 25442362 | C33: =IFERROR(INDEX(الحسابات!M3:M14,COUNTA(المدخلات!B4:B15)-1),"") -> 0 | D33: =IF(OR(C33=0,C33=""),"",(B33-C33)/C33) | E33: =IF(D33="","",IF(D33>0,"▲ ","▼ ")) | F33: =IF(D33="","",IF(D33>0,"✅","🔴"))
A35: 💚 صافي الربح الحقيقي | B35: آخر شهر | C35: الشهر السابق | D35: التغير % | E35: 📈 | F35: الوضع
B36: =IFERROR(LOOKUP(2,1/(المدخلات!B4:B15<>""),الحسابات!N3:N14),"") -> 1.3640964e+08 | C36: =IFERROR(INDEX(الحسابات!N3:N14,COUNTA(المدخلات!B4:B15)-1),"") -> 165033000 | D36: =IF(OR(C36=0,C36=""),"",(B36-C36)/C36) -> -0.17344023 | E36: =IF(D36="","",IF(D36>0,"▲ ","▼ ")) -> ▼ | F36: =IF(D36="","",IF(D36>0,"✅","🔴")) -> 🔴
A38: 💡 الربح الحقيقي = المبيعات − تكلفة المواد المستهلكة فعلياً (من أرشيف المخزون) − المصاريف الأخرى. وهو أدق من بطاقة "الربح/الخسارة" أعلاه لأنه لا يعتمد على قيمة المشتريات الشهرية بل على ما استُهلك فعلياً من المخزون.

Sheet الرسوم البيانية
A1: 📊 الرسوم البيانية
A2: 🟠 مصاريف | 🟢 ديون لنا | 🔴 ديون علينا | 💜 صافي الدين | 💵 دولار — كل نقطة = شهر واحد، الخط المتموج يوضح الاتجاه العام
Q3: الشهر | R3: المصاريف | S3: نسبة المصاريف | T3: دين لنا (ل.س) | U3: دين علينا (ل.س) | V3: صافي الدين (ل.س) | W3: دين لنا ($) | X3: دين علينا ($) | Y3: صافي الدين ($) | Z3: قيمة المخزون | AA3: تكلفة المواد المستهلكة | AB3: صافي الربح الحقيقي
Q4: =المدخلات!A4 -> يناير | R4: =IF(المدخلات!D4="","",المدخلات!D4) -> 38000000 | S4: =IF(OR(المدخلات!B4=0,المدخلات!B4=""),"",المدخلات!D4/المدخلات!B4) -> 0.31952643 | T4: =IF(المدخلات!H4="","",المدخلات!H4) -> 70767000 | U4: =IF(المدخلات!J4="","",المدخلات!J4) -> 4123000 | V4: =IF(OR(المدخلات!H4="",المدخلات!J4=""),"",المدخلات!H4-المدخلات!J4) -> 66644000 | W4: =IF(المدخلات!I4="","",المدخلات!I4) -> 6080 | X4: =IF(المدخلات!K4="","",المدخلات!K4) -> 14534 | Y4: =IF(OR(المدخلات!I4="",المدخلات!K4=""),"",المدخلات!I4-المدخلات!K4) -> -8454 | Z4: =IF(الحسابات!L3="","",الحسابات!L3) -> 0 | AA4: =IF(الحسابات!M3="","",الحسابات!M3) -> 0 | AB4: =IF(الحسابات!N3="","",الحسابات!N3) -> 80926000
Q5: =المدخلات!A5 -> فبراير | R5: =IF(المدخلات!D5="","",المدخلات!D5) -> 36215000 | S5: =IF(OR(المدخلات!B5=0,المدخلات!B5=""),"",المدخلات!D5/المدخلات!B5) -> 0.41219454 | T5: =IF(المدخلات!H5="","",المدخلات!H5) -> 58684000 | U5: =IF(المدخلات!J5="","",المدخلات!J5) -> 3838000 | V5: =IF(OR(المدخلات!H5="",المدخلات!J5=""),"",المدخلات!H5-المدخلات!J5) -> 54846000 | W5: =IF(المدخلات!I5="","",المدخلات!I5) -> 5052 | X5: =IF(المدخلات!K5="","",المدخلات!K5) -> 12974 | Y5: =IF(OR(المدخلات!I5="",المدخلات!K5=""),"",المدخلات!I5-المدخلات!K5) -> -7922 | Z5: =IF(الحسابات!L4="","",الحسابات!L4) -> 0 | AA5: =IF(الحسابات!M4="","",الحسابات!M4) -> 0 | AB5: =IF(الحسابات!N4="","",الحسابات!N4) -> 51644000
Q6: =المدخلات!A6 -> مارس | R6: =IF(المدخلات!D6="","",المدخلات!D6) -> 37203000 | S6: =IF(OR(المدخلات!B6=0,المدخلات!B6=""),"",المدخلات!D6/المدخلات!B6) -> 0.3528257 | T6: =IF(المدخلات!H6="","",المدخلات!H6) -> 66327000 | U6: =IF(المدخلات!J6="","",المدخلات!J6) -> 4536000 | V6: =IF(OR(المدخلات!H6="",المدخلات!J6=""),"",المدخلات!H6-المدخلات!J6) -> 61791000 | W6: =IF(المدخلات!I6="","",المدخلات!I6) -> 5156 | X6: =IF(المدخلات!K6="","",المدخلات!K6) -> 12826 | Y6: =IF(OR(المدخلات!I6="",المدخلات!K6=""),"",المدخلات!I6-المدخلات!K6) -> -7670 | Z6: =IF(الحسابات!L5="","",الحسابات!L5) -> 0 | AA6: =IF(الحسابات!M5="","",الحسابات!M5) -> 0 | AB6: =IF(الحسابات!N5="","",الحسابات!N5) -> 68240000
Q7: =المدخلات!A7 -> أبريل | R7: =IF(المدخلات!D7="","",المدخلات!D7) -> 38371000 | S7: =IF(OR(المدخلات!B7=0,المدخلات!B7=""),"",المدخلات!D7/المدخلات!B7) -> 0.23019239 | T7: =IF(المدخلات!H7="","",المدخلات!H7) -> 70574000 | U7: =IF(المدخلات!J7="","",المدخلات!J7) -> 5924000 | V7: =IF(OR(المدخلات!H7="",المدخلات!J7=""),"",المدخلات!H7-المدخلات!J7) -> 64650000 | W7: =IF(المدخلات!I7="","",المدخلات!I7) -> 7360 | X7: =IF(المدخلات!K7="","",المدخلات!K7) -> 11459 | Y7: =IF(OR(المدخلات!I7="",المدخلات!K7=""),"",المدخلات!I7-المدخلات!K7) -> -4099 | Z7: =IF(الحسابات!L6="","",الحسابات!L6) -> 0 | AA7: =IF(الحسابات!M6="","",الحسابات!M6) -> 0 | AB7: =IF(الحسابات!N6="","",الحسابات!N6) -> 128320000
Q8: =المدخلات!A8 -> مايو | R8: =IF(المدخلات!D8="","",المدخلات!D8) -> 26000000 | S8: =IF(OR(المدخلات!B8=0,المدخلات!B8=""),"",المدخلات!D8/المدخلات!B8) -> 0.15918302 | T8: =IF(المدخلات!H8="","",المدخلات!H8) -> 35913000 | U8: =IF(المدخلات!J8="","",المدخلات!J8) -> 8730000 | V8: =IF(OR(المدخلات!H8="",المدخلات!J8=""),"",المدخلات!H8-المدخلات!J8) -> 27183000 | W8: =IF(المدخلات!I8="","",المدخلات!I8) -> 6270 | X8: =IF(المدخلات!K8="","",المدخلات!K8) -> 5679 | Y8: =IF(OR(المدخلات!I8="",المدخلات!K8=""),"",المدخلات!I8-المدخلات!K8) -> 591 | Z8: =IF(الحسابات!L7="","",الحسابات!L7) -> 0 | AA8: =IF(الحسابات!M7="","",الحسابات!M7) -> 0 | AB8: =IF(الحسابات!N7="","",الحسابات!N7) -> 137334000
Q9: =المدخلات!A9 -> يونيو | R9: =IF(المدخلات!D9="","",المدخلات!D9) -> 32391000 | S9: =IF(OR(المدخلات!B9=0,المدخلات!B9=""),"",المدخلات!D9/المدخلات!B9) -> 0.1640682 | T9: =IF(المدخلات!H9="","",المدخلات!H9) -> 35652000 | U9: =IF(المدخلات!J9="","",المدخلات!J9) -> 6647000 | V9: =IF(OR(المدخلات!H9="",المدخلات!J9=""),"",المدخلات!H9-المدخلات!J9) -> 29005000 | W9: =IF(المدخلات!I9="","",المدخلات!I9) -> 11283 | X9: =IF(المدخلات!K9="","",المدخلات!K9) -> 5101 | Y9: =IF(OR(المدخلات!I9="",المدخلات!K9=""),"",المدخلات!I9-المدخلات!K9) -> 6182 | Z9: =IF(الحسابات!L8="","",الحسابات!L8) -> 4.7082131e+08 | AA9: =IF(الحسابات!M8="","",الحسابات!M8) -> 0 | AB9: =IF(الحسابات!N8="","",الحسابات!N8) -> 165033000
Q10: =المدخلات!A10 -> يوليو | R10: =IF(المدخلات!D10="","",المدخلات!D10) -> 29190000 | S10: =IF(OR(المدخلات!B10=0,المدخلات!B10=""),"",المدخلات!D10/المدخلات!B10) -> 0.15279363 | T10: =IF(المدخلات!H10="","",المدخلات!H10) -> 46227000 | U10: =IF(المدخلات!J10="","",المدخلات!J10) -> 8341000 | V10: =IF(OR(المدخلات!H10="",المدخلات!J10=""),"",المدخلات!H10-المدخلات!J10) -> 37886000 | W10: =IF(المدخلات!I10="","",المدخلات!I10) -> 10118 | X10: =IF(المدخلات!K10="","",المدخلات!K10) -> 7147 | Y10: =IF(OR(المدخلات!I10="",المدخلات!K10=""),"",المدخلات!I10-المدخلات!K10) -> 2971 | Z10: =IF(الحسابات!L9="","",الحسابات!L9) -> 5.3775681e+08 | AA10: =IF(الحسابات!M9="","",الحسابات!M9) -> 25442362 | AB10: =IF(الحسابات!N9="","",الحسابات!N9) -> 1.3640964e+08
Q11: =المدخلات!A11 -> أغسطس | R11: =IF(المدخلات!D11="","",المدخلات!D11) | S11: =IF(OR(المدخلات!B11=0,المدخلات!B11=""),"",المدخلات!D11/المدخلات!B11) | T11: =IF(المدخلات!H11="","",المدخلات!H11) | U11: =IF(المدخلات!J11="","",المدخلات!J11) | V11: =IF(OR(المدخلات!H11="",المدخلات!J11=""),"",المدخلات!H11-المدخلات!J11) | W11: =IF(المدخلات!I11="","",المدخلات!I11) | X11: =IF(المدخلات!K11="","",المدخلات!K11) | Y11: =IF(OR(المدخلات!I11="",المدخلات!K11=""),"",المدخلات!I11-المدخلات!K11) | Z11: =IF(الحسابات!L10="","",الحسابات!L10) | AA11: =IF(الحسابات!M10="","",الحسابات!M10) | AB11: =IF(الحسابات!N10="","",الحسابات!N10)
Q12: =المدخلات!A12 -> سبتمبر | R12: =IF(المدخلات!D12="","",المدخلات!D12) | S12: =IF(OR(المدخلات!B12=0,المدخلات!B12=""),"",المدخلات!D12/المدخلات!B12) | T12: =IF(المدخلات!H12="","",المدخلات!H12) | U12: =IF(المدخلات!J12="","",المدخلات!J12) | V12: =IF(OR(المدخلات!H12="",المدخلات!J12=""),"",المدخلات!H12-المدخلات!J12) | W12: =IF(المدخلات!I12="","",المدخلات!I12) | X12: =IF(المدخلات!K12="","",المدخلات!K12) | Y12: =IF(OR(المدخلات!I12="",المدخلات!K12=""),"",المدخلات!I12-المدخلات!K12) | Z12: =IF(الحسابات!L11="","",الحسابات!L11) | AA12: =IF(الحسابات!M11="","",الحسابات!M11) | AB12: =IF(الحسابات!N11="","",الحسابات!N11)
Q13: =المدخلات!A13 -> أكتوبر | R13: =IF(المدخلات!D13="","",المدخلات!D13) | S13: =IF(OR(المدخلات!B13=0,المدخلات!B13=""),"",المدخلات!D13/المدخلات!B13) | T13: =IF(المدخلات!H13="","",المدخلات!H13) | U13: =IF(المدخلات!J13="","",المدخلات!J13) | V13: =IF(OR(المدخلات!H13="",المدخلات!J13=""),"",المدخلات!H13-المدخلات!J13) | W13: =IF(المدخلات!I13="","",المدخلات!I13) | X13: =IF(المدخلات!K13="","",المدخلات!K13) | Y13: =IF(OR(المدخلات!I13="",المدخلات!K13=""),"",المدخلات!I13-المدخلات!K13) | Z13: =IF(الحسابات!L12="","",الحسابات!L12) | AA13: =IF(الحسابات!M12="","",الحسابات!M12) | AB13: =IF(الحسابات!N12="","",الحسابات!N12)
Q14: =المدخلات!A14 -> نوفمبر | R14: =IF(المدخلات!D14="","",المدخلات!D14) | S14: =IF(OR(المدخلات!B14=0,المدخلات!B14=""),"",المدخلات!D14/المدخلات!B14) | T14: =IF(المدخلات!H14="","",المدخلات!H14) | U14: =IF(المدخلات!J14="","",المدخلات!J14) | V14: =IF(OR(المدخلات!H14="",المدخلات!J14=""),"",المدخلات!H14-المدخلات!J14) | W14: =IF(المدخلات!I14="","",المدخلات!I14) | X14: =IF(المدخلات!K14="","",المدخلات!K14) | Y14: =IF(OR(المدخلات!I14="",المدخلات!K14=""),"",المدخلات!I14-المدخلات!K14) | Z14: =IF(الحسابات!L13="","",الحسابات!L13) | AA14: =IF(الحسابات!M13="","",الحسابات!M13) | AB14: =IF(الحسابات!N13="","",الحسابات!N13)
Q15: =المدخلات!A15 -> ديسمبر | R15: =IF(المدخلات!D15="","",المدخلات!D15) | S15: =IF(OR(المدخلات!B15=0,المدخلات!B15=""),"",المدخلات!D15/المدخلات!B15) | T15: =IF(المدخلات!H15="","",المدخلات!H15) | U15: =IF(المدخلات!J15="","",المدخلات!J15) | V15: =IF(OR(المدخلات!H15="",المدخلات!J15=""),"",المدخلات!H15-المدخلات!J15) | W15: =IF(المدخلات!I15="","",المدخلات!I15) | X15: =IF(المدخلات!K15="","",المدخلات!K15) | Y15: =IF(OR(المدخلات!I15="",المدخلات!K15=""),"",المدخلات!I15-المدخلات!K15) | Z15: =IF(الحسابات!L14="","",الحسابات!L14) | AA15: =IF(الحسابات!M14="","",الحسابات!M14) | AB15: =IF(الحسابات!N14="","",الحسابات!N14)
A56: 📦 قيمة المخزون | 🧾 تكلفة المواد المستهلكة | 💚 صافي الربح الحقيقي — مبنية على أرشيف المخزون الفعلي وليس على المشتريات

Sheet تقرير السيولة
A1: 💧 تقرير السيولة
A2: ="📅 تقرير شهر: "&IFERROR(LOOKUP(2,1/(المدخلات!B4:B15<>""),المدخلات!A4:A15),"") -> 📅 تقرير شهر: يوليو
A4: 🇸🇾 السيولة بالليرة السورية
A5: البيان | B5: المبلغ | C5: الوضع | D5: ملاحظة
A6: المبيعات | B6: =IFERROR(LOOKUP(2,1/(المدخلات!B4:B15<>""),المدخلات!B4:B15),"") -> 191042000 | C6: =IF(B6="","",IF(B6>0,"✅","🔴")) -> ✅
A7: المشتريات | B7: =IFERROR(LOOKUP(2,1/(المدخلات!B4:B15<>""),المدخلات!C4:C15),"") -> 140673000 | C7: =IF(B7="","",IF(B7>0,"✅","🔴")) -> ✅
A8: المصاريف | B8: =IFERROR(LOOKUP(2,1/(المدخلات!B4:B15<>""),المدخلات!D4:D15),"") -> 29190000 | C8: =IF(B8="","",IF(B8>0,"✅","🔴")) -> ✅
A9: الربح التشغيلي | B9: =IFERROR(LOOKUP(2,1/(المدخلات!B4:B15<>""),الحسابات!B3:B14),"") -> 21179000 | C9: =IF(B9="","",IF(B9>0,"✅","🔴")) -> ✅
A10: كاش الصندوق | B10: =IFERROR(LOOKUP(2,1/(المدخلات!B4:B15<>""),المدخلات!F4:F15),"") -> 4287000 | C10: =IF(B10="","",IF(B10>0,"✅","🔴")) -> ✅
A11: ديون لنا | B11: =IFERROR(LOOKUP(2,1/(المدخلات!B4:B15<>""),المدخلات!H4:H15),"") -> 46227000 | C11: =IF(B11="","",IF(B11>0,"✅","🔴")) -> ✅
A12: ديون علينا | B12: =IFERROR(LOOKUP(2,1/(المدخلات!B4:B15<>""),المدخلات!J4:J15),"") -> 8341000 | C12: =IF(B12="","",IF(B12>0,"✅","🔴")) -> ✅
A13: صافي الدين | B13: =IFERROR(LOOKUP(2,1/(المدخلات!B4:B15<>""),الحسابات!H3:H14),"") -> 37886000 | C13: =IF(B13="","",IF(B13>0,"✅","🔴")) -> ✅
A15: 🇺🇸 السيولة بالدولار الأمريكي
A16: البيان | B16: المبلغ | C16: الوضع | D16: ملاحظة
A17: كاش الصندوق | B17: =IFERROR(LOOKUP(2,1/(المدخلات!B4:B15<>""),المدخلات!G4:G15),"") -> 330 | C17: =IF(B17="","",IF(B17>0,"✅","🔴")) -> ✅
A18: ديون لنا | B18: =IFERROR(LOOKUP(2,1/(المدخلات!B4:B15<>""),المدخلات!I4:I15),"") -> 10118 | C18: =IF(B18="","",IF(B18>0,"✅","🔴")) -> ✅
A19: ديون علينا | B19: =IFERROR(LOOKUP(2,1/(المدخلات!B4:B15<>""),المدخلات!K4:K15),"") -> 7147 | C19: =IF(B19="","",IF(B19>0,"✅","🔴")) -> ✅
A20: صافي الدين | B20: =IFERROR(LOOKUP(2,1/(المدخلات!B4:B15<>""),الحسابات!I3:I14),"") -> 2971 | C20: =IF(B20="","",IF(B20>0,"✅","🔴")) -> ✅

Sheet استيراد بيانات الشهر
A1: 📥 استيراد بيانات الشهر (من برنامج المحاسبة)
A2: 💡 خطوات الاستيراد كل شهر: 1) عبّئ مفتاح الشهر واسم الشهر أدناه. 2) الصق تقرير الأصناف بالكامل من برنامج المحاسبة في A7 بنفس أعمدته التسعة (اسم الصنف، الكمية، سعر الجملة، القطاعي، جملة الجملة، العملة، الفئة، الفئة الفرعية، الشراء) دون أي تعديل بالترتيب — العمود المعتمد كسعر شراء للمخزون هو عمود "الشراء". 3) تأكد أن عمود "فحص" (L) يظهر ✅ لكل الأصناف. 4) انسخ النطاق المُجهّز للأرشفة N7:S(آخر صف) والصقه (قيم فقط) أسفل آخر صف مستخدم في جدول "أرشيف المخزون" — هذه هي خطوة الأرشفة الوحيدة التي تحافظ على تاريخ كل الأشهر.
A3: مفتاح الشهر (YYYYMM): | B3: 202607
A4: اسم الشهر للعرض: | B4: يوليو 2026
N5: 📋 مُجهّز جاهز للنسخ إلى أرشيف المخزون (بنفس ترتيب أعمدة الأرشيف)
A6: اسم الصنف | B6: الكمية | C6: سعر الجملة | D6: القطاعي | E6: جملة الجملة | F6: العملة | G6: الفــئة | H6: الفــئة الفرعية | I6: الشراء | J6: مفتاح الشهر (تلقائي) | K6: اسم الشهر (تلقائي) | L6: فحص | N6: مفتاح الشهر | O6: اسم الشهر | P6: اسم المادة | Q6: الكمية | R6: سعر الشراء | S6: العملة
A7: مياه مقطرة 4 لتر | B7: 0 | C7: 6000 | D7: 6000 | E7: 6000 | F7: ليرة سورية | G7: All | H7: مواد جاهزة للبيع | I7: 3250 | J7: =IF($B$3="","",$B$3) -> 202607 | K7: =IF($B$4="","",$B$4) -> يوليو 2026 | L7: =IF(A7="","",IF(OR(B7="",B7=0),"⚠️ كمية مفقودة/صفر",IF(I7="","⚠️ سعر شراء مفقود",IF(F7="","⚠️ عملة مفقودة",IF(COUNTIF($A$7:$A$505,A7)>1,"⚠️ مادة مكررة بالقائمة","✅ جاهز"))))) -> ⚠️ كمية مفقودة/صفر | N7: =J7 -> 202607 | O7: =K7 -> يوليو 2026 | P7: =A7 -> مياه مقطرة 4 لتر | Q7: =B7 -> 0 | R7: =I7 -> 3250 | S7: =F7 -> ليرة سورية
A8: مياه مقطرة 1 لتر | B8: 0 | C8: 1800 | D8: 1800 | E8: 1800 | F8: ليرة سورية | G8: All | H8: مواد جاهزة للبيع | I8: 1700 | J8: =IF($B$3="","",$B$3) -> 202607 | K8: =IF($B$4="","",$B$4) -> يوليو 2026 | L8: =IF(A8="","",IF(OR(B8="",B8=0),"⚠️ كمية مفقودة/صفر",IF(I8="","⚠️ سعر شراء مفقود",IF(F8="","⚠️ عملة مفقودة",IF(COUNTIF($A$7:$A$505,A8)>1,"⚠️ مادة مكررة بالقائمة","✅ جاهز"))))) -> ⚠️ كمية مفقودة/صفر | N8: =J8 -> 202607 | O8: =K8 -> يوليو 2026 | P8: =A8 -> مياه مقطرة 1 لتر | Q8: =B8 -> 0 | R8: =I8 -> 1700 | S8: =F8 -> ليرة سورية
A9: مهسهس زفته - معجون | B9: 12 | C9: 14000 | D9: 14000 | E9: 14000 | F9: ليرة سورية | G9: All | H9: مواد جاهزة للبيع | I9: 10000 | J9: =IF($B$3="","",$B$3) -> 202607 | K9: =IF($B$4="","",$B$4) -> يوليو 2026 | L9: =IF(A9="","",IF(OR(B9="",B9=0),"⚠️ كمية مفقودة/صفر",IF(I9="","⚠️ سعر شراء مفقود",IF(F9="","⚠️ عملة مفقودة",IF(COUNTIF($A$7:$A$505,A9)>1,"⚠️ مادة مكررة بالقائمة","✅ جاهز"))))) -> ✅ جاهز | N9: =J9 -> 202607 | O9: =K9 -> يوليو 2026 | P9: =A9 -> مهسهس زفته - معجون | Q9: =B9 -> 12 | R9: =I9 -> 10000 | S9: =F9 -> ليرة سورية
A10: مماسح مكتب َ | B10: 5.15 | C10: 220000 | D10: 220000 | E10: 220000 | F10: ليرة سورية | G10: All | H10: مواد جاهزة للبيع | I10: 108000 | J10: =IF($B$3="","",$B$3) -> 202607 | K10: =IF($B$4="","",$B$4) -> يوليو 2026 | L10: =IF(A10="","",IF(OR(B10="",B10=0),"⚠️ كمية مفقودة/صفر",IF(I10="","⚠️ سعر شراء مفقود",IF(F10="","⚠️ عملة مفقودة",IF(COUNTIF($A$7:$A$505,A10)>1,"⚠️ مادة مكررة بالقائمة","✅ جاهز"))))) -> ✅ جاهز | N10: =J10 -> 202607 | O10: =K10 -> يوليو 2026 | P10: =A10 -> مماسح مكتب َ | Q10: =B10 -> 5.15 | R10: =I10 -> 108000 | S10: =F10 -> ليرة سورية
A11: مماسح قماش عائلة فايبر | B11: 0 | C11: 420000 | D11: 420000 | E11: 420000 | F11: ليرة سورية | G11: All | H11: مواد جاهزة للبيع | I11: 360000 | J11: =IF($B$3="","",$B$3) -> 202607 | K11: =IF($B$4="","",$B$4) -> يوليو 2026 | L11: =IF(A11="","",IF(OR(B11="",B11=0),"⚠️ كمية مفقودة/صفر",IF(I11="","⚠️ سعر شراء مفقود",IF(F11="","⚠️ عملة مفقودة",IF(COUNTIF($A$7:$A$505,A11)>1,"⚠️ مادة مكررة بالقائمة","✅ جاهز"))))) -> ⚠️ كمية مفقودة/صفر | N11: =J11 -> 202607 | O11: =K11 -> يوليو 2026 | P11: =A11 -> مماسح قماش عائلة فايبر | Q11: =B11 -> 0 | R11: =I11 -> 360000 | S11: =F11 -> ليرة سورية
A12: مماسح جلدية | B12: 0 | C12: 0 | D12: 0 | E12: 0 | F12: ليرة سورية | G12: All | H12: All | I12: 25000 | J12: =IF($B$3="","",$B$3) -> 202607 | K12: =IF($B$4="","",$B$4) -> يوليو 2026 | L12: =IF(A12="","",IF(OR(B12="",B12=0),"⚠️ كمية مفقودة/صفر",IF(I12="","⚠️ سعر شراء مفقود",IF(F12="","⚠️ عملة مفقودة",IF(COUNTIF($A$7:$A$505,A12)>1,"⚠️ مادة مكررة بالقائمة","✅ جاهز"))))) -> ⚠️ كمية مفقودة/صفر | N12: =J12 -> 202607 | O12: =K12 -> يوليو 2026 | P12: =A12 -> مماسح جلدية | Q12: =B12 -> 0 | R12: =I12 -> 25000 | S12: =F12 -> ليرة سورية
A13: مماسح بلور | B13: 27 | C13: 13000 | D13: 13000 | E13: 13000 | F13: ليرة سورية | G13: All | H13: مواد جاهزة للبيع | I13: 50000 | J13: =IF($B$3="","",$B$3) -> 202607 | K13: =IF($B$4="","",$B$4) -> يوليو 2026 | L13: =IF(A13="","",IF(OR(B13="",B13=0),"⚠️ كمية مفقودة/صفر",IF(I13="","⚠️ سعر شراء مفقود",IF(F13="","⚠️ عملة مفقودة",IF(COUNTIF($A$7:$A$505,A13)>1,"⚠️ مادة مكررة بالقائمة","✅ جاهز"))))) -> ✅ جاهز | N13: =J13 -> 202607 | O13: =K13 -> يوليو 2026 | P13: =A13 -> مماسح بلور | Q13: =B13 -> 27 | R13: =I13 -> 50000 | S13: =F13 -> ليرة سورية
A14: مماسح ارضيات | B14: 9.42 | C14: 110000 | D14: 110000 | E14: 110000 | F14: ليرة سورية | G14: All | H14: مواد جاهزة للبيع | I14: 72000 | J14: =IF($B$3="","",$B$3) -> 202607 | K14: =IF($B$4="","",$B$4) -> يوليو 2026 | L14: =IF(A14="","",IF(OR(B14="",B14=0),"⚠️ كمية مفقودة/صفر",IF(I14="","⚠️ سعر شراء مفقود",IF(F14="","⚠️ عملة مفقودة",IF(COUNTIF($A$7:$A$505,A14)>1,"⚠️ مادة مكررة بالقائمة","✅ جاهز"))))) -> ✅ جاهز | N14: =J14 -> 202607 | O14: =K14 -> يوليو 2026 | P14: =A14 -> مماسح ارضيات | Q14: =B14 -> 9.42 | R14: =I14 -> 72000 | S14: =F14 -> ليرة سورية
A15: ملمع سيارات 3 لتر | B15: 0 | C15: 35000 | D15: 35000 | E15: 35000 | F15: ليرة سورية | G15: All | H15: مواد جاهزة للبيع | I15: 28000 | J15: =IF($B$3="","",$B$3) -> 202607 | K15: =IF($B$4="","",$B$4) -> يوليو 2026 | L15: =IF(A15="","",IF(OR(B15="",B15=0),"⚠️ كمية مفقودة/صفر",IF(I15="","⚠️ سعر شراء مفقود",IF(F15="","⚠️ عملة مفقودة",IF(COUNTIF($A$7:$A$505,A15)>1,"⚠️ مادة مكررة بالقائمة","✅ جاهز"))))) -> ⚠️ كمية مفقودة/صفر | N15: =J15 -> 202607 | O15: =K15 -> يوليو 2026 | P15: =A15 -> ملمع سيارات 3 لتر | Q15: =B15 -> 0 | R15: =I15 -> 28000 | S15: =F15 -> ليرة سورية
A16: ملمع سيارات / فرط | B16: 8 | C16: 15000 | D16: 15000 | E16: 15000 | F16: ليرة سورية | G16: All | H16: مواد جاهزة للبيع | I16: 8500 | J16: =IF($B$3="","",$B$3) -> 202607 | K16: =IF($B$4="","",$B$4) -> يوليو 2026 | L16: =IF(A16="","",IF(OR(B16="",B16=0),"⚠️ كمية مفقودة/صفر",IF(I16="","⚠️ سعر شراء مفقود",IF(F16="","⚠️ عملة مفقودة",IF(COUNTIF($A$7:$A$505,A16)>1,"⚠️ مادة مكررة بالقائمة","✅ جاهز"))))) -> ✅ جاهز | N16: =J16 -> 202607 | O16: =K16 -> يوليو 2026 | P16: =A16 -> ملمع سيارات / فرط | Q16: =B16 -> 8 | R16: =I16 -> 8500 | S16: =F16 -> ليرة سورية
A17: ملمع زجاج خام | B17: 0 | C17: 0 | D17: 0 | E17: 0 | F17: دولار أمريكي | G17: All | H17: الطبخات | I17: 175 | J17: =IF($B$3="","",$B$3) -> 202607 | K17: =IF($B$4="","",$B$4) -> يوليو 2026 | L17: =IF(A17="","",IF(OR(B17="",B17=0),"⚠️ كمية مفقودة/صفر",IF(I17="","⚠️ سعر شراء مفقود",IF(F17="","⚠️ عملة مفقودة",IF(COUNTIF($A$7:$A$505,A17)>1,"⚠️ مادة مكررة بالقائمة","✅ جاهز"))))) -> ⚠️ كمية مفقودة/صفر | N17: =J17 -> 202607 | O17: =K17 -> يوليو 2026 | P17: =A17 -> ملمع زجاج خام | Q17: =B17 -> 0 | R17: =I17 -> 175 | S17: =F17 -> دولار أمريكي
A18: ملمع زجاج الكرمل | B18: 0 | C18: 156000 | D18: 156000 | E18: 156000 | F18: ليرة سورية | G18: All | H18: مواد جاهزة للبيع | I18: 120000 | J18: =IF($B$3="","",$B$3) -> 202607 | K18: =IF($B$4="","",$B$4) -> يوليو 2026 | L18: =IF(A18="","",IF(OR(B18="",B18=0),"⚠️ كمية مفقودة/صفر",IF(I18="","⚠️ سعر شراء مفقود",IF(F18="","⚠️ عملة مفقودة",IF(COUNTIF($A$7:$A$505,A18)>1,"⚠️ مادة مكررة بالقائمة","✅ جاهز"))))) -> ⚠️ كمية مفقودة/صفر | N18: =J18 -> 202607 | O18: =K18 -> يوليو 2026 | P18: =A18 -> ملمع زجاج الكرمل | Q18: =B18 -> 0 | R18: =I18 -> 120000 | S18: =F18 -> ليرة سورية
... A246: أسيد 1 لتر | B246: 0 | C246: 5500 | D246: 5500 | E246: 5500 | F246: ليرة سورية | G246: All | H246: مواد جاهزة للبيع | I246: 3500 | J246: =IF($B$3="","",$B$3) -> 202607 | K246: =IF($B$4="","",$B$4) -> يوليو 2026 | L246: =IF(A246="","",IF(OR(B246="",B246=0),"⚠️ كمية مفقودة/صفر",IF(I246="","⚠️ سعر شراء مفقود",IF(F246="","⚠️ عملة مفقودة",IF(COUNTIF($A$7:$A$505,A246)>1,"⚠️ مادة مكررة بالقائمة","✅ جاهز"))))) -> ⚠️ كمية مفقودة/صفر | N246: =J246 -> 202607 | O246: =K246 -> يوليو 2026 | P246: =A246 -> أسيد 1 لتر | Q246: =B246 -> 0 | R246: =I246 -> 3500 | S246: =F246 -> ليرة سورية
J247: =IF($B$3="","",$B$3) -> 202607 | K247: =IF($B$4="","",$B$4) -> يوليو 2026 | L247: =IF(A247="","",IF(OR(B247="",B247=0),"⚠️ كمية مفقودة/صفر",IF(I247="","⚠️ سعر شراء مفقود",IF(F247="","⚠️ عملة مفقودة",IF(COUNTIF($A$7:$A$505,A247)>1,"⚠️ مادة مكررة بالقائمة","✅ جاهز"))))) | N247: =J247 -> 202607 | O247: =K247 -> يوليو 2026 | P247: =A247 -> 0 | Q247: =B247 -> 0 | R247: =I247 -> 0 | S247: =F247 -> 0
J248: =IF($B$3="","",$B$3) -> 202607 | K248: =IF($B$4="","",$B$4) -> يوليو 2026 | L248: =IF(A248="","",IF(OR(B248="",B248=0),"⚠️ كمية مفقودة/صفر",IF(I248="","⚠️ سعر شراء مفقود",IF(F248="","⚠️ عملة مفقودة",IF(COUNTIF($A$7:$A$505,A248)>1,"⚠️ مادة مكررة بالقائمة","✅ جاهز"))))) | N248: =J248 -> 202607 | O248: =K248 -> يوليو 2026 | P248: =A248 -> 0 | Q248: =B248 -> 0 | R248: =I248 -> 0 | S248: =F248 -> 0
J249: =IF($B$3="","",$B$3) -> 202607 | K249: =IF($B$4="","",$B$4) -> يوليو 2026 | L249: =IF(A249="","",IF(OR(B249="",B249=0),"⚠️ كمية مفقودة/صفر",IF(I249="","⚠️ سعر شراء مفقود",IF(F249="","⚠️ عملة مفقودة",IF(COUNTIF($A$7:$A$505,A249)>1,"⚠️ مادة مكررة بالقائمة","✅ جاهز"))))) | N249: =J249 -> 202607 | O249: =K249 -> يوليو 2026 | P249: =A249 -> 0 | Q249: =B249 -> 0 | R249: =I249 -> 0 | S249: =F249 -> 0
J250: =IF($B$3="","",$B$3) -> 202607 | K250: =IF($B$4="","",$B$4) -> يوليو 2026 | L250: =IF(A250="","",IF(OR(B250="",B250=0),"⚠️ كمية مفقودة/صفر",IF(I250="","⚠️ سعر شراء مفقود",IF(F250="","⚠️ عملة مفقودة",IF(COUNTIF($A$7:$A$505,A250)>1,"⚠️ مادة مكررة بالقائمة","✅ جاهز"))))) | N250: =J250 -> 202607 | O250: =K250 -> يوليو 2026 | P250: =A250 -> 0 | Q250: =B250 -> 0 | R250: =I250 -> 0 | S250: =F250 -> 0
J251: =IF($B$3="","",$B$3) -> 202607 | K251: =IF($B$4="","",$B$4) -> يوليو 2026 | L251: =IF(A251="","",IF(OR(B251="",B251=0),"⚠️ كمية مفقودة/صفر",IF(I251="","⚠️ سعر شراء مفقود",IF(F251="","⚠️ عملة مفقودة",IF(COUNTIF($A$7:$A$505,A251)>1,"⚠️ مادة مكررة بالقائمة","✅ جاهز"))))) | N251: =J251 -> 202607 | O251: =K251 -> يوليو 2026 | P251: =A251 -> 0 | Q251: =B251 -> 0 | R251: =I251 -> 0 | S251: =F251 -> 0
J252: =IF($B$3="","",$B$3) -> 202607 | K252: =IF($B$4="","",$B$4) -> يوليو 2026 | L252: =IF(A252="","",IF(OR(B252="",B252=0),"⚠️ كمية مفقودة/صفر",IF(I252="","⚠️ سعر شراء مفقود",IF(F252="","⚠️ عملة مفقودة",IF(COUNTIF($A$7:$A$505,A252)>1,"⚠️ مادة مكررة بالقائمة","✅ جاهز"))))) | N252: =J252 -> 202607 | O252: =K252 -> يوليو 2026 | P252: =A252 -> 0 | Q252: =B252 -> 0 | R252: =I252 -> 0 | S252: =F252 -> 0
J253: =IF($B$3="","",$B$3) -> 202607 | K253: =IF($B$4="","",$B$4) -> يوليو 2026 | L253: =IF(A253="","",IF(OR(B253="",B253=0),"⚠️ كمية مفقودة/صفر",IF(I253="","⚠️ سعر شراء مفقود",IF(F253="","⚠️ عملة مفقودة",IF(COUNTIF($A$7:$A$505,A253)>1,"⚠️ مادة مكررة بالقائمة","✅ جاهز"))))) | N253: =J253 -> 202607 | O253: =K253 -> يوليو 2026 | P253: =A253 -> 0 | Q253: =B253 -> 0 | R253: =I253 -> 0 | S253: =F253 -> 0
J254: =IF($B$3="","",$B$3) -> 202607 | K254: =IF($B$4="","",$B$4) -> يوليو 2026 | L254: =IF(A254="","",IF(OR(B254="",B254=0),"⚠️ كمية مفقودة/صفر",IF(I254="","⚠️ سعر شراء مفقود",IF(F254="","⚠️ عملة مفقودة",IF(COUNTIF($A$7:$A$505,A254)>1,"⚠️ مادة مكررة بالقائمة","✅ جاهز"))))) | N254: =J254 -> 202607 | O254: =K254 -> يوليو 2026 | P254: =A254 -> 0 | Q254: =B254 -> 0 | R254: =I254 -> 0 | S254: =F254 -> 0
J255: =IF($B$3="","",$B$3) -> 202607 | K255: =IF($B$4="","",$B$4) -> يوليو 2026 | L255: =IF(A255="","",IF(OR(B255="",B255=0),"⚠️ كمية مفقودة/صفر",IF(I255="","⚠️ سعر شراء مفقود",IF(F255="","⚠️ عملة مفقودة",IF(COUNTIF($A$7:$A$505,A255)>1,"⚠️ مادة مكررة بالقائمة","✅ جاهز"))))) | N255: =J255 -> 202607 | O255: =K255 -> يوليو 2026 | P255: =A255 -> 0 | Q255: =B255 -> 0 | R255: =I255 -> 0 | S255: =F255 -> 0
J256: =IF($B$3="","",$B$3) -> 202607 | K256: =IF($B$4="","",$B$4) -> يوليو 2026 | L256: =IF(A256="","",IF(OR(B256="",B256=0),"⚠️ كمية مفقودة/صفر",IF(I256="","⚠️ سعر شراء مفقود",IF(F256="","⚠️ عملة مفقودة",IF(COUNTIF($A$7:$A$505,A256)>1,"⚠️ مادة مكررة بالقائمة","✅ جاهز"))))) | N256: =J256 -> 202607 | O256: =K256 -> يوليو 2026 | P256: =A256 -> 0 | Q256: =B256 -> 0 | R256: =I256 -> 0 | S256: =F256 -> 0
J257: =IF($B$3="","",$B$3) -> 202607 | K257: =IF($B$4="","",$B$4) -> يوليو 2026 | L257: =IF(A257="","",IF(OR(B257="",B257=0),"⚠️ كمية مفقودة/صفر",IF(I257="","⚠️ سعر شراء مفقود",IF(F257="","⚠️ عملة مفقودة",IF(COUNTIF($A$7:$A$505,A257)>1,"⚠️ مادة مكررة بالقائمة","✅ جاهز"))))) | N257: =J257 -> 202607 | O257: =K257 -> يوليو 2026 | P257: =A257 -> 0 | Q257: =B257 -> 0 | R257: =I257 -> 0 | S257: =F257 -> 0
J258: =IF($B$3="","",$B$3) -> 202607 | K258: =IF($B$4="","",$B$4) -> يوليو 2026 | L258: =IF(A258="","",IF(OR(B258="",B258=0),"⚠️ كمية مفقودة/صفر",IF(I258="","⚠️ سعر شراء مفقود",IF(F258="","⚠️ عملة مفقودة",IF(COUNTIF($A$7:$A$505,A258)>1,"⚠️ مادة مكررة بالقائمة","✅ جاهز"))))) | N258: =J258 -> 202607 | O258: =K258 -> يوليو 2026 | P258: =A258 -> 0 | Q258: =B258 -> 0 | R258: =I258 -> 0 | S258: =F258 -> 0
... J505: =IF($B$3="","",$B$3) -> 202607 | K505: =IF($B$4="","",$B$4) -> يوليو 2026 | L505: =IF(A505="","",IF(OR(B505="",B505=0),"⚠️ كمية مفقودة/صفر",IF(I505="","⚠️ سعر شراء مفقود",IF(F505="","⚠️ عملة مفقودة",IF(COUNTIF($A$7:$A$505,A505)>1,"⚠️ مادة مكررة بالقائمة","✅ جاهز"))))) | N505: =J505 -> 202607 | O505: =K505 -> يوليو 2026 | P505: =A505 -> 0 | Q505: =B505 -> 0 | R505: =I505 -> 0 | S505: =F505 -> 0

Sheet أرشيف المخزون
A1: 🗄️ أرشيف المخزون — السجل التاريخي الدائم
A2: 💡 هذا الجدول يحفظ بيانات كل شهر بشكل دائم (لا يُحذف عند استيراد شهر جديد). كل شهر جديد = صفوف جديدة تُضاف أسفل آخر صف مستخدم. الصق فقط في الأعمدة A:F (القيم، وليس المعادلات) من صفحة "استيراد بيانات الشهر". بقية الأعمدة (G:L) محسوبة تلقائياً ومُجهّزة مسبقاً لعدد كبير من الصفوف.
A4: مفتاح الشهر | B4: اسم الشهر | C4: اسم المادة | D4: الكمية | E4: سعر الشراء | F4: العملة | G4: قيمة المادة | H4: آخر مفتاح شهر سابق* | I4: الكمية بالشهر السابق | J4: الكمية المستهلكة | K4: تكلفة المواد المستهلكة | L4: ملاحظة/فحص | M4: سعر الصرف المستخدم | N4: قيمة المادة (موحدة ل.س) | O4: تكلفة الاستهلاك (موحدة ل.س)
A5: 202606 | B5: يونيو 2026 | C5: ملمع زجاج خام | D5: 0 | E5: 175 | F5: دولار أمريكي | G5: =IF(OR(D5="",E5=""),"",D5*E5) -> 0 | H5: =IF(C5="","",IFERROR(_xlfn.MAXIFS($A$5:$A$2003,$C$5:$C$2003,C5,$A$5:$A$2003,"<"&A5),0)) -> 0 | I5: =IF(OR(H5="",H5=0),"",IFERROR(SUMIFS($D$5:$D$2003,$C$5:$C$2003,C5,$A$5:$A$2003,H5),"")) | J5: =IF(C5="","",IF(I5="",0,MAX(I5-D5,0))) -> 0 | K5: =IF(J5="","",J5*E5) -> 0 | L5: =IF(C5="","",IF(COUNTIFS($A$5:$A$2003,A5,$C$5:$C$2003,C5)>1,"⚠️ مادة مكررة بنفس الشهر",IF(OR(H5="",H5=0),"🆕 أول ظهور لهذه المادة",IF(D5>I5,"ℹ️ زيادة كمية (شراء/تصحيح) - لا تُحتسب استهلاكاً",IF(D5=I5,"➖ لا تغيير",""))))) -> 🆕 أول ظهور لهذه المادة | M5: =IF(A5="","",IFERROR(INDEX(المدخلات!$M$4:$M$15,MATCH(A5,المدخلات!$L$4:$L$15,0)),"")) -> 13300 | N5: =IF(OR(G5="",F5=""),"",IF(F5="دولار أمريكي",IF(M5="","⚠️ لا يوجد سعر صرف",G5*M5),G5)) -> 0 | O5: =IF(OR(K5="",F5=""),"",IF(F5="دولار أمريكي",IF(M5="","⚠️ لا يوجد سعر صرف",K5*M5),K5)) -> 0
A6: 202606 | B6: يونيو 2026 | C6: ملمع دواليب خام | D6: 0 | E6: 63 | F6: دولار أمريكي | G6: =IF(OR(D6="",E6=""),"",D6*E6) -> 0 | H6: =IF(C6="","",IFERROR(_xlfn.MAXIFS($A$5:$A$2003,$C$5:$C$2003,C6,$A$5:$A$2003,"<"&A6),0)) -> 0 | I6: =IF(OR(H6="",H6=0),"",IFERROR(SUMIFS($D$5:$D$2003,$C$5:$C$2003,C6,$A$5:$A$2003,H6),"")) | J6: =IF(C6="","",IF(I6="",0,MAX(I6-D6,0))) -> 0 | K6: =IF(J6="","",J6*E6) -> 0 | L6: =IF(C6="","",IF(COUNTIFS($A$5:$A$2003,A6,$C$5:$C$2003,C6)>1,"⚠️ مادة مكررة بنفس الشهر",IF(OR(H6="",H6=0),"🆕 أول ظهور لهذه المادة",IF(D6>I6,"ℹ️ زيادة كمية (شراء/تصحيح) - لا تُحتسب استهلاكاً",IF(D6=I6,"➖ لا تغيير",""))))) -> 🆕 أول ظهور لهذه المادة | M6: =IF(A6="","",IFERROR(INDEX(المدخلات!$M$4:$M$15,MATCH(A6,المدخلات!$L$4:$L$15,0)),"")) -> 13300 | N6: =IF(OR(G6="",F6=""),"",IF(F6="دولار أمريكي",IF(M6="","⚠️ لا يوجد سعر صرف",G6*M6),G6)) -> 0 | O6: =IF(OR(K6="",F6=""),"",IF(F6="دولار أمريكي",IF(M6="","⚠️ لا يوجد سعر صرف",K6*M6),K6)) -> 0
A7: 202606 | B7: يونيو 2026 | C7: ملح | D7: 138.04 | E7: 2.1 | F7: دولار أمريكي | G7: =IF(OR(D7="",E7=""),"",D7*E7) -> 289.884 | H7: =IF(C7="","",IFERROR(_xlfn.MAXIFS($A$5:$A$2003,$C$5:$C$2003,C7,$A$5:$A$2003,"<"&A7),0)) -> 0 | I7: =IF(OR(H7="",H7=0),"",IFERROR(SUMIFS($D$5:$D$2003,$C$5:$C$2003,C7,$A$5:$A$2003,H7),"")) | J7: =IF(C7="","",IF(I7="",0,MAX(I7-D7,0))) -> 0 | K7: =IF(J7="","",J7*E7) -> 0 | L7: =IF(C7="","",IF(COUNTIFS($A$5:$A$2003,A7,$C$5:$C$2003,C7)>1,"⚠️ مادة مكررة بنفس الشهر",IF(OR(H7="",H7=0),"🆕 أول ظهور لهذه المادة",IF(D7>I7,"ℹ️ زيادة كمية (شراء/تصحيح) - لا تُحتسب استهلاكاً",IF(D7=I7,"➖ لا تغيير",""))))) -> 🆕 أول ظهور لهذه المادة | M7: =IF(A7="","",IFERROR(INDEX(المدخلات!$M$4:$M$15,MATCH(A7,المدخلات!$L$4:$L$15,0)),"")) -> 13300 | N7: =IF(OR(G7="",F7=""),"",IF(F7="دولار أمريكي",IF(M7="","⚠️ لا يوجد سعر صرف",G7*M7),G7)) -> 3855457.2 | O7: =IF(OR(K7="",F7=""),"",IF(F7="دولار أمريكي",IF(M7="","⚠️ لا يوجد سعر صرف",K7*M7),K7)) -> 0
A8: 202606 | B8: يونيو 2026 | C8: مقصب | D8: 2 | E8: 3 | F8: دولار أمريكي | G8: =IF(OR(D8="",E8=""),"",D8*E8) -> 6 | H8: =IF(C8="","",IFERROR(_xlfn.MAXIFS($A$5:$A$2003,$C$5:$C$2003,C8,$A$5:$A$2003,"<"&A8),0)) -> 0 | I8: =IF(OR(H8="",H8=0),"",IFERROR(SUMIFS($D$5:$D$2003,$C$5:$C$2003,C8,$A$5:$A$2003,H8),"")) | J8: =IF(C8="","",IF(I8="",0,MAX(I8-D8,0))) -> 0 | K8: =IF(J8="","",J8*E8) -> 0 | L8: =IF(C8="","",IF(COUNTIFS($A$5:$A$2003,A8,$C$5:$C$2003,C8)>1,"⚠️ مادة مكررة بنفس الشهر",IF(OR(H8="",H8=0),"🆕 أول ظهور لهذه المادة",IF(D8>I8,"ℹ️ زيادة كمية (شراء/تصحيح) - لا تُحتسب استهلاكاً",IF(D8=I8,"➖ لا تغيير",""))))) -> 🆕 أول ظهور لهذه المادة | M8: =IF(A8="","",IFERROR(INDEX(المدخلات!$M$4:$M$15,MATCH(A8,المدخلات!$L$4:$L$15,0)),"")) -> 13300 | N8: =IF(OR(G8="",F8=""),"",IF(F8="دولار أمريكي",IF(M8="","⚠️ لا يوجد سعر صرف",G8*M8),G8)) -> 79800 | O8: =IF(OR(K8="",F8=""),"",IF(F8="دولار أمريكي",IF(M8="","⚠️ لا يوجد سعر صرف",K8*M8),K8)) -> 0
A9: 202606 | B9: يونيو 2026 | C9: معطر فانيليا خام | D9: 0 | E9: 44 | F9: دولار أمريكي | G9: =IF(OR(D9="",E9=""),"",D9*E9) -> 0 | H9: =IF(C9="","",IFERROR(_xlfn.MAXIFS($A$5:$A$2003,$C$5:$C$2003,C9,$A$5:$A$2003,"<"&A9),0)) -> 0 | I9: =IF(OR(H9="",H9=0),"",IFERROR(SUMIFS($D$5:$D$2003,$C$5:$C$2003,C9,$A$5:$A$2003,H9),"")) | J9: =IF(C9="","",IF(I9="",0,MAX(I9-D9,0))) -> 0 | K9: =IF(J9="","",J9*E9) -> 0 | L9: =IF(C9="","",IF(COUNTIFS($A$5:$A$2003,A9,$C$5:$C$2003,C9)>1,"⚠️ مادة مكررة بنفس الشهر",IF(OR(H9="",H9=0),"🆕 أول ظهور لهذه المادة",IF(D9>I9,"ℹ️ زيادة كمية (شراء/تصحيح) - لا تُحتسب استهلاكاً",IF(D9=I9,"➖ لا تغيير",""))))) -> 🆕 أول ظهور لهذه المادة | M9: =IF(A9="","",IFERROR(INDEX(المدخلات!$M$4:$M$15,MATCH(A9,المدخلات!$L$4:$L$15,0)),"")) -> 13300 | N9: =IF(OR(G9="",F9=""),"",IF(F9="دولار أمريكي",IF(M9="","⚠️ لا يوجد سعر صرف",G9*M9),G9)) -> 0 | O9: =IF(OR(K9="",F9=""),"",IF(F9="دولار أمريكي",IF(M9="","⚠️ لا يوجد سعر صرف",K9*M9),K9)) -> 0
A10: 202606 | B10: يونيو 2026 | C10: معطر ارضيات نسيم المحيط خام | D10: 0 | E10: 215 | F10: دولار أمريكي | G10: =IF(OR(D10="",E10=""),"",D10*E10) -> 0 | H10: =IF(C10="","",IFERROR(_xlfn.MAXIFS($A$5:$A$2003,$C$5:$C$2003,C10,$A$5:$A$2003,"<"&A10),0)) -> 0 | I10: =IF(OR(H10="",H10=0),"",IFERROR(SUMIFS($D$5:$D$2003,$C$5:$C$2003,C10,$A$5:$A$2003,H10),"")) | J10: =IF(C10="","",IF(I10="",0,MAX(I10-D10,0))) -> 0 | K10: =IF(J10="","",J10*E10) -> 0 | L10: =IF(C10="","",IF(COUNTIFS($A$5:$A$2003,A10,$C$5:$C$2003,C10)>1,"⚠️ مادة مكررة بنفس الشهر",IF(OR(H10="",H10=0),"🆕 أول ظهور لهذه المادة",IF(D10>I10,"ℹ️ زيادة كمية (شراء/تصحيح) - لا تُحتسب استهلاكاً",IF(D10=I10,"➖ لا تغيير",""))))) -> 🆕 أول ظهور لهذه المادة | M10: =IF(A10="","",IFERROR(INDEX(المدخلات!$M$4:$M$15,MATCH(A10,المدخلات!$L$4:$L$15,0)),"")) -> 13300 | N10: =IF(OR(G10="",F10=""),"",IF(F10="دولار أمريكي",IF(M10="","⚠️ لا يوجد سعر صرف",G10*M10),G10)) -> 0 | O10: =IF(OR(K10="",F10=""),"",IF(F10="دولار أمريكي",IF(M10="","⚠️ لا يوجد سعر صرف",K10*M10),K10)) -> 0
A11: 202606 | B11: يونيو 2026 | C11: معطر ارضيات ليلك خام | D11: 0 | E11: 205 | F11: دولار أمريكي | G11: =IF(OR(D11="",E11=""),"",D11*E11) -> 0 | H11: =IF(C11="","",IFERROR(_xlfn.MAXIFS($A$5:$A$2003,$C$5:$C$2003,C11,$A$5:$A$2003,"<"&A11),0)) -> 0 | I11: =IF(OR(H11="",H11=0),"",IFERROR(SUMIFS($D$5:$D$2003,$C$5:$C$2003,C11,$A$5:$A$2003,H11),"")) | J11: =IF(C11="","",IF(I11="",0,MAX(I11-D11,0))) -> 0 | K11: =IF(J11="","",J11*E11) -> 0 | L11: =IF(C11="","",IF(COUNTIFS($A$5:$A$2003,A11,$C$5:$C$2003,C11)>1,"⚠️ مادة مكررة بنفس الشهر",IF(OR(H11="",H11=0),"🆕 أول ظهور لهذه المادة",IF(D11>I11,"ℹ️ زيادة كمية (شراء/تصحيح) - لا تُحتسب استهلاكاً",IF(D11=I11,"➖ لا تغيير",""))))) -> 🆕 أول ظهور لهذه المادة | M11: =IF(A11="","",IFERROR(INDEX(المدخلات!$M$4:$M$15,MATCH(A11,المدخلات!$L$4:$L$15,0)),"")) -> 13300 | N11: =IF(OR(G11="",F11=""),"",IF(F11="دولار أمريكي",IF(M11="","⚠️ لا يوجد سعر صرف",G11*M11),G11)) -> 0 | O11: =IF(OR(K11="",F11=""),"",IF(F11="دولار أمريكي",IF(M11="","⚠️ لا يوجد سعر صرف",K11*M11),K11)) -> 0
A12: 202606 | B12: يونيو 2026 | C12: معطر ارضيات زهرة التوليب خام | D12: 0 | E12: 205 | F12: دولار أمريكي | G12: =IF(OR(D12="",E12=""),"",D12*E12) -> 0 | H12: =IF(C12="","",IFERROR(_xlfn.MAXIFS($A$5:$A$2003,$C$5:$C$2003,C12,$A$5:$A$2003,"<"&A12),0)) -> 0 | I12: =IF(OR(H12="",H12=0),"",IFERROR(SUMIFS($D$5:$D$2003,$C$5:$C$2003,C12,$A$5:$A$2003,H12),"")) | J12: =IF(C12="","",IF(I12="",0,MAX(I12-D12,0))) -> 0 | K12: =IF(J12="","",J12*E12) -> 0 | L12: =IF(C12="","",IF(COUNTIFS($A$5:$A$2003,A12,$C$5:$C$2003,C12)>1,"⚠️ مادة مكررة بنفس الشهر",IF(OR(H12="",H12=0),"🆕 أول ظهور لهذه المادة",IF(D12>I12,"ℹ️ زيادة كمية (شراء/تصحيح) - لا تُحتسب استهلاكاً",IF(D12=I12,"➖ لا تغيير",""))))) -> 🆕 أول ظهور لهذه المادة | M12: =IF(A12="","",IFERROR(INDEX(المدخلات!$M$4:$M$15,MATCH(A12,المدخلات!$L$4:$L$15,0)),"")) -> 13300 | N12: =IF(OR(G12="",F12=""),"",IF(F12="دولار أمريكي",IF(M12="","⚠️ لا يوجد سعر صرف",G12*M12),G12)) -> 0 | O12: =IF(OR(K12="",F12=""),"",IF(F12="دولار أمريكي",IF(M12="","⚠️ لا يوجد سعر صرف",K12*M12),K12)) -> 0
A13: 202606 | B13: يونيو 2026 | C13: معطر ارضيات رائحة الورود خام | D13: 0 | E13: 180 | F13: دولار أمريكي | G13: =IF(OR(D13="",E13=""),"",D13*E13) -> 0 | H13: =IF(C13="","",IFERROR(_xlfn.MAXIFS($A$5:$A$2003,$C$5:$C$2003,C13,$A$5:$A$2003,"<"&A13),0)) -> 0 | I13: =IF(OR(H13="",H13=0),"",IFERROR(SUMIFS($D$5:$D$2003,$C$5:$C$2003,C13,$A$5:$A$2003,H13),"")) | J13: =IF(C13="","",IF(I13="",0,MAX(I13-D13,0))) -> 0 | K13: =IF(J13="","",J13*E13) -> 0 | L13: =IF(C13="","",IF(COUNTIFS($A$5:$A$2003,A13,$C$5:$C$2003,C13)>1,"⚠️ مادة مكررة بنفس الشهر",IF(OR(H13="",H13=0),"🆕 أول ظهور لهذه المادة",IF(D13>I13,"ℹ️ زيادة كمية (شراء/تصحيح) - لا تُحتسب استهلاكاً",IF(D13=I13,"➖ لا تغيير",""))))) -> 🆕 أول ظهور لهذه المادة | M13: =IF(A13="","",IFERROR(INDEX(المدخلات!$M$4:$M$15,MATCH(A13,المدخلات!$L$4:$L$15,0)),"")) -> 13300 | N13: =IF(OR(G13="",F13=""),"",IF(F13="دولار أمريكي",IF(M13="","⚠️ لا يوجد سعر صرف",G13*M13),G13)) -> 0 | O13: =IF(OR(K13="",F13=""),"",IF(F13="دولار أمريكي",IF(M13="","⚠️ لا يوجد سعر صرف",K13*M13),K13)) -> 0
A14: 202606 | B14: يونيو 2026 | C14: معطر ارضيات ببوري خام | D14: 0 | E14: 150 | F14: دولار أمريكي | G14: =IF(OR(D14="",E14=""),"",D14*E14) -> 0 | H14: =IF(C14="","",IFERROR(_xlfn.MAXIFS($A$5:$A$2003,$C$5:$C$2003,C14,$A$5:$A$2003,"<"&A14),0)) -> 0 | I14: =IF(OR(H14="",H14=0),"",IFERROR(SUMIFS($D$5:$D$2003,$C$5:$C$2003,C14,$A$5:$A$2003,H14),"")) | J14: =IF(C14="","",IF(I14="",0,MAX(I14-D14,0))) -> 0 | K14: =IF(J14="","",J14*E14) -> 0 | L14: =IF(C14="","",IF(COUNTIFS($A$5:$A$2003,A14,$C$5:$C$2003,C14)>1,"⚠️ مادة مكررة بنفس الشهر",IF(OR(H14="",H14=0),"🆕 أول ظهور لهذه المادة",IF(D14>I14,"ℹ️ زيادة كمية (شراء/تصحيح) - لا تُحتسب استهلاكاً",IF(D14=I14,"➖ لا تغيير",""))))) -> 🆕 أول ظهور لهذه المادة | M14: =IF(A14="","",IFERROR(INDEX(المدخلات!$M$4:$M$15,MATCH(A14,المدخلات!$L$4:$L$15,0)),"")) -> 13300 | N14: =IF(OR(G14="",F14=""),"",IF(F14="دولار أمريكي",IF(M14="","⚠️ لا يوجد سعر صرف",G14*M14),G14)) -> 0 | O14: =IF(OR(K14="",F14=""),"",IF(F14="دولار أمريكي",IF(M14="","⚠️ لا يوجد سعر صرف",K14*M14),K14)) -> 0
A15: 202606 | B15: يونيو 2026 | C15: معطر ارضيات الليمون المنعش خام | D15: 0 | E15: 160 | F15: دولار أمريكي | G15: =IF(OR(D15="",E15=""),"",D15*E15) -> 0 | H15: =IF(C15="","",IFERROR(_xlfn.MAXIFS($A$5:$A$2003,$C$5:$C$2003,C15,$A$5:$A$2003,"<"&A15),0)) -> 0 | I15: =IF(OR(H15="",H15=0),"",IFERROR(SUMIFS($D$5:$D$2003,$C$5:$C$2003,C15,$A$5:$A$2003,H15),"")) | J15: =IF(C15="","",IF(I15="",0,MAX(I15-D15,0))) -> 0 | K15: =IF(J15="","",J15*E15) -> 0 | L15: =IF(C15="","",IF(COUNTIFS($A$5:$A$2003,A15,$C$5:$C$2003,C15)>1,"⚠️ مادة مكررة بنفس الشهر",IF(OR(H15="",H15=0),"🆕 أول ظهور لهذه المادة",IF(D15>I15,"ℹ️ زيادة كمية (شراء/تصحيح) - لا تُحتسب استهلاكاً",IF(D15=I15,"➖ لا تغيير",""))))) -> 🆕 أول ظهور لهذه المادة | M15: =IF(A15="","",IFERROR(INDEX(المدخلات!$M$4:$M$15,MATCH(A15,المدخلات!$L$4:$L$15,0)),"")) -> 13300 | N15: =IF(OR(G15="",F15=""),"",IF(F15="دولار أمريكي",IF(M15="","⚠️ لا يوجد سعر صرف",G15*M15),G15)) -> 0 | O15: =IF(OR(K15="",F15=""),"",IF(F15="دولار أمريكي",IF(M15="","⚠️ لا يوجد سعر صرف",K15*M15),K15)) -> 0
A16: 202606 | B16: يونيو 2026 | C16: معطر ارضيات العود خام | D16: 0 | E16: 215 | F16: دولار أمريكي | G16: =IF(OR(D16="",E16=""),"",D16*E16) -> 0 | H16: =IF(C16="","",IFERROR(_xlfn.MAXIFS($A$5:$A$2003,$C$5:$C$2003,C16,$A$5:$A$2003,"<"&A16),0)) -> 0 | I16: =IF(OR(H16="",H16=0),"",IFERROR(SUMIFS($D$5:$D$2003,$C$5:$C$2003,C16,$A$5:$A$2003,H16),"")) | J16: =IF(C16="","",IF(I16="",0,MAX(I16-D16,0))) -> 0 | K16: =IF(J16="","",J16*E16) -> 0 | L16: =IF(C16="","",IF(COUNTIFS($A$5:$A$2003,A16,$C$5:$C$2003,C16)>1,"⚠️ مادة مكررة بنفس الشهر",IF(OR(H16="",H16=0),"🆕 أول ظهور لهذه المادة",IF(D16>I16,"ℹ️ زيادة كمية (شراء/تصحيح) - لا تُحتسب استهلاكاً",IF(D16=I16,"➖ لا تغيير",""))))) -> 🆕 أول ظهور لهذه المادة | M16: =IF(A16="","",IFERROR(INDEX(المدخلات!$M$4:$M$15,MATCH(A16,المدخلات!$L$4:$L$15,0)),"")) -> 13300 | N16: =IF(OR(G16="",F16=""),"",IF(F16="دولار أمريكي",IF(M16="","⚠️ لا يوجد سعر صرف",G16*M16),G16)) -> 0 | O16: =IF(OR(K16="",F16=""),"",IF(F16="دولار أمريكي",IF(M16="","⚠️ لا يوجد سعر صرف",K16*M16),K16)) -> 0
... A481: 202607 | B481: يوليو 2026 | C481: أسيد 1 لتر | D481: 0 | E481: 3500 | F481: ليرة سورية | G481: =IF(OR(D481="",E481=""),"",D481*E481) -> 0 | H481: =IF(C481="","",IFERROR(_xlfn.MAXIFS($A$5:$A$2003,$C$5:$C$2003,C481,$A$5:$A$2003,"<"&A481),0)) -> 202606 | I481: =IF(OR(H481="",H481=0),"",IFERROR(SUMIFS($D$5:$D$2003,$C$5:$C$2003,C481,$A$5:$A$2003,H481),"")) -> 0 | J481: =IF(C481="","",IF(I481="",0,MAX(I481-D481,0))) -> 0 | K481: =IF(J481="","",J481*E481) -> 0 | L481: =IF(C481="","",IF(COUNTIFS($A$5:$A$2003,A481,$C$5:$C$2003,C481)>1,"⚠️ مادة مكررة بنفس الشهر",IF(OR(H481="",H481=0),"🆕 أول ظهور لهذه المادة",IF(D481>I481,"ℹ️ زيادة كمية (شراء/تصحيح) - لا تُحتسب استهلاكاً",IF(D481=I481,"➖ لا تغيير",""))))) -> ➖ لا تغيير | M481: =IF(A481="","",IFERROR(INDEX(المدخلات!$M$4:$M$15,MATCH(A481,المدخلات!$L$4:$L$15,0)),"")) -> 13200 | N481: =IF(OR(G481="",F481=""),"",IF(F481="دولار أمريكي",IF(M481="","⚠️ لا يوجد سعر صرف",G481*M481),G481)) -> 0 | O481: =IF(OR(K481="",F481=""),"",IF(F481="دولار أمريكي",IF(M481="","⚠️ لا يوجد سعر صرف",K481*M481),K481)) -> 0
G482: =IF(OR(D482="",E482=""),"",D482*E482) | H482: =IF(C482="","",IFERROR(_xlfn.MAXIFS($A$5:$A$2003,$C$5:$C$2003,C482,$A$5:$A$2003,"<"&A482),0)) | I482: =IF(OR(H482="",H482=0),"",IFERROR(SUMIFS($D$5:$D$2003,$C$5:$C$2003,C482,$A$5:$A$2003,H482),"")) | J482: =IF(C482="","",IF(I482="",0,MAX(I482-D482,0))) | K482: =IF(J482="","",J482*E482) | L482: =IF(C482="","",IF(COUNTIFS($A$5:$A$2003,A482,$C$5:$C$2003,C482)>1,"⚠️ مادة مكررة بنفس الشهر",IF(OR(H482="",H482=0),"🆕 أول ظهور لهذه المادة",IF(D482>I482,"ℹ️ زيادة كمية (شراء/تصحيح) - لا تُحتسب استهلاكاً",IF(D482=I482,"➖ لا تغيير",""))))) | M482: =IF(A482="","",IFERROR(INDEX(المدخلات!$M$4:$M$15,MATCH(A482,المدخلات!$L$4:$L$15,0)),"")) | N482: =IF(OR(G482="",F482=""),"",IF(F482="دولار أمريكي",IF(M482="","⚠️ لا يوجد سعر صرف",G482*M482),G482)) | O482: =IF(OR(K482="",F482=""),"",IF(F482="دولار أمريكي",IF(M482="","⚠️ لا يوجد سعر صرف",K482*M482),K482))
