Workbook

Sheet الملخص السنوي
A1: الملخص السنوي الشامل — 2026
A2: يعرض هذا الملخص صافي راتب كل موظف لكل شهر خلال السنة
A4: # | B4: اسم الموظف | C4: الراتب الشهري | D4: يناير | E4: فبراير | F4: مارس | G4: أبريل | H4: مايو | I4: يونيو | J4: يوليو | K4: أغسطس | L4: سبتمبر | M4: أكتوبر | N4: نوفمبر | O4: ديسمبر | P4: إجمالي الخصومات | Q4: الراتب السنوي الصافي
A5: 1 | B5: ='بيانات الموظفين'!B5 -> أبو بكر | C5: ='بيانات الموظفين'!C5 -> 7000000 | D5: =IF(ISNUMBER(يناير!AM7),يناير!AM7,"") -> 7233333.3 | E5: =IF(ISNUMBER(فبراير!AJ7),فبراير!AJ7,"") -> 7000000 | F5: =IF(ISNUMBER(مارس!AM7),مارس!AM7,"") -> 7233333.3 | G5: =IF(ISNUMBER(أبريل!AL7),أبريل!AL7,"") -> 7000000 | H5: =IF(ISNUMBER(مايو!AM7),مايو!AM7,"") -> 7233333.3 | I5: =IF(ISNUMBER(يونيو!AL7),يونيو!AL7,"") -> 6300000 | J5: =IF(ISNUMBER(يوليو!AM7),يوليو!AM7,"") -> 7233333.3 | K5: =IF(ISNUMBER(أغسطس!AM7),أغسطس!AM7,"") -> 7233333.3 | L5: =IF(ISNUMBER(سبتمبر!AL7),سبتمبر!AL7,"") -> 7000000 | M5: =IF(ISNUMBER(أكتوبر!AM7),أكتوبر!AM7,"") -> 7233333.3 | N5: =IF(ISNUMBER(نوفمبر!AL7),نوفمبر!AL7,"") -> 7000000 | O5: =IF(ISNUMBER(ديسمبر!AM7),ديسمبر!AM7,"") -> 7233333.3 | P5: =IF(ISNUMBER(يناير!AL7),يناير!AL7,0)+IF(ISNUMBER(فبراير!AI7),فبراير!AI7,0)+IF(ISNUMBER(مارس!AL7),مارس!AL7,0)+IF(ISNUMBER(أبريل!AK7),أبريل!AK7,0)+IF(ISNUMBER(مايو!AL7),مايو!AL7,0)+IF(ISNUMBER(يونيو!AK7),يونيو!AK7,0)+IF(ISNUMBER(يوليو!AL7),يوليو!AL7,0)+IF(ISNUMBER(أغسطس!AL7),أغسطس!AL7,0)+IF(ISNUMBER(سبتمبر!AK7),سبتمبر!AK7,0)+IF(ISNUMBER(أكتوبر!AL7),أكتوبر!AL7,0)+IF(ISNUMBER(نوفمبر!AK7),نوفمبر!AK7,0)+IF(ISNUMBER(ديسمبر!AL7),ديسمبر!AL7,0) -> 700000 | Q5: =IFERROR(SUM(D5:O5),"") -> 84933333
A6: 2 | B6: ='بيانات الموظفين'!B6 -> هيثم صمادي | C6: ='بيانات الموظفين'!C6 -> 3000000 | D6: =IF(ISNUMBER(يناير!AM8),يناير!AM8,"") -> 3100000 | E6: =IF(ISNUMBER(فبراير!AJ8),فبراير!AJ8,"") -> 3000000 | F6: =IF(ISNUMBER(مارس!AM8),مارس!AM8,"") -> 3100000 | G6: =IF(ISNUMBER(أبريل!AL8),أبريل!AL8,"") -> 3000000 | H6: =IF(ISNUMBER(مايو!AM8),مايو!AM8,"") -> 3100000 | I6: =IF(ISNUMBER(يونيو!AL8),يونيو!AL8,"") -> 2866666.7 | J6: =IF(ISNUMBER(يوليو!AM8),يوليو!AM8,"") -> 3100000 | K6: =IF(ISNUMBER(أغسطس!AM8),أغسطس!AM8,"") -> 3100000 | L6: =IF(ISNUMBER(سبتمبر!AL8),سبتمبر!AL8,"") -> 3000000 | M6: =IF(ISNUMBER(أكتوبر!AM8),أكتوبر!AM8,"") -> 3100000 | N6: =IF(ISNUMBER(نوفمبر!AL8),نوفمبر!AL8,"") -> 3000000 | O6: =IF(ISNUMBER(ديسمبر!AM8),ديسمبر!AM8,"") -> 3100000 | P6: =IF(ISNUMBER(يناير!AL8),يناير!AL8,0)+IF(ISNUMBER(فبراير!AI8),فبراير!AI8,0)+IF(ISNUMBER(مارس!AL8),مارس!AL8,0)+IF(ISNUMBER(أبريل!AK8),أبريل!AK8,0)+IF(ISNUMBER(مايو!AL8),مايو!AL8,0)+IF(ISNUMBER(يونيو!AK8),يونيو!AK8,0)+IF(ISNUMBER(يوليو!AL8),يوليو!AL8,0)+IF(ISNUMBER(أغسطس!AL8),أغسطس!AL8,0)+IF(ISNUMBER(سبتمبر!AK8),سبتمبر!AK8,0)+IF(ISNUMBER(أكتوبر!AL8),أكتوبر!AL8,0)+IF(ISNUMBER(نوفمبر!AK8),نوفمبر!AK8,0)+IF(ISNUMBER(ديسمبر!AL8),ديسمبر!AL8,0) -> 200000 | Q6: =IFERROR(SUM(D6:O6),"") -> 36566667
A7: 3 | B7: ='بيانات الموظفين'!B7 -> حسام كبريتة | C7: ='بيانات الموظفين'!C7 -> 2500000 | D7: =IF(ISNUMBER(يناير!AM9),يناير!AM9,"") -> 2583333.3 | E7: =IF(ISNUMBER(فبراير!AJ9),فبراير!AJ9,"") -> 2500000 | F7: =IF(ISNUMBER(مارس!AM9),مارس!AM9,"") -> 2583333.3 | G7: =IF(ISNUMBER(أبريل!AL9),أبريل!AL9,"") -> 2500000 | H7: =IF(ISNUMBER(مايو!AM9),مايو!AM9,"") -> 2583333.3 | I7: =IF(ISNUMBER(يونيو!AL9),يونيو!AL9,"") -> 2305555.6 | J7: =IF(ISNUMBER(يوليو!AM9),يوليو!AM9,"") -> 2583333.3 | K7: =IF(ISNUMBER(أغسطس!AM9),أغسطس!AM9,"") -> 2583333.3 | L7: =IF(ISNUMBER(سبتمبر!AL9),سبتمبر!AL9,"") -> 2500000 | M7: =IF(ISNUMBER(أكتوبر!AM9),أكتوبر!AM9,"") -> 2583333.3 | N7: =IF(ISNUMBER(نوفمبر!AL9),نوفمبر!AL9,"") -> 2500000 | O7: =IF(ISNUMBER(ديسمبر!AM9),ديسمبر!AM9,"") -> 2583333.3 | P7: =IF(ISNUMBER(يناير!AL9),يناير!AL9,0)+IF(ISNUMBER(فبراير!AI9),فبراير!AI9,0)+IF(ISNUMBER(مارس!AL9),مارس!AL9,0)+IF(ISNUMBER(أبريل!AK9),أبريل!AK9,0)+IF(ISNUMBER(مايو!AL9),مايو!AL9,0)+IF(ISNUMBER(يونيو!AK9),يونيو!AK9,0)+IF(ISNUMBER(يوليو!AL9),يوليو!AL9,0)+IF(ISNUMBER(أغسطس!AL9),أغسطس!AL9,0)+IF(ISNUMBER(سبتمبر!AK9),سبتمبر!AK9,0)+IF(ISNUMBER(أكتوبر!AL9),أكتوبر!AL9,0)+IF(ISNUMBER(نوفمبر!AK9),نوفمبر!AK9,0)+IF(ISNUMBER(ديسمبر!AL9),ديسمبر!AL9,0) -> 250000 | Q7: =IFERROR(SUM(D7:O7),"") -> 30388889
A8: 4 | B8: ='بيانات الموظفين'!B8 -> انس المنسي | C8: ='بيانات الموظفين'!C8 -> 800000 | D8: =IF(ISNUMBER(يناير!AM10),يناير!AM10,"") -> 826666.67 | E8: =IF(ISNUMBER(فبراير!AJ10),فبراير!AJ10,"") -> 800000 | F8: =IF(ISNUMBER(مارس!AM10),مارس!AM10,"") -> 826666.67 | G8: =IF(ISNUMBER(أبريل!AL10),أبريل!AL10,"") -> 800000 | H8: =IF(ISNUMBER(مايو!AM10),مايو!AM10,"") -> 826666.67 | I8: =IF(ISNUMBER(يونيو!AL10),يونيو!AL10,"") -> 506666.67 | J8: =IF(ISNUMBER(يوليو!AM10),يوليو!AM10,"") -> 826666.67 | K8: =IF(ISNUMBER(أغسطس!AM10),أغسطس!AM10,"") -> 826666.67 | L8: =IF(ISNUMBER(سبتمبر!AL10),سبتمبر!AL10,"") -> 800000 | M8: =IF(ISNUMBER(أكتوبر!AM10),أكتوبر!AM10,"") -> 826666.67 | N8: =IF(ISNUMBER(نوفمبر!AL10),نوفمبر!AL10,"") -> 800000 | O8: =IF(ISNUMBER(ديسمبر!AM10),ديسمبر!AM10,"") -> 826666.67 | P8: =IF(ISNUMBER(يناير!AL10),يناير!AL10,0)+IF(ISNUMBER(فبراير!AI10),فبراير!AI10,0)+IF(ISNUMBER(مارس!AL10),مارس!AL10,0)+IF(ISNUMBER(أبريل!AK10),أبريل!AK10,0)+IF(ISNUMBER(مايو!AL10),مايو!AL10,0)+IF(ISNUMBER(يونيو!AK10),يونيو!AK10,0)+IF(ISNUMBER(يوليو!AL10),يوليو!AL10,0)+IF(ISNUMBER(أغسطس!AL10),أغسطس!AL10,0)+IF(ISNUMBER(سبتمبر!AK10),سبتمبر!AK10,0)+IF(ISNUMBER(أكتوبر!AL10),أكتوبر!AL10,0)+IF(ISNUMBER(نوفمبر!AK10),نوفمبر!AK10,0)+IF(ISNUMBER(ديسمبر!AL10),ديسمبر!AL10,0) -> 293333.33 | Q8: =IFERROR(SUM(D8:O8),"") -> 9493333.4
A9: 5 | B9: ='بيانات الموظفين'!B9 -> عمار مجيد | C9: ='بيانات الموظفين'!C9 -> 2000000 | D9: =IF(ISNUMBER(يناير!AM11),يناير!AM11,"") -> 2066666.7 | E9: =IF(ISNUMBER(فبراير!AJ11),فبراير!AJ11,"") -> 2000000 | F9: =IF(ISNUMBER(مارس!AM11),مارس!AM11,"") -> 2066666.7 | G9: =IF(ISNUMBER(أبريل!AL11),أبريل!AL11,"") -> 2000000 | H9: =IF(ISNUMBER(مايو!AM11),مايو!AM11,"") -> 2066666.7 | I9: =IF(ISNUMBER(يونيو!AL11),يونيو!AL11,"") -> 540740.74 | J9: =IF(ISNUMBER(يوليو!AM11),يوليو!AM11,"") -> 2066666.7 | K9: =IF(ISNUMBER(أغسطس!AM11),أغسطس!AM11,"") -> 2066666.7 | L9: =IF(ISNUMBER(سبتمبر!AL11),سبتمبر!AL11,"") -> 2000000 | M9: =IF(ISNUMBER(أكتوبر!AM11),أكتوبر!AM11,"") -> 2066666.7 | N9: =IF(ISNUMBER(نوفمبر!AL11),نوفمبر!AL11,"") -> 2000000 | O9: =IF(ISNUMBER(ديسمبر!AM11),ديسمبر!AM11,"") -> 2066666.7 | P9: =IF(ISNUMBER(يناير!AL11),يناير!AL11,0)+IF(ISNUMBER(فبراير!AI11),فبراير!AI11,0)+IF(ISNUMBER(مارس!AL11),مارس!AL11,0)+IF(ISNUMBER(أبريل!AK11),أبريل!AK11,0)+IF(ISNUMBER(مايو!AL11),مايو!AL11,0)+IF(ISNUMBER(يونيو!AK11),يونيو!AK11,0)+IF(ISNUMBER(يوليو!AL11),يوليو!AL11,0)+IF(ISNUMBER(أغسطس!AL11),أغسطس!AL11,0)+IF(ISNUMBER(سبتمبر!AK11),سبتمبر!AK11,0)+IF(ISNUMBER(أكتوبر!AL11),أكتوبر!AL11,0)+IF(ISNUMBER(نوفمبر!AK11),نوفمبر!AK11,0)+IF(ISNUMBER(ديسمبر!AL11),ديسمبر!AL11,0) -> 1466666.7 | Q9: =IFERROR(SUM(D9:O9),"") -> 23007407
A10: 6 | B10: ='بيانات الموظفين'!B10 -> 0 | C10: ='بيانات الموظفين'!C10 -> 0 | D10: =IF(ISNUMBER(يناير!AM12),يناير!AM12,"") | E10: =IF(ISNUMBER(فبراير!AJ12),فبراير!AJ12,"") | F10: =IF(ISNUMBER(مارس!AM12),مارس!AM12,"") | G10: =IF(ISNUMBER(أبريل!AL12),أبريل!AL12,"") | H10: =IF(ISNUMBER(مايو!AM12),مايو!AM12,"") | I10: =IF(ISNUMBER(يونيو!AL12),يونيو!AL12,"") | J10: =IF(ISNUMBER(يوليو!AM12),يوليو!AM12,"") | K10: =IF(ISNUMBER(أغسطس!AM12),أغسطس!AM12,"") | L10: =IF(ISNUMBER(سبتمبر!AL12),سبتمبر!AL12,"") | M10: =IF(ISNUMBER(أكتوبر!AM12),أكتوبر!AM12,"") | N10: =IF(ISNUMBER(نوفمبر!AL12),نوفمبر!AL12,"") | O10: =IF(ISNUMBER(ديسمبر!AM12),ديسمبر!AM12,"") | P10: =IF(ISNUMBER(يناير!AL12),يناير!AL12,0)+IF(ISNUMBER(فبراير!AI12),فبراير!AI12,0)+IF(ISNUMBER(مارس!AL12),مارس!AL12,0)+IF(ISNUMBER(أبريل!AK12),أبريل!AK12,0)+IF(ISNUMBER(مايو!AL12),مايو!AL12,0)+IF(ISNUMBER(يونيو!AK12),يونيو!AK12,0)+IF(ISNUMBER(يوليو!AL12),يوليو!AL12,0)+IF(ISNUMBER(أغسطس!AL12),أغسطس!AL12,0)+IF(ISNUMBER(سبتمبر!AK12),سبتمبر!AK12,0)+IF(ISNUMBER(أكتوبر!AL12),أكتوبر!AL12,0)+IF(ISNUMBER(نوفمبر!AK12),نوفمبر!AK12,0)+IF(ISNUMBER(ديسمبر!AL12),ديسمبر!AL12,0) -> 0 | Q10: =IFERROR(SUM(D10:O10),"") -> 0
A11: 7 | B11: ='بيانات الموظفين'!B11 -> 0 | C11: ='بيانات الموظفين'!C11 -> 0 | D11: =IF(ISNUMBER(يناير!AM13),يناير!AM13,"") | E11: =IF(ISNUMBER(فبراير!AJ13),فبراير!AJ13,"") | F11: =IF(ISNUMBER(مارس!AM13),مارس!AM13,"") | G11: =IF(ISNUMBER(أبريل!AL13),أبريل!AL13,"") | H11: =IF(ISNUMBER(مايو!AM13),مايو!AM13,"") | I11: =IF(ISNUMBER(يونيو!AL13),يونيو!AL13,"") | J11: =IF(ISNUMBER(يوليو!AM13),يوليو!AM13,"") | K11: =IF(ISNUMBER(أغسطس!AM13),أغسطس!AM13,"") | L11: =IF(ISNUMBER(سبتمبر!AL13),سبتمبر!AL13,"") | M11: =IF(ISNUMBER(أكتوبر!AM13),أكتوبر!AM13,"") | N11: =IF(ISNUMBER(نوفمبر!AL13),نوفمبر!AL13,"") | O11: =IF(ISNUMBER(ديسمبر!AM13),ديسمبر!AM13,"") | P11: =IF(ISNUMBER(يناير!AL13),يناير!AL13,0)+IF(ISNUMBER(فبراير!AI13),فبراير!AI13,0)+IF(ISNUMBER(مارس!AL13),مارس!AL13,0)+IF(ISNUMBER(أبريل!AK13),أبريل!AK13,0)+IF(ISNUMBER(مايو!AL13),مايو!AL13,0)+IF(ISNUMBER(يونيو!AK13),يونيو!AK13,0)+IF(ISNUMBER(يوليو!AL13),يوليو!AL13,0)+IF(ISNUMBER(أغسطس!AL13),أغسطس!AL13,0)+IF(ISNUMBER(سبتمبر!AK13),سبتمبر!AK13,0)+IF(ISNUMBER(أكتوبر!AL13),أكتوبر!AL13,0)+IF(ISNUMBER(نوفمبر!AK13),نوفمبر!AK13,0)+IF(ISNUMBER(ديسمبر!AL13),ديسمبر!AL13,0) -> 0 | Q11: =IFERROR(SUM(D11:O11),"") -> 0
A12: 8 | B12: ='بيانات الموظفين'!B12 -> 0 | C12: ='بيانات الموظفين'!C12 -> 0 | D12: =IF(ISNUMBER(يناير!AM14),يناير!AM14,"") | E12: =IF(ISNUMBER(فبراير!AJ14),فبراير!AJ14,"") | F12: =IF(ISNUMBER(مارس!AM14),مارس!AM14,"") | G12: =IF(ISNUMBER(أبريل!AL14),أبريل!AL14,"") | H12: =IF(ISNUMBER(مايو!AM14),مايو!AM14,"") | I12: =IF(ISNUMBER(يونيو!AL14),يونيو!AL14,"") | J12: =IF(ISNUMBER(يوليو!AM14),يوليو!AM14,"") | K12: =IF(ISNUMBER(أغسطس!AM14),أغسطس!AM14,"") | L12: =IF(ISNUMBER(سبتمبر!AL14),سبتمبر!AL14,"") | M12: =IF(ISNUMBER(أكتوبر!AM14),أكتوبر!AM14,"") | N12: =IF(ISNUMBER(نوفمبر!AL14),نوفمبر!AL14,"") | O12: =IF(ISNUMBER(ديسمبر!AM14),ديسمبر!AM14,"") | P12: =IF(ISNUMBER(يناير!AL14),يناير!AL14,0)+IF(ISNUMBER(فبراير!AI14),فبراير!AI14,0)+IF(ISNUMBER(مارس!AL14),مارس!AL14,0)+IF(ISNUMBER(أبريل!AK14),أبريل!AK14,0)+IF(ISNUMBER(مايو!AL14),مايو!AL14,0)+IF(ISNUMBER(يونيو!AK14),يونيو!AK14,0)+IF(ISNUMBER(يوليو!AL14),يوليو!AL14,0)+IF(ISNUMBER(أغسطس!AL14),أغسطس!AL14,0)+IF(ISNUMBER(سبتمبر!AK14),سبتمبر!AK14,0)+IF(ISNUMBER(أكتوبر!AL14),أكتوبر!AL14,0)+IF(ISNUMBER(نوفمبر!AK14),نوفمبر!AK14,0)+IF(ISNUMBER(ديسمبر!AL14),ديسمبر!AL14,0) -> 0 | Q12: =IFERROR(SUM(D12:O12),"") -> 0
A13: 9 | B13: ='بيانات الموظفين'!B13 -> 0 | C13: ='بيانات الموظفين'!C13 -> 0 | D13: =IF(ISNUMBER(يناير!AM15),يناير!AM15,"") | E13: =IF(ISNUMBER(فبراير!AJ15),فبراير!AJ15,"") | F13: =IF(ISNUMBER(مارس!AM15),مارس!AM15,"") | G13: =IF(ISNUMBER(أبريل!AL15),أبريل!AL15,"") | H13: =IF(ISNUMBER(مايو!AM15),مايو!AM15,"") | I13: =IF(ISNUMBER(يونيو!AL15),يونيو!AL15,"") | J13: =IF(ISNUMBER(يوليو!AM15),يوليو!AM15,"") | K13: =IF(ISNUMBER(أغسطس!AM15),أغسطس!AM15,"") | L13: =IF(ISNUMBER(سبتمبر!AL15),سبتمبر!AL15,"") | M13: =IF(ISNUMBER(أكتوبر!AM15),أكتوبر!AM15,"") | N13: =IF(ISNUMBER(نوفمبر!AL15),نوفمبر!AL15,"") | O13: =IF(ISNUMBER(ديسمبر!AM15),ديسمبر!AM15,"") | P13: =IF(ISNUMBER(يناير!AL15),يناير!AL15,0)+IF(ISNUMBER(فبراير!AI15),فبراير!AI15,0)+IF(ISNUMBER(مارس!AL15),مارس!AL15,0)+IF(ISNUMBER(أبريل!AK15),أبريل!AK15,0)+IF(ISNUMBER(مايو!AL15),مايو!AL15,0)+IF(ISNUMBER(يونيو!AK15),يونيو!AK15,0)+IF(ISNUMBER(يوليو!AL15),يوليو!AL15,0)+IF(ISNUMBER(أغسطس!AL15),أغسطس!AL15,0)+IF(ISNUMBER(سبتمبر!AK15),سبتمبر!AK15,0)+IF(ISNUMBER(أكتوبر!AL15),أكتوبر!AL15,0)+IF(ISNUMBER(نوفمبر!AK15),نوفمبر!AK15,0)+IF(ISNUMBER(ديسمبر!AL15),ديسمبر!AL15,0) -> 0 | Q13: =IFERROR(SUM(D13:O13),"") -> 0
A14: 10 | B14: ='بيانات الموظفين'!B14 -> 0 | C14: ='بيانات الموظفين'!C14 -> 0 | D14: =IF(ISNUMBER(يناير!AM16),يناير!AM16,"") | E14: =IF(ISNUMBER(فبراير!AJ16),فبراير!AJ16,"") | F14: =IF(ISNUMBER(مارس!AM16),مارس!AM16,"") | G14: =IF(ISNUMBER(أبريل!AL16),أبريل!AL16,"") | H14: =IF(ISNUMBER(مايو!AM16),مايو!AM16,"") | I14: =IF(ISNUMBER(يونيو!AL16),يونيو!AL16,"") | J14: =IF(ISNUMBER(يوليو!AM16),يوليو!AM16,"") | K14: =IF(ISNUMBER(أغسطس!AM16),أغسطس!AM16,"") | L14: =IF(ISNUMBER(سبتمبر!AL16),سبتمبر!AL16,"") | M14: =IF(ISNUMBER(أكتوبر!AM16),أكتوبر!AM16,"") | N14: =IF(ISNUMBER(نوفمبر!AL16),نوفمبر!AL16,"") | O14: =IF(ISNUMBER(ديسمبر!AM16),ديسمبر!AM16,"") | P14: =IF(ISNUMBER(يناير!AL16),يناير!AL16,0)+IF(ISNUMBER(فبراير!AI16),فبراير!AI16,0)+IF(ISNUMBER(مارس!AL16),مارس!AL16,0)+IF(ISNUMBER(أبريل!AK16),أبريل!AK16,0)+IF(ISNUMBER(مايو!AL16),مايو!AL16,0)+IF(ISNUMBER(يونيو!AK16),يونيو!AK16,0)+IF(ISNUMBER(يوليو!AL16),يوليو!AL16,0)+IF(ISNUMBER(أغسطس!AL16),أغسطس!AL16,0)+IF(ISNUMBER(سبتمبر!AK16),سبتمبر!AK16,0)+IF(ISNUMBER(أكتوبر!AL16),أكتوبر!AL16,0)+IF(ISNUMBER(نوفمبر!AK16),نوفمبر!AK16,0)+IF(ISNUMBER(ديسمبر!AL16),ديسمبر!AL16,0) -> 0 | Q14: =IFERROR(SUM(D14:O14),"") -> 0
A15: الإجمالي الكلي | C15: =IFERROR(SUM(C5:C14),0) -> 15300000 | D15: =IFERROR(SUM(D5:D14),0) -> 15810000 | E15: =IFERROR(SUM(E5:E14),0) -> 15300000 | F15: =IFERROR(SUM(F5:F14),0) -> 15810000 | G15: =IFERROR(SUM(G5:G14),0) -> 15300000 | H15: =IFERROR(SUM(H5:H14),0) -> 15810000 | I15: =IFERROR(SUM(I5:I14),0) -> 12519630 | J15: =IFERROR(SUM(J5:J14),0) -> 15810000 | ... Q15: =IFERROR(SUM(Q5:Q14),0) -> 1.8438963e+08

Sheet بيانات الموظفين
A1: بيانات الموظفين — نظام ضبط الغياب 2026
A2: ساعات العمل اليومية: | B2: عدّل الخلية G2 ← | D2: أدخل أسماء الموظفين ورواتبهم في الجدول أدناه | G2: 9 | H2: ساعة/يوم ✏
A4: # | B4: اسم الموظف | C4: الراتب الشهري | D4: ملاحظات | E4: تاريخ التعيين | F4: الحالة
A5: 1 | B5: أبو بكر | C5: 7000000 | F5: نشط
A6: 2 | B6: هيثم صمادي | C6: 3000000 | F6: نشط
A7: 3 | B7: حسام كبريتة | C7: 2500000 | F7: نشط
A8: 4 | B8: انس المنسي | C8: 800000 | F8: نشط
A9: 5 | B9: عمار مجيد | C9: 2000000 | F9: نشط
A10: 6 | F10: نشط
A11: 7 | F11: نشط
A12: 8 | F12: نشط
A13: 9 | F13: نشط
A14: 10 | F14: نشط
A17: 📋 دليل رموز الغياب
A18: الرمز | B18: التفسير
A19: فارغ | B19: حضور كامل — لا تكتب شيئاً
A20: غ | B20: غياب يوم كامل — يُخصم يوم من الراتب
A21: نصف | B21: حضور نصف يوم — يُخصم نصف يوم
A22: رقم (مثال: 3) | B22: ساعات إضافية — يُضاف بدلها للراتب

Sheet يناير
A1: جدول ضبط الغياب وحساب الرواتب ◀ يناير 2026 ★ يوم إضافي مضاف
A2: فارغ=حضور | غ=غياب يوم | نصف=نصف يوم | رقم=ساعات إضافية | 🔴 الجمعة باللون الأحمر
A4: اسم الموظف | B4: الخميس | C4: الجمعة | D4: السبت | E4: الأحد | F4: الاثنين | G4: الثلاثاء | H4: الأربعاء | I4: الخميس | J4: الجمعة | K4: السبت | L4: الأحد | M4: الاثنين | N4: الثلاثاء | O4: الأربعاء | P4: الخميس | Q4: الجمعة | R4: السبت | S4: الأحد | T4: الاثنين | U4: الثلاثاء | V4: الأربعاء | W4: الخميس | X4: الجمعة | Y4: السبت | Z4: الأحد | AA4: الاثنين | AB4: الثلاثاء | AC4: الأربعاء | AD4: الخميس | AE4: الجمعة | AF4: السبت | AG4: أيام الغياب | AH4: نصف يوم | AI4: ساعات إضافية | AJ4: قيمة الإضافي | AK4: أيام العمل | AL4: خصم الغياب | AM4: صافي الراتب
B5: 1 | C5: 2 | D5: 3 | E5: 4 | F5: 5 | G5: 6 | H5: 7 | I5: 8 | J5: 9 | K5: 10 | L5: 11 | M5: 12 | N5: 13 | O5: 14 | P5: 15 | Q5: 16 | R5: 17 | S5: 18 | T5: 19 | U5: 20 | V5: 21 | W5: 22 | X5: 23 | Y5: 24 | Z5: 25 | AA5: 26 | AB5: 27 | AC5: 28 | AD5: 29 | AE5: 30 | AF5: 31
A7: ='بيانات الموظفين'!B5 -> أبو بكر | AG7: =COUNTIF(B7:AF7,"غ") -> 0 | AH7: =COUNTIF(B7:AF7,"نصف") -> 0 | AI7: =SUMIF(B7:AF7,">"&0) -> 0 | AJ7: =IF(OR('بيانات الموظفين'!C5="",NOT(ISNUMBER('بيانات الموظفين'!G2)),AI7=0),"-",ROUND(AI7*(('بيانات الموظفين'!C5/31)/'بيانات الموظفين'!G2),2)) -> - | AK7: =IF('بيانات الموظفين'!C5="","-",31-AG7-AH7*0.5) -> 31 | AL7: =IF('بيانات الموظفين'!C5="","-",ROUND(('بيانات الموظفين'!C5/31)*AG7+(('بيانات الموظفين'!C5/31)/2)*AH7,2)) -> 0 | AM7: =IF('بيانات الموظفين'!C5="","-",ROUND('بيانات الموظفين'!C5+ROUND('بيانات الموظفين'!C5/30,2)+IF(ISNUMBER(AJ7),AJ7,0)-IF(ISNUMBER(AL7),AL7,0),2)) -> 7233333.3
A8: ='بيانات الموظفين'!B6 -> هيثم صمادي | AG8: =COUNTIF(B8:AF8,"غ") -> 0 | AH8: =COUNTIF(B8:AF8,"نصف") -> 0 | AI8: =SUMIF(B8:AF8,">"&0) -> 0 | AJ8: =IF(OR('بيانات الموظفين'!C6="",NOT(ISNUMBER('بيانات الموظفين'!G2)),AI8=0),"-",ROUND(AI8*(('بيانات الموظفين'!C6/31)/'بيانات الموظفين'!G2),2)) -> - | AK8: =IF('بيانات الموظفين'!C6="","-",31-AG8-AH8*0.5) -> 31 | AL8: =IF('بيانات الموظفين'!C6="","-",ROUND(('بيانات الموظفين'!C6/31)*AG8+(('بيانات الموظفين'!C6/31)/2)*AH8,2)) -> 0 | AM8: =IF('بيانات الموظفين'!C6="","-",ROUND('بيانات الموظفين'!C6+ROUND('بيانات الموظفين'!C6/30,2)+IF(ISNUMBER(AJ8),AJ8,0)-IF(ISNUMBER(AL8),AL8,0),2)) -> 3100000
A9: ='بيانات الموظفين'!B7 -> حسام كبريتة | AG9: =COUNTIF(B9:AF9,"غ") -> 0 | AH9: =COUNTIF(B9:AF9,"نصف") -> 0 | AI9: =SUMIF(B9:AF9,">"&0) -> 0 | AJ9: =IF(OR('بيانات الموظفين'!C7="",NOT(ISNUMBER('بيانات الموظفين'!G2)),AI9=0),"-",ROUND(AI9*(('بيانات الموظفين'!C7/31)/'بيانات الموظفين'!G2),2)) -> - | AK9: =IF('بيانات الموظفين'!C7="","-",31-AG9-AH9*0.5) -> 31 | AL9: =IF('بيانات الموظفين'!C7="","-",ROUND(('بيانات الموظفين'!C7/31)*AG9+(('بيانات الموظفين'!C7/31)/2)*AH9,2)) -> 0 | AM9: =IF('بيانات الموظفين'!C7="","-",ROUND('بيانات الموظفين'!C7+ROUND('بيانات الموظفين'!C7/30,2)+IF(ISNUMBER(AJ9),AJ9,0)-IF(ISNUMBER(AL9),AL9,0),2)) -> 2583333.3
A10: ='بيانات الموظفين'!B8 -> انس المنسي | AG10: =COUNTIF(B10:AF10,"غ") -> 0 | AH10: =COUNTIF(B10:AF10,"نصف") -> 0 | AI10: =SUMIF(B10:AF10,">"&0) -> 0 | AJ10: =IF(OR('بيانات الموظفين'!C8="",NOT(ISNUMBER('بيانات الموظفين'!G2)),AI10=0),"-",ROUND(AI10*(('بيانات الموظفين'!C8/31)/'بيانات الموظفين'!G2),2)) -> - | AK10: =IF('بيانات الموظفين'!C8="","-",31-AG10-AH10*0.5) -> 31 | AL10: =IF('بيانات الموظفين'!C8="","-",ROUND(('بيانات الموظفين'!C8/31)*AG10+(('بيانات الموظفين'!C8/31)/2)*AH10,2)) -> 0 | AM10: =IF('بيانات الموظفين'!C8="","-",ROUND('بيانات الموظفين'!C8+ROUND('بيانات الموظفين'!C8/30,2)+IF(ISNUMBER(AJ10),AJ10,0)-IF(ISNUMBER(AL10),AL10,0),2)) -> 826666.67
A11: ='بيانات الموظفين'!B9 -> عمار مجيد | AG11: =COUNTIF(B11:AF11,"غ") -> 0 | AH11: =COUNTIF(B11:AF11,"نصف") -> 0 | AI11: =SUMIF(B11:AF11,">"&0) -> 0 | AJ11: =IF(OR('بيانات الموظفين'!C9="",NOT(ISNUMBER('بيانات الموظفين'!G2)),AI11=0),"-",ROUND(AI11*(('بيانات الموظفين'!C9/31)/'بيانات الموظفين'!G2),2)) -> - | AK11: =IF('بيانات الموظفين'!C9="","-",31-AG11-AH11*0.5) -> 31 | AL11: =IF('بيانات الموظفين'!C9="","-",ROUND(('بيانات الموظفين'!C9/31)*AG11+(('بيانات الموظفين'!C9/31)/2)*AH11,2)) -> 0 | AM11: =IF('بيانات الموظفين'!C9="","-",ROUND('بيانات الموظفين'!C9+ROUND('بيانات الموظفين'!C9/30,2)+IF(ISNUMBER(AJ11),AJ11,0)-IF(ISNUMBER(AL11),AL11,0),2)) -> 2066666.7
A12: ='بيانات الموظفين'!B10 -> 0 | AG12: =COUNTIF(B12:AF12,"غ") -> 0 | AH12: =COUNTIF(B12:AF12,"نصف") -> 0 | AI12: =SUMIF(B12:AF12,">"&0) -> 0 | AJ12: =IF(OR('بيانات الموظفين'!C10="",NOT(ISNUMBER('بيانات الموظفين'!G2)),AI12=0),"-",ROUND(AI12*(('بيانات الموظفين'!C10/31)/'بيانات الموظفين'!G2),2)) -> - | AK12: =IF('بيانات الموظفين'!C10="","-",31-AG12-AH12*0.5) -> - | AL12: =IF('بيانات الموظفين'!C10="","-",ROUND(('بيانات الموظفين'!C10/31)*AG12+(('بيانات الموظفين'!C10/31)/2)*AH12,2)) -> - | AM12: =IF('بيانات الموظفين'!C10="","-",ROUND('بيانات الموظفين'!C10+ROUND('بيانات الموظفين'!C10/30,2)+IF(ISNUMBER(AJ12),AJ12,0)-IF(ISNUMBER(AL12),AL12,0),2)) -> -
A13: ='بيانات الموظفين'!B11 -> 0 | AG13: =COUNTIF(B13:AF13,"غ") -> 0 | AH13: =COUNTIF(B13:AF13,"نصف") -> 0 | AI13: =SUMIF(B13:AF13,">"&0) -> 0 | AJ13: =IF(OR('بيانات الموظفين'!C11="",NOT(ISNUMBER('بيانات الموظفين'!G2)),AI13=0),"-",ROUND(AI13*(('بيانات الموظفين'!C11/31)/'بيانات الموظفين'!G2),2)) -> - | AK13: =IF('بيانات الموظفين'!C11="","-",31-AG13-AH13*0.5) -> - | AL13: =IF('بيانات الموظفين'!C11="","-",ROUND(('بيانات الموظفين'!C11/31)*AG13+(('بيانات الموظفين'!C11/31)/2)*AH13,2)) -> - | AM13: =IF('بيانات الموظفين'!C11="","-",ROUND('بيانات الموظفين'!C11+ROUND('بيانات الموظفين'!C11/30,2)+IF(ISNUMBER(AJ13),AJ13,0)-IF(ISNUMBER(AL13),AL13,0),2)) -> -
A14: ='بيانات الموظفين'!B12 -> 0 | AG14: =COUNTIF(B14:AF14,"غ") -> 0 | AH14: =COUNTIF(B14:AF14,"نصف") -> 0 | AI14: =SUMIF(B14:AF14,">"&0) -> 0 | AJ14: =IF(OR('بيانات الموظفين'!C12="",NOT(ISNUMBER('بيانات الموظفين'!G2)),AI14=0),"-",ROUND(AI14*(('بيانات الموظفين'!C12/31)/'بيانات الموظفين'!G2),2)) -> - | AK14: =IF('بيانات الموظفين'!C12="","-",31-AG14-AH14*0.5) -> - | AL14: =IF('بيانات الموظفين'!C12="","-",ROUND(('بيانات الموظفين'!C12/31)*AG14+(('بيانات الموظفين'!C12/31)/2)*AH14,2)) -> - | AM14: =IF('بيانات الموظفين'!C12="","-",ROUND('بيانات الموظفين'!C12+ROUND('بيانات الموظفين'!C12/30,2)+IF(ISNUMBER(AJ14),AJ14,0)-IF(ISNUMBER(AL14),AL14,0),2)) -> -
A15: ='بيانات الموظفين'!B13 -> 0 | AG15: =COUNTIF(B15:AF15,"غ") -> 0 | AH15: =COUNTIF(B15:AF15,"نصف") -> 0 | AI15: =SUMIF(B15:AF15,">"&0) -> 0 | AJ15: =IF(OR('بيانات الموظفين'!C13="",NOT(ISNUMBER('بيانات الموظفين'!G2)),AI15=0),"-",ROUND(AI15*(('بيانات الموظفين'!C13/31)/'بيانات الموظفين'!G2),2)) -> - | AK15: =IF('بيانات الموظفين'!C13="","-",31-AG15-AH15*0.5) -> - | AL15: =IF('بيانات الموظفين'!C13="","-",ROUND(('بيانات الموظفين'!C13/31)*AG15+(('بيانات الموظفين'!C13/31)/2)*AH15,2)) -> - | AM15: =IF('بيانات الموظفين'!C13="","-",ROUND('بيانات الموظفين'!C13+ROUND('بيانات الموظفين'!C13/30,2)+IF(ISNUMBER(AJ15),AJ15,0)-IF(ISNUMBER(AL15),AL15,0),2)) -> -
A16: ='بيانات الموظفين'!B14 -> 0 | AG16: =COUNTIF(B16:AF16,"غ") -> 0 | AH16: =COUNTIF(B16:AF16,"نصف") -> 0 | AI16: =SUMIF(B16:AF16,">"&0) -> 0 | AJ16: =IF(OR('بيانات الموظفين'!C14="",NOT(ISNUMBER('بيانات الموظفين'!G2)),AI16=0),"-",ROUND(AI16*(('بيانات الموظفين'!C14/31)/'بيانات الموظفين'!G2),2)) -> - | AK16: =IF('بيانات الموظفين'!C14="","-",31-AG16-AH16*0.5) -> - | AL16: =IF('بيانات الموظفين'!C14="","-",ROUND(('بيانات الموظفين'!C14/31)*AG16+(('بيانات الموظفين'!C14/31)/2)*AH16,2)) -> - | AM16: =IF('بيانات الموظفين'!C14="","-",ROUND('بيانات الموظفين'!C14+ROUND('بيانات الموظفين'!C14/30,2)+IF(ISNUMBER(AJ16),AJ16,0)-IF(ISNUMBER(AL16),AL16,0),2)) -> -
A17: إجمالي الغياب اليومي — يناير | B17: =COUNTIF(B7:B16,"غ")+COUNTIF(B7:B16,"نصف")*0.5 -> 0 | C17: =COUNTIF(C7:C16,"غ")+COUNTIF(C7:C16,"نصف")*0.5 -> 0 | D17: =COUNTIF(D7:D16,"غ")+COUNTIF(D7:D16,"نصف")*0.5 -> 0 | E17: =COUNTIF(E7:E16,"غ")+COUNTIF(E7:E16,"نصف")*0.5 -> 0 | F17: =COUNTIF(F7:F16,"غ")+COUNTIF(F7:F16,"نصف")*0.5 -> 0 | G17: =COUNTIF(G7:G16,"غ")+COUNTIF(G7:G16,"نصف")*0.5 -> 0 | H17: =COUNTIF(H7:H16,"غ")+COUNTIF(H7:H16,"نصف")*0.5 -> 0 | I17: =COUNTIF(I7:I16,"غ")+COUNTIF(I7:I16,"نصف")*0.5 -> 0 | ... AF17: =COUNTIF(AF7:AF16,"غ")+COUNTIF(AF7:AF16,"نصف")*0.5 -> 0 | AG17: =SUM(AG7:AG16) -> 0 | AH17: =SUM(AH7:AH16) -> 0 | AI17: =SUM(AI7:AI16) -> 0 | AJ17: =SUM(AJ7:AJ16) -> 0 | AL17: =SUM(AL7:AL16) -> 0 | AM17: =SUM(AM7:AM16) -> 15810000
A19: 📊 الملخص الشهري للرواتب — يناير 2026
A20: # | B20: اسم الموظف | C20: الراتب الأساسي | D20: أيام الغياب | E20: نصف يوم | F20: خصم الغياب | G20: ساعات إضافية | H20: قيمة الإضافي | I20: صافي الراتب
A21: 1 | B21: ='بيانات الموظفين'!B5 -> أبو بكر | C21: =IF('بيانات الموظفين'!C5="","-",'بيانات الموظفين'!C5) -> 7000000 | D21: =AG7 -> 0 | E21: =AH7 -> 0 | F21: =AL7 -> 0 | G21: =AI7 -> 0 | H21: =AJ7 -> - | I21: =AM7 -> 7233333.3
A22: 2 | B22: ='بيانات الموظفين'!B6 -> هيثم صمادي | C22: =IF('بيانات الموظفين'!C6="","-",'بيانات الموظفين'!C6) -> 3000000 | D22: =AG8 -> 0 | E22: =AH8 -> 0 | F22: =AL8 -> 0 | G22: =AI8 -> 0 | H22: =AJ8 -> - | I22: =AM8 -> 3100000
A23: 3 | B23: ='بيانات الموظفين'!B7 -> حسام كبريتة | C23: =IF('بيانات الموظفين'!C7="","-",'بيانات الموظفين'!C7) -> 2500000 | D23: =AG9 -> 0 | E23: =AH9 -> 0 | F23: =AL9 -> 0 | G23: =AI9 -> 0 | H23: =AJ9 -> - | I23: =AM9 -> 2583333.3
A24: 4 | B24: ='بيانات الموظفين'!B8 -> انس المنسي | C24: =IF('بيانات الموظفين'!C8="","-",'بيانات الموظفين'!C8) -> 800000 | D24: =AG10 -> 0 | E24: =AH10 -> 0 | F24: =AL10 -> 0 | G24: =AI10 -> 0 | H24: =AJ10 -> - | I24: =AM10 -> 826666.67
A25: 5 | B25: ='بيانات الموظفين'!B9 -> عمار مجيد | C25: =IF('بيانات الموظفين'!C9="","-",'بيانات الموظفين'!C9) -> 2000000 | D25: =AG11 -> 0 | E25: =AH11 -> 0 | F25: =AL11 -> 0 | G25: =AI11 -> 0 | H25: =AJ11 -> - | I25: =AM11 -> 2066666.7
A26: 6 | B26: ='بيانات الموظفين'!B10 -> 0 | C26: =IF('بيانات الموظفين'!C10="","-",'بيانات الموظفين'!C10) -> - | D26: =AG12 -> 0 | E26: =AH12 -> 0 | F26: =AL12 -> - | G26: =AI12 -> 0 | H26: =AJ12 -> - | I26: =AM12 -> -
A27: 7 | B27: ='بيانات الموظفين'!B11 -> 0 | C27: =IF('بيانات الموظفين'!C11="","-",'بيانات الموظفين'!C11) -> - | D27: =AG13 -> 0 | E27: =AH13 -> 0 | F27: =AL13 -> - | G27: =AI13 -> 0 | H27: =AJ13 -> - | I27: =AM13 -> -
A28: 8 | B28: ='بيانات الموظفين'!B12 -> 0 | C28: =IF('بيانات الموظفين'!C12="","-",'بيانات الموظفين'!C12) -> - | D28: =AG14 -> 0 | E28: =AH14 -> 0 | F28: =AL14 -> - | G28: =AI14 -> 0 | H28: =AJ14 -> - | I28: =AM14 -> -
A29: 9 | B29: ='بيانات الموظفين'!B13 -> 0 | C29: =IF('بيانات الموظفين'!C13="","-",'بيانات الموظفين'!C13) -> - | D29: =AG15 -> 0 | E29: =AH15 -> 0 | F29: =AL15 -> - | G29: =AI15 -> 0 | H29: =AJ15 -> - | I29: =AM15 -> -
A30: 10 | B30: ='بيانات الموظفين'!B14 -> 0 | C30: =IF('بيانات الموظفين'!C14="","-",'بيانات الموظفين'!C14) -> - | D30: =AG16 -> 0 | E30: =AH16 -> 0 | F30: =AL16 -> - | G30: =AI16 -> 0 | H30: =AJ16 -> - | I30: =AM16 -> -
A31: الإجمالي الكلي | C31: =SUM(C21:C30) -> 15300000 | D31: =SUM(D21:D30) -> 0 | E31: =SUM(E21:E30) -> 0 | F31: =SUM(F21:F30) -> 0 | G31: =SUM(G21:G30) -> 0 | H31: =SUM(H21:H30) -> 0 | I31: =SUM(I21:I30) -> 15810000

Sheet فبراير
A1: جدول ضبط الغياب وحساب الرواتب ◀ فبراير 2026
A2: فارغ=حضور | غ=غياب يوم | نصف=نصف يوم | رقم=ساعات إضافية | 🔴 الجمعة باللون الأحمر
A4: اسم الموظف | B4: الأحد | C4: الاثنين | D4: الثلاثاء | E4: الأربعاء | F4: الخميس | G4: الجمعة | H4: السبت | I4: الأحد | J4: الاثنين | K4: الثلاثاء | L4: الأربعاء | M4: الخميس | N4: الجمعة | O4: السبت | P4: الأحد | Q4: الاثنين | R4: الثلاثاء | S4: الأربعاء | T4: الخميس | U4: الجمعة | V4: السبت | W4: الأحد | X4: الاثنين | Y4: الثلاثاء | Z4: الأربعاء | AA4: الخميس | AB4: الجمعة | AC4: السبت | AD4: أيام الغياب | AE4: نصف يوم | AF4: ساعات إضافية | AG4: قيمة الإضافي | AH4: أيام العمل | AI4: خصم الغياب | AJ4: صافي الراتب
B5: 1 | C5: 2 | D5: 3 | E5: 4 | F5: 5 | G5: 6 | H5: 7 | I5: 8 | J5: 9 | K5: 10 | L5: 11 | M5: 12 | N5: 13 | O5: 14 | P5: 15 | Q5: 16 | R5: 17 | S5: 18 | T5: 19 | U5: 20 | V5: 21 | W5: 22 | X5: 23 | Y5: 24 | Z5: 25 | AA5: 26 | AB5: 27 | AC5: 28
A7: ='بيانات الموظفين'!B5 -> أبو بكر | AD7: =COUNTIF(B7:AC7,"غ") -> 0 | AE7: =COUNTIF(B7:AC7,"نصف") -> 0 | AF7: =SUMIF(B7:AC7,">"&0) -> 0 | AG7: =IF(OR('بيانات الموظفين'!C5="",NOT(ISNUMBER('بيانات الموظفين'!G2)),AF7=0),"-",ROUND(AF7*(('بيانات الموظفين'!C5/28)/'بيانات الموظفين'!G2),2)) -> - | AH7: =IF('بيانات الموظفين'!C5="","-",28-AD7-AE7*0.5) -> 28 | AI7: =IF('بيانات الموظفين'!C5="","-",ROUND(('بيانات الموظفين'!C5/28)*AD7+(('بيانات الموظفين'!C5/28)/2)*AE7,2)) -> 0 | AJ7: =IF('بيانات الموظفين'!C5="","-",ROUND('بيانات الموظفين'!C5+IF(ISNUMBER(AG7),AG7,0)-IF(ISNUMBER(AI7),AI7,0),2)) -> 7000000
A8: ='بيانات الموظفين'!B6 -> هيثم صمادي | AD8: =COUNTIF(B8:AC8,"غ") -> 0 | AE8: =COUNTIF(B8:AC8,"نصف") -> 0 | AF8: =SUMIF(B8:AC8,">"&0) -> 0 | AG8: =IF(OR('بيانات الموظفين'!C6="",NOT(ISNUMBER('بيانات الموظفين'!G2)),AF8=0),"-",ROUND(AF8*(('بيانات الموظفين'!C6/28)/'بيانات الموظفين'!G2),2)) -> - | AH8: =IF('بيانات الموظفين'!C6="","-",28-AD8-AE8*0.5) -> 28 | AI8: =IF('بيانات الموظفين'!C6="","-",ROUND(('بيانات الموظفين'!C6/28)*AD8+(('بيانات الموظفين'!C6/28)/2)*AE8,2)) -> 0 | AJ8: =IF('بيانات الموظفين'!C6="","-",ROUND('بيانات الموظفين'!C6+IF(ISNUMBER(AG8),AG8,0)-IF(ISNUMBER(AI8),AI8,0),2)) -> 3000000
A9: ='بيانات الموظفين'!B7 -> حسام كبريتة | AD9: =COUNTIF(B9:AC9,"غ") -> 0 | AE9: =COUNTIF(B9:AC9,"نصف") -> 0 | AF9: =SUMIF(B9:AC9,">"&0) -> 0 | AG9: =IF(OR('بيانات الموظفين'!C7="",NOT(ISNUMBER('بيانات الموظفين'!G2)),AF9=0),"-",ROUND(AF9*(('بيانات الموظفين'!C7/28)/'بيانات الموظفين'!G2),2)) -> - | AH9: =IF('بيانات الموظفين'!C7="","-",28-AD9-AE9*0.5) -> 28 | AI9: =IF('بيانات الموظفين'!C7="","-",ROUND(('بيانات الموظفين'!C7/28)*AD9+(('بيانات الموظفين'!C7/28)/2)*AE9,2)) -> 0 | AJ9: =IF('بيانات الموظفين'!C7="","-",ROUND('بيانات الموظفين'!C7+IF(ISNUMBER(AG9),AG9,0)-IF(ISNUMBER(AI9),AI9,0),2)) -> 2500000
A10: ='بيانات الموظفين'!B8 -> انس المنسي | AD10: =COUNTIF(B10:AC10,"غ") -> 0 | AE10: =COUNTIF(B10:AC10,"نصف") -> 0 | AF10: =SUMIF(B10:AC10,">"&0) -> 0 | AG10: =IF(OR('بيانات الموظفين'!C8="",NOT(ISNUMBER('بيانات الموظفين'!G2)),AF10=0),"-",ROUND(AF10*(('بيانات الموظفين'!C8/28)/'بيانات الموظفين'!G2),2)) -> - | AH10: =IF('بيانات الموظفين'!C8="","-",28-AD10-AE10*0.5) -> 28 | AI10: =IF('بيانات الموظفين'!C8="","-",ROUND(('بيانات الموظفين'!C8/28)*AD10+(('بيانات الموظفين'!C8/28)/2)*AE10,2)) -> 0 | AJ10: =IF('بيانات الموظفين'!C8="","-",ROUND('بيانات الموظفين'!C8+IF(ISNUMBER(AG10),AG10,0)-IF(ISNUMBER(AI10),AI10,0),2)) -> 800000
A11: ='بيانات الموظفين'!B9 -> عمار مجيد | AD11: =COUNTIF(B11:AC11,"غ") -> 0 | AE11: =COUNTIF(B11:AC11,"نصف") -> 0 | AF11: =SUMIF(B11:AC11,">"&0) -> 0 | AG11: =IF(OR('بيانات الموظفين'!C9="",NOT(ISNUMBER('بيانات الموظفين'!G2)),AF11=0),"-",ROUND(AF11*(('بيانات الموظفين'!C9/28)/'بيانات الموظفين'!G2),2)) -> - | AH11: =IF('بيانات الموظفين'!C9="","-",28-AD11-AE11*0.5) -> 28 | AI11: =IF('بيانات الموظفين'!C9="","-",ROUND(('بيانات الموظفين'!C9/28)*AD11+(('بيانات الموظفين'!C9/28)/2)*AE11,2)) -> 0 | AJ11: =IF('بيانات الموظفين'!C9="","-",ROUND('بيانات الموظفين'!C9+IF(ISNUMBER(AG11),AG11,0)-IF(ISNUMBER(AI11),AI11,0),2)) -> 2000000
A12: ='بيانات الموظفين'!B10 -> 0 | AD12: =COUNTIF(B12:AC12,"غ") -> 0 | AE12: =COUNTIF(B12:AC12,"نصف") -> 0 | AF12: =SUMIF(B12:AC12,">"&0) -> 0 | AG12: =IF(OR('بيانات الموظفين'!C10="",NOT(ISNUMBER('بيانات الموظفين'!G2)),AF12=0),"-",ROUND(AF12*(('بيانات الموظفين'!C10/28)/'بيانات الموظفين'!G2),2)) -> - | AH12: =IF('بيانات الموظفين'!C10="","-",28-AD12-AE12*0.5) -> - | AI12: =IF('بيانات الموظفين'!C10="","-",ROUND(('بيانات الموظفين'!C10/28)*AD12+(('بيانات الموظفين'!C10/28)/2)*AE12,2)) -> - | AJ12: =IF('بيانات الموظفين'!C10="","-",ROUND('بيانات الموظفين'!C10+IF(ISNUMBER(AG12),AG12,0)-IF(ISNUMBER(AI12),AI12,0),2)) -> -
A13: ='بيانات الموظفين'!B11 -> 0 | AD13: =COUNTIF(B13:AC13,"غ") -> 0 | AE13: =COUNTIF(B13:AC13,"نصف") -> 0 | AF13: =SUMIF(B13:AC13,">"&0) -> 0 | AG13: =IF(OR('بيانات الموظفين'!C11="",NOT(ISNUMBER('بيانات الموظفين'!G2)),AF13=0),"-",ROUND(AF13*(('بيانات الموظفين'!C11/28)/'بيانات الموظفين'!G2),2)) -> - | AH13: =IF('بيانات الموظفين'!C11="","-",28-AD13-AE13*0.5) -> - | AI13: =IF('بيانات الموظفين'!C11="","-",ROUND(('بيانات الموظفين'!C11/28)*AD13+(('بيانات الموظفين'!C11/28)/2)*AE13,2)) -> - | AJ13: =IF('بيانات الموظفين'!C11="","-",ROUND('بيانات الموظفين'!C11+IF(ISNUMBER(AG13),AG13,0)-IF(ISNUMBER(AI13),AI13,0),2)) -> -
A14: ='بيانات الموظفين'!B12 -> 0 | AD14: =COUNTIF(B14:AC14,"غ") -> 0 | AE14: =COUNTIF(B14:AC14,"نصف") -> 0 | AF14: =SUMIF(B14:AC14,">"&0) -> 0 | AG14: =IF(OR('بيانات الموظفين'!C12="",NOT(ISNUMBER('بيانات الموظفين'!G2)),AF14=0),"-",ROUND(AF14*(('بيانات الموظفين'!C12/28)/'بيانات الموظفين'!G2),2)) -> - | AH14: =IF('بيانات الموظفين'!C12="","-",28-AD14-AE14*0.5) -> - | AI14: =IF('بيانات الموظفين'!C12="","-",ROUND(('بيانات الموظفين'!C12/28)*AD14+(('بيانات الموظفين'!C12/28)/2)*AE14,2)) -> - | AJ14: =IF('بيانات الموظفين'!C12="","-",ROUND('بيانات الموظفين'!C12+IF(ISNUMBER(AG14),AG14,0)-IF(ISNUMBER(AI14),AI14,0),2)) -> -
A15: ='بيانات الموظفين'!B13 -> 0 | AD15: =COUNTIF(B15:AC15,"غ") -> 0 | AE15: =COUNTIF(B15:AC15,"نصف") -> 0 | AF15: =SUMIF(B15:AC15,">"&0) -> 0 | AG15: =IF(OR('بيانات الموظفين'!C13="",NOT(ISNUMBER('بيانات الموظفين'!G2)),AF15=0),"-",ROUND(AF15*(('بيانات الموظفين'!C13/28)/'بيانات الموظفين'!G2),2)) -> - | AH15: =IF('بيانات الموظفين'!C13="","-",28-AD15-AE15*0.5) -> - | AI15: =IF('بيانات الموظفين'!C13="","-",ROUND(('بيانات الموظفين'!C13/28)*AD15+(('بيانات الموظفين'!C13/28)/2)*AE15,2)) -> - | AJ15: =IF('بيانات الموظفين'!C13="","-",ROUND('بيانات الموظفين'!C13+IF(ISNUMBER(AG15),AG15,0)-IF(ISNUMBER(AI15),AI15,0),2)) -> -
A16: ='بيانات الموظفين'!B14 -> 0 | AD16: =COUNTIF(B16:AC16,"غ") -> 0 | AE16: =COUNTIF(B16:AC16,"نصف") -> 0 | AF16: =SUMIF(B16:AC16,">"&0) -> 0 | AG16: =IF(OR('بيانات الموظفين'!C14="",NOT(ISNUMBER('بيانات الموظفين'!G2)),AF16=0),"-",ROUND(AF16*(('بيانات الموظفين'!C14/28)/'بيانات الموظفين'!G2),2)) -> - | AH16: =IF('بيانات الموظفين'!C14="","-",28-AD16-AE16*0.5) -> - | AI16: =IF('بيانات الموظفين'!C14="","-",ROUND(('بيانات الموظفين'!C14/28)*AD16+(('بيانات الموظفين'!C14/28)/2)*AE16,2)) -> - | AJ16: =IF('بيانات الموظفين'!C14="","-",ROUND('بيانات الموظفين'!C14+IF(ISNUMBER(AG16),AG16,0)-IF(ISNUMBER(AI16),AI16,0),2)) -> -
A17: إجمالي الغياب اليومي — فبراير | B17: =COUNTIF(B7:B16,"غ")+COUNTIF(B7:B16,"نصف")*0.5 -> 0 | C17: =COUNTIF(C7:C16,"غ")+COUNTIF(C7:C16,"نصف")*0.5 -> 0 | D17: =COUNTIF(D7:D16,"غ")+COUNTIF(D7:D16,"نصف")*0.5 -> 0 | E17: =COUNTIF(E7:E16,"غ")+COUNTIF(E7:E16,"نصف")*0.5 -> 0 | F17: =COUNTIF(F7:F16,"غ")+COUNTIF(F7:F16,"نصف")*0.5 -> 0 | G17: =COUNTIF(G7:G16,"غ")+COUNTIF(G7:G16,"نصف")*0.5 -> 0 | H17: =COUNTIF(H7:H16,"غ")+COUNTIF(H7:H16,"نصف")*0.5 -> 0 | I17: =COUNTIF(I7:I16,"غ")+COUNTIF(I7:I16,"نصف")*0.5 -> 0 | ... AC17: =COUNTIF(AC7:AC16,"غ")+COUNTIF(AC7:AC16,"نصف")*0.5 -> 0 | AD17: =SUM(AD7:AD16) -> 0 | AE17: =SUM(AE7:AE16) -> 0 | AF17: =SUM(AF7:AF16) -> 0 | AG17: =SUM(AG7:AG16) -> 0 | AI17: =SUM(AI7:AI16) -> 0 | AJ17: =SUM(AJ7:AJ16) -> 15300000
A19: 📊 الملخص الشهري للرواتب — فبراير 2026
A20: # | B20: اسم الموظف | C20: الراتب الأساسي | D20: أيام الغياب | E20: نصف يوم | F20: خصم الغياب | G20: ساعات إضافية | H20: قيمة الإضافي | I20: صافي الراتب
A21: 1 | B21: ='بيانات الموظفين'!B5 -> أبو بكر | C21: =IF('بيانات الموظفين'!C5="","-",'بيانات الموظفين'!C5) -> 7000000 | D21: =AD7 -> 0 | E21: =AE7 -> 0 | F21: =AI7 -> 0 | G21: =AF7 -> 0 | H21: =AG7 -> - | I21: =AJ7 -> 7000000
A22: 2 | B22: ='بيانات الموظفين'!B6 -> هيثم صمادي | C22: =IF('بيانات الموظفين'!C6="","-",'بيانات الموظفين'!C6) -> 3000000 | D22: =AD8 -> 0 | E22: =AE8 -> 0 | F22: =AI8 -> 0 | G22: =AF8 -> 0 | H22: =AG8 -> - | I22: =AJ8 -> 3000000
A23: 3 | B23: ='بيانات الموظفين'!B7 -> حسام كبريتة | C23: =IF('بيانات الموظفين'!C7="","-",'بيانات الموظفين'!C7) -> 2500000 | D23: =AD9 -> 0 | E23: =AE9 -> 0 | F23: =AI9 -> 0 | G23: =AF9 -> 0 | H23: =AG9 -> - | I23: =AJ9 -> 2500000
A24: 4 | B24: ='بيانات الموظفين'!B8 -> انس المنسي | C24: =IF('بيانات الموظفين'!C8="","-",'بيانات الموظفين'!C8) -> 800000 | D24: =AD10 -> 0 | E24: =AE10 -> 0 | F24: =AI10 -> 0 | G24: =AF10 -> 0 | H24: =AG10 -> - | I24: =AJ10 -> 800000
A25: 5 | B25: ='بيانات الموظفين'!B9 -> عمار مجيد | C25: =IF('بيانات الموظفين'!C9="","-",'بيانات الموظفين'!C9) -> 2000000 | D25: =AD11 -> 0 | E25: =AE11 -> 0 | F25: =AI11 -> 0 | G25: =AF11 -> 0 | H25: =AG11 -> - | I25: =AJ11 -> 2000000
A26: 6 | B26: ='بيانات الموظفين'!B10 -> 0 | C26: =IF('بيانات الموظفين'!C10="","-",'بيانات الموظفين'!C10) -> - | D26: =AD12 -> 0 | E26: =AE12 -> 0 | F26: =AI12 -> - | G26: =AF12 -> 0 | H26: =AG12 -> - | I26: =AJ12 -> -
A27: 7 | B27: ='بيانات الموظفين'!B11 -> 0 | C27: =IF('بيانات الموظفين'!C11="","-",'بيانات الموظفين'!C11) -> - | D27: =AD13 -> 0 | E27: =AE13 -> 0 | F27: =AI13 -> - | G27: =AF13 -> 0 | H27: =AG13 -> - | I27: =AJ13 -> -
A28: 8 | B28: ='بيانات الموظفين'!B12 -> 0 | C28: =IF('بيانات الموظفين'!C12="","-",'بيانات الموظفين'!C12) -> - | D28: =AD14 -> 0 | E28: =AE14 -> 0 | F28: =AI14 -> - | G28: =AF14 -> 0 | H28: =AG14 -> - | I28: =AJ14 -> -
A29: 9 | B29: ='بيانات الموظفين'!B13 -> 0 | C29: =IF('بيانات الموظفين'!C13="","-",'بيانات الموظفين'!C13) -> - | D29: =AD15 -> 0 | E29: =AE15 -> 0 | F29: =AI15 -> - | G29: =AF15 -> 0 | H29: =AG15 -> - | I29: =AJ15 -> -
A30: 10 | B30: ='بيانات الموظفين'!B14 -> 0 | C30: =IF('بيانات الموظفين'!C14="","-",'بيانات الموظفين'!C14) -> - | D30: =AD16 -> 0 | E30: =AE16 -> 0 | F30: =AI16 -> - | G30: =AF16 -> 0 | H30: =AG16 -> - | I30: =AJ16 -> -
A31: الإجمالي الكلي | C31: =SUM(C21:C30) -> 15300000 | D31: =SUM(D21:D30) -> 0 | E31: =SUM(E21:E30) -> 0 | F31: =SUM(F21:F30) -> 0 | G31: =SUM(G21:G30) -> 0 | H31: =SUM(H21:H30) -> 0 | I31: =SUM(I21:I30) -> 15300000

Sheet مارس
A1: جدول ضبط الغياب وحساب الرواتب ◀ مارس 2026 ★ يوم إضافي مضاف
A2: فارغ=حضور | غ=غياب يوم | نصف=نصف يوم | رقم=ساعات إضافية | 🔴 الجمعة باللون الأحمر
A4: اسم الموظف | B4: الأحد | C4: الاثنين | D4: الثلاثاء | E4: الأربعاء | F4: الخميس | G4: الجمعة | H4: السبت | I4: الأحد | J4: الاثنين | K4: الثلاثاء | L4: الأربعاء | M4: الخميس | N4: الجمعة | O4: السبت | P4: الأحد | Q4: الاثنين | R4: الثلاثاء | S4: الأربعاء | T4: الخميس | U4: الجمعة | V4: السبت | W4: الأحد | X4: الاثنين | Y4: الثلاثاء | Z4: الأربعاء | AA4: الخميس | AB4: الجمعة | AC4: السبت | AD4: الأحد | AE4: الاثنين | AF4: الثلاثاء | AG4: أيام الغياب | AH4: نصف يوم | AI4: ساعات إضافية | AJ4: قيمة الإضافي | AK4: أيام العمل | AL4: خصم الغياب | AM4: صافي الراتب
B5: 1 | C5: 2 | D5: 3 | E5: 4 | F5: 5 | G5: 6 | H5: 7 | I5: 8 | J5: 9 | K5: 10 | L5: 11 | M5: 12 | N5: 13 | O5: 14 | P5: 15 | Q5: 16 | R5: 17 | S5: 18 | T5: 19 | U5: 20 | V5: 21 | W5: 22 | X5: 23 | Y5: 24 | Z5: 25 | AA5: 26 | AB5: 27 | AC5: 28 | AD5: 29 | AE5: 30 | AF5: 31
A7: ='بيانات الموظفين'!B5 -> أبو بكر | AG7: =COUNTIF(B7:AF7,"غ") -> 0 | AH7: =COUNTIF(B7:AF7,"نصف") -> 0 | AI7: =SUMIF(B7:AF7,">"&0) -> 0 | AJ7: =IF(OR('بيانات الموظفين'!C5="",NOT(ISNUMBER('بيانات الموظفين'!G2)),AI7=0),"-",ROUND(AI7*(('بيانات الموظفين'!C5/31)/'بيانات الموظفين'!G2),2)) -> - | AK7: =IF('بيانات الموظفين'!C5="","-",31-AG7-AH7*0.5) -> 31 | AL7: =IF('بيانات الموظفين'!C5="","-",ROUND(('بيانات الموظفين'!C5/31)*AG7+(('بيانات الموظفين'!C5/31)/2)*AH7,2)) -> 0 | AM7: =IF('بيانات الموظفين'!C5="","-",ROUND('بيانات الموظفين'!C5+ROUND('بيانات الموظفين'!C5/30,2)+IF(ISNUMBER(AJ7),AJ7,0)-IF(ISNUMBER(AL7),AL7,0),2)) -> 7233333.3
A8: ='بيانات الموظفين'!B6 -> هيثم صمادي | AG8: =COUNTIF(B8:AF8,"غ") -> 0 | AH8: =COUNTIF(B8:AF8,"نصف") -> 0 | AI8: =SUMIF(B8:AF8,">"&0) -> 0 | AJ8: =IF(OR('بيانات الموظفين'!C6="",NOT(ISNUMBER('بيانات الموظفين'!G2)),AI8=0),"-",ROUND(AI8*(('بيانات الموظفين'!C6/31)/'بيانات الموظفين'!G2),2)) -> - | AK8: =IF('بيانات الموظفين'!C6="","-",31-AG8-AH8*0.5) -> 31 | AL8: =IF('بيانات الموظفين'!C6="","-",ROUND(('بيانات الموظفين'!C6/31)*AG8+(('بيانات الموظفين'!C6/31)/2)*AH8,2)) -> 0 | AM8: =IF('بيانات الموظفين'!C6="","-",ROUND('بيانات الموظفين'!C6+ROUND('بيانات الموظفين'!C6/30,2)+IF(ISNUMBER(AJ8),AJ8,0)-IF(ISNUMBER(AL8),AL8,0),2)) -> 3100000
A9: ='بيانات الموظفين'!B7 -> حسام كبريتة | AG9: =COUNTIF(B9:AF9,"غ") -> 0 | AH9: =COUNTIF(B9:AF9,"نصف") -> 0 | AI9: =SUMIF(B9:AF9,">"&0) -> 0 | AJ9: =IF(OR('بيانات الموظفين'!C7="",NOT(ISNUMBER('بيانات الموظفين'!G2)),AI9=0),"-",ROUND(AI9*(('بيانات الموظفين'!C7/31)/'بيانات الموظفين'!G2),2)) -> - | AK9: =IF('بيانات الموظفين'!C7="","-",31-AG9-AH9*0.5) -> 31 | AL9: =IF('بيانات الموظفين'!C7="","-",ROUND(('بيانات الموظفين'!C7/31)*AG9+(('بيانات الموظفين'!C7/31)/2)*AH9,2)) -> 0 | AM9: =IF('بيانات الموظفين'!C7="","-",ROUND('بيانات الموظفين'!C7+ROUND('بيانات الموظفين'!C7/30,2)+IF(ISNUMBER(AJ9),AJ9,0)-IF(ISNUMBER(AL9),AL9,0),2)) -> 2583333.3
A10: ='بيانات الموظفين'!B8 -> انس المنسي | AG10: =COUNTIF(B10:AF10,"غ") -> 0 | AH10: =COUNTIF(B10:AF10,"نصف") -> 0 | AI10: =SUMIF(B10:AF10,">"&0) -> 0 | AJ10: =IF(OR('بيانات الموظفين'!C8="",NOT(ISNUMBER('بيانات الموظفين'!G2)),AI10=0),"-",ROUND(AI10*(('بيانات الموظفين'!C8/31)/'بيانات الموظفين'!G2),2)) -> - | AK10: =IF('بيانات الموظفين'!C8="","-",31-AG10-AH10*0.5) -> 31 | AL10: =IF('بيانات الموظفين'!C8="","-",ROUND(('بيانات الموظفين'!C8/31)*AG10+(('بيانات الموظفين'!C8/31)/2)*AH10,2)) -> 0 | AM10: =IF('بيانات الموظفين'!C8="","-",ROUND('بيانات الموظفين'!C8+ROUND('بيانات الموظفين'!C8/30,2)+IF(ISNUMBER(AJ10),AJ10,0)-IF(ISNUMBER(AL10),AL10,0),2)) -> 826666.67
A11: ='بيانات الموظفين'!B9 -> عمار مجيد | AG11: =COUNTIF(B11:AF11,"غ") -> 0 | AH11: =COUNTIF(B11:AF11,"نصف") -> 0 | AI11: =SUMIF(B11:AF11,">"&0) -> 0 | AJ11: =IF(OR('بيانات الموظفين'!C9="",NOT(ISNUMBER('بيانات الموظفين'!G2)),AI11=0),"-",ROUND(AI11*(('بيانات الموظفين'!C9/31)/'بيانات الموظفين'!G2),2)) -> - | AK11: =IF('بيانات الموظفين'!C9="","-",31-AG11-AH11*0.5) -> 31 | AL11: =IF('بيانات الموظفين'!C9="","-",ROUND(('بيانات الموظفين'!C9/31)*AG11+(('بيانات الموظفين'!C9/31)/2)*AH11,2)) -> 0 | AM11: =IF('بيانات الموظفين'!C9="","-",ROUND('بيانات الموظفين'!C9+ROUND('بيانات الموظفين'!C9/30,2)+IF(ISNUMBER(AJ11),AJ11,0)-IF(ISNUMBER(AL11),AL11,0),2)) -> 2066666.7
A12: ='بيانات الموظفين'!B10 -> 0 | AG12: =COUNTIF(B12:AF12,"غ") -> 0 | AH12: =COUNTIF(B12:AF12,"نصف") -> 0 | AI12: =SUMIF(B12:AF12,">"&0) -> 0 | AJ12: =IF(OR('بيانات الموظفين'!C10="",NOT(ISNUMBER('بيانات الموظفين'!G2)),AI12=0),"-",ROUND(AI12*(('بيانات الموظفين'!C10/31)/'بيانات الموظفين'!G2),2)) -> - | AK12: =IF('بيانات الموظفين'!C10="","-",31-AG12-AH12*0.5) -> - | AL12: =IF('بيانات الموظفين'!C10="","-",ROUND(('بيانات الموظفين'!C10/31)*AG12+(('بيانات الموظفين'!C10/31)/2)*AH12,2)) -> - | AM12: =IF('بيانات الموظفين'!C10="","-",ROUND('بيانات الموظفين'!C10+ROUND('بيانات الموظفين'!C10/30,2)+IF(ISNUMBER(AJ12),AJ12,0)-IF(ISNUMBER(AL12),AL12,0),2)) -> -
A13: ='بيانات الموظفين'!B11 -> 0 | AG13: =COUNTIF(B13:AF13,"غ") -> 0 | AH13: =COUNTIF(B13:AF13,"نصف") -> 0 | AI13: =SUMIF(B13:AF13,">"&0) -> 0 | AJ13: =IF(OR('بيانات الموظفين'!C11="",NOT(ISNUMBER('بيانات الموظفين'!G2)),AI13=0),"-",ROUND(AI13*(('بيانات الموظفين'!C11/31)/'بيانات الموظفين'!G2),2)) -> - | AK13: =IF('بيانات الموظفين'!C11="","-",31-AG13-AH13*0.5) -> - | AL13: =IF('بيانات الموظفين'!C11="","-",ROUND(('بيانات الموظفين'!C11/31)*AG13+(('بيانات الموظفين'!C11/31)/2)*AH13,2)) -> - | AM13: =IF('بيانات الموظفين'!C11="","-",ROUND('بيانات الموظفين'!C11+ROUND('بيانات الموظفين'!C11/30,2)+IF(ISNUMBER(AJ13),AJ13,0)-IF(ISNUMBER(AL13),AL13,0),2)) -> -
A14: ='بيانات الموظفين'!B12 -> 0 | AG14: =COUNTIF(B14:AF14,"غ") -> 0 | AH14: =COUNTIF(B14:AF14,"نصف") -> 0 | AI14: =SUMIF(B14:AF14,">"&0) -> 0 | AJ14: =IF(OR('بيانات الموظفين'!C12="",NOT(ISNUMBER('بيانات الموظفين'!G2)),AI14=0),"-",ROUND(AI14*(('بيانات الموظفين'!C12/31)/'بيانات الموظفين'!G2),2)) -> - | AK14: =IF('بيانات الموظفين'!C12="","-",31-AG14-AH14*0.5) -> - | AL14: =IF('بيانات الموظفين'!C12="","-",ROUND(('بيانات الموظفين'!C12/31)*AG14+(('بيانات الموظفين'!C12/31)/2)*AH14,2)) -> - | AM14: =IF('بيانات الموظفين'!C12="","-",ROUND('بيانات الموظفين'!C12+ROUND('بيانات الموظفين'!C12/30,2)+IF(ISNUMBER(AJ14),AJ14,0)-IF(ISNUMBER(AL14),AL14,0),2)) -> -
A15: ='بيانات الموظفين'!B13 -> 0 | AG15: =COUNTIF(B15:AF15,"غ") -> 0 | AH15: =COUNTIF(B15:AF15,"نصف") -> 0 | AI15: =SUMIF(B15:AF15,">"&0) -> 0 | AJ15: =IF(OR('بيانات الموظفين'!C13="",NOT(ISNUMBER('بيانات الموظفين'!G2)),AI15=0),"-",ROUND(AI15*(('بيانات الموظفين'!C13/31)/'بيانات الموظفين'!G2),2)) -> - | AK15: =IF('بيانات الموظفين'!C13="","-",31-AG15-AH15*0.5) -> - | AL15: =IF('بيانات الموظفين'!C13="","-",ROUND(('بيانات الموظفين'!C13/31)*AG15+(('بيانات الموظفين'!C13/31)/2)*AH15,2)) -> - | AM15: =IF('بيانات الموظفين'!C13="","-",ROUND('بيانات الموظفين'!C13+ROUND('بيانات الموظفين'!C13/30,2)+IF(ISNUMBER(AJ15),AJ15,0)-IF(ISNUMBER(AL15),AL15,0),2)) -> -
A16: ='بيانات الموظفين'!B14 -> 0 | AG16: =COUNTIF(B16:AF16,"غ") -> 0 | AH16: =COUNTIF(B16:AF16,"نصف") -> 0 | AI16: =SUMIF(B16:AF16,">"&0) -> 0 | AJ16: =IF(OR('بيانات الموظفين'!C14="",NOT(ISNUMBER('بيانات الموظفين'!G2)),AI16=0),"-",ROUND(AI16*(('بيانات الموظفين'!C14/31)/'بيانات الموظفين'!G2),2)) -> - | AK16: =IF('بيانات الموظفين'!C14="","-",31-AG16-AH16*0.5) -> - | AL16: =IF('بيانات الموظفين'!C14="","-",ROUND(('بيانات الموظفين'!C14/31)*AG16+(('بيانات الموظفين'!C14/31)/2)*AH16,2)) -> - | AM16: =IF('بيانات الموظفين'!C14="","-",ROUND('بيانات الموظفين'!C14+ROUND('بيانات الموظفين'!C14/30,2)+IF(ISNUMBER(AJ16),AJ16,0)-IF(ISNUMBER(AL16),AL16,0),2)) -> -
A17: إجمالي الغياب اليومي — مارس | B17: =COUNTIF(B7:B16,"غ")+COUNTIF(B7:B16,"نصف")*0.5 -> 0 | C17: =COUNTIF(C7:C16,"غ")+COUNTIF(C7:C16,"نصف")*0.5 -> 0 | D17: =COUNTIF(D7:D16,"غ")+COUNTIF(D7:D16,"نصف")*0.5 -> 0 | E17: =COUNTIF(E7:E16,"غ")+COUNTIF(E7:E16,"نصف")*0.5 -> 0 | F17: =COUNTIF(F7:F16,"غ")+COUNTIF(F7:F16,"نصف")*0.5 -> 0 | G17: =COUNTIF(G7:G16,"غ")+COUNTIF(G7:G16,"نصف")*0.5 -> 0 | H17: =COUNTIF(H7:H16,"غ")+COUNTIF(H7:H16,"نصف")*0.5 -> 0 | I17: =COUNTIF(I7:I16,"غ")+COUNTIF(I7:I16,"نصف")*0.5 -> 0 | ... AF17: =COUNTIF(AF7:AF16,"غ")+COUNTIF(AF7:AF16,"نصف")*0.5 -> 0 | AG17: =SUM(AG7:AG16) -> 0 | AH17: =SUM(AH7:AH16) -> 0 | AI17: =SUM(AI7:AI16) -> 0 | AJ17: =SUM(AJ7:AJ16) -> 0 | AL17: =SUM(AL7:AL16) -> 0 | AM17: =SUM(AM7:AM16) -> 15810000
A19: 📊 الملخص الشهري للرواتب — مارس 2026
A20: # | B20: اسم الموظف | C20: الراتب الأساسي | D20: أيام الغياب | E20: نصف يوم | F20: خصم الغياب | G20: ساعات إضافية | H20: قيمة الإضافي | I20: صافي الراتب
A21: 1 | B21: ='بيانات الموظفين'!B5 -> أبو بكر | C21: =IF('بيانات الموظفين'!C5="","-",'بيانات الموظفين'!C5) -> 7000000 | D21: =AG7 -> 0 | E21: =AH7 -> 0 | F21: =AL7 -> 0 | G21: =AI7 -> 0 | H21: =AJ7 -> - | I21: =AM7 -> 7233333.3
A22: 2 | B22: ='بيانات الموظفين'!B6 -> هيثم صمادي | C22: =IF('بيانات الموظفين'!C6="","-",'بيانات الموظفين'!C6) -> 3000000 | D22: =AG8 -> 0 | E22: =AH8 -> 0 | F22: =AL8 -> 0 | G22: =AI8 -> 0 | H22: =AJ8 -> - | I22: =AM8 -> 3100000
A23: 3 | B23: ='بيانات الموظفين'!B7 -> حسام كبريتة | C23: =IF('بيانات الموظفين'!C7="","-",'بيانات الموظفين'!C7) -> 2500000 | D23: =AG9 -> 0 | E23: =AH9 -> 0 | F23: =AL9 -> 0 | G23: =AI9 -> 0 | H23: =AJ9 -> - | I23: =AM9 -> 2583333.3
A24: 4 | B24: ='بيانات الموظفين'!B8 -> انس المنسي | C24: =IF('بيانات الموظفين'!C8="","-",'بيانات الموظفين'!C8) -> 800000 | D24: =AG10 -> 0 | E24: =AH10 -> 0 | F24: =AL10 -> 0 | G24: =AI10 -> 0 | H24: =AJ10 -> - | I24: =AM10 -> 826666.67
A25: 5 | B25: ='بيانات الموظفين'!B9 -> عمار مجيد | C25: =IF('بيانات الموظفين'!C9="","-",'بيانات الموظفين'!C9) -> 2000000 | D25: =AG11 -> 0 | E25: =AH11 -> 0 | F25: =AL11 -> 0 | G25: =AI11 -> 0 | H25: =AJ11 -> - | I25: =AM11 -> 2066666.7
A26: 6 | B26: ='بيانات الموظفين'!B10 -> 0 | C26: =IF('بيانات الموظفين'!C10="","-",'بيانات الموظفين'!C10) -> - | D26: =AG12 -> 0 | E26: =AH12 -> 0 | F26: =AL12 -> - | G26: =AI12 -> 0 | H26: =AJ12 -> - | I26: =AM12 -> -
A27: 7 | B27: ='بيانات الموظفين'!B11 -> 0 | C27: =IF('بيانات الموظفين'!C11="","-",'بيانات الموظفين'!C11) -> - | D27: =AG13 -> 0 | E27: =AH13 -> 0 | F27: =AL13 -> - | G27: =AI13 -> 0 | H27: =AJ13 -> - | I27: =AM13 -> -
A28: 8 | B28: ='بيانات الموظفين'!B12 -> 0 | C28: =IF('بيانات الموظفين'!C12="","-",'بيانات الموظفين'!C12) -> - | D28: =AG14 -> 0 | E28: =AH14 -> 0 | F28: =AL14 -> - | G28: =AI14 -> 0 | H28: =AJ14 -> - | I28: =AM14 -> -
A29: 9 | B29: ='بيانات الموظفين'!B13 -> 0 | C29: =IF('بيانات الموظفين'!C13="","-",'بيانات الموظفين'!C13) -> - | D29: =AG15 -> 0 | E29: =AH15 -> 0 | F29: =AL15 -> - | G29: =AI15 -> 0 | H29: =AJ15 -> - | I29: =AM15 -> -
A30: 10 | B30: ='بيانات الموظفين'!B14 -> 0 | C30: =IF('بيانات الموظفين'!C14="","-",'بيانات الموظفين'!C14) -> - | D30: =AG16 -> 0 | E30: =AH16 -> 0 | F30: =AL16 -> - | G30: =AI16 -> 0 | H30: =AJ16 -> - | I30: =AM16 -> -
A31: الإجمالي الكلي | C31: =SUM(C21:C30) -> 15300000 | D31: =SUM(D21:D30) -> 0 | E31: =SUM(E21:E30) -> 0 | F31: =SUM(F21:F30) -> 0 | G31: =SUM(G21:G30) -> 0 | H31: =SUM(H21:H30) -> 0 | I31: =SUM(I21:I30) -> 15810000

Sheet أبريل
A1: جدول ضبط الغياب وحساب الرواتب ◀ أبريل 2026
A2: فارغ=حضور | غ=غياب يوم | نصف=نصف يوم | رقم=ساعات إضافية | 🔴 الجمعة باللون الأحمر
A4: اسم الموظف | B4: الأربعاء | C4: الخميس | D4: الجمعة | E4: السبت | F4: الأحد | G4: الاثنين | H4: الثلاثاء | I4: الأربعاء | J4: الخميس | K4: الجمعة | L4: السبت | M4: الأحد | N4: الاثنين | O4: الثلاثاء | P4: الأربعاء | Q4: الخميس | R4: الجمعة | S4: السبت | T4: الأحد | U4: الاثنين | V4: الثلاثاء | W4: الأربعاء | X4: الخميس | Y4: الجمعة | Z4: السبت | AA4: الأحد | AB4: الاثنين | AC4: الثلاثاء | AD4: الأربعاء | AE4: الخميس | AF4: أيام الغياب | AG4: نصف يوم | AH4: ساعات إضافية | AI4: قيمة الإضافي | AJ4: أيام العمل | AK4: خصم الغياب | AL4: صافي الراتب
B5: 1 | C5: 2 | D5: 3 | E5: 4 | F5: 5 | G5: 6 | H5: 7 | I5: 8 | J5: 9 | K5: 10 | L5: 11 | M5: 12 | N5: 13 | O5: 14 | P5: 15 | Q5: 16 | R5: 17 | S5: 18 | T5: 19 | U5: 20 | V5: 21 | W5: 22 | X5: 23 | Y5: 24 | Z5: 25 | AA5: 26 | AB5: 27 | AC5: 28 | AD5: 29 | AE5: 30
A7: ='بيانات الموظفين'!B5 -> أبو بكر | AF7: =COUNTIF(B7:AE7,"غ") -> 0 | AG7: =COUNTIF(B7:AE7,"نصف") -> 0 | AH7: =SUMIF(B7:AE7,">"&0) -> 0 | AI7: =IF(OR('بيانات الموظفين'!C5="",NOT(ISNUMBER('بيانات الموظفين'!G2)),AH7=0),"-",ROUND(AH7*(('بيانات الموظفين'!C5/30)/'بيانات الموظفين'!G2),2)) -> - | AJ7: =IF('بيانات الموظفين'!C5="","-",30-AF7-AG7*0.5) -> 30 | AK7: =IF('بيانات الموظفين'!C5="","-",ROUND(('بيانات الموظفين'!C5/30)*AF7+(('بيانات الموظفين'!C5/30)/2)*AG7,2)) -> 0 | AL7: =IF('بيانات الموظفين'!C5="","-",ROUND('بيانات الموظفين'!C5+IF(ISNUMBER(AI7),AI7,0)-IF(ISNUMBER(AK7),AK7,0),2)) -> 7000000
A8: ='بيانات الموظفين'!B6 -> هيثم صمادي | AF8: =COUNTIF(B8:AE8,"غ") -> 0 | AG8: =COUNTIF(B8:AE8,"نصف") -> 0 | AH8: =SUMIF(B8:AE8,">"&0) -> 0 | AI8: =IF(OR('بيانات الموظفين'!C6="",NOT(ISNUMBER('بيانات الموظفين'!G2)),AH8=0),"-",ROUND(AH8*(('بيانات الموظفين'!C6/30)/'بيانات الموظفين'!G2),2)) -> - | AJ8: =IF('بيانات الموظفين'!C6="","-",30-AF8-AG8*0.5) -> 30 | AK8: =IF('بيانات الموظفين'!C6="","-",ROUND(('بيانات الموظفين'!C6/30)*AF8+(('بيانات الموظفين'!C6/30)/2)*AG8,2)) -> 0 | AL8: =IF('بيانات الموظفين'!C6="","-",ROUND('بيانات الموظفين'!C6+IF(ISNUMBER(AI8),AI8,0)-IF(ISNUMBER(AK8),AK8,0),2)) -> 3000000
A9: ='بيانات الموظفين'!B7 -> حسام كبريتة | AF9: =COUNTIF(B9:AE9,"غ") -> 0 | AG9: =COUNTIF(B9:AE9,"نصف") -> 0 | AH9: =SUMIF(B9:AE9,">"&0) -> 0 | AI9: =IF(OR('بيانات الموظفين'!C7="",NOT(ISNUMBER('بيانات الموظفين'!G2)),AH9=0),"-",ROUND(AH9*(('بيانات الموظفين'!C7/30)/'بيانات الموظفين'!G2),2)) -> - | AJ9: =IF('بيانات الموظفين'!C7="","-",30-AF9-AG9*0.5) -> 30 | AK9: =IF('بيانات الموظفين'!C7="","-",ROUND(('بيانات الموظفين'!C7/30)*AF9+(('بيانات الموظفين'!C7/30)/2)*AG9,2)) -> 0 | AL9: =IF('بيانات الموظفين'!C7="","-",ROUND('بيانات الموظفين'!C7+IF(ISNUMBER(AI9),AI9,0)-IF(ISNUMBER(AK9),AK9,0),2)) -> 2500000
A10: ='بيانات الموظفين'!B8 -> انس المنسي | AF10: =COUNTIF(B10:AE10,"غ") -> 0 | AG10: =COUNTIF(B10:AE10,"نصف") -> 0 | AH10: =SUMIF(B10:AE10,">"&0) -> 0 | AI10: =IF(OR('بيانات الموظفين'!C8="",NOT(ISNUMBER('بيانات الموظفين'!G2)),AH10=0),"-",ROUND(AH10*(('بيانات الموظفين'!C8/30)/'بيانات الموظفين'!G2),2)) -> - | AJ10: =IF('بيانات الموظفين'!C8="","-",30-AF10-AG10*0.5) -> 30 | AK10: =IF('بيانات الموظفين'!C8="","-",ROUND(('بيانات الموظفين'!C8/30)*AF10+(('بيانات الموظفين'!C8/30)/2)*AG10,2)) -> 0 | AL10: =IF('بيانات الموظفين'!C8="","-",ROUND('بيانات الموظفين'!C8+IF(ISNUMBER(AI10),AI10,0)-IF(ISNUMBER(AK10),AK10,0),2)) -> 800000
A11: ='بيانات الموظفين'!B9 -> عمار مجيد | AF11: =COUNTIF(B11:AE11,"غ") -> 0 | AG11: =COUNTIF(B11:AE11,"نصف") -> 0 | AH11: =SUMIF(B11:AE11,">"&0) -> 0 | AI11: =IF(OR('بيانات الموظفين'!C9="",NOT(ISNUMBER('بيانات الموظفين'!G2)),AH11=0),"-",ROUND(AH11*(('بيانات الموظفين'!C9/30)/'بيانات الموظفين'!G2),2)) -> - | AJ11: =IF('بيانات الموظفين'!C9="","-",30-AF11-AG11*0.5) -> 30 | AK11: =IF('بيانات الموظفين'!C9="","-",ROUND(('بيانات الموظفين'!C9/30)*AF11+(('بيانات الموظفين'!C9/30)/2)*AG11,2)) -> 0 | AL11: =IF('بيانات الموظفين'!C9="","-",ROUND('بيانات الموظفين'!C9+IF(ISNUMBER(AI11),AI11,0)-IF(ISNUMBER(AK11),AK11,0),2)) -> 2000000
A12: ='بيانات الموظفين'!B10 -> 0 | AF12: =COUNTIF(B12:AE12,"غ") -> 0 | AG12: =COUNTIF(B12:AE12,"نصف") -> 0 | AH12: =SUMIF(B12:AE12,">"&0) -> 0 | AI12: =IF(OR('بيانات الموظفين'!C10="",NOT(ISNUMBER('بيانات الموظفين'!G2)),AH12=0),"-",ROUND(AH12*(('بيانات الموظفين'!C10/30)/'بيانات الموظفين'!G2),2)) -> - | AJ12: =IF('بيانات الموظفين'!C10="","-",30-AF12-AG12*0.5) -> - | AK12: =IF('بيانات الموظفين'!C10="","-",ROUND(('بيانات الموظفين'!C10/30)*AF12+(('بيانات الموظفين'!C10/30)/2)*AG12,2)) -> - | AL12: =IF('بيانات الموظفين'!C10="","-",ROUND('بيانات الموظفين'!C10+IF(ISNUMBER(AI12),AI12,0)-IF(ISNUMBER(AK12),AK12,0),2)) -> -
A13: ='بيانات الموظفين'!B11 -> 0 | AF13: =COUNTIF(B13:AE13,"غ") -> 0 | AG13: =COUNTIF(B13:AE13,"نصف") -> 0 | AH13: =SUMIF(B13:AE13,">"&0) -> 0 | AI13: =IF(OR('بيانات الموظفين'!C11="",NOT(ISNUMBER('بيانات الموظفين'!G2)),AH13=0),"-",ROUND(AH13*(('بيانات الموظفين'!C11/30)/'بيانات الموظفين'!G2),2)) -> - | AJ13: =IF('بيانات الموظفين'!C11="","-",30-AF13-AG13*0.5) -> - | AK13: =IF('بيانات الموظفين'!C11="","-",ROUND(('بيانات الموظفين'!C11/30)*AF13+(('بيانات الموظفين'!C11/30)/2)*AG13,2)) -> - | AL13: =IF('بيانات الموظفين'!C11="","-",ROUND('بيانات الموظفين'!C11+IF(ISNUMBER(AI13),AI13,0)-IF(ISNUMBER(AK13),AK13,0),2)) -> -
A14: ='بيانات الموظفين'!B12 -> 0 | AF14: =COUNTIF(B14:AE14,"غ") -> 0 | AG14: =COUNTIF(B14:AE14,"نصف") -> 0 | AH14: =SUMIF(B14:AE14,">"&0) -> 0 | AI14: =IF(OR('بيانات الموظفين'!C12="",NOT(ISNUMBER('بيانات الموظفين'!G2)),AH14=0),"-",ROUND(AH14*(('بيانات الموظفين'!C12/30)/'بيانات الموظفين'!G2),2)) -> - | AJ14: =IF('بيانات الموظفين'!C12="","-",30-AF14-AG14*0.5) -> - | AK14: =IF('بيانات الموظفين'!C12="","-",ROUND(('بيانات الموظفين'!C12/30)*AF14+(('بيانات الموظفين'!C12/30)/2)*AG14,2)) -> - | AL14: =IF('بيانات الموظفين'!C12="","-",ROUND('بيانات الموظفين'!C12+IF(ISNUMBER(AI14),AI14,0)-IF(ISNUMBER(AK14),AK14,0),2)) -> -
A15: ='بيانات الموظفين'!B13 -> 0 | AF15: =COUNTIF(B15:AE15,"غ") -> 0 | AG15: =COUNTIF(B15:AE15,"نصف") -> 0 | AH15: =SUMIF(B15:AE15,">"&0) -> 0 | AI15: =IF(OR('بيانات الموظفين'!C13="",NOT(ISNUMBER('بيانات الموظفين'!G2)),AH15=0),"-",ROUND(AH15*(('بيانات الموظفين'!C13/30)/'بيانات الموظفين'!G2),2)) -> - | AJ15: =IF('بيانات الموظفين'!C13="","-",30-AF15-AG15*0.5) -> - | AK15: =IF('بيانات الموظفين'!C13="","-",ROUND(('بيانات الموظفين'!C13/30)*AF15+(('بيانات الموظفين'!C13/30)/2)*AG15,2)) -> - | AL15: =IF('بيانات الموظفين'!C13="","-",ROUND('بيانات الموظفين'!C13+IF(ISNUMBER(AI15),AI15,0)-IF(ISNUMBER(AK15),AK15,0),2)) -> -
A16: ='بيانات الموظفين'!B14 -> 0 | AF16: =COUNTIF(B16:AE16,"غ") -> 0 | AG16: =COUNTIF(B16:AE16,"نصف") -> 0 | AH16: =SUMIF(B16:AE16,">"&0) -> 0 | AI16: =IF(OR('بيانات الموظفين'!C14="",NOT(ISNUMBER('بيانات الموظفين'!G2)),AH16=0),"-",ROUND(AH16*(('بيانات الموظفين'!C14/30)/'بيانات الموظفين'!G2),2)) -> - | AJ16: =IF('بيانات الموظفين'!C14="","-",30-AF16-AG16*0.5) -> - | AK16: =IF('بيانات الموظفين'!C14="","-",ROUND(('بيانات الموظفين'!C14/30)*AF16+(('بيانات الموظفين'!C14/30)/2)*AG16,2)) -> - | AL16: =IF('بيانات الموظفين'!C14="","-",ROUND('بيانات الموظفين'!C14+IF(ISNUMBER(AI16),AI16,0)-IF(ISNUMBER(AK16),AK16,0),2)) -> -
A17: إجمالي الغياب اليومي — أبريل | B17: =COUNTIF(B7:B16,"غ")+COUNTIF(B7:B16,"نصف")*0.5 -> 0 | C17: =COUNTIF(C7:C16,"غ")+COUNTIF(C7:C16,"نصف")*0.5 -> 0 | D17: =COUNTIF(D7:D16,"غ")+COUNTIF(D7:D16,"نصف")*0.5 -> 0 | E17: =COUNTIF(E7:E16,"غ")+COUNTIF(E7:E16,"نصف")*0.5 -> 0 | F17: =COUNTIF(F7:F16,"غ")+COUNTIF(F7:F16,"نصف")*0.5 -> 0 | G17: =COUNTIF(G7:G16,"غ")+COUNTIF(G7:G16,"نصف")*0.5 -> 0 | H17: =COUNTIF(H7:H16,"غ")+COUNTIF(H7:H16,"نصف")*0.5 -> 0 | I17: =COUNTIF(I7:I16,"غ")+COUNTIF(I7:I16,"نصف")*0.5 -> 0 | ... AE17: =COUNTIF(AE7:AE16,"غ")+COUNTIF(AE7:AE16,"نصف")*0.5 -> 0 | AF17: =SUM(AF7:AF16) -> 0 | AG17: =SUM(AG7:AG16) -> 0 | AH17: =SUM(AH7:AH16) -> 0 | AI17: =SUM(AI7:AI16) -> 0 | AK17: =SUM(AK7:AK16) -> 0 | AL17: =SUM(AL7:AL16) -> 15300000
A19: 📊 الملخص الشهري للرواتب — أبريل 2026
A20: # | B20: اسم الموظف | C20: الراتب الأساسي | D20: أيام الغياب | E20: نصف يوم | F20: خصم الغياب | G20: ساعات إضافية | H20: قيمة الإضافي | I20: صافي الراتب
A21: 1 | B21: ='بيانات الموظفين'!B5 -> أبو بكر | C21: =IF('بيانات الموظفين'!C5="","-",'بيانات الموظفين'!C5) -> 7000000 | D21: =AF7 -> 0 | E21: =AG7 -> 0 | F21: =AK7 -> 0 | G21: =AH7 -> 0 | H21: =AI7 -> - | I21: =AL7 -> 7000000
A22: 2 | B22: ='بيانات الموظفين'!B6 -> هيثم صمادي | C22: =IF('بيانات الموظفين'!C6="","-",'بيانات الموظفين'!C6) -> 3000000 | D22: =AF8 -> 0 | E22: =AG8 -> 0 | F22: =AK8 -> 0 | G22: =AH8 -> 0 | H22: =AI8 -> - | I22: =AL8 -> 3000000
A23: 3 | B23: ='بيانات الموظفين'!B7 -> حسام كبريتة | C23: =IF('بيانات الموظفين'!C7="","-",'بيانات الموظفين'!C7) -> 2500000 | D23: =AF9 -> 0 | E23: =AG9 -> 0 | F23: =AK9 -> 0 | G23: =AH9 -> 0 | H23: =AI9 -> - | I23: =AL9 -> 2500000
A24: 4 | B24: ='بيانات الموظفين'!B8 -> انس المنسي | C24: =IF('بيانات الموظفين'!C8="","-",'بيانات الموظفين'!C8) -> 800000 | D24: =AF10 -> 0 | E24: =AG10 -> 0 | F24: =AK10 -> 0 | G24: =AH10 -> 0 | H24: =AI10 -> - | I24: =AL10 -> 800000
A25: 5 | B25: ='بيانات الموظفين'!B9 -> عمار مجيد | C25: =IF('بيانات الموظفين'!C9="","-",'بيانات الموظفين'!C9) -> 2000000 | D25: =AF11 -> 0 | E25: =AG11 -> 0 | F25: =AK11 -> 0 | G25: =AH11 -> 0 | H25: =AI11 -> - | I25: =AL11 -> 2000000
A26: 6 | B26: ='بيانات الموظفين'!B10 -> 0 | C26: =IF('بيانات الموظفين'!C10="","-",'بيانات الموظفين'!C10) -> - | D26: =AF12 -> 0 | E26: =AG12 -> 0 | F26: =AK12 -> - | G26: =AH12 -> 0 | H26: =AI12 -> - | I26: =AL12 -> -
A27: 7 | B27: ='بيانات الموظفين'!B11 -> 0 | C27: =IF('بيانات الموظفين'!C11="","-",'بيانات الموظفين'!C11) -> - | D27: =AF13 -> 0 | E27: =AG13 -> 0 | F27: =AK13 -> - | G27: =AH13 -> 0 | H27: =AI13 -> - | I27: =AL13 -> -
A28: 8 | B28: ='بيانات الموظفين'!B12 -> 0 | C28: =IF('بيانات الموظفين'!C12="","-",'بيانات الموظفين'!C12) -> - | D28: =AF14 -> 0 | E28: =AG14 -> 0 | F28: =AK14 -> - | G28: =AH14 -> 0 | H28: =AI14 -> - | I28: =AL14 -> -
A29: 9 | B29: ='بيانات الموظفين'!B13 -> 0 | C29: =IF('بيانات الموظفين'!C13="","-",'بيانات الموظفين'!C13) -> - | D29: =AF15 -> 0 | E29: =AG15 -> 0 | F29: =AK15 -> - | G29: =AH15 -> 0 | H29: =AI15 -> - | I29: =AL15 -> -
A30: 10 | B30: ='بيانات الموظفين'!B14 -> 0 | C30: =IF('بيانات الموظفين'!C14="","-",'بيانات الموظفين'!C14) -> - | D30: =AF16 -> 0 | E30: =AG16 -> 0 | F30: =AK16 -> - | G30: =AH16 -> 0 | H30: =AI16 -> - | I30: =AL16 -> -
A31: الإجمالي الكلي | C31: =SUM(C21:C30) -> 15300000 | D31: =SUM(D21:D30) -> 0 | E31: =SUM(E21:E30) -> 0 | F31: =SUM(F21:F30) -> 0 | G31: =SUM(G21:G30) -> 0 | H31: =SUM(H21:H30) -> 0 | I31: =SUM(I21:I30) -> 15300000

Sheet مايو
A1: جدول ضبط الغياب وحساب الرواتب ◀ مايو 2026 ★ يوم إضافي مضاف
A2: فارغ=حضور | غ=غياب يوم | نصف=نصف يوم | رقم=ساعات إضافية | 🔴 الجمعة باللون الأحمر
A4: اسم الموظف | B4: الجمعة | C4: السبت | D4: الأحد | E4: الاثنين | F4: الثلاثاء | G4: الأربعاء | H4: الخميس | I4: الجمعة | J4: السبت | K4: الأحد | L4: الاثنين | M4: الثلاثاء | N4: الأربعاء | O4: الخميس | P4: الجمعة | Q4: السبت | R4: الأحد | S4: الاثنين | T4: الثلاثاء | U4: الأربعاء | V4: الخميس | W4: الجمعة | X4: السبت | Y4: الأحد | Z4: الاثنين | AA4: الثلاثاء | AB4: الأربعاء | AC4: الخميس | AD4: الجمعة | AE4: السبت | AF4: الأحد | AG4: أيام الغياب | AH4: نصف يوم | AI4: ساعات إضافية | AJ4: قيمة الإضافي | AK4: أيام العمل | AL4: خصم الغياب | AM4: صافي الراتب
B5: 1 | C5: 2 | D5: 3 | E5: 4 | F5: 5 | G5: 6 | H5: 7 | I5: 8 | J5: 9 | K5: 10 | L5: 11 | M5: 12 | N5: 13 | O5: 14 | P5: 15 | Q5: 16 | R5: 17 | S5: 18 | T5: 19 | U5: 20 | V5: 21 | W5: 22 | X5: 23 | Y5: 24 | Z5: 25 | AA5: 26 | AB5: 27 | AC5: 28 | AD5: 29 | AE5: 30 | AF5: 31
A7: ='بيانات الموظفين'!B5 -> أبو بكر | AG7: =COUNTIF(B7:AF7,"غ") -> 0 | AH7: =COUNTIF(B7:AF7,"نصف") -> 0 | AI7: =SUMIF(B7:AF7,">"&0) -> 0 | AJ7: =IF(OR('بيانات الموظفين'!C5="",NOT(ISNUMBER('بيانات الموظفين'!G2)),AI7=0),"-",ROUND(AI7*(('بيانات الموظفين'!C5/31)/'بيانات الموظفين'!G2),2)) -> - | AK7: =IF('بيانات الموظفين'!C5="","-",31-AG7-AH7*0.5) -> 31 | AL7: =IF('بيانات الموظفين'!C5="","-",ROUND(('بيانات الموظفين'!C5/31)*AG7+(('بيانات الموظفين'!C5/31)/2)*AH7,2)) -> 0 | AM7: =IF('بيانات الموظفين'!C5="","-",ROUND('بيانات الموظفين'!C5+ROUND('بيانات الموظفين'!C5/30,2)+IF(ISNUMBER(AJ7),AJ7,0)-IF(ISNUMBER(AL7),AL7,0),2)) -> 7233333.3
A8: ='بيانات الموظفين'!B6 -> هيثم صمادي | AG8: =COUNTIF(B8:AF8,"غ") -> 0 | AH8: =COUNTIF(B8:AF8,"نصف") -> 0 | AI8: =SUMIF(B8:AF8,">"&0) -> 0 | AJ8: =IF(OR('بيانات الموظفين'!C6="",NOT(ISNUMBER('بيانات الموظفين'!G2)),AI8=0),"-",ROUND(AI8*(('بيانات الموظفين'!C6/31)/'بيانات الموظفين'!G2),2)) -> - | AK8: =IF('بيانات الموظفين'!C6="","-",31-AG8-AH8*0.5) -> 31 | AL8: =IF('بيانات الموظفين'!C6="","-",ROUND(('بيانات الموظفين'!C6/31)*AG8+(('بيانات الموظفين'!C6/31)/2)*AH8,2)) -> 0 | AM8: =IF('بيانات الموظفين'!C6="","-",ROUND('بيانات الموظفين'!C6+ROUND('بيانات الموظفين'!C6/30,2)+IF(ISNUMBER(AJ8),AJ8,0)-IF(ISNUMBER(AL8),AL8,0),2)) -> 3100000
A9: ='بيانات الموظفين'!B7 -> حسام كبريتة | AG9: =COUNTIF(B9:AF9,"غ") -> 0 | AH9: =COUNTIF(B9:AF9,"نصف") -> 0 | AI9: =SUMIF(B9:AF9,">"&0) -> 0 | AJ9: =IF(OR('بيانات الموظفين'!C7="",NOT(ISNUMBER('بيانات الموظفين'!G2)),AI9=0),"-",ROUND(AI9*(('بيانات الموظفين'!C7/31)/'بيانات الموظفين'!G2),2)) -> - | AK9: =IF('بيانات الموظفين'!C7="","-",31-AG9-AH9*0.5) -> 31 | AL9: =IF('بيانات الموظفين'!C7="","-",ROUND(('بيانات الموظفين'!C7/31)*AG9+(('بيانات الموظفين'!C7/31)/2)*AH9,2)) -> 0 | AM9: =IF('بيانات الموظفين'!C7="","-",ROUND('بيانات الموظفين'!C7+ROUND('بيانات الموظفين'!C7/30,2)+IF(ISNUMBER(AJ9),AJ9,0)-IF(ISNUMBER(AL9),AL9,0),2)) -> 2583333.3
