Workbook

Sheet لوحة التحكم
A1: لوحة تحكم مستودع معمل المنظفات
A2: عدد الطبخات المسجلة: 43 | عدد المواد الخام: 94 | جميع الأرقام تُحدَّث تلقائياً
A4: إجمالي عدد المواد | C4: مواد برصيد سالب (تحتاج مراجعة) | E4: عدد الطبخات المعرّفة
A5: =COUNTA(المواد!$A$2:$A$319) -> 178 | C5: =COUNTIF('الرصيد الحالي'!$E$2:$E$320,"❌*") -> 3 | E5: =COUNTIF(قوائم!$B$2:$B$150,"?*") -> 45
A7: إجمالي عمليات الإدخال | C7: إجمالي عمليات الإنتاج | E7: إجمالي عمليات الصرف المباشر
A8: =COUNTA(الإدخالات!$C$2:$C$501) -> 176 | C8: =COUNTA('سجل الإنتاج'!$C$2:$C$501) -> 1 | E8: =COUNTA('الصرف المباشر'!$C$2:$C$501) -> 1
A12: ❌ تنبيه: مواد برصيد سالب - تحتاج مراجعة فورية
A13: اسم المادة | B13: الرصيد الحالي | C13: الوحدة | D13: الحالة
A14: =IFERROR(INDEX('الرصيد الحالي'!$A$2:$A$320,MATCH(1,'الرصيد الحالي'!$F$2:$F$320,0)),"") -> غليسيرين | B14: =IF($A14="","",IFERROR(INDEX('الرصيد الحالي'!$C$2:$C$320,MATCH($A14,'الرصيد الحالي'!$A$2:$A$320,0)),"")) -> -5 | C14: =IF($A14="","",IFERROR(INDEX('الرصيد الحالي'!$B$2:$B$320,MATCH($A14,'الرصيد الحالي'!$A$2:$A$320,0)),"")) -> كغ | D14: =IF($A14="","",IFERROR(INDEX('الرصيد الحالي'!$E$2:$E$320,MATCH($A14,'الرصيد الحالي'!$A$2:$A$320,0)),"")) -> ❌ رصيد سالب - يحتاج مراجعة
A15: =IFERROR(INDEX('الرصيد الحالي'!$A$2:$A$320,MATCH(2,'الرصيد الحالي'!$F$2:$F$320,0)),"") -> عطر-رمان apple grandada - 322730 | B15: =IF($A15="","",IFERROR(INDEX('الرصيد الحالي'!$C$2:$C$320,MATCH($A15,'الرصيد الحالي'!$A$2:$A$320,0)),"")) -> -1.34 | C15: =IF($A15="","",IFERROR(INDEX('الرصيد الحالي'!$B$2:$B$320,MATCH($A15,'الرصيد الحالي'!$A$2:$A$320,0)),"")) -> كغ | D15: =IF($A15="","",IFERROR(INDEX('الرصيد الحالي'!$E$2:$E$320,MATCH($A15,'الرصيد الحالي'!$A$2:$A$320,0)),"")) -> ❌ رصيد سالب - يحتاج مراجعة
A16: =IFERROR(INDEX('الرصيد الحالي'!$A$2:$A$320,MATCH(3,'الرصيد الحالي'!$F$2:$F$320,0)),"") -> صبغة | B16: =IF($A16="","",IFERROR(INDEX('الرصيد الحالي'!$C$2:$C$320,MATCH($A16,'الرصيد الحالي'!$A$2:$A$320,0)),"")) -> -25 | C16: =IF($A16="","",IFERROR(INDEX('الرصيد الحالي'!$B$2:$B$320,MATCH($A16,'الرصيد الحالي'!$A$2:$A$320,0)),"")) -> كغ | D16: =IF($A16="","",IFERROR(INDEX('الرصيد الحالي'!$E$2:$E$320,MATCH($A16,'الرصيد الحالي'!$A$2:$A$320,0)),"")) -> ❌ رصيد سالب - يحتاج مراجعة
A17: =IFERROR(INDEX('الرصيد الحالي'!$A$2:$A$320,MATCH(4,'الرصيد الحالي'!$F$2:$F$320,0)),"") | B17: =IF($A17="","",IFERROR(INDEX('الرصيد الحالي'!$C$2:$C$320,MATCH($A17,'الرصيد الحالي'!$A$2:$A$320,0)),"")) | C17: =IF($A17="","",IFERROR(INDEX('الرصيد الحالي'!$B$2:$B$320,MATCH($A17,'الرصيد الحالي'!$A$2:$A$320,0)),"")) | D17: =IF($A17="","",IFERROR(INDEX('الرصيد الحالي'!$E$2:$E$320,MATCH($A17,'الرصيد الحالي'!$A$2:$A$320,0)),""))
A18: =IFERROR(INDEX('الرصيد الحالي'!$A$2:$A$320,MATCH(5,'الرصيد الحالي'!$F$2:$F$320,0)),"") | B18: =IF($A18="","",IFERROR(INDEX('الرصيد الحالي'!$C$2:$C$320,MATCH($A18,'الرصيد الحالي'!$A$2:$A$320,0)),"")) | C18: =IF($A18="","",IFERROR(INDEX('الرصيد الحالي'!$B$2:$B$320,MATCH($A18,'الرصيد الحالي'!$A$2:$A$320,0)),"")) | D18: =IF($A18="","",IFERROR(INDEX('الرصيد الحالي'!$E$2:$E$320,MATCH($A18,'الرصيد الحالي'!$A$2:$A$320,0)),""))
A19: =IFERROR(INDEX('الرصيد الحالي'!$A$2:$A$320,MATCH(6,'الرصيد الحالي'!$F$2:$F$320,0)),"") | B19: =IF($A19="","",IFERROR(INDEX('الرصيد الحالي'!$C$2:$C$320,MATCH($A19,'الرصيد الحالي'!$A$2:$A$320,0)),"")) | C19: =IF($A19="","",IFERROR(INDEX('الرصيد الحالي'!$B$2:$B$320,MATCH($A19,'الرصيد الحالي'!$A$2:$A$320,0)),"")) | D19: =IF($A19="","",IFERROR(INDEX('الرصيد الحالي'!$E$2:$E$320,MATCH($A19,'الرصيد الحالي'!$A$2:$A$320,0)),""))
A20: =IFERROR(INDEX('الرصيد الحالي'!$A$2:$A$320,MATCH(7,'الرصيد الحالي'!$F$2:$F$320,0)),"") | B20: =IF($A20="","",IFERROR(INDEX('الرصيد الحالي'!$C$2:$C$320,MATCH($A20,'الرصيد الحالي'!$A$2:$A$320,0)),"")) | C20: =IF($A20="","",IFERROR(INDEX('الرصيد الحالي'!$B$2:$B$320,MATCH($A20,'الرصيد الحالي'!$A$2:$A$320,0)),"")) | D20: =IF($A20="","",IFERROR(INDEX('الرصيد الحالي'!$E$2:$E$320,MATCH($A20,'الرصيد الحالي'!$A$2:$A$320,0)),""))
A21: =IFERROR(INDEX('الرصيد الحالي'!$A$2:$A$320,MATCH(8,'الرصيد الحالي'!$F$2:$F$320,0)),"") | B21: =IF($A21="","",IFERROR(INDEX('الرصيد الحالي'!$C$2:$C$320,MATCH($A21,'الرصيد الحالي'!$A$2:$A$320,0)),"")) | C21: =IF($A21="","",IFERROR(INDEX('الرصيد الحالي'!$B$2:$B$320,MATCH($A21,'الرصيد الحالي'!$A$2:$A$320,0)),"")) | D21: =IF($A21="","",IFERROR(INDEX('الرصيد الحالي'!$E$2:$E$320,MATCH($A21,'الرصيد الحالي'!$A$2:$A$320,0)),""))
A22: =IFERROR(INDEX('الرصيد الحالي'!$A$2:$A$320,MATCH(9,'الرصيد الحالي'!$F$2:$F$320,0)),"") | B22: =IF($A22="","",IFERROR(INDEX('الرصيد الحالي'!$C$2:$C$320,MATCH($A22,'الرصيد الحالي'!$A$2:$A$320,0)),"")) | C22: =IF($A22="","",IFERROR(INDEX('الرصيد الحالي'!$B$2:$B$320,MATCH($A22,'الرصيد الحالي'!$A$2:$A$320,0)),"")) | D22: =IF($A22="","",IFERROR(INDEX('الرصيد الحالي'!$E$2:$E$320,MATCH($A22,'الرصيد الحالي'!$A$2:$A$320,0)),""))
A23: =IFERROR(INDEX('الرصيد الحالي'!$A$2:$A$320,MATCH(10,'الرصيد الحالي'!$F$2:$F$320,0)),"") | B23: =IF($A23="","",IFERROR(INDEX('الرصيد الحالي'!$C$2:$C$320,MATCH($A23,'الرصيد الحالي'!$A$2:$A$320,0)),"")) | C23: =IF($A23="","",IFERROR(INDEX('الرصيد الحالي'!$B$2:$B$320,MATCH($A23,'الرصيد الحالي'!$A$2:$A$320,0)),"")) | D23: =IF($A23="","",IFERROR(INDEX('الرصيد الحالي'!$E$2:$E$320,MATCH($A23,'الرصيد الحالي'!$A$2:$A$320,0)),""))
A24: =IFERROR(INDEX('الرصيد الحالي'!$A$2:$A$320,MATCH(11,'الرصيد الحالي'!$F$2:$F$320,0)),"") | B24: =IF($A24="","",IFERROR(INDEX('الرصيد الحالي'!$C$2:$C$320,MATCH($A24,'الرصيد الحالي'!$A$2:$A$320,0)),"")) | C24: =IF($A24="","",IFERROR(INDEX('الرصيد الحالي'!$B$2:$B$320,MATCH($A24,'الرصيد الحالي'!$A$2:$A$320,0)),"")) | D24: =IF($A24="","",IFERROR(INDEX('الرصيد الحالي'!$E$2:$E$320,MATCH($A24,'الرصيد الحالي'!$A$2:$A$320,0)),""))
A25: =IFERROR(INDEX('الرصيد الحالي'!$A$2:$A$320,MATCH(12,'الرصيد الحالي'!$F$2:$F$320,0)),"") | B25: =IF($A25="","",IFERROR(INDEX('الرصيد الحالي'!$C$2:$C$320,MATCH($A25,'الرصيد الحالي'!$A$2:$A$320,0)),"")) | C25: =IF($A25="","",IFERROR(INDEX('الرصيد الحالي'!$B$2:$B$320,MATCH($A25,'الرصيد الحالي'!$A$2:$A$320,0)),"")) | D25: =IF($A25="","",IFERROR(INDEX('الرصيد الحالي'!$E$2:$E$320,MATCH($A25,'الرصيد الحالي'!$A$2:$A$320,0)),""))
A26: =IFERROR(INDEX('الرصيد الحالي'!$A$2:$A$320,MATCH(13,'الرصيد الحالي'!$F$2:$F$320,0)),"") | B26: =IF($A26="","",IFERROR(INDEX('الرصيد الحالي'!$C$2:$C$320,MATCH($A26,'الرصيد الحالي'!$A$2:$A$320,0)),"")) | C26: =IF($A26="","",IFERROR(INDEX('الرصيد الحالي'!$B$2:$B$320,MATCH($A26,'الرصيد الحالي'!$A$2:$A$320,0)),"")) | D26: =IF($A26="","",IFERROR(INDEX('الرصيد الحالي'!$E$2:$E$320,MATCH($A26,'الرصيد الحالي'!$A$2:$A$320,0)),""))
A27: =IFERROR(INDEX('الرصيد الحالي'!$A$2:$A$320,MATCH(14,'الرصيد الحالي'!$F$2:$F$320,0)),"") | B27: =IF($A27="","",IFERROR(INDEX('الرصيد الحالي'!$C$2:$C$320,MATCH($A27,'الرصيد الحالي'!$A$2:$A$320,0)),"")) | C27: =IF($A27="","",IFERROR(INDEX('الرصيد الحالي'!$B$2:$B$320,MATCH($A27,'الرصيد الحالي'!$A$2:$A$320,0)),"")) | D27: =IF($A27="","",IFERROR(INDEX('الرصيد الحالي'!$E$2:$E$320,MATCH($A27,'الرصيد الحالي'!$A$2:$A$320,0)),""))
A28: =IFERROR(INDEX('الرصيد الحالي'!$A$2:$A$320,MATCH(15,'الرصيد الحالي'!$F$2:$F$320,0)),"") | B28: =IF($A28="","",IFERROR(INDEX('الرصيد الحالي'!$C$2:$C$320,MATCH($A28,'الرصيد الحالي'!$A$2:$A$320,0)),"")) | C28: =IF($A28="","",IFERROR(INDEX('الرصيد الحالي'!$B$2:$B$320,MATCH($A28,'الرصيد الحالي'!$A$2:$A$320,0)),"")) | D28: =IF($A28="","",IFERROR(INDEX('الرصيد الحالي'!$E$2:$E$320,MATCH($A28,'الرصيد الحالي'!$A$2:$A$320,0)),""))
A30: 📊 أكثر 5 مواد استهلاكاً | D30: 🏆 أكثر 5 طبخات إنتاجاً
A31: اسم المادة | B31: إجمالي الاستهلاك | C31: الوحدة | D31: اسم الطبخة | E31: عدد مرات الإنتاج
A32: =IFERROR(INDEX(قوائم!$A$2:$A$320,MATCH(LARGE(قوائم!$F$2:$F$320,1),قوائم!$F$2:$F$320,0)),"") | B32: =IFERROR(LARGE(قوائم!$F$2:$F$320,1),"") | C32: =IF($A32="","",IFERROR(INDEX(المواد!$B$2:$B$319,MATCH($A32,المواد!$A$2:$A$319,0)),"")) | D32: =IFERROR(INDEX(قوائم!$B$2:$B$150,MATCH(LARGE(قوائم!$D$2:$D$150,1),قوائم!$D$2:$D$150,0)),"") -> لودلين فريز أول | E32: =IFERROR(LARGE(قوائم!$D$2:$D$150,1),"") -> 1
A33: =IFERROR(INDEX(قوائم!$A$2:$A$320,MATCH(LARGE(قوائم!$F$2:$F$320,2),قوائم!$F$2:$F$320,0)),"") | B33: =IFERROR(LARGE(قوائم!$F$2:$F$320,2),"") | C33: =IF($A33="","",IFERROR(INDEX(المواد!$B$2:$B$319,MATCH($A33,المواد!$A$2:$A$319,0)),"")) | D33: =IFERROR(INDEX(قوائم!$B$2:$B$150,MATCH(LARGE(قوائم!$D$2:$D$150,2),قوائم!$D$2:$D$150,0)),"") -> دوا غسيل بودرا 157 كغ - ببوري | E33: =IFERROR(LARGE(قوائم!$D$2:$D$150,2),"") -> 0
A34: =IFERROR(INDEX(قوائم!$A$2:$A$320,MATCH(LARGE(قوائم!$F$2:$F$320,3),قوائم!$F$2:$F$320,0)),"") | B34: =IFERROR(LARGE(قوائم!$F$2:$F$320,3),"") | C34: =IF($A34="","",IFERROR(INDEX(المواد!$B$2:$B$319,MATCH($A34,المواد!$A$2:$A$319,0)),"")) | D34: =IFERROR(INDEX(قوائم!$B$2:$B$150,MATCH(LARGE(قوائم!$D$2:$D$150,3),قوائم!$D$2:$D$150,0)),"") -> دوا غسيل بودرا 157 كغ - ببوري | E34: =IFERROR(LARGE(قوائم!$D$2:$D$150,3),"") -> 0
A35: =IFERROR(INDEX(قوائم!$A$2:$A$320,MATCH(LARGE(قوائم!$F$2:$F$320,4),قوائم!$F$2:$F$320,0)),"") | B35: =IFERROR(LARGE(قوائم!$F$2:$F$320,4),"") | C35: =IF($A35="","",IFERROR(INDEX(المواد!$B$2:$B$319,MATCH($A35,المواد!$A$2:$A$319,0)),"")) | D35: =IFERROR(INDEX(قوائم!$B$2:$B$150,MATCH(LARGE(قوائم!$D$2:$D$150,4),قوائم!$D$2:$D$150,0)),"") -> دوا غسيل بودرا 157 كغ - ببوري | E35: =IFERROR(LARGE(قوائم!$D$2:$D$150,4),"") -> 0
A36: =IFERROR(INDEX(قوائم!$A$2:$A$320,MATCH(LARGE(قوائم!$F$2:$F$320,5),قوائم!$F$2:$F$320,0)),"") | B36: =IFERROR(LARGE(قوائم!$F$2:$F$320,5),"") | C36: =IF($A36="","",IFERROR(INDEX(المواد!$B$2:$B$319,MATCH($A36,المواد!$A$2:$A$319,0)),"")) | D36: =IFERROR(INDEX(قوائم!$B$2:$B$150,MATCH(LARGE(قوائم!$D$2:$D$150,5),قوائم!$D$2:$D$150,0)),"") -> دوا غسيل بودرا 157 كغ - ببوري | E36: =IFERROR(LARGE(قوائم!$D$2:$D$150,5),"") -> 0
A38: 🕓 آخر 5 عمليات إدخال (شراء) | D38: 🕓 آخر 5 عمليات إنتاج
A39: التاريخ | B39: المادة | C39: الكمية | D39: التاريخ | E39: الطبخة
A40: =IF((COUNTA(الإدخالات!$C$2:$C$501)-0)<1,"",INDEX(الإدخالات!$B$2:$B$501,COUNTA(الإدخالات!$C$2:$C$501)-0)) -> 46218 | B40: =IF((COUNTA(الإدخالات!$C$2:$C$501)-0)<1,"",INDEX(الإدخالات!$C$2:$C$501,COUNTA(الإدخالات!$C$2:$C$501)-0)) -> أسيد 1 لتر | C40: =IF((COUNTA(الإدخالات!$C$2:$C$501)-0)<1,"",INDEX(الإدخالات!$D$2:$D$501,COUNTA(الإدخالات!$C$2:$C$501)-0)) -> 0 | D40: =IF((COUNTA('سجل الإنتاج'!$C$2:$C$501)-0)<1,"",INDEX('سجل الإنتاج'!$B$2:$B$501,COUNTA('سجل الإنتاج'!$C$2:$C$501)-0)) -> 46225 | E40: =IF((COUNTA('سجل الإنتاج'!$C$2:$C$501)-0)<1,"",INDEX('سجل الإنتاج'!$C$2:$C$501,COUNTA('سجل الإنتاج'!$C$2:$C$501)-0)) -> لودلين فريز أول
A41: =IF((COUNTA(الإدخالات!$C$2:$C$501)-1)<1,"",INDEX(الإدخالات!$B$2:$B$501,COUNTA(الإدخالات!$C$2:$C$501)-1)) -> 46218 | B41: =IF((COUNTA(الإدخالات!$C$2:$C$501)-1)<1,"",INDEX(الإدخالات!$C$2:$C$501,COUNTA(الإدخالات!$C$2:$C$501)-1)) -> أسيد 3 لتر | C41: =IF((COUNTA(الإدخالات!$C$2:$C$501)-1)<1,"",INDEX(الإدخالات!$D$2:$D$501,COUNTA(الإدخالات!$C$2:$C$501)-1)) -> 0 | D41: =IF((COUNTA('سجل الإنتاج'!$C$2:$C$501)-1)<1,"",INDEX('سجل الإنتاج'!$B$2:$B$501,COUNTA('سجل الإنتاج'!$C$2:$C$501)-1)) | E41: =IF((COUNTA('سجل الإنتاج'!$C$2:$C$501)-1)<1,"",INDEX('سجل الإنتاج'!$C$2:$C$501,COUNTA('سجل الإنتاج'!$C$2:$C$501)-1))
A42: =IF((COUNTA(الإدخالات!$C$2:$C$501)-2)<1,"",INDEX(الإدخالات!$B$2:$B$501,COUNTA(الإدخالات!$C$2:$C$501)-2)) -> 46218 | B42: =IF((COUNTA(الإدخالات!$C$2:$C$501)-2)<1,"",INDEX(الإدخالات!$C$2:$C$501,COUNTA(الإدخالات!$C$2:$C$501)-2)) -> اسيد 3 لتر | C42: =IF((COUNTA(الإدخالات!$C$2:$C$501)-2)<1,"",INDEX(الإدخالات!$D$2:$D$501,COUNTA(الإدخالات!$C$2:$C$501)-2)) -> 0 | D42: =IF((COUNTA('سجل الإنتاج'!$C$2:$C$501)-2)<1,"",INDEX('سجل الإنتاج'!$B$2:$B$501,COUNTA('سجل الإنتاج'!$C$2:$C$501)-2)) | E42: =IF((COUNTA('سجل الإنتاج'!$C$2:$C$501)-2)<1,"",INDEX('سجل الإنتاج'!$C$2:$C$501,COUNTA('سجل الإنتاج'!$C$2:$C$501)-2))
A43: =IF((COUNTA(الإدخالات!$C$2:$C$501)-3)<1,"",INDEX(الإدخالات!$B$2:$B$501,COUNTA(الإدخالات!$C$2:$C$501)-3)) -> 46218 | B43: =IF((COUNTA(الإدخالات!$C$2:$C$501)-3)<1,"",INDEX(الإدخالات!$C$2:$C$501,COUNTA(الإدخالات!$C$2:$C$501)-3)) -> اقراص كلور | C43: =IF((COUNTA(الإدخالات!$C$2:$C$501)-3)<1,"",INDEX(الإدخالات!$D$2:$D$501,COUNTA(الإدخالات!$C$2:$C$501)-3)) -> 0 | D43: =IF((COUNTA('سجل الإنتاج'!$C$2:$C$501)-3)<1,"",INDEX('سجل الإنتاج'!$B$2:$B$501,COUNTA('سجل الإنتاج'!$C$2:$C$501)-3)) | E43: =IF((COUNTA('سجل الإنتاج'!$C$2:$C$501)-3)<1,"",INDEX('سجل الإنتاج'!$C$2:$C$501,COUNTA('سجل الإنتاج'!$C$2:$C$501)-3))
A44: =IF((COUNTA(الإدخالات!$C$2:$C$501)-4)<1,"",INDEX(الإدخالات!$B$2:$B$501,COUNTA(الإدخالات!$C$2:$C$501)-4)) -> 46218 | B44: =IF((COUNTA(الإدخالات!$C$2:$C$501)-4)<1,"",INDEX(الإدخالات!$C$2:$C$501,COUNTA(الإدخالات!$C$2:$C$501)-4)) -> برميل تكسبون فارغ | C44: =IF((COUNTA(الإدخالات!$C$2:$C$501)-4)<1,"",INDEX(الإدخالات!$D$2:$D$501,COUNTA(الإدخالات!$C$2:$C$501)-4)) -> 0 | D44: =IF((COUNTA('سجل الإنتاج'!$C$2:$C$501)-4)<1,"",INDEX('سجل الإنتاج'!$B$2:$B$501,COUNTA('سجل الإنتاج'!$C$2:$C$501)-4)) | E44: =IF((COUNTA('سجل الإنتاج'!$C$2:$C$501)-4)<1,"",INDEX('سجل الإنتاج'!$C$2:$C$501,COUNTA('سجل الإنتاج'!$C$2:$C$501)-4))
A46: 🕓 آخر 5 عمليات صرف مباشر
A47: التاريخ | B47: المادة | C47: الكمية
A48: =IF((COUNTA('الصرف المباشر'!$C$2:$C$501)-0)<1,"",INDEX('الصرف المباشر'!$B$2:$B$501,COUNTA('الصرف المباشر'!$C$2:$C$501)-0)) -> 46225 | B48: =IF((COUNTA('الصرف المباشر'!$C$2:$C$501)-0)<1,"",INDEX('الصرف المباشر'!$C$2:$C$501,COUNTA('الصرف المباشر'!$C$2:$C$501)-0)) -> ملح | C48: =IF((COUNTA('الصرف المباشر'!$C$2:$C$501)-0)<1,"",INDEX('الصرف المباشر'!$D$2:$D$501,COUNTA('الصرف المباشر'!$C$2:$C$501)-0)) -> 10
...

Sheet الإدخالات
A1: رقم العملية | B1: التاريخ | C1: المادة | D1: الكمية | E1: المورد | F1: رقم الفاتورة | G1: ملاحظات
A2: =IF(C2="","",ROW()-1) -> 1 | B2: 46218 | C2: ملح | D2: 138.04 | E2: امين | F2: - | G2: تنزيل البيانات لأول مرة
A3: =IF(C3="","",ROW()-1) -> 2 | B3: 46218 | C3: مقصب | D3: 2 | E3: امين | F3: - | G3: تنزيل البيانات لأول مرة
A4: =IF(C4="","",ROW()-1) -> 3 | B4: 46218 | C4: مجمد | D4: 63.5 | E4: امين | F4: - | G4: تنزيل البيانات لأول مرة
A5: =IF(C5="","",ROW()-1) -> 4 | B5: 46218 | C5: مانع رغوة مائي | D5: 0 | E5: امين | F5: - | G5: تنزيل البيانات لأول مرة
A6: =IF(C6="","",ROW()-1) -> 5 | B6: 46218 | C6: مانع رغوة سيليكون | D6: 0 | E6: امين | F6: - | G6: تنزيل البيانات لأول مرة
A7: =IF(C7="","",ROW()-1) -> 6 | B7: 46218 | C7: ماء مقطرة | D7: 28622 | E7: امين | F7: - | G7: تنزيل البيانات لأول مرة
A8: =IF(C8="","",ROW()-1) -> 7 | B8: 46218 | C8: ماء بلسم | D8: 3 | E8: امين | F8: - | G8: تنزيل البيانات لأول مرة
A9: =IF(C9="","",ROW()-1) -> 8 | B9: 46218 | C9: لانيت 16 ماليزي | D9: 0 | E9: امين | F9: - | G9: تنزيل البيانات لأول مرة
A10: =IF(C10="","",ROW()-1) -> 9 | B10: 46218 | C10: كوستيك-قطرونة | D10: 27.71 | E10: امين | F10: - | G10: تنزيل البيانات لأول مرة
A11: =IF(C11="","",ROW()-1) -> 10 | B11: 46218 | C11: كمبرلان | D11: 0 | E11: امين | F11: - | G11: تنزيل البيانات لأول مرة
A12: =IF(C12="","",ROW()-1) -> 11 | B12: 46218 | C12: كليمازول | D12: 0 | E12: امين | F12: - | G12: تنزيل البيانات لأول مرة
A13: =IF(C13="","",ROW()-1) -> 12 | B13: 46218 | C13: كلور خام | D13: 272 | E13: امين | F13: - | G13: تنزيل البيانات لأول مرة
... A75: =IF(C75="","",ROW()-1) -> 74 | B75: 46218 | C75: ديتول خام | D75: 0 | E75: امين | F75: - | G75: تنزيل البيانات لأول مرة
A76: =IF(C76="","",ROW()-1) -> 75 | B76: 46218 | C76: غطا عبوة 3لتر
A77: =IF(C77="","",ROW()-1) -> 76 | B77: 46218 | C77: مياه مقطرة 4 لتر
A78: =IF(C78="","",ROW()-1) -> 77 | B78: 46218 | C78: مياه مقطرة 1 لتر
A79: =IF(C79="","",ROW()-1) -> 78 | B79: 46218 | C79: مهسهس زفته - معجون
A80: =IF(C80="","",ROW()-1) -> 79 | B80: 46218 | C80: مماسح مكتب َ
A81: =IF(C81="","",ROW()-1) -> 80 | B81: 46218 | C81: مماسح قماش عائلة فايبر
A82: =IF(C82="","",ROW()-1) -> 81 | B82: 46218 | C82: مماسح بلور
A83: =IF(C83="","",ROW()-1) -> 82 | B83: 46218 | C83: مماسح ارضيات
A84: =IF(C84="","",ROW()-1) -> 83 | B84: 46218 | C84: ملمع سيارات 3 لتر
A85: =IF(C85="","",ROW()-1) -> 84 | B85: 46218 | C85: ملمع سيارات / فرط
A86: =IF(C86="","",ROW()-1) -> 85 | B86: 46218 | C86: ملمع زجاج الكرمل
A87: =IF(C87="","",ROW()-1) -> 86 | B87: 46218 | C87: ملمع زجاج 3 لتر
... A177: =IF(C177="","",ROW()-1) -> 176 | B177: 46218 | C177: أسيد 1 لتر
A178: =IF(C178="","",ROW()-1)
A179: =IF(C179="","",ROW()-1)
A180: =IF(C180="","",ROW()-1)
A181: =IF(C181="","",ROW()-1)
A182: =IF(C182="","",ROW()-1)
A183: =IF(C183="","",ROW()-1)
A184: =IF(C184="","",ROW()-1)
A185: =IF(C185="","",ROW()-1)
A186: =IF(C186="","",ROW()-1)
A187: =IF(C187="","",ROW()-1)
A188: =IF(C188="","",ROW()-1)
A189: =IF(C189="","",ROW()-1)
... A501: =IF(C501="","",ROW()-1)

Sheet سجل الإنتاج
A1: رقم العملية | B1: التاريخ | C1: اسم الطبخة | D1: ملاحظات
A2: 2 | B2: 46225 | C2: لودلين فريز أول | D2: تجريبية
A5: =IF(C5="","",ROW()-1)
A6: =IF(C6="","",ROW()-1)
A7: =IF(C7="","",ROW()-1)
A8: =IF(C8="","",ROW()-1)
A9: =IF(C9="","",ROW()-1)
A10: =IF(C10="","",ROW()-1)
A11: =IF(C11="","",ROW()-1)
A12: =IF(C12="","",ROW()-1)
A13: =IF(C13="","",ROW()-1)
A14: =IF(C14="","",ROW()-1)
A15: =IF(C15="","",ROW()-1)
A16: =IF(C16="","",ROW()-1)
... A501: =IF(C501="","",ROW()-1)

Sheet الصرف المباشر
A1: رقم العملية | B1: التاريخ | C1: المادة | D1: الكمية | E1: الجهة المستفيدة | F1: ملاحظات
B2: 46225 | C2: ملح | D2: 10 | E2: أبو خليل | F2: منشان يطبخ مي وملح
A4: =IF(C4="","",ROW()-1)
A5: =IF(C5="","",ROW()-1)
A6: =IF(C6="","",ROW()-1)
A7: =IF(C7="","",ROW()-1)
A8: =IF(C8="","",ROW()-1)
A9: =IF(C9="","",ROW()-1)
A10: =IF(C10="","",ROW()-1)
A11: =IF(C11="","",ROW()-1)
A12: =IF(C12="","",ROW()-1)
A13: =IF(C13="","",ROW()-1)
A14: =IF(C14="","",ROW()-1)
A15: =IF(C15="","",ROW()-1)
... A501: =IF(C501="","",ROW()-1)

Sheet تعديل الجرد
A1: رقم العملية | B1: التاريخ | C1: المادة | D1: الرصيد النظامي (قبل هذا التعديل) | E1: الكمية الفعلية (الجرد) | F1: الفرق | G1: سبب التعديل | H1: ملاحظات
A3: =IF(C3="","",ROW()-1) | D3: =IF($C3="","",ROUND(SUMIFS(الإدخالات!$D$2:$D$501,الإدخالات!$C$2:$C$501,$C3)+SUMIFS($F$1:F2,$C$1:C2,$C3)-SUMIFS('الصرف المباشر'!$D$2:$D$501,'الصرف المباشر'!$C$2:$C$501,$C3)-SUMPRODUCT((الطبخات!$B$2:$B$900=$C3)*الطبخات!$C$2:$C$900*COUNTIF('سجل الإنتاج'!$C$2:$C$501,الطبخات!$A$2:$A$900)),3)) | F3: =IF(OR($C3="",$E3=""),"",ROUND($E3-$D3,3))
A4: =IF(C4="","",ROW()-1) | D4: =IF($C4="","",ROUND(SUMIFS(الإدخالات!$D$2:$D$501,الإدخالات!$C$2:$C$501,$C4)+SUMIFS($F$1:F3,$C$1:C3,$C4)-SUMIFS('الصرف المباشر'!$D$2:$D$501,'الصرف المباشر'!$C$2:$C$501,$C4)-SUMPRODUCT((الطبخات!$B$2:$B$900=$C4)*الطبخات!$C$2:$C$900*COUNTIF('سجل الإنتاج'!$C$2:$C$501,الطبخات!$A$2:$A$900)),3)) | F4: =IF(OR($C4="",$E4=""),"",ROUND($E4-$D4,3))
A5: =IF(C5="","",ROW()-1) | D5: =IF($C5="","",ROUND(SUMIFS(الإدخالات!$D$2:$D$501,الإدخالات!$C$2:$C$501,$C5)+SUMIFS($F$1:F4,$C$1:C4,$C5)-SUMIFS('الصرف المباشر'!$D$2:$D$501,'الصرف المباشر'!$C$2:$C$501,$C5)-SUMPRODUCT((الطبخات!$B$2:$B$900=$C5)*الطبخات!$C$2:$C$900*COUNTIF('سجل الإنتاج'!$C$2:$C$501,الطبخات!$A$2:$A$900)),3)) | F5: =IF(OR($C5="",$E5=""),"",ROUND($E5-$D5,3))
A6: =IF(C6="","",ROW()-1) | D6: =IF($C6="","",ROUND(SUMIFS(الإدخالات!$D$2:$D$501,الإدخالات!$C$2:$C$501,$C6)+SUMIFS($F$1:F5,$C$1:C5,$C6)-SUMIFS('الصرف المباشر'!$D$2:$D$501,'الصرف المباشر'!$C$2:$C$501,$C6)-SUMPRODUCT((الطبخات!$B$2:$B$900=$C6)*الطبخات!$C$2:$C$900*COUNTIF('سجل الإنتاج'!$C$2:$C$501,الطبخات!$A$2:$A$900)),3)) | F6: =IF(OR($C6="",$E6=""),"",ROUND($E6-$D6,3))
A7: =IF(C7="","",ROW()-1) | D7: =IF($C7="","",ROUND(SUMIFS(الإدخالات!$D$2:$D$501,الإدخالات!$C$2:$C$501,$C7)+SUMIFS($F$1:F6,$C$1:C6,$C7)-SUMIFS('الصرف المباشر'!$D$2:$D$501,'الصرف المباشر'!$C$2:$C$501,$C7)-SUMPRODUCT((الطبخات!$B$2:$B$900=$C7)*الطبخات!$C$2:$C$900*COUNTIF('سجل الإنتاج'!$C$2:$C$501,الطبخات!$A$2:$A$900)),3)) | F7: =IF(OR($C7="",$E7=""),"",ROUND($E7-$D7,3))
A8: =IF(C8="","",ROW()-1) | D8: =IF($C8="","",ROUND(SUMIFS(الإدخالات!$D$2:$D$501,الإدخالات!$C$2:$C$501,$C8)+SUMIFS($F$1:F7,$C$1:C7,$C8)-SUMIFS('الصرف المباشر'!$D$2:$D$501,'الصرف المباشر'!$C$2:$C$501,$C8)-SUMPRODUCT((الطبخات!$B$2:$B$900=$C8)*الطبخات!$C$2:$C$900*COUNTIF('سجل الإنتاج'!$C$2:$C$501,الطبخات!$A$2:$A$900)),3)) | F8: =IF(OR($C8="",$E8=""),"",ROUND($E8-$D8,3))
A9: =IF(C9="","",ROW()-1) | D9: =IF($C9="","",ROUND(SUMIFS(الإدخالات!$D$2:$D$501,الإدخالات!$C$2:$C$501,$C9)+SUMIFS($F$1:F8,$C$1:C8,$C9)-SUMIFS('الصرف المباشر'!$D$2:$D$501,'الصرف المباشر'!$C$2:$C$501,$C9)-SUMPRODUCT((الطبخات!$B$2:$B$900=$C9)*الطبخات!$C$2:$C$900*COUNTIF('سجل الإنتاج'!$C$2:$C$501,الطبخات!$A$2:$A$900)),3)) | F9: =IF(OR($C9="",$E9=""),"",ROUND($E9-$D9,3))
A10: =IF(C10="","",ROW()-1) | D10: =IF($C10="","",ROUND(SUMIFS(الإدخالات!$D$2:$D$501,الإدخالات!$C$2:$C$501,$C10)+SUMIFS($F$1:F9,$C$1:C9,$C10)-SUMIFS('الصرف المباشر'!$D$2:$D$501,'الصرف المباشر'!$C$2:$C$501,$C10)-SUMPRODUCT((الطبخات!$B$2:$B$900=$C10)*الطبخات!$C$2:$C$900*COUNTIF('سجل الإنتاج'!$C$2:$C$501,الطبخات!$A$2:$A$900)),3)) | F10: =IF(OR($C10="",$E10=""),"",ROUND($E10-$D10,3))
A11: =IF(C11="","",ROW()-1) | D11: =IF($C11="","",ROUND(SUMIFS(الإدخالات!$D$2:$D$501,الإدخالات!$C$2:$C$501,$C11)+SUMIFS($F$1:F10,$C$1:C10,$C11)-SUMIFS('الصرف المباشر'!$D$2:$D$501,'الصرف المباشر'!$C$2:$C$501,$C11)-SUMPRODUCT((الطبخات!$B$2:$B$900=$C11)*الطبخات!$C$2:$C$900*COUNTIF('سجل الإنتاج'!$C$2:$C$501,الطبخات!$A$2:$A$900)),3)) | F11: =IF(OR($C11="",$E11=""),"",ROUND($E11-$D11,3))
A12: =IF(C12="","",ROW()-1) | D12: =IF($C12="","",ROUND(SUMIFS(الإدخالات!$D$2:$D$501,الإدخالات!$C$2:$C$501,$C12)+SUMIFS($F$1:F11,$C$1:C11,$C12)-SUMIFS('الصرف المباشر'!$D$2:$D$501,'الصرف المباشر'!$C$2:$C$501,$C12)-SUMPRODUCT((الطبخات!$B$2:$B$900=$C12)*الطبخات!$C$2:$C$900*COUNTIF('سجل الإنتاج'!$C$2:$C$501,الطبخات!$A$2:$A$900)),3)) | F12: =IF(OR($C12="",$E12=""),"",ROUND($E12-$D12,3))
A13: =IF(C13="","",ROW()-1) | D13: =IF($C13="","",ROUND(SUMIFS(الإدخالات!$D$2:$D$501,الإدخالات!$C$2:$C$501,$C13)+SUMIFS($F$1:F12,$C$1:C12,$C13)-SUMIFS('الصرف المباشر'!$D$2:$D$501,'الصرف المباشر'!$C$2:$C$501,$C13)-SUMPRODUCT((الطبخات!$B$2:$B$900=$C13)*الطبخات!$C$2:$C$900*COUNTIF('سجل الإنتاج'!$C$2:$C$501,الطبخات!$A$2:$A$900)),3)) | F13: =IF(OR($C13="",$E13=""),"",ROUND($E13-$D13,3))
A14: =IF(C14="","",ROW()-1) | D14: =IF($C14="","",ROUND(SUMIFS(الإدخالات!$D$2:$D$501,الإدخالات!$C$2:$C$501,$C14)+SUMIFS($F$1:F13,$C$1:C13,$C14)-SUMIFS('الصرف المباشر'!$D$2:$D$501,'الصرف المباشر'!$C$2:$C$501,$C14)-SUMPRODUCT((الطبخات!$B$2:$B$900=$C14)*الطبخات!$C$2:$C$900*COUNTIF('سجل الإنتاج'!$C$2:$C$501,الطبخات!$A$2:$A$900)),3)) | F14: =IF(OR($C14="",$E14=""),"",ROUND($E14-$D14,3))
... A501: =IF(C501="","",ROW()-1) | D501: =IF($C501="","",ROUND(SUMIFS(الإدخالات!$D$2:$D$501,الإدخالات!$C$2:$C$501,$C501)+SUMIFS($F$1:F500,$C$1:C500,$C501)-SUMIFS('الصرف المباشر'!$D$2:$D$501,'الصرف المباشر'!$C$2:$C$501,$C501)-SUMPRODUCT((الطبخات!$B$2:$B$900=$C501)*الطبخات!$C$2:$C$900*COUNTIF('سجل الإنتاج'!$C$2:$C$501,الطبخات!$A$2:$A$900)),3)) | F501: =IF(OR($C501="",$E501=""),"",ROUND($E501-$D501,3))

Sheet الرصيد الحالي
A1: اسم المادة | B1: الوحدة | C1: الرصيد الحالي | D1: إجمالي الاستهلاك (كل الوقت) | E1: حالة الرصيد | F1: ترتيب مساعد (لا يُعدَّل)
A2: =المواد!A2 -> ملح | B2: =المواد!B2 -> كغ | C2: =IF($A2="","",ROUND(SUMIFS(الإدخالات!$D$2:$D$501,الإدخالات!$C$2:$C$501,$A2)+SUMIFS('تعديل الجرد'!$F$2:$F$501,'تعديل الجرد'!$C$2:$C$501,$A2)-SUMIFS('الصرف المباشر'!$D$2:$D$501,'الصرف المباشر'!$C$2:$C$501,$A2)-SUMPRODUCT((الطبخات!$B$2:$B$900=$A2)*الطبخات!$C$2:$C$900*COUNTIF('سجل الإنتاج'!$C$2:$C$501,الطبخات!$A$2:$A$900)),3)) -> 128.04 | D2: =IF($A2="","",ROUND(SUMIFS('الصرف المباشر'!$D$2:$D$501,'الصرف المباشر'!$C$2:$C$501,$A2)+SUMPRODUCT((الطبخات!$B$2:$B$900=$A2)*الطبخات!$C$2:$C$900*COUNTIF('سجل الإنتاج'!$C$2:$C$501,الطبخات!$A$2:$A$900)),3)) -> 10 | E2: =IF($A2="","",IF($C2<0,"❌ رصيد سالب - يحتاج مراجعة","✔ طبيعي")) -> ✔ طبيعي | F2: =IF(AND($A2<>"",$E2<>"✔ طبيعي"),SUMPRODUCT(('الرصيد الحالي'!$E$2:$E2<>"✔ طبيعي")*('الرصيد الحالي'!$E$2:$E2<>"")*('الرصيد الحالي'!$A$2:$A2<>"")),"")
A3: =المواد!A3 -> مقصب | B3: =المواد!B3 -> كغ | C3: =IF($A3="","",ROUND(SUMIFS(الإدخالات!$D$2:$D$501,الإدخالات!$C$2:$C$501,$A3)+SUMIFS('تعديل الجرد'!$F$2:$F$501,'تعديل الجرد'!$C$2:$C$501,$A3)-SUMIFS('الصرف المباشر'!$D$2:$D$501,'الصرف المباشر'!$C$2:$C$501,$A3)-SUMPRODUCT((الطبخات!$B$2:$B$900=$A3)*الطبخات!$C$2:$C$900*COUNTIF('سجل الإنتاج'!$C$2:$C$501,الطبخات!$A$2:$A$900)),3)) -> 2 | D3: =IF($A3="","",ROUND(SUMIFS('الصرف المباشر'!$D$2:$D$501,'الصرف المباشر'!$C$2:$C$501,$A3)+SUMPRODUCT((الطبخات!$B$2:$B$900=$A3)*الطبخات!$C$2:$C$900*COUNTIF('سجل الإنتاج'!$C$2:$C$501,الطبخات!$A$2:$A$900)),3)) -> 0 | E3: =IF($A3="","",IF($C3<0,"❌ رصيد سالب - يحتاج مراجعة","✔ طبيعي")) -> ✔ طبيعي | F3: =IF(AND($A3<>"",$E3<>"✔ طبيعي"),SUMPRODUCT(('الرصيد الحالي'!$E$2:$E3<>"✔ طبيعي")*('الرصيد الحالي'!$E$2:$E3<>"")*('الرصيد الحالي'!$A$2:$A3<>"")),"")
A4: =المواد!A4 -> مجمد | B4: =المواد!B4 -> كغ | C4: =IF($A4="","",ROUND(SUMIFS(الإدخالات!$D$2:$D$501,الإدخالات!$C$2:$C$501,$A4)+SUMIFS('تعديل الجرد'!$F$2:$F$501,'تعديل الجرد'!$C$2:$C$501,$A4)-SUMIFS('الصرف المباشر'!$D$2:$D$501,'الصرف المباشر'!$C$2:$C$501,$A4)-SUMPRODUCT((الطبخات!$B$2:$B$900=$A4)*الطبخات!$C$2:$C$900*COUNTIF('سجل الإنتاج'!$C$2:$C$501,الطبخات!$A$2:$A$900)),3)) -> 63.5 | D4: =IF($A4="","",ROUND(SUMIFS('الصرف المباشر'!$D$2:$D$501,'الصرف المباشر'!$C$2:$C$501,$A4)+SUMPRODUCT((الطبخات!$B$2:$B$900=$A4)*الطبخات!$C$2:$C$900*COUNTIF('سجل الإنتاج'!$C$2:$C$501,الطبخات!$A$2:$A$900)),3)) -> 0 | E4: =IF($A4="","",IF($C4<0,"❌ رصيد سالب - يحتاج مراجعة","✔ طبيعي")) -> ✔ طبيعي | F4: =IF(AND($A4<>"",$E4<>"✔ طبيعي"),SUMPRODUCT(('الرصيد الحالي'!$E$2:$E4<>"✔ طبيعي")*('الرصيد الحالي'!$E$2:$E4<>"")*('الرصيد الحالي'!$A$2:$A4<>"")),"")
A5: =المواد!A5 -> مانع رغوة مائي | B5: =المواد!B5 -> كغ | C5: =IF($A5="","",ROUND(SUMIFS(الإدخالات!$D$2:$D$501,الإدخالات!$C$2:$C$501,$A5)+SUMIFS('تعديل الجرد'!$F$2:$F$501,'تعديل الجرد'!$C$2:$C$501,$A5)-SUMIFS('الصرف المباشر'!$D$2:$D$501,'الصرف المباشر'!$C$2:$C$501,$A5)-SUMPRODUCT((الطبخات!$B$2:$B$900=$A5)*الطبخات!$C$2:$C$900*COUNTIF('سجل الإنتاج'!$C$2:$C$501,الطبخات!$A$2:$A$900)),3)) -> 0 | D5: =IF($A5="","",ROUND(SUMIFS('الصرف المباشر'!$D$2:$D$501,'الصرف المباشر'!$C$2:$C$501,$A5)+SUMPRODUCT((الطبخات!$B$2:$B$900=$A5)*الطبخات!$C$2:$C$900*COUNTIF('سجل الإنتاج'!$C$2:$C$501,الطبخات!$A$2:$A$900)),3)) -> 0 | E5: =IF($A5="","",IF($C5<0,"❌ رصيد سالب - يحتاج مراجعة","✔ طبيعي")) -> ✔ طبيعي | F5: =IF(AND($A5<>"",$E5<>"✔ طبيعي"),SUMPRODUCT(('الرصيد الحالي'!$E$2:$E5<>"✔ طبيعي")*('الرصيد الحالي'!$E$2:$E5<>"")*('الرصيد الحالي'!$A$2:$A5<>"")),"")
A6: =المواد!A6 -> مانع رغوة سيليكون | B6: =المواد!B6 -> كغ | C6: =IF($A6="","",ROUND(SUMIFS(الإدخالات!$D$2:$D$501,الإدخالات!$C$2:$C$501,$A6)+SUMIFS('تعديل الجرد'!$F$2:$F$501,'تعديل الجرد'!$C$2:$C$501,$A6)-SUMIFS('الصرف المباشر'!$D$2:$D$501,'الصرف المباشر'!$C$2:$C$501,$A6)-SUMPRODUCT((الطبخات!$B$2:$B$900=$A6)*الطبخات!$C$2:$C$900*COUNTIF('سجل الإنتاج'!$C$2:$C$501,الطبخات!$A$2:$A$900)),3)) -> 0 | D6: =IF($A6="","",ROUND(SUMIFS('الصرف المباشر'!$D$2:$D$501,'الصرف المباشر'!$C$2:$C$501,$A6)+SUMPRODUCT((الطبخات!$B$2:$B$900=$A6)*الطبخات!$C$2:$C$900*COUNTIF('سجل الإنتاج'!$C$2:$C$501,الطبخات!$A$2:$A$900)),3)) -> 0 | E6: =IF($A6="","",IF($C6<0,"❌ رصيد سالب - يحتاج مراجعة","✔ طبيعي")) -> ✔ طبيعي | F6: =IF(AND($A6<>"",$E6<>"✔ طبيعي"),SUMPRODUCT(('الرصيد الحالي'!$E$2:$E6<>"✔ طبيعي")*('الرصيد الحالي'!$E$2:$E6<>"")*('الرصيد الحالي'!$A$2:$A6<>"")),"")
A7: =المواد!A7 -> ماء مقطرة | B7: =المواد!B7 -> كغ | C7: =IF($A7="","",ROUND(SUMIFS(الإدخالات!$D$2:$D$501,الإدخالات!$C$2:$C$501,$A7)+SUMIFS('تعديل الجرد'!$F$2:$F$501,'تعديل الجرد'!$C$2:$C$501,$A7)-SUMIFS('الصرف المباشر'!$D$2:$D$501,'الصرف المباشر'!$C$2:$C$501,$A7)-SUMPRODUCT((الطبخات!$B$2:$B$900=$A7)*الطبخات!$C$2:$C$900*COUNTIF('سجل الإنتاج'!$C$2:$C$501,الطبخات!$A$2:$A$900)),3)) -> 27947 | D7: =IF($A7="","",ROUND(SUMIFS('الصرف المباشر'!$D$2:$D$501,'الصرف المباشر'!$C$2:$C$501,$A7)+SUMPRODUCT((الطبخات!$B$2:$B$900=$A7)*الطبخات!$C$2:$C$900*COUNTIF('سجل الإنتاج'!$C$2:$C$501,الطبخات!$A$2:$A$900)),3)) -> 675 | E7: =IF($A7="","",IF($C7<0,"❌ رصيد سالب - يحتاج مراجعة","✔ طبيعي")) -> ✔ طبيعي | F7: =IF(AND($A7<>"",$E7<>"✔ طبيعي"),SUMPRODUCT(('الرصيد الحالي'!$E$2:$E7<>"✔ طبيعي")*('الرصيد الحالي'!$E$2:$E7<>"")*('الرصيد الحالي'!$A$2:$A7<>"")),"")
A8: =المواد!A8 -> ماء بلسم | B8: =المواد!B8 -> كغ | C8: =IF($A8="","",ROUND(SUMIFS(الإدخالات!$D$2:$D$501,الإدخالات!$C$2:$C$501,$A8)+SUMIFS('تعديل الجرد'!$F$2:$F$501,'تعديل الجرد'!$C$2:$C$501,$A8)-SUMIFS('الصرف المباشر'!$D$2:$D$501,'الصرف المباشر'!$C$2:$C$501,$A8)-SUMPRODUCT((الطبخات!$B$2:$B$900=$A8)*الطبخات!$C$2:$C$900*COUNTIF('سجل الإنتاج'!$C$2:$C$501,الطبخات!$A$2:$A$900)),3)) -> 0 | D8: =IF($A8="","",ROUND(SUMIFS('الصرف المباشر'!$D$2:$D$501,'الصرف المباشر'!$C$2:$C$501,$A8)+SUMPRODUCT((الطبخات!$B$2:$B$900=$A8)*الطبخات!$C$2:$C$900*COUNTIF('سجل الإنتاج'!$C$2:$C$501,الطبخات!$A$2:$A$900)),3)) -> 0 | E8: =IF($A8="","",IF($C8<0,"❌ رصيد سالب - يحتاج مراجعة","✔ طبيعي")) -> ✔ طبيعي | F8: =IF(AND($A8<>"",$E8<>"✔ طبيعي"),SUMPRODUCT(('الرصيد الحالي'!$E$2:$E8<>"✔ طبيعي")*('الرصيد الحالي'!$E$2:$E8<>"")*('الرصيد الحالي'!$A$2:$A8<>"")),"")
A9: =المواد!A9 -> لانيت 16 ماليزي | B9: =المواد!B9 -> كغ | C9: =IF($A9="","",ROUND(SUMIFS(الإدخالات!$D$2:$D$501,الإدخالات!$C$2:$C$501,$A9)+SUMIFS('تعديل الجرد'!$F$2:$F$501,'تعديل الجرد'!$C$2:$C$501,$A9)-SUMIFS('الصرف المباشر'!$D$2:$D$501,'الصرف المباشر'!$C$2:$C$501,$A9)-SUMPRODUCT((الطبخات!$B$2:$B$900=$A9)*الطبخات!$C$2:$C$900*COUNTIF('سجل الإنتاج'!$C$2:$C$501,الطبخات!$A$2:$A$900)),3)) -> 0 | D9: =IF($A9="","",ROUND(SUMIFS('الصرف المباشر'!$D$2:$D$501,'الصرف المباشر'!$C$2:$C$501,$A9)+SUMPRODUCT((الطبخات!$B$2:$B$900=$A9)*الطبخات!$C$2:$C$900*COUNTIF('سجل الإنتاج'!$C$2:$C$501,الطبخات!$A$2:$A$900)),3)) -> 0 | E9: =IF($A9="","",IF($C9<0,"❌ رصيد سالب - يحتاج مراجعة","✔ طبيعي")) -> ✔ طبيعي | F9: =IF(AND($A9<>"",$E9<>"✔ طبيعي"),SUMPRODUCT(('الرصيد الحالي'!$E$2:$E9<>"✔ طبيعي")*('الرصيد الحالي'!$E$2:$E9<>"")*('الرصيد الحالي'!$A$2:$A9<>"")),"")
A10: =المواد!A10 -> كوستيك-قطرونة | B10: =المواد!B10 -> كغ | C10: =IF($A10="","",ROUND(SUMIFS(الإدخالات!$D$2:$D$501,الإدخالات!$C$2:$C$501,$A10)+SUMIFS('تعديل الجرد'!$F$2:$F$501,'تعديل الجرد'!$C$2:$C$501,$A10)-SUMIFS('الصرف المباشر'!$D$2:$D$501,'الصرف المباشر'!$C$2:$C$501,$A10)-SUMPRODUCT((الطبخات!$B$2:$B$900=$A10)*الطبخات!$C$2:$C$900*COUNTIF('سجل الإنتاج'!$C$2:$C$501,الطبخات!$A$2:$A$900)),3)) -> 8.71 | D10: =IF($A10="","",ROUND(SUMIFS('الصرف المباشر'!$D$2:$D$501,'الصرف المباشر'!$C$2:$C$501,$A10)+SUMPRODUCT((الطبخات!$B$2:$B$900=$A10)*الطبخات!$C$2:$C$900*COUNTIF('سجل الإنتاج'!$C$2:$C$501,الطبخات!$A$2:$A$900)),3)) -> 19 | E10: =IF($A10="","",IF($C10<0,"❌ رصيد سالب - يحتاج مراجعة","✔ طبيعي")) -> ✔ طبيعي | F10: =IF(AND($A10<>"",$E10<>"✔ طبيعي"),SUMPRODUCT(('الرصيد الحالي'!$E$2:$E10<>"✔ طبيعي")*('الرصيد الحالي'!$E$2:$E10<>"")*('الرصيد الحالي'!$A$2:$A10<>"")),"")
A11: =المواد!A11 -> كمبرلان | B11: =المواد!B11 -> كغ | C11: =IF($A11="","",ROUND(SUMIFS(الإدخالات!$D$2:$D$501,الإدخالات!$C$2:$C$501,$A11)+SUMIFS('تعديل الجرد'!$F$2:$F$501,'تعديل الجرد'!$C$2:$C$501,$A11)-SUMIFS('الصرف المباشر'!$D$2:$D$501,'الصرف المباشر'!$C$2:$C$501,$A11)-SUMPRODUCT((الطبخات!$B$2:$B$900=$A11)*الطبخات!$C$2:$C$900*COUNTIF('سجل الإنتاج'!$C$2:$C$501,الطبخات!$A$2:$A$900)),3)) -> 0 | D11: =IF($A11="","",ROUND(SUMIFS('الصرف المباشر'!$D$2:$D$501,'الصرف المباشر'!$C$2:$C$501,$A11)+SUMPRODUCT((الطبخات!$B$2:$B$900=$A11)*الطبخات!$C$2:$C$900*COUNTIF('سجل الإنتاج'!$C$2:$C$501,الطبخات!$A$2:$A$900)),3)) -> 0 | E11: =IF($A11="","",IF($C11<0,"❌ رصيد سالب - يحتاج مراجعة","✔ طبيعي")) -> ✔ طبيعي | F11: =IF(AND($A11<>"",$E11<>"✔ طبيعي"),SUMPRODUCT(('الرصيد الحالي'!$E$2:$E11<>"✔ طبيعي")*('الرصيد الحالي'!$E$2:$E11<>"")*('الرصيد الحالي'!$A$2:$A11<>"")),"")
A12: =المواد!A12 -> كليمازول | B12: =المواد!B12 -> كغ | C12: =IF($A12="","",ROUND(SUMIFS(الإدخالات!$D$2:$D$501,الإدخالات!$C$2:$C$501,$A12)+SUMIFS('تعديل الجرد'!$F$2:$F$501,'تعديل الجرد'!$C$2:$C$501,$A12)-SUMIFS('الصرف المباشر'!$D$2:$D$501,'الصرف المباشر'!$C$2:$C$501,$A12)-SUMPRODUCT((الطبخات!$B$2:$B$900=$A12)*الطبخات!$C$2:$C$900*COUNTIF('سجل الإنتاج'!$C$2:$C$501,الطبخات!$A$2:$A$900)),3)) -> 0 | D12: =IF($A12="","",ROUND(SUMIFS('الصرف المباشر'!$D$2:$D$501,'الصرف المباشر'!$C$2:$C$501,$A12)+SUMPRODUCT((الطبخات!$B$2:$B$900=$A12)*الطبخات!$C$2:$C$900*COUNTIF('سجل الإنتاج'!$C$2:$C$501,الطبخات!$A$2:$A$900)),3)) -> 0 | E12: =IF($A12="","",IF($C12<0,"❌ رصيد سالب - يحتاج مراجعة","✔ طبيعي")) -> ✔ طبيعي | F12: =IF(AND($A12<>"",$E12<>"✔ طبيعي"),SUMPRODUCT(('الرصيد الحالي'!$E$2:$E12<>"✔ طبيعي")*('الرصيد الحالي'!$E$2:$E12<>"")*('الرصيد الحالي'!$A$2:$A12<>"")),"")
A13: =المواد!A13 -> كلور خام | B13: =المواد!B13 -> كغ | C13: =IF($A13="","",ROUND(SUMIFS(الإدخالات!$D$2:$D$501,الإدخالات!$C$2:$C$501,$A13)+SUMIFS('تعديل الجرد'!$F$2:$F$501,'تعديل الجرد'!$C$2:$C$501,$A13)-SUMIFS('الصرف المباشر'!$D$2:$D$501,'الصرف المباشر'!$C$2:$C$501,$A13)-SUMPRODUCT((الطبخات!$B$2:$B$900=$A13)*الطبخات!$C$2:$C$900*COUNTIF('سجل الإنتاج'!$C$2:$C$501,الطبخات!$A$2:$A$900)),3)) -> 272 | D13: =IF($A13="","",ROUND(SUMIFS('الصرف المباشر'!$D$2:$D$501,'الصرف المباشر'!$C$2:$C$501,$A13)+SUMPRODUCT((الطبخات!$B$2:$B$900=$A13)*الطبخات!$C$2:$C$900*COUNTIF('سجل الإنتاج'!$C$2:$C$501,الطبخات!$A$2:$A$900)),3)) -> 0 | E13: =IF($A13="","",IF($C13<0,"❌ رصيد سالب - يحتاج مراجعة","✔ طبيعي")) -> ✔ طبيعي | F13: =IF(AND($A13<>"",$E13<>"✔ طبيعي"),SUMPRODUCT(('الرصيد الحالي'!$E$2:$E13<>"✔ طبيعي")*('الرصيد الحالي'!$E$2:$E13<>"")*('الرصيد الحالي'!$A$2:$A13<>"")),"")
... A74: =المواد!A74 -> عبوات حليبي | B74: =المواد!B74 -> قطعة | C74: =IF($A74="","",ROUND(SUMIFS(الإدخالات!$D$2:$D$501,الإدخالات!$C$2:$C$501,$A74)+SUMIFS('تعديل الجرد'!$F$2:$F$501,'تعديل الجرد'!$C$2:$C$501,$A74)-SUMIFS('الصرف المباشر'!$D$2:$D$501,'الصرف المباشر'!$C$2:$C$501,$A74)-SUMPRODUCT((الطبخات!$B$2:$B$900=$A74)*الطبخات!$C$2:$C$900*COUNTIF('سجل الإنتاج'!$C$2:$C$501,الطبخات!$A$2:$A$900)),3)) -> 93.75 | D74: =IF($A74="","",ROUND(SUMIFS('الصرف المباشر'!$D$2:$D$501,'الصرف المباشر'!$C$2:$C$501,$A74)+SUMPRODUCT((الطبخات!$B$2:$B$900=$A74)*الطبخات!$C$2:$C$900*COUNTIF('سجل الإنتاج'!$C$2:$C$501,الطبخات!$A$2:$A$900)),3)) -> 0 | E74: =IF($A74="","",IF($C74<0,"❌ رصيد سالب - يحتاج مراجعة","✔ طبيعي")) -> ✔ طبيعي | F74: =IF(AND($A74<>"",$E74<>"✔ طبيعي"),SUMPRODUCT(('الرصيد الحالي'!$E$2:$E74<>"✔ طبيعي")*('الرصيد الحالي'!$E$2:$E74<>"")*('الرصيد الحالي'!$A$2:$A74<>"")),"")
A75: =المواد!#REF! -> #REF! | B75: =المواد!#REF! -> #REF! | C75: =IF($A75="","",ROUND(SUMIFS(الإدخالات!$D$2:$D$501,الإدخالات!$C$2:$C$501,$A75)+SUMIFS('تعديل الجرد'!$F$2:$F$501,'تعديل الجرد'!$C$2:$C$501,$A75)-SUMIFS('الصرف المباشر'!$D$2:$D$501,'الصرف المباشر'!$C$2:$C$501,$A75)-SUMPRODUCT((الطبخات!$B$2:$B$900=$A75)*الطبخات!$C$2:$C$900*COUNTIF('سجل الإنتاج'!$C$2:$C$501,الطبخات!$A$2:$A$900)),3)) -> #REF! | D75: =IF($A75="","",ROUND(SUMIFS('الصرف المباشر'!$D$2:$D$501,'الصرف المباشر'!$C$2:$C$501,$A75)+SUMPRODUCT((الطبخات!$B$2:$B$900=$A75)*الطبخات!$C$2:$C$900*COUNTIF('سجل الإنتاج'!$C$2:$C$501,الطبخات!$A$2:$A$900)),3)) -> #REF! | E75: =IF($A75="","",IF($C75<0,"❌ رصيد سالب - يحتاج مراجعة","✔ طبيعي")) -> #REF! | F75: =IF(AND($A75<>"",$E75<>"✔ طبيعي"),SUMPRODUCT(('الرصيد الحالي'!$E$2:$E75<>"✔ طبيعي")*('الرصيد الحالي'!$E$2:$E75<>"")*('الرصيد الحالي'!$A$2:$A75<>"")),"") -> #REF!
A76: =المواد!A75 -> عطر عود | B76: =المواد!B75 -> كغ | C76: =IF($A76="","",ROUND(SUMIFS(الإدخالات!$D$2:$D$501,الإدخالات!$C$2:$C$501,$A76)+SUMIFS('تعديل الجرد'!$F$2:$F$501,'تعديل الجرد'!$C$2:$C$501,$A76)-SUMIFS('الصرف المباشر'!$D$2:$D$501,'الصرف المباشر'!$C$2:$C$501,$A76)-SUMPRODUCT((الطبخات!$B$2:$B$900=$A76)*الطبخات!$C$2:$C$900*COUNTIF('سجل الإنتاج'!$C$2:$C$501,الطبخات!$A$2:$A$900)),3)) -> 0 | D76: =IF($A76="","",ROUND(SUMIFS('الصرف المباشر'!$D$2:$D$501,'الصرف المباشر'!$C$2:$C$501,$A76)+SUMPRODUCT((الطبخات!$B$2:$B$900=$A76)*الطبخات!$C$2:$C$900*COUNTIF('سجل الإنتاج'!$C$2:$C$501,الطبخات!$A$2:$A$900)),3)) -> 0 | E76: =IF($A76="","",IF($C76<0,"❌ رصيد سالب - يحتاج مراجعة","✔ طبيعي")) -> ✔ طبيعي | F76: =IF(AND($A76<>"",$E76<>"✔ طبيعي"),SUMPRODUCT(('الرصيد الحالي'!$E$2:$E76<>"✔ طبيعي")*('الرصيد الحالي'!$E$2:$E76<>"")*('الرصيد الحالي'!$A$2:$A76<>"")),"")
A77: =المواد!A76 -> بربولين غيلمول | B77: =المواد!B76 -> كغ | C77: =IF($A77="","",ROUND(SUMIFS(الإدخالات!$D$2:$D$501,الإدخالات!$C$2:$C$501,$A77)+SUMIFS('تعديل الجرد'!$F$2:$F$501,'تعديل الجرد'!$C$2:$C$501,$A77)-SUMIFS('الصرف المباشر'!$D$2:$D$501,'الصرف المباشر'!$C$2:$C$501,$A77)-SUMPRODUCT((الطبخات!$B$2:$B$900=$A77)*الطبخات!$C$2:$C$900*COUNTIF('سجل الإنتاج'!$C$2:$C$501,الطبخات!$A$2:$A$900)),3)) -> 0 | D77: =IF($A77="","",ROUND(SUMIFS('الصرف المباشر'!$D$2:$D$501,'الصرف المباشر'!$C$2:$C$501,$A77)+SUMPRODUCT((الطبخات!$B$2:$B$900=$A77)*الطبخات!$C$2:$C$900*COUNTIF('سجل الإنتاج'!$C$2:$C$501,الطبخات!$A$2:$A$900)),3)) -> 0 | E77: =IF($A77="","",IF($C77<0,"❌ رصيد سالب - يحتاج مراجعة","✔ طبيعي")) -> ✔ طبيعي | F77: =IF(AND($A77<>"",$E77<>"✔ طبيعي"),SUMPRODUCT(('الرصيد الحالي'!$E$2:$E77<>"✔ طبيعي")*('الرصيد الحالي'!$E$2:$E77<>"")*('الرصيد الحالي'!$A$2:$A77<>"")),"")
A78: =المواد!A77 -> حبيبات ملونة | B78: =المواد!B77 -> كغ | C78: =IF($A78="","",ROUND(SUMIFS(الإدخالات!$D$2:$D$501,الإدخالات!$C$2:$C$501,$A78)+SUMIFS('تعديل الجرد'!$F$2:$F$501,'تعديل الجرد'!$C$2:$C$501,$A78)-SUMIFS('الصرف المباشر'!$D$2:$D$501,'الصرف المباشر'!$C$2:$C$501,$A78)-SUMPRODUCT((الطبخات!$B$2:$B$900=$A78)*الطبخات!$C$2:$C$900*COUNTIF('سجل الإنتاج'!$C$2:$C$501,الطبخات!$A$2:$A$900)),3)) -> 0 | D78: =IF($A78="","",ROUND(SUMIFS('الصرف المباشر'!$D$2:$D$501,'الصرف المباشر'!$C$2:$C$501,$A78)+SUMPRODUCT((الطبخات!$B$2:$B$900=$A78)*الطبخات!$C$2:$C$900*COUNTIF('سجل الإنتاج'!$C$2:$C$501,الطبخات!$A$2:$A$900)),3)) -> 0 | E78: =IF($A78="","",IF($C78<0,"❌ رصيد سالب - يحتاج مراجعة","✔ طبيعي")) -> ✔ طبيعي | F78: =IF(AND($A78<>"",$E78<>"✔ طبيعي"),SUMPRODUCT(('الرصيد الحالي'!$E$2:$E78<>"✔ طبيعي")*('الرصيد الحالي'!$E$2:$E78<>"")*('الرصيد الحالي'!$A$2:$A78<>"")),"")
A79: =المواد!A78 -> غطا عبوة 3لتر | B79: =المواد!B78 -> قطعة | C79: =IF($A79="","",ROUND(SUMIFS(الإدخالات!$D$2:$D$501,الإدخالات!$C$2:$C$501,$A79)+SUMIFS('تعديل الجرد'!$F$2:$F$501,'تعديل الجرد'!$C$2:$C$501,$A79)-SUMIFS('الصرف المباشر'!$D$2:$D$501,'الصرف المباشر'!$C$2:$C$501,$A79)-SUMPRODUCT((الطبخات!$B$2:$B$900=$A79)*الطبخات!$C$2:$C$900*COUNTIF('سجل الإنتاج'!$C$2:$C$501,الطبخات!$A$2:$A$900)),3)) -> 0 | D79: =IF($A79="","",ROUND(SUMIFS('الصرف المباشر'!$D$2:$D$501,'الصرف المباشر'!$C$2:$C$501,$A79)+SUMPRODUCT((الطبخات!$B$2:$B$900=$A79)*الطبخات!$C$2:$C$900*COUNTIF('سجل الإنتاج'!$C$2:$C$501,الطبخات!$A$2:$A$900)),3)) -> 0 | E79: =IF($A79="","",IF($C79<0,"❌ رصيد سالب - يحتاج مراجعة","✔ طبيعي")) -> ✔ طبيعي | F79: =IF(AND($A79<>"",$E79<>"✔ طبيعي"),SUMPRODUCT(('الرصيد الحالي'!$E$2:$E79<>"✔ طبيعي")*('الرصيد الحالي'!$E$2:$E79<>"")*('الرصيد الحالي'!$A$2:$A79<>"")),"")
A80: =المواد!A79 -> مياه مقطرة 4 لتر | B80: =المواد!B79 -> عبوة | C80: =IF($A80="","",ROUND(SUMIFS(الإدخالات!$D$2:$D$501,الإدخالات!$C$2:$C$501,$A80)+SUMIFS('تعديل الجرد'!$F$2:$F$501,'تعديل الجرد'!$C$2:$C$501,$A80)-SUMIFS('الصرف المباشر'!$D$2:$D$501,'الصرف المباشر'!$C$2:$C$501,$A80)-SUMPRODUCT((الطبخات!$B$2:$B$900=$A80)*الطبخات!$C$2:$C$900*COUNTIF('سجل الإنتاج'!$C$2:$C$501,الطبخات!$A$2:$A$900)),3)) -> 0 | D80: =IF($A80="","",ROUND(SUMIFS('الصرف المباشر'!$D$2:$D$501,'الصرف المباشر'!$C$2:$C$501,$A80)+SUMPRODUCT((الطبخات!$B$2:$B$900=$A80)*الطبخات!$C$2:$C$900*COUNTIF('سجل الإنتاج'!$C$2:$C$501,الطبخات!$A$2:$A$900)),3)) -> 0 | E80: =IF($A80="","",IF($C80<0,"❌ رصيد سالب - يحتاج مراجعة","✔ طبيعي")) -> ✔ طبيعي | F80: =IF(AND($A80<>"",$E80<>"✔ طبيعي"),SUMPRODUCT(('الرصيد الحالي'!$E$2:$E80<>"✔ طبيعي")*('الرصيد الحالي'!$E$2:$E80<>"")*('الرصيد الحالي'!$A$2:$A80<>"")),"")
A81: =المواد!A80 -> مياه مقطرة 1 لتر | B81: =المواد!B80 -> عبوة | C81: =IF($A81="","",ROUND(SUMIFS(الإدخالات!$D$2:$D$501,الإدخالات!$C$2:$C$501,$A81)+SUMIFS('تعديل الجرد'!$F$2:$F$501,'تعديل الجرد'!$C$2:$C$501,$A81)-SUMIFS('الصرف المباشر'!$D$2:$D$501,'الصرف المباشر'!$C$2:$C$501,$A81)-SUMPRODUCT((الطبخات!$B$2:$B$900=$A81)*الطبخات!$C$2:$C$900*COUNTIF('سجل الإنتاج'!$C$2:$C$501,الطبخات!$A$2:$A$900)),3)) -> 0 | D81: =IF($A81="","",ROUND(SUMIFS('الصرف المباشر'!$D$2:$D$501,'الصرف المباشر'!$C$2:$C$501,$A81)+SUMPRODUCT((الطبخات!$B$2:$B$900=$A81)*الطبخات!$C$2:$C$900*COUNTIF('سجل الإنتاج'!$C$2:$C$501,الطبخات!$A$2:$A$900)),3)) -> 0 | E81: =IF($A81="","",IF($C81<0,"❌ رصيد سالب - يحتاج مراجعة","✔ طبيعي")) -> ✔ طبيعي | F81: =IF(AND($A81<>"",$E81<>"✔ طبيعي"),SUMPRODUCT(('الرصيد الحالي'!$E$2:$E81<>"✔ طبيعي")*('الرصيد الحالي'!$E$2:$E81<>"")*('الرصيد الحالي'!$A$2:$A81<>"")),"")
A82: =المواد!A81 -> مهسهس زفته - معجون | B82: =المواد!B81 -> كغ | C82: =IF($A82="","",ROUND(SUMIFS(الإدخالات!$D$2:$D$501,الإدخالات!$C$2:$C$501,$A82)+SUMIFS('تعديل الجرد'!$F$2:$F$501,'تعديل الجرد'!$C$2:$C$501,$A82)-SUMIFS('الصرف المباشر'!$D$2:$D$501,'الصرف المباشر'!$C$2:$C$501,$A82)-SUMPRODUCT((الطبخات!$B$2:$B$900=$A82)*الطبخات!$C$2:$C$900*COUNTIF('سجل الإنتاج'!$C$2:$C$501,الطبخات!$A$2:$A$900)),3)) -> 0 | D82: =IF($A82="","",ROUND(SUMIFS('الصرف المباشر'!$D$2:$D$501,'الصرف المباشر'!$C$2:$C$501,$A82)+SUMPRODUCT((الطبخات!$B$2:$B$900=$A82)*الطبخات!$C$2:$C$900*COUNTIF('سجل الإنتاج'!$C$2:$C$501,الطبخات!$A$2:$A$900)),3)) -> 0 | E82: =IF($A82="","",IF($C82<0,"❌ رصيد سالب - يحتاج مراجعة","✔ طبيعي")) -> ✔ طبيعي | F82: =IF(AND($A82<>"",$E82<>"✔ طبيعي"),SUMPRODUCT(('الرصيد الحالي'!$E$2:$E82<>"✔ طبيعي")*('الرصيد الحالي'!$E$2:$E82<>"")*('الرصيد الحالي'!$A$2:$A82<>"")),"")
A83: =المواد!A82 -> مماسح مكتب َ | B83: =المواد!B82 -> كيس | C83: =IF($A83="","",ROUND(SUMIFS(الإدخالات!$D$2:$D$501,الإدخالات!$C$2:$C$501,$A83)+SUMIFS('تعديل الجرد'!$F$2:$F$501,'تعديل الجرد'!$C$2:$C$501,$A83)-SUMIFS('الصرف المباشر'!$D$2:$D$501,'الصرف المباشر'!$C$2:$C$501,$A83)-SUMPRODUCT((الطبخات!$B$2:$B$900=$A83)*الطبخات!$C$2:$C$900*COUNTIF('سجل الإنتاج'!$C$2:$C$501,الطبخات!$A$2:$A$900)),3)) -> 0 | D83: =IF($A83="","",ROUND(SUMIFS('الصرف المباشر'!$D$2:$D$501,'الصرف المباشر'!$C$2:$C$501,$A83)+SUMPRODUCT((الطبخات!$B$2:$B$900=$A83)*الطبخات!$C$2:$C$900*COUNTIF('سجل الإنتاج'!$C$2:$C$501,الطبخات!$A$2:$A$900)),3)) -> 0 | E83: =IF($A83="","",IF($C83<0,"❌ رصيد سالب - يحتاج مراجعة","✔ طبيعي")) -> ✔ طبيعي | F83: =IF(AND($A83<>"",$E83<>"✔ طبيعي"),SUMPRODUCT(('الرصيد الحالي'!$E$2:$E83<>"✔ طبيعي")*('الرصيد الحالي'!$E$2:$E83<>"")*('الرصيد الحالي'!$A$2:$A83<>"")),"")
A84: =المواد!A83 -> مماسح قماش عائلة فايبر | B84: =المواد!B83 -> كيس | C84: =IF($A84="","",ROUND(SUMIFS(الإدخالات!$D$2:$D$501,الإدخالات!$C$2:$C$501,$A84)+SUMIFS('تعديل الجرد'!$F$2:$F$501,'تعديل الجرد'!$C$2:$C$501,$A84)-SUMIFS('الصرف المباشر'!$D$2:$D$501,'الصرف المباشر'!$C$2:$C$501,$A84)-SUMPRODUCT((الطبخات!$B$2:$B$900=$A84)*الطبخات!$C$2:$C$900*COUNTIF('سجل الإنتاج'!$C$2:$C$501,الطبخات!$A$2:$A$900)),3)) -> 0 | D84: =IF($A84="","",ROUND(SUMIFS('الصرف المباشر'!$D$2:$D$501,'الصرف المباشر'!$C$2:$C$501,$A84)+SUMPRODUCT((الطبخات!$B$2:$B$900=$A84)*الطبخات!$C$2:$C$900*COUNTIF('سجل الإنتاج'!$C$2:$C$501,الطبخات!$A$2:$A$900)),3)) -> 0 | E84: =IF($A84="","",IF($C84<0,"❌ رصيد سالب - يحتاج مراجعة","✔ طبيعي")) -> ✔ طبيعي | F84: =IF(AND($A84<>"",$E84<>"✔ طبيعي"),SUMPRODUCT(('الرصيد الحالي'!$E$2:$E84<>"✔ طبيعي")*('الرصيد الحالي'!$E$2:$E84<>"")*('الرصيد الحالي'!$A$2:$A84<>"")),"")
A85: =المواد!A84 -> مماسح بلور | B85: =المواد!B84 -> كيس | C85: =IF($A85="","",ROUND(SUMIFS(الإدخالات!$D$2:$D$501,الإدخالات!$C$2:$C$501,$A85)+SUMIFS('تعديل الجرد'!$F$2:$F$501,'تعديل الجرد'!$C$2:$C$501,$A85)-SUMIFS('الصرف المباشر'!$D$2:$D$501,'الصرف المباشر'!$C$2:$C$501,$A85)-SUMPRODUCT((الطبخات!$B$2:$B$900=$A85)*الطبخات!$C$2:$C$900*COUNTIF('سجل الإنتاج'!$C$2:$C$501,الطبخات!$A$2:$A$900)),3)) -> 0 | D85: =IF($A85="","",ROUND(SUMIFS('الصرف المباشر'!$D$2:$D$501,'الصرف المباشر'!$C$2:$C$501,$A85)+SUMPRODUCT((الطبخات!$B$2:$B$900=$A85)*الطبخات!$C$2:$C$900*COUNTIF('سجل الإنتاج'!$C$2:$C$501,الطبخات!$A$2:$A$900)),3)) -> 0 | E85: =IF($A85="","",IF($C85<0,"❌ رصيد سالب - يحتاج مراجعة","✔ طبيعي")) -> ✔ طبيعي | F85: =IF(AND($A85<>"",$E85<>"✔ طبيعي"),SUMPRODUCT(('الرصيد الحالي'!$E$2:$E85<>"✔ طبيعي")*('الرصيد الحالي'!$E$2:$E85<>"")*('الرصيد الحالي'!$A$2:$A85<>"")),"")
A86: =المواد!A85 -> مماسح ارضيات | B86: =المواد!B85 -> كيس | C86: =IF($A86="","",ROUND(SUMIFS(الإدخالات!$D$2:$D$501,الإدخالات!$C$2:$C$501,$A86)+SUMIFS('تعديل الجرد'!$F$2:$F$501,'تعديل الجرد'!$C$2:$C$501,$A86)-SUMIFS('الصرف المباشر'!$D$2:$D$501,'الصرف المباشر'!$C$2:$C$501,$A86)-SUMPRODUCT((الطبخات!$B$2:$B$900=$A86)*الطبخات!$C$2:$C$900*COUNTIF('سجل الإنتاج'!$C$2:$C$501,الطبخات!$A$2:$A$900)),3)) -> 0 | D86: =IF($A86="","",ROUND(SUMIFS('الصرف المباشر'!$D$2:$D$501,'الصرف المباشر'!$C$2:$C$501,$A86)+SUMPRODUCT((الطبخات!$B$2:$B$900=$A86)*الطبخات!$C$2:$C$900*COUNTIF('سجل الإنتاج'!$C$2:$C$501,الطبخات!$A$2:$A$900)),3)) -> 0 | E86: =IF($A86="","",IF($C86<0,"❌ رصيد سالب - يحتاج مراجعة","✔ طبيعي")) -> ✔ طبيعي | F86: =IF(AND($A86<>"",$E86<>"✔ طبيعي"),SUMPRODUCT(('الرصيد الحالي'!$E$2:$E86<>"✔ طبيعي")*('الرصيد الحالي'!$E$2:$E86<>"")*('الرصيد الحالي'!$A$2:$A86<>"")),"")
A87: =المواد!A86 -> ملمع سيارات 3 لتر | B87: =المواد!B86 -> عبوة | C87: =IF($A87="","",ROUND(SUMIFS(الإدخالات!$D$2:$D$501,الإدخالات!$C$2:$C$501,$A87)+SUMIFS('تعديل الجرد'!$F$2:$F$501,'تعديل الجرد'!$C$2:$C$501,$A87)-SUMIFS('الصرف المباشر'!$D$2:$D$501,'الصرف المباشر'!$C$2:$C$501,$A87)-SUMPRODUCT((الطبخات!$B$2:$B$900=$A87)*الطبخات!$C$2:$C$900*COUNTIF('سجل الإنتاج'!$C$2:$C$501,الطبخات!$A$2:$A$900)),3)) -> 0 | D87: =IF($A87="","",ROUND(SUMIFS('الصرف المباشر'!$D$2:$D$501,'الصرف المباشر'!$C$2:$C$501,$A87)+SUMPRODUCT((الطبخات!$B$2:$B$900=$A87)*الطبخات!$C$2:$C$900*COUNTIF('سجل الإنتاج'!$C$2:$C$501,الطبخات!$A$2:$A$900)),3)) -> 0 | E87: =IF($A87="","",IF($C87<0,"❌ رصيد سالب - يحتاج مراجعة","✔ طبيعي")) -> ✔ طبيعي | F87: =IF(AND($A87<>"",$E87<>"✔ طبيعي"),SUMPRODUCT(('الرصيد الحالي'!$E$2:$E87<>"✔ طبيعي")*('الرصيد الحالي'!$E$2:$E87<>"")*('الرصيد الحالي'!$A$2:$A87<>"")),"")
... A320: =المواد!A319 -> 0 | B320: =المواد!B319 -> 0 | C320: =IF($A320="","",ROUND(SUMIFS(الإدخالات!$D$2:$D$501,الإدخالات!$C$2:$C$501,$A320)+SUMIFS('تعديل الجرد'!$F$2:$F$501,'تعديل الجرد'!$C$2:$C$501,$A320)-SUMIFS('الصرف المباشر'!$D$2:$D$501,'الصرف المباشر'!$C$2:$C$501,$A320)-SUMPRODUCT((الطبخات!$B$2:$B$900=$A320)*الطبخات!$C$2:$C$900*COUNTIF('سجل الإنتاج'!$C$2:$C$501,الطبخات!$A$2:$A$900)),3)) -> 0 | D320: =IF($A320="","",ROUND(SUMIFS('الصرف المباشر'!$D$2:$D$501,'الصرف المباشر'!$C$2:$C$501,$A320)+SUMPRODUCT((الطبخات!$B$2:$B$900=$A320)*الطبخات!$C$2:$C$900*COUNTIF('سجل الإنتاج'!$C$2:$C$501,الطبخات!$A$2:$A$900)),3)) -> 0 | E320: =IF($A320="","",IF($C320<0,"❌ رصيد سالب - يحتاج مراجعة","✔ طبيعي")) -> ✔ طبيعي | F320: =IF(AND($A320<>"",$E320<>"✔ طبيعي"),SUMPRODUCT(('الرصيد الحالي'!$E$2:$E320<>"✔ طبيعي")*('الرصيد الحالي'!$E$2:$E320<>"")*('الرصيد الحالي'!$A$2:$A320<>"")),"")

Sheet سجل الحركات
A1: التاريخ | B1: نوع الحركة | C1: المرجع (طبخة/مورد/جهة/سبب) | D1: المادة | E1: الكمية (+ إدخال / - إخراج) | F1: ملاحظات | H1: ملاحظة: هذه الصفحة مضغوطة تلقائياً (بدون فراغات) وتعرض العمليات الأربع كلها - شراء، ثم صرف مباشر، ثم إنتاج، ثم تعديل جرد - كل نوع بترتيب إدخاله. للعرض حسب التاريخ فقط استخدم عامل التصفية/الفرز على عمود "التاريخ".
A2: =IFERROR(INDEX('بيانات الحركات'!A:A,MATCH(1,'بيانات الحركات'!$G:$G,0)),"") -> 46218 | B2: =IFERROR(INDEX('بيانات الحركات'!B:B,MATCH(1,'بيانات الحركات'!$G:$G,0)),"") -> شراء | C2: =IFERROR(INDEX('بيانات الحركات'!C:C,MATCH(1,'بيانات الحركات'!$G:$G,0)),"") -> امين | D2: =IFERROR(INDEX('بيانات الحركات'!D:D,MATCH(1,'بيانات الحركات'!$G:$G,0)),"") -> ملح | E2: =IF($B2="إنتاج طبخة","",IFERROR(INDEX('بيانات الحركات'!E:E,MATCH(1,'بيانات الحركات'!$G:$G,0)),"")) -> 138.04 | F2: =IFERROR(INDEX('بيانات الحركات'!F:F,MATCH(1,'بيانات الحركات'!$G:$G,0)),"") -> تنزيل البيانات لأول مرة
A3: =IFERROR(INDEX('بيانات الحركات'!A:A,MATCH(2,'بيانات الحركات'!$G:$G,0)),"") -> 46218 | B3: =IFERROR(INDEX('بيانات الحركات'!B:B,MATCH(2,'بيانات الحركات'!$G:$G,0)),"") -> شراء | C3: =IFERROR(INDEX('بيانات الحركات'!C:C,MATCH(2,'بيانات الحركات'!$G:$G,0)),"") -> امين | D3: =IFERROR(INDEX('بيانات الحركات'!D:D,MATCH(2,'بيانات الحركات'!$G:$G,0)),"") -> مقصب | E3: =IF($B3="إنتاج طبخة","",IFERROR(INDEX('بيانات الحركات'!E:E,MATCH(2,'بيانات الحركات'!$G:$G,0)),"")) -> 2 | F3: =IFERROR(INDEX('بيانات الحركات'!F:F,MATCH(2,'بيانات الحركات'!$G:$G,0)),"") -> تنزيل البيانات لأول مرة
A4: =IFERROR(INDEX('بيانات الحركات'!A:A,MATCH(3,'بيانات الحركات'!$G:$G,0)),"") -> 46218 | B4: =IFERROR(INDEX('بيانات الحركات'!B:B,MATCH(3,'بيانات الحركات'!$G:$G,0)),"") -> شراء | C4: =IFERROR(INDEX('بيانات الحركات'!C:C,MATCH(3,'بيانات الحركات'!$G:$G,0)),"") -> امين | D4: =IFERROR(INDEX('بيانات الحركات'!D:D,MATCH(3,'بيانات الحركات'!$G:$G,0)),"") -> مجمد | E4: =IF($B4="إنتاج طبخة","",IFERROR(INDEX('بيانات الحركات'!E:E,MATCH(3,'بيانات الحركات'!$G:$G,0)),"")) -> 63.5 | F4: =IFERROR(INDEX('بيانات الحركات'!F:F,MATCH(3,'بيانات الحركات'!$G:$G,0)),"") -> تنزيل البيانات لأول مرة
A5: =IFERROR(INDEX('بيانات الحركات'!A:A,MATCH(4,'بيانات الحركات'!$G:$G,0)),"") -> 46218 | B5: =IFERROR(INDEX('بيانات الحركات'!B:B,MATCH(4,'بيانات الحركات'!$G:$G,0)),"") -> شراء | C5: =IFERROR(INDEX('بيانات الحركات'!C:C,MATCH(4,'بيانات الحركات'!$G:$G,0)),"") -> امين | D5: =IFERROR(INDEX('بيانات الحركات'!D:D,MATCH(4,'بيانات الحركات'!$G:$G,0)),"") -> مانع رغوة مائي | E5: =IF($B5="إنتاج طبخة","",IFERROR(INDEX('بيانات الحركات'!E:E,MATCH(4,'بيانات الحركات'!$G:$G,0)),"")) -> 0 | F5: =IFERROR(INDEX('بيانات الحركات'!F:F,MATCH(4,'بيانات الحركات'!$G:$G,0)),"") -> تنزيل البيانات لأول مرة
A6: =IFERROR(INDEX('بيانات الحركات'!A:A,MATCH(5,'بيانات الحركات'!$G:$G,0)),"") -> 46218 | B6: =IFERROR(INDEX('بيانات الحركات'!B:B,MATCH(5,'بيانات الحركات'!$G:$G,0)),"") -> شراء | C6: =IFERROR(INDEX('بيانات الحركات'!C:C,MATCH(5,'بيانات الحركات'!$G:$G,0)),"") -> امين | D6: =IFERROR(INDEX('بيانات الحركات'!D:D,MATCH(5,'بيانات الحركات'!$G:$G,0)),"") -> مانع رغوة سيليكون | E6: =IF($B6="إنتاج طبخة","",IFERROR(INDEX('بيانات الحركات'!E:E,MATCH(5,'بيانات الحركات'!$G:$G,0)),"")) -> 0 | F6: =IFERROR(INDEX('بيانات الحركات'!F:F,MATCH(5,'بيانات الحركات'!$G:$G,0)),"") -> تنزيل البيانات لأول مرة
A7: =IFERROR(INDEX('بيانات الحركات'!A:A,MATCH(6,'بيانات الحركات'!$G:$G,0)),"") -> 46218 | B7: =IFERROR(INDEX('بيانات الحركات'!B:B,MATCH(6,'بيانات الحركات'!$G:$G,0)),"") -> شراء | C7: =IFERROR(INDEX('بيانات الحركات'!C:C,MATCH(6,'بيانات الحركات'!$G:$G,0)),"") -> امين | D7: =IFERROR(INDEX('بيانات الحركات'!D:D,MATCH(6,'بيانات الحركات'!$G:$G,0)),"") -> ماء مقطرة | E7: =IF($B7="إنتاج طبخة","",IFERROR(INDEX('بيانات الحركات'!E:E,MATCH(6,'بيانات الحركات'!$G:$G,0)),"")) -> 28622 | F7: =IFERROR(INDEX('بيانات الحركات'!F:F,MATCH(6,'بيانات الحركات'!$G:$G,0)),"") -> تنزيل البيانات لأول مرة
A8: =IFERROR(INDEX('بيانات الحركات'!A:A,MATCH(7,'بيانات الحركات'!$G:$G,0)),"") -> 46218 | B8: =IFERROR(INDEX('بيانات الحركات'!B:B,MATCH(7,'بيانات الحركات'!$G:$G,0)),"") -> شراء | C8: =IFERROR(INDEX('بيانات الحركات'!C:C,MATCH(7,'بيانات الحركات'!$G:$G,0)),"") -> امين | D8: =IFERROR(INDEX('بيانات الحركات'!D:D,MATCH(7,'بيانات الحركات'!$G:$G,0)),"") -> ماء بلسم | E8: =IF($B8="إنتاج طبخة","",IFERROR(INDEX('بيانات الحركات'!E:E,MATCH(7,'بيانات الحركات'!$G:$G,0)),"")) -> 3 | F8: =IFERROR(INDEX('بيانات الحركات'!F:F,MATCH(7,'بيانات الحركات'!$G:$G,0)),"") -> تنزيل البيانات لأول مرة
A9: =IFERROR(INDEX('بيانات الحركات'!A:A,MATCH(8,'بيانات الحركات'!$G:$G,0)),"") -> 46218 | B9: =IFERROR(INDEX('بيانات الحركات'!B:B,MATCH(8,'بيانات الحركات'!$G:$G,0)),"") -> شراء | C9: =IFERROR(INDEX('بيانات الحركات'!C:C,MATCH(8,'بيانات الحركات'!$G:$G,0)),"") -> امين | D9: =IFERROR(INDEX('بيانات الحركات'!D:D,MATCH(8,'بيانات الحركات'!$G:$G,0)),"") -> لانيت 16 ماليزي | E9: =IF($B9="إنتاج طبخة","",IFERROR(INDEX('بيانات الحركات'!E:E,MATCH(8,'بيانات الحركات'!$G:$G,0)),"")) -> 0 | F9: =IFERROR(INDEX('بيانات الحركات'!F:F,MATCH(8,'بيانات الحركات'!$G:$G,0)),"") -> تنزيل البيانات لأول مرة
A10: =IFERROR(INDEX('بيانات الحركات'!A:A,MATCH(9,'بيانات الحركات'!$G:$G,0)),"") -> 46218 | B10: =IFERROR(INDEX('بيانات الحركات'!B:B,MATCH(9,'بيانات الحركات'!$G:$G,0)),"") -> شراء | C10: =IFERROR(INDEX('بيانات الحركات'!C:C,MATCH(9,'بيانات الحركات'!$G:$G,0)),"") -> امين | D10: =IFERROR(INDEX('بيانات الحركات'!D:D,MATCH(9,'بيانات الحركات'!$G:$G,0)),"") -> كوستيك-قطرونة | E10: =IF($B10="إنتاج طبخة","",IFERROR(INDEX('بيانات الحركات'!E:E,MATCH(9,'بيانات الحركات'!$G:$G,0)),"")) -> 27.71 | F10: =IFERROR(INDEX('بيانات الحركات'!F:F,MATCH(9,'بيانات الحركات'!$G:$G,0)),"") -> تنزيل البيانات لأول مرة
A11: =IFERROR(INDEX('بيانات الحركات'!A:A,MATCH(10,'بيانات الحركات'!$G:$G,0)),"") -> 46218 | B11: =IFERROR(INDEX('بيانات الحركات'!B:B,MATCH(10,'بيانات الحركات'!$G:$G,0)),"") -> شراء | C11: =IFERROR(INDEX('بيانات الحركات'!C:C,MATCH(10,'بيانات الحركات'!$G:$G,0)),"") -> امين | D11: =IFERROR(INDEX('بيانات الحركات'!D:D,MATCH(10,'بيانات الحركات'!$G:$G,0)),"") -> كمبرلان | E11: =IF($B11="إنتاج طبخة","",IFERROR(INDEX('بيانات الحركات'!E:E,MATCH(10,'بيانات الحركات'!$G:$G,0)),"")) -> 0 | F11: =IFERROR(INDEX('بيانات الحركات'!F:F,MATCH(10,'بيانات الحركات'!$G:$G,0)),"") -> تنزيل البيانات لأول مرة
A12: =IFERROR(INDEX('بيانات الحركات'!A:A,MATCH(11,'بيانات الحركات'!$G:$G,0)),"") -> 46218 | B12: =IFERROR(INDEX('بيانات الحركات'!B:B,MATCH(11,'بيانات الحركات'!$G:$G,0)),"") -> شراء | C12: =IFERROR(INDEX('بيانات الحركات'!C:C,MATCH(11,'بيانات الحركات'!$G:$G,0)),"") -> امين | D12: =IFERROR(INDEX('بيانات الحركات'!D:D,MATCH(11,'بيانات الحركات'!$G:$G,0)),"") -> كليمازول | E12: =IF($B12="إنتاج طبخة","",IFERROR(INDEX('بيانات الحركات'!E:E,MATCH(11,'بيانات الحركات'!$G:$G,0)),"")) -> 0 | F12: =IFERROR(INDEX('بيانات الحركات'!F:F,MATCH(11,'بيانات الحركات'!$G:$G,0)),"") -> تنزيل البيانات لأول مرة
A13: =IFERROR(INDEX('بيانات الحركات'!A:A,MATCH(12,'بيانات الحركات'!$G:$G,0)),"") -> 46218 | B13: =IFERROR(INDEX('بيانات الحركات'!B:B,MATCH(12,'بيانات الحركات'!$G:$G,0)),"") -> شراء | C13: =IFERROR(INDEX('بيانات الحركات'!C:C,MATCH(12,'بيانات الحركات'!$G:$G,0)),"") -> امين | D13: =IFERROR(INDEX('بيانات الحركات'!D:D,MATCH(12,'بيانات الحركات'!$G:$G,0)),"") -> كلور خام | E13: =IF($B13="إنتاج طبخة","",IFERROR(INDEX('بيانات الحركات'!E:E,MATCH(12,'بيانات الحركات'!$G:$G,0)),"")) -> 272 | F13: =IFERROR(INDEX('بيانات الحركات'!F:F,MATCH(12,'بيانات الحركات'!$G:$G,0)),"") -> تنزيل البيانات لأول مرة
A14: =IFERROR(INDEX('بيانات الحركات'!A:A,MATCH(13,'بيانات الحركات'!$G:$G,0)),"") -> 46218 | B14: =IFERROR(INDEX('بيانات الحركات'!B:B,MATCH(13,'بيانات الحركات'!$G:$G,0)),"") -> شراء | C14: =IFERROR(INDEX('بيانات الحركات'!C:C,MATCH(13,'بيانات الحركات'!$G:$G,0)),"") -> امين | D14: =IFERROR(INDEX('بيانات الحركات'!D:D,MATCH(13,'بيانات الحركات'!$G:$G,0)),"") -> كحول (ايثانول) | E14: =IF($B14="إنتاج طبخة","",IFERROR(INDEX('بيانات الحركات'!E:E,MATCH(13,'بيانات الحركات'!$G:$G,0)),"")) -> 25 | F14: =IFERROR(INDEX('بيانات الحركات'!F:F,MATCH(13,'بيانات الحركات'!$G:$G,0)),"") -> تنزيل البيانات لأول مرة
A15: =IFERROR(INDEX('بيانات الحركات'!A:A,MATCH(14,'بيانات الحركات'!$G:$G,0)),"") -> 46218 | B15: =IFERROR(INDEX('بيانات الحركات'!B:B,MATCH(14,'بيانات الحركات'!$G:$G,0)),"") -> شراء | C15: =IFERROR(INDEX('بيانات الحركات'!C:C,MATCH(14,'بيانات الحركات'!$G:$G,0)),"") -> امين | D15: =IFERROR(INDEX('بيانات الحركات'!D:D,MATCH(14,'بيانات الحركات'!$G:$G,0)),"") -> فورمول ( سم ) | E15: =IF($B15="إنتاج طبخة","",IFERROR(INDEX('بيانات الحركات'!E:E,MATCH(14,'بيانات الحركات'!$G:$G,0)),"")) -> 1.64 | F15: =IFERROR(INDEX('بيانات الحركات'!F:F,MATCH(14,'بيانات الحركات'!$G:$G,0)),"") -> تنزيل البيانات لأول مرة
A16: =IFERROR(INDEX('بيانات الحركات'!A:A,MATCH(15,'بيانات الحركات'!$G:$G,0)),"") -> 46218 | B16: =IFERROR(INDEX('بيانات الحركات'!B:B,MATCH(15,'بيانات الحركات'!$G:$G,0)),"") -> شراء | C16: =IFERROR(INDEX('بيانات الحركات'!C:C,MATCH(15,'بيانات الحركات'!$G:$G,0)),"") -> امين | D16: =IFERROR(INDEX('بيانات الحركات'!D:D,MATCH(15,'بيانات الحركات'!$G:$G,0)),"") -> فاتي كحول | E16: =IF($B16="إنتاج طبخة","",IFERROR(INDEX('بيانات الحركات'!E:E,MATCH(15,'بيانات الحركات'!$G:$G,0)),"")) -> 251.4 | F16: =IFERROR(INDEX('بيانات الحركات'!F:F,MATCH(15,'بيانات الحركات'!$G:$G,0)),"") -> تنزيل البيانات لأول مرة
A17: =IFERROR(INDEX('بيانات الحركات'!A:A,MATCH(16,'بيانات الحركات'!$G:$G,0)),"") -> 46218 | B17: =IFERROR(INDEX('بيانات الحركات'!B:B,MATCH(16,'بيانات الحركات'!$G:$G,0)),"") -> شراء | C17: =IFERROR(INDEX('بيانات الحركات'!C:C,MATCH(16,'بيانات الحركات'!$G:$G,0)),"") -> امين | D17: =IFERROR(INDEX('بيانات الحركات'!D:D,MATCH(16,'بيانات الحركات'!$G:$G,0)),"") -> غليسيرين | E17: =IF($B17="إنتاج طبخة","",IFERROR(INDEX('بيانات الحركات'!E:E,MATCH(16,'بيانات الحركات'!$G:$G,0)),"")) -> 0 | F17: =IFERROR(INDEX('بيانات الحركات'!F:F,MATCH(16,'بيانات الحركات'!$G:$G,0)),"") -> تنزيل البيانات لأول مرة
A18: =IFERROR(INDEX('بيانات الحركات'!A:A,MATCH(17,'بيانات الحركات'!$G:$G,0)),"") -> 46218 | B18: =IFERROR(INDEX('بيانات الحركات'!B:B,MATCH(17,'بيانات الحركات'!$G:$G,0)),"") -> شراء | C18: =IFERROR(INDEX('بيانات الحركات'!C:C,MATCH(17,'بيانات الحركات'!$G:$G,0)),"") -> امين | D18: =IFERROR(INDEX('بيانات الحركات'!D:D,MATCH(17,'بيانات الحركات'!$G:$G,0)),"") -> عطر-نسيم-المحيط ocean-breeze - 327993 | E18: =IF($B18="إنتاج طبخة","",IFERROR(INDEX('بيانات الحركات'!E:E,MATCH(17,'بيانات الحركات'!$G:$G,0)),"")) -> 0.59 | F18: =IFERROR(INDEX('بيانات الحركات'!F:F,MATCH(17,'بيانات الحركات'!$G:$G,0)),"") -> تنزيل البيانات لأول مرة
A19: =IFERROR(INDEX('بيانات الحركات'!A:A,MATCH(18,'بيانات الحركات'!$G:$G,0)),"") -> 46218 | B19: =IFERROR(INDEX('بيانات الحركات'!B:B,MATCH(18,'بيانات الحركات'!$G:$G,0)),"") -> شراء | C19: =IFERROR(INDEX('بيانات الحركات'!C:C,MATCH(18,'بيانات الحركات'!$G:$G,0)),"") -> امين | D19: =IFERROR(INDEX('بيانات الحركات'!D:D,MATCH(18,'بيانات الحركات'!$G:$G,0)),"") -> عطر-ليمون shiny-star - 485764 | E19: =IF($B19="إنتاج طبخة","",IFERROR(INDEX('بيانات الحركات'!E:E,MATCH(18,'بيانات الحركات'!$G:$G,0)),"")) -> 0.52 | F19: =IFERROR(INDEX('بيانات الحركات'!F:F,MATCH(18,'بيانات الحركات'!$G:$G,0)),"") -> تنزيل البيانات لأول مرة
A20: =IFERROR(INDEX('بيانات الحركات'!A:A,MATCH(19,'بيانات الحركات'!$G:$G,0)),"") -> 46218 | B20: =IFERROR(INDEX('بيانات الحركات'!B:B,MATCH(19,'بيانات الحركات'!$G:$G,0)),"") -> شراء | C20: =IFERROR(INDEX('بيانات الحركات'!C:C,MATCH(19,'بيانات الحركات'!$G:$G,0)),"") -> امين | D20: =IFERROR(INDEX('بيانات الحركات'!D:D,MATCH(19,'بيانات الحركات'!$G:$G,0)),"") -> عطر-ليمون citrus lemon new - 321639 | E20: =IF($B20="إنتاج طبخة","",IFERROR(INDEX('بيانات الحركات'!E:E,MATCH(19,'بيانات الحركات'!$G:$G,0)),"")) -> 0.36 | F20: =IFERROR(INDEX('بيانات الحركات'!F:F,MATCH(19,'بيانات الحركات'!$G:$G,0)),"") -> تنزيل البيانات لأول مرة
A21: =IFERROR(INDEX('بيانات الحركات'!A:A,MATCH(20,'بيانات الحركات'!$G:$G,0)),"") -> 46218 | B21: =IFERROR(INDEX('بيانات الحركات'!B:B,MATCH(20,'بيانات الحركات'!$G:$G,0)),"") -> شراء | C21: =IFERROR(INDEX('بيانات الحركات'!C:C,MATCH(20,'بيانات الحركات'!$G:$G,0)),"") -> امين | D21: =IFERROR(INDEX('بيانات الحركات'!D:D,MATCH(20,'بيانات الحركات'!$G:$G,0)),"") -> عطر-ليلك ariel-sensation - 318728 | E21: =IF($B21="إنتاج طبخة","",IFERROR(INDEX('بيانات الحركات'!E:E,MATCH(20,'بيانات الحركات'!$G:$G,0)),"")) -> 0.74 | F21: =IFERROR(INDEX('بيانات الحركات'!F:F,MATCH(20,'بيانات الحركات'!$G:$G,0)),"") -> تنزيل البيانات لأول مرة
A22: =IFERROR(INDEX('بيانات الحركات'!A:A,MATCH(21,'بيانات الحركات'!$G:$G,0)),"") -> 46218 | B22: =IFERROR(INDEX('بيانات الحركات'!B:B,MATCH(21,'بيانات الحركات'!$G:$G,0)),"") -> شراء | C22: =IFERROR(INDEX('بيانات الحركات'!C:C,MATCH(21,'بيانات الحركات'!$G:$G,0)),"") -> امين | D22: =IFERROR(INDEX('بيانات الحركات'!D:D,MATCH(21,'بيانات الحركات'!$G:$G,0)),"") -> عطر-سلطان | E22: =IF($B22="إنتاج طبخة","",IFERROR(INDEX('بيانات الحركات'!E:E,MATCH(21,'بيانات الحركات'!$G:$G,0)),"")) -> 2.59 | F22: =IFERROR(INDEX('بيانات الحركات'!F:F,MATCH(21,'بيانات الحركات'!$G:$G,0)),"") -> تنزيل البيانات لأول مرة
A23: =IFERROR(INDEX('بيانات الحركات'!A:A,MATCH(22,'بيانات الحركات'!$G:$G,0)),"") -> 46218 | B23: =IFERROR(INDEX('بيانات الحركات'!B:B,MATCH(22,'بيانات الحركات'!$G:$G,0)),"") -> شراء | C23: =IFERROR(INDEX('بيانات الحركات'!C:C,MATCH(22,'بيانات الحركات'!$G:$G,0)),"") -> امين | D23: =IFERROR(INDEX('بيانات الحركات'!D:D,MATCH(22,'بيانات الحركات'!$G:$G,0)),"") -> عطر-زهور lovely-petals - 485718 | E23: =IF($B23="إنتاج طبخة","",IFERROR(INDEX('بيانات الحركات'!E:E,MATCH(22,'بيانات الحركات'!$G:$G,0)),"")) -> 0.53 | F23: =IFERROR(INDEX('بيانات الحركات'!F:F,MATCH(22,'بيانات الحركات'!$G:$G,0)),"") -> تنزيل البيانات لأول مرة
A24: =IFERROR(INDEX('بيانات الحركات'!A:A,MATCH(23,'بيانات الحركات'!$G:$G,0)),"") -> 46218 | B24: =IFERROR(INDEX('بيانات الحركات'!B:B,MATCH(23,'بيانات الحركات'!$G:$G,0)),"") -> شراء | C24: =IFERROR(INDEX('بيانات الحركات'!C:C,MATCH(23,'بيانات الحركات'!$G:$G,0)),"") -> امين | D24: =IFERROR(INDEX('بيانات الحركات'!D:D,MATCH(23,'بيانات الحركات'!$G:$G,0)),"") -> عطر-رمان apple grandada - 322730 | E24: =IF($B24="إنتاج طبخة","",IFERROR(INDEX('بيانات الحركات'!E:E,MATCH(23,'بيانات الحركات'!$G:$G,0)),"")) -> 0.66 | F24: =IFERROR(INDEX('بيانات الحركات'!F:F,MATCH(23,'بيانات الحركات'!$G:$G,0)),"") -> تنزيل البيانات لأول مرة
