Workbook

Sheet لوحة التحكم
A1: لوحة تحكم مستودع معمل المنظفات
A2: عدد الطبخات المسجلة: 43 | عدد المواد الخام: 94 | جميع الأرقام تُحدَّث تلقائياً
A4: إجمالي عدد المواد | C4: مواد برصيد سالب (تحتاج مراجعة) | E4: عدد الطبخات المعرّفة
A5: =COUNTA(المواد!$A$2:$A$320) -> 74 | C5: =COUNTIF('الرصيد الحالي'!$E$2:$E$320,"❌*") -> 0 | E5: =COUNTIF(قوائم!$B$2:$B$150,"?*") -> 44
A7: إجمالي عمليات الإدخال | C7: إجمالي عمليات الإنتاج | E7: إجمالي عمليات الصرف المباشر
A8: =COUNTA(الإدخالات!$C$2:$C$501) -> 74 | C8: =COUNTA('سجل الإنتاج'!$C$2:$C$501) -> 1 | E8: =COUNTA('الصرف المباشر'!$C$2:$C$501) -> 2
A12: ❌ تنبيه: مواد برصيد سالب - تحتاج مراجعة فورية
A13: اسم المادة | B13: الرصيد الحالي | C13: الوحدة | D13: الحالة
A14: =IFERROR(INDEX('الرصيد الحالي'!$A$2:$A$320,MATCH(1,'الرصيد الحالي'!$F$2:$F$320,0)),"") | B14: =IF($A14="","",IFERROR(INDEX('الرصيد الحالي'!$C$2:$C$320,MATCH($A14,'الرصيد الحالي'!$A$2:$A$320,0)),"")) | C14: =IF($A14="","",IFERROR(INDEX('الرصيد الحالي'!$B$2:$B$320,MATCH($A14,'الرصيد الحالي'!$A$2:$A$320,0)),"")) | D14: =IF($A14="","",IFERROR(INDEX('الرصيد الحالي'!$E$2:$E$320,MATCH($A14,'الرصيد الحالي'!$A$2:$A$320,0)),""))
A15: =IFERROR(INDEX('الرصيد الحالي'!$A$2:$A$320,MATCH(2,'الرصيد الحالي'!$F$2:$F$320,0)),"") | B15: =IF($A15="","",IFERROR(INDEX('الرصيد الحالي'!$C$2:$C$320,MATCH($A15,'الرصيد الحالي'!$A$2:$A$320,0)),"")) | C15: =IF($A15="","",IFERROR(INDEX('الرصيد الحالي'!$B$2:$B$320,MATCH($A15,'الرصيد الحالي'!$A$2:$A$320,0)),"")) | D15: =IF($A15="","",IFERROR(INDEX('الرصيد الحالي'!$E$2:$E$320,MATCH($A15,'الرصيد الحالي'!$A$2:$A$320,0)),""))
A16: =IFERROR(INDEX('الرصيد الحالي'!$A$2:$A$320,MATCH(3,'الرصيد الحالي'!$F$2:$F$320,0)),"") | B16: =IF($A16="","",IFERROR(INDEX('الرصيد الحالي'!$C$2:$C$320,MATCH($A16,'الرصيد الحالي'!$A$2:$A$320,0)),"")) | C16: =IF($A16="","",IFERROR(INDEX('الرصيد الحالي'!$B$2:$B$320,MATCH($A16,'الرصيد الحالي'!$A$2:$A$320,0)),"")) | D16: =IF($A16="","",IFERROR(INDEX('الرصيد الحالي'!$E$2:$E$320,MATCH($A16,'الرصيد الحالي'!$A$2:$A$320,0)),""))
A17: =IFERROR(INDEX('الرصيد الحالي'!$A$2:$A$320,MATCH(4,'الرصيد الحالي'!$F$2:$F$320,0)),"") | B17: =IF($A17="","",IFERROR(INDEX('الرصيد الحالي'!$C$2:$C$320,MATCH($A17,'الرصيد الحالي'!$A$2:$A$320,0)),"")) | C17: =IF($A17="","",IFERROR(INDEX('الرصيد الحالي'!$B$2:$B$320,MATCH($A17,'الرصيد الحالي'!$A$2:$A$320,0)),"")) | D17: =IF($A17="","",IFERROR(INDEX('الرصيد الحالي'!$E$2:$E$320,MATCH($A17,'الرصيد الحالي'!$A$2:$A$320,0)),""))
A18: =IFERROR(INDEX('الرصيد الحالي'!$A$2:$A$320,MATCH(5,'الرصيد الحالي'!$F$2:$F$320,0)),"") | B18: =IF($A18="","",IFERROR(INDEX('الرصيد الحالي'!$C$2:$C$320,MATCH($A18,'الرصيد الحالي'!$A$2:$A$320,0)),"")) | C18: =IF($A18="","",IFERROR(INDEX('الرصيد الحالي'!$B$2:$B$320,MATCH($A18,'الرصيد الحالي'!$A$2:$A$320,0)),"")) | D18: =IF($A18="","",IFERROR(INDEX('الرصيد الحالي'!$E$2:$E$320,MATCH($A18,'الرصيد الحالي'!$A$2:$A$320,0)),""))
A19: =IFERROR(INDEX('الرصيد الحالي'!$A$2:$A$320,MATCH(6,'الرصيد الحالي'!$F$2:$F$320,0)),"") | B19: =IF($A19="","",IFERROR(INDEX('الرصيد الحالي'!$C$2:$C$320,MATCH($A19,'الرصيد الحالي'!$A$2:$A$320,0)),"")) | C19: =IF($A19="","",IFERROR(INDEX('الرصيد الحالي'!$B$2:$B$320,MATCH($A19,'الرصيد الحالي'!$A$2:$A$320,0)),"")) | D19: =IF($A19="","",IFERROR(INDEX('الرصيد الحالي'!$E$2:$E$320,MATCH($A19,'الرصيد الحالي'!$A$2:$A$320,0)),""))
A20: =IFERROR(INDEX('الرصيد الحالي'!$A$2:$A$320,MATCH(7,'الرصيد الحالي'!$F$2:$F$320,0)),"") | B20: =IF($A20="","",IFERROR(INDEX('الرصيد الحالي'!$C$2:$C$320,MATCH($A20,'الرصيد الحالي'!$A$2:$A$320,0)),"")) | C20: =IF($A20="","",IFERROR(INDEX('الرصيد الحالي'!$B$2:$B$320,MATCH($A20,'الرصيد الحالي'!$A$2:$A$320,0)),"")) | D20: =IF($A20="","",IFERROR(INDEX('الرصيد الحالي'!$E$2:$E$320,MATCH($A20,'الرصيد الحالي'!$A$2:$A$320,0)),""))
A21: =IFERROR(INDEX('الرصيد الحالي'!$A$2:$A$320,MATCH(8,'الرصيد الحالي'!$F$2:$F$320,0)),"") | B21: =IF($A21="","",IFERROR(INDEX('الرصيد الحالي'!$C$2:$C$320,MATCH($A21,'الرصيد الحالي'!$A$2:$A$320,0)),"")) | C21: =IF($A21="","",IFERROR(INDEX('الرصيد الحالي'!$B$2:$B$320,MATCH($A21,'الرصيد الحالي'!$A$2:$A$320,0)),"")) | D21: =IF($A21="","",IFERROR(INDEX('الرصيد الحالي'!$E$2:$E$320,MATCH($A21,'الرصيد الحالي'!$A$2:$A$320,0)),""))
A22: =IFERROR(INDEX('الرصيد الحالي'!$A$2:$A$320,MATCH(9,'الرصيد الحالي'!$F$2:$F$320,0)),"") | B22: =IF($A22="","",IFERROR(INDEX('الرصيد الحالي'!$C$2:$C$320,MATCH($A22,'الرصيد الحالي'!$A$2:$A$320,0)),"")) | C22: =IF($A22="","",IFERROR(INDEX('الرصيد الحالي'!$B$2:$B$320,MATCH($A22,'الرصيد الحالي'!$A$2:$A$320,0)),"")) | D22: =IF($A22="","",IFERROR(INDEX('الرصيد الحالي'!$E$2:$E$320,MATCH($A22,'الرصيد الحالي'!$A$2:$A$320,0)),""))
A23: =IFERROR(INDEX('الرصيد الحالي'!$A$2:$A$320,MATCH(10,'الرصيد الحالي'!$F$2:$F$320,0)),"") | B23: =IF($A23="","",IFERROR(INDEX('الرصيد الحالي'!$C$2:$C$320,MATCH($A23,'الرصيد الحالي'!$A$2:$A$320,0)),"")) | C23: =IF($A23="","",IFERROR(INDEX('الرصيد الحالي'!$B$2:$B$320,MATCH($A23,'الرصيد الحالي'!$A$2:$A$320,0)),"")) | D23: =IF($A23="","",IFERROR(INDEX('الرصيد الحالي'!$E$2:$E$320,MATCH($A23,'الرصيد الحالي'!$A$2:$A$320,0)),""))
A24: =IFERROR(INDEX('الرصيد الحالي'!$A$2:$A$320,MATCH(11,'الرصيد الحالي'!$F$2:$F$320,0)),"") | B24: =IF($A24="","",IFERROR(INDEX('الرصيد الحالي'!$C$2:$C$320,MATCH($A24,'الرصيد الحالي'!$A$2:$A$320,0)),"")) | C24: =IF($A24="","",IFERROR(INDEX('الرصيد الحالي'!$B$2:$B$320,MATCH($A24,'الرصيد الحالي'!$A$2:$A$320,0)),"")) | D24: =IF($A24="","",IFERROR(INDEX('الرصيد الحالي'!$E$2:$E$320,MATCH($A24,'الرصيد الحالي'!$A$2:$A$320,0)),""))
A25: =IFERROR(INDEX('الرصيد الحالي'!$A$2:$A$320,MATCH(12,'الرصيد الحالي'!$F$2:$F$320,0)),"") | B25: =IF($A25="","",IFERROR(INDEX('الرصيد الحالي'!$C$2:$C$320,MATCH($A25,'الرصيد الحالي'!$A$2:$A$320,0)),"")) | C25: =IF($A25="","",IFERROR(INDEX('الرصيد الحالي'!$B$2:$B$320,MATCH($A25,'الرصيد الحالي'!$A$2:$A$320,0)),"")) | D25: =IF($A25="","",IFERROR(INDEX('الرصيد الحالي'!$E$2:$E$320,MATCH($A25,'الرصيد الحالي'!$A$2:$A$320,0)),""))
A26: =IFERROR(INDEX('الرصيد الحالي'!$A$2:$A$320,MATCH(13,'الرصيد الحالي'!$F$2:$F$320,0)),"") | B26: =IF($A26="","",IFERROR(INDEX('الرصيد الحالي'!$C$2:$C$320,MATCH($A26,'الرصيد الحالي'!$A$2:$A$320,0)),"")) | C26: =IF($A26="","",IFERROR(INDEX('الرصيد الحالي'!$B$2:$B$320,MATCH($A26,'الرصيد الحالي'!$A$2:$A$320,0)),"")) | D26: =IF($A26="","",IFERROR(INDEX('الرصيد الحالي'!$E$2:$E$320,MATCH($A26,'الرصيد الحالي'!$A$2:$A$320,0)),""))
A27: =IFERROR(INDEX('الرصيد الحالي'!$A$2:$A$320,MATCH(14,'الرصيد الحالي'!$F$2:$F$320,0)),"") | B27: =IF($A27="","",IFERROR(INDEX('الرصيد الحالي'!$C$2:$C$320,MATCH($A27,'الرصيد الحالي'!$A$2:$A$320,0)),"")) | C27: =IF($A27="","",IFERROR(INDEX('الرصيد الحالي'!$B$2:$B$320,MATCH($A27,'الرصيد الحالي'!$A$2:$A$320,0)),"")) | D27: =IF($A27="","",IFERROR(INDEX('الرصيد الحالي'!$E$2:$E$320,MATCH($A27,'الرصيد الحالي'!$A$2:$A$320,0)),""))
A28: =IFERROR(INDEX('الرصيد الحالي'!$A$2:$A$320,MATCH(15,'الرصيد الحالي'!$F$2:$F$320,0)),"") | B28: =IF($A28="","",IFERROR(INDEX('الرصيد الحالي'!$C$2:$C$320,MATCH($A28,'الرصيد الحالي'!$A$2:$A$320,0)),"")) | C28: =IF($A28="","",IFERROR(INDEX('الرصيد الحالي'!$B$2:$B$320,MATCH($A28,'الرصيد الحالي'!$A$2:$A$320,0)),"")) | D28: =IF($A28="","",IFERROR(INDEX('الرصيد الحالي'!$E$2:$E$320,MATCH($A28,'الرصيد الحالي'!$A$2:$A$320,0)),""))
A30: 📊 أكثر 5 مواد استهلاكاً | D30: 🏆 أكثر 5 طبخات إنتاجاً
A31: اسم المادة | B31: إجمالي الاستهلاك | C31: الوحدة | D31: اسم الطبخة | E31: عدد مرات الإنتاج
A32: =IFERROR(INDEX(قوائم!$A$2:$A$320,MATCH(LARGE(قوائم!$F$2:$F$320,1),قوائم!$F$2:$F$320,0)),"") -> ماء مقطرة | B32: =IFERROR(LARGE(قوائم!$F$2:$F$320,1),"") -> 890 | C32: =IF($A32="","",IFERROR(INDEX(المواد!$B$2:$B$320,MATCH($A32,المواد!$A$2:$A$320,0)),"")) -> كغ | D32: =IFERROR(INDEX(قوائم!$B$2:$B$150,MATCH(LARGE(قوائم!$D$2:$D$150,1),قوائم!$D$2:$D$150,0)),"") -> لودلين سادة رابع | E32: =IFERROR(LARGE(قوائم!$D$2:$D$150,1),"") -> 1
A33: =IFERROR(INDEX(قوائم!$A$2:$A$320,MATCH(LARGE(قوائم!$F$2:$F$320,2),قوائم!$F$2:$F$320,0)),"") -> ملح | B33: =IFERROR(LARGE(قوائم!$F$2:$F$320,2),"") -> 100 | C33: =IF($A33="","",IFERROR(INDEX(المواد!$B$2:$B$320,MATCH($A33,المواد!$A$2:$A$320,0)),"")) -> كغ | D33: =IFERROR(INDEX(قوائم!$B$2:$B$150,MATCH(LARGE(قوائم!$D$2:$D$150,2),قوائم!$D$2:$D$150,0)),"") -> دوا غسيل بودرا 157 كغ - ببوري | E33: =IFERROR(LARGE(قوائم!$D$2:$D$150,2),"") -> 0
A34: =IFERROR(INDEX(قوائم!$A$2:$A$320,MATCH(LARGE(قوائم!$F$2:$F$320,3),قوائم!$F$2:$F$320,0)),"") -> تكسبون | B34: =IFERROR(LARGE(قوائم!$F$2:$F$320,3),"") -> 43 | C34: =IF($A34="","",IFERROR(INDEX(المواد!$B$2:$B$320,MATCH($A34,المواد!$A$2:$A$320,0)),"")) -> كغ | D34: =IFERROR(INDEX(قوائم!$B$2:$B$150,MATCH(LARGE(قوائم!$D$2:$D$150,3),قوائم!$D$2:$D$150,0)),"") -> دوا غسيل بودرا 157 كغ - ببوري | E34: =IFERROR(LARGE(قوائم!$D$2:$D$150,3),"") -> 0
A35: =IFERROR(INDEX(قوائم!$A$2:$A$320,MATCH(LARGE(قوائم!$F$2:$F$320,4),قوائم!$F$2:$F$320,0)),"") -> زفتة | B35: =IFERROR(LARGE(قوائم!$F$2:$F$320,4),"") -> 40 | C35: =IF($A35="","",IFERROR(INDEX(المواد!$B$2:$B$320,MATCH($A35,المواد!$A$2:$A$320,0)),"")) -> كغ | D35: =IFERROR(INDEX(قوائم!$B$2:$B$150,MATCH(LARGE(قوائم!$D$2:$D$150,4),قوائم!$D$2:$D$150,0)),"") -> دوا غسيل بودرا 157 كغ - ببوري | E35: =IFERROR(LARGE(قوائم!$D$2:$D$150,4),"") -> 0
A36: =IFERROR(INDEX(قوائم!$A$2:$A$320,MATCH(LARGE(قوائم!$F$2:$F$320,5),قوائم!$F$2:$F$320,0)),"") -> بيتائين | B36: =IFERROR(LARGE(قوائم!$F$2:$F$320,5),"") -> 15 | C36: =IF($A36="","",IFERROR(INDEX(المواد!$B$2:$B$320,MATCH($A36,المواد!$A$2:$A$320,0)),"")) -> كغ | D36: =IFERROR(INDEX(قوائم!$B$2:$B$150,MATCH(LARGE(قوائم!$D$2:$D$150,5),قوائم!$D$2:$D$150,0)),"") -> دوا غسيل بودرا 157 كغ - ببوري | E36: =IFERROR(LARGE(قوائم!$D$2:$D$150,5),"") -> 0
A38: 🕓 آخر 5 عمليات إدخال (شراء) | D38: 🕓 آخر 5 عمليات إنتاج
A39: التاريخ | B39: المادة | C39: الكمية | D39: التاريخ | E39: الطبخة
A40: =IF((COUNTA(الإدخالات!$C$2:$C$501)-0)<1,"",INDEX(الإدخالات!$B$2:$B$501,COUNTA(الإدخالات!$C$2:$C$501)-0)) -> 46218 | B40: =IF((COUNTA(الإدخالات!$C$2:$C$501)-0)<1,"",INDEX(الإدخالات!$C$2:$C$501,COUNTA(الإدخالات!$C$2:$C$501)-0)) -> ديتول خام | C40: =IF((COUNTA(الإدخالات!$C$2:$C$501)-0)<1,"",INDEX(الإدخالات!$D$2:$D$501,COUNTA(الإدخالات!$C$2:$C$501)-0)) -> 0 | D40: =IF((COUNTA('سجل الإنتاج'!$C$2:$C$501)-0)<1,"",INDEX('سجل الإنتاج'!$B$2:$B$501,COUNTA('سجل الإنتاج'!$C$2:$C$501)-0)) -> 46211 | E40: =IF((COUNTA('سجل الإنتاج'!$C$2:$C$501)-0)<1,"",INDEX('سجل الإنتاج'!$C$2:$C$501,COUNTA('سجل الإنتاج'!$C$2:$C$501)-0)) -> لودلين سادة رابع
A41: =IF((COUNTA(الإدخالات!$C$2:$C$501)-1)<1,"",INDEX(الإدخالات!$B$2:$B$501,COUNTA(الإدخالات!$C$2:$C$501)-1)) -> 46218 | B41: =IF((COUNTA(الإدخالات!$C$2:$C$501)-1)<1,"",INDEX(الإدخالات!$C$2:$C$501,COUNTA(الإدخالات!$C$2:$C$501)-1)) -> عبوات حليبي | C41: =IF((COUNTA(الإدخالات!$C$2:$C$501)-1)<1,"",INDEX(الإدخالات!$D$2:$D$501,COUNTA(الإدخالات!$C$2:$C$501)-1)) -> 93.75 | D41: =IF((COUNTA('سجل الإنتاج'!$C$2:$C$501)-1)<1,"",INDEX('سجل الإنتاج'!$B$2:$B$501,COUNTA('سجل الإنتاج'!$C$2:$C$501)-1)) | E41: =IF((COUNTA('سجل الإنتاج'!$C$2:$C$501)-1)<1,"",INDEX('سجل الإنتاج'!$C$2:$C$501,COUNTA('سجل الإنتاج'!$C$2:$C$501)-1))
A42: =IF((COUNTA(الإدخالات!$C$2:$C$501)-2)<1,"",INDEX(الإدخالات!$B$2:$B$501,COUNTA(الإدخالات!$C$2:$C$501)-2)) -> 46218 | B42: =IF((COUNTA(الإدخالات!$C$2:$C$501)-2)<1,"",INDEX(الإدخالات!$C$2:$C$501,COUNTA(الإدخالات!$C$2:$C$501)-2)) -> عبوات شفافة 3 لتر | C42: =IF((COUNTA(الإدخالات!$C$2:$C$501)-2)<1,"",INDEX(الإدخالات!$D$2:$D$501,COUNTA(الإدخالات!$C$2:$C$501)-2)) -> 11.16 | D42: =IF((COUNTA('سجل الإنتاج'!$C$2:$C$501)-2)<1,"",INDEX('سجل الإنتاج'!$B$2:$B$501,COUNTA('سجل الإنتاج'!$C$2:$C$501)-2)) | E42: =IF((COUNTA('سجل الإنتاج'!$C$2:$C$501)-2)<1,"",INDEX('سجل الإنتاج'!$C$2:$C$501,COUNTA('سجل الإنتاج'!$C$2:$C$501)-2))
A43: =IF((COUNTA(الإدخالات!$C$2:$C$501)-3)<1,"",INDEX(الإدخالات!$B$2:$B$501,COUNTA(الإدخالات!$C$2:$C$501)-3)) -> 46218 | B43: =IF((COUNTA(الإدخالات!$C$2:$C$501)-3)<1,"",INDEX(الإدخالات!$C$2:$C$501,COUNTA(الإدخالات!$C$2:$C$501)-3)) -> عبوات كلور + فلاش فارغة | C43: =IF((COUNTA(الإدخالات!$C$2:$C$501)-3)<1,"",INDEX(الإدخالات!$D$2:$D$501,COUNTA(الإدخالات!$C$2:$C$501)-3)) -> 19.83 | D43: =IF((COUNTA('سجل الإنتاج'!$C$2:$C$501)-3)<1,"",INDEX('سجل الإنتاج'!$B$2:$B$501,COUNTA('سجل الإنتاج'!$C$2:$C$501)-3)) | E43: =IF((COUNTA('سجل الإنتاج'!$C$2:$C$501)-3)<1,"",INDEX('سجل الإنتاج'!$C$2:$C$501,COUNTA('سجل الإنتاج'!$C$2:$C$501)-3))
A44: =IF((COUNTA(الإدخالات!$C$2:$C$501)-4)<1,"",INDEX(الإدخالات!$B$2:$B$501,COUNTA(الإدخالات!$C$2:$C$501)-4)) -> 46218 | B44: =IF((COUNTA(الإدخالات!$C$2:$C$501)-4)<1,"",INDEX(الإدخالات!$C$2:$C$501,COUNTA(الإدخالات!$C$2:$C$501)-4)) -> فازلين | C44: =IF((COUNTA(الإدخالات!$C$2:$C$501)-4)<1,"",INDEX(الإدخالات!$D$2:$D$501,COUNTA(الإدخالات!$C$2:$C$501)-4)) -> 0 | D44: =IF((COUNTA('سجل الإنتاج'!$C$2:$C$501)-4)<1,"",INDEX('سجل الإنتاج'!$B$2:$B$501,COUNTA('سجل الإنتاج'!$C$2:$C$501)-4)) | E44: =IF((COUNTA('سجل الإنتاج'!$C$2:$C$501)-4)<1,"",INDEX('سجل الإنتاج'!$C$2:$C$501,COUNTA('سجل الإنتاج'!$C$2:$C$501)-4))
A46: 🕓 آخر 5 عمليات صرف مباشر
A47: التاريخ | B47: المادة | C47: الكمية
A48: =IF((COUNTA('الصرف المباشر'!$C$2:$C$501)-0)<1,"",INDEX('الصرف المباشر'!$B$2:$B$501,COUNTA('الصرف المباشر'!$C$2:$C$501)-0)) -> 46219 | B48: =IF((COUNTA('الصرف المباشر'!$C$2:$C$501)-0)<1,"",INDEX('الصرف المباشر'!$C$2:$C$501,COUNTA('الصرف المباشر'!$C$2:$C$501)-0)) -> زفتة | C48: =IF((COUNTA('الصرف المباشر'!$C$2:$C$501)-0)<1,"",INDEX('الصرف المباشر'!$D$2:$D$501,COUNTA('الصرف المباشر'!$C$2:$C$501)-0)) -> 20
...

Sheet المواد
A1: اسم المادة | B1: وحدة القياس | C1: الرصيد الحالي | D1: ملاحظات
A2: ملح | B2: كغ | C2: =IF(A2="","",ROUND(SUMIFS(الإدخالات!$D$2:$D$501,الإدخالات!$C$2:$C$501,A2)+SUMIFS('تعديل الجرد'!$F$2:$F$501,'تعديل الجرد'!$C$2:$C$501,A2)-SUMIFS('الصرف المباشر'!$D$2:$D$501,'الصرف المباشر'!$C$2:$C$501,A2)-SUMPRODUCT((الطبخات!$B$2:$B$900=A2)*الطبخات!$C$2:$C$900*COUNTIF('سجل الإنتاج'!$C$2:$C$501,الطبخات!$A$2:$A$900)),3)) -> 38.04
A3: مقصب | B3: كغ | C3: =IF(A3="","",ROUND(SUMIFS(الإدخالات!$D$2:$D$501,الإدخالات!$C$2:$C$501,A3)+SUMIFS('تعديل الجرد'!$F$2:$F$501,'تعديل الجرد'!$C$2:$C$501,A3)-SUMIFS('الصرف المباشر'!$D$2:$D$501,'الصرف المباشر'!$C$2:$C$501,A3)-SUMPRODUCT((الطبخات!$B$2:$B$900=A3)*الطبخات!$C$2:$C$900*COUNTIF('سجل الإنتاج'!$C$2:$C$501,الطبخات!$A$2:$A$900)),3)) -> 2
A4: مجمد | B4: كغ | C4: =IF(A4="","",ROUND(SUMIFS(الإدخالات!$D$2:$D$501,الإدخالات!$C$2:$C$501,A4)+SUMIFS('تعديل الجرد'!$F$2:$F$501,'تعديل الجرد'!$C$2:$C$501,A4)-SUMIFS('الصرف المباشر'!$D$2:$D$501,'الصرف المباشر'!$C$2:$C$501,A4)-SUMPRODUCT((الطبخات!$B$2:$B$900=A4)*الطبخات!$C$2:$C$900*COUNTIF('سجل الإنتاج'!$C$2:$C$501,الطبخات!$A$2:$A$900)),3)) -> 63.5
A5: مانع رغوة مائي | B5: كغ | C5: =IF(A5="","",ROUND(SUMIFS(الإدخالات!$D$2:$D$501,الإدخالات!$C$2:$C$501,A5)+SUMIFS('تعديل الجرد'!$F$2:$F$501,'تعديل الجرد'!$C$2:$C$501,A5)-SUMIFS('الصرف المباشر'!$D$2:$D$501,'الصرف المباشر'!$C$2:$C$501,A5)-SUMPRODUCT((الطبخات!$B$2:$B$900=A5)*الطبخات!$C$2:$C$900*COUNTIF('سجل الإنتاج'!$C$2:$C$501,الطبخات!$A$2:$A$900)),3)) -> 0
A6: مانع رغوة سيليكون | B6: كغ | C6: =IF(A6="","",ROUND(SUMIFS(الإدخالات!$D$2:$D$501,الإدخالات!$C$2:$C$501,A6)+SUMIFS('تعديل الجرد'!$F$2:$F$501,'تعديل الجرد'!$C$2:$C$501,A6)-SUMIFS('الصرف المباشر'!$D$2:$D$501,'الصرف المباشر'!$C$2:$C$501,A6)-SUMPRODUCT((الطبخات!$B$2:$B$900=A6)*الطبخات!$C$2:$C$900*COUNTIF('سجل الإنتاج'!$C$2:$C$501,الطبخات!$A$2:$A$900)),3)) -> 0
A7: ماء مقطرة | B7: كغ | C7: =IF(A7="","",ROUND(SUMIFS(الإدخالات!$D$2:$D$501,الإدخالات!$C$2:$C$501,A7)+SUMIFS('تعديل الجرد'!$F$2:$F$501,'تعديل الجرد'!$C$2:$C$501,A7)-SUMIFS('الصرف المباشر'!$D$2:$D$501,'الصرف المباشر'!$C$2:$C$501,A7)-SUMPRODUCT((الطبخات!$B$2:$B$900=A7)*الطبخات!$C$2:$C$900*COUNTIF('سجل الإنتاج'!$C$2:$C$501,الطبخات!$A$2:$A$900)),3)) -> 27732
A8: ماء بلسم | B8: كغ | C8: =IF(A8="","",ROUND(SUMIFS(الإدخالات!$D$2:$D$501,الإدخالات!$C$2:$C$501,A8)+SUMIFS('تعديل الجرد'!$F$2:$F$501,'تعديل الجرد'!$C$2:$C$501,A8)-SUMIFS('الصرف المباشر'!$D$2:$D$501,'الصرف المباشر'!$C$2:$C$501,A8)-SUMPRODUCT((الطبخات!$B$2:$B$900=A8)*الطبخات!$C$2:$C$900*COUNTIF('سجل الإنتاج'!$C$2:$C$501,الطبخات!$A$2:$A$900)),3)) -> 3
A9: لانيت 16 ماليزي | B9: كغ | C9: =IF(A9="","",ROUND(SUMIFS(الإدخالات!$D$2:$D$501,الإدخالات!$C$2:$C$501,A9)+SUMIFS('تعديل الجرد'!$F$2:$F$501,'تعديل الجرد'!$C$2:$C$501,A9)-SUMIFS('الصرف المباشر'!$D$2:$D$501,'الصرف المباشر'!$C$2:$C$501,A9)-SUMPRODUCT((الطبخات!$B$2:$B$900=A9)*الطبخات!$C$2:$C$900*COUNTIF('سجل الإنتاج'!$C$2:$C$501,الطبخات!$A$2:$A$900)),3)) -> 0
A10: كوستيك-قطرونة | B10: كغ | C10: =IF(A10="","",ROUND(SUMIFS(الإدخالات!$D$2:$D$501,الإدخالات!$C$2:$C$501,A10)+SUMIFS('تعديل الجرد'!$F$2:$F$501,'تعديل الجرد'!$C$2:$C$501,A10)-SUMIFS('الصرف المباشر'!$D$2:$D$501,'الصرف المباشر'!$C$2:$C$501,A10)-SUMPRODUCT((الطبخات!$B$2:$B$900=A10)*الطبخات!$C$2:$C$900*COUNTIF('سجل الإنتاج'!$C$2:$C$501,الطبخات!$A$2:$A$900)),3)) -> 27.71
A11: كمبرلان | B11: كغ | C11: =IF(A11="","",ROUND(SUMIFS(الإدخالات!$D$2:$D$501,الإدخالات!$C$2:$C$501,A11)+SUMIFS('تعديل الجرد'!$F$2:$F$501,'تعديل الجرد'!$C$2:$C$501,A11)-SUMIFS('الصرف المباشر'!$D$2:$D$501,'الصرف المباشر'!$C$2:$C$501,A11)-SUMPRODUCT((الطبخات!$B$2:$B$900=A11)*الطبخات!$C$2:$C$900*COUNTIF('سجل الإنتاج'!$C$2:$C$501,الطبخات!$A$2:$A$900)),3)) -> 0
A12: كليمازول | B12: كغ | C12: =IF(A12="","",ROUND(SUMIFS(الإدخالات!$D$2:$D$501,الإدخالات!$C$2:$C$501,A12)+SUMIFS('تعديل الجرد'!$F$2:$F$501,'تعديل الجرد'!$C$2:$C$501,A12)-SUMIFS('الصرف المباشر'!$D$2:$D$501,'الصرف المباشر'!$C$2:$C$501,A12)-SUMPRODUCT((الطبخات!$B$2:$B$900=A12)*الطبخات!$C$2:$C$900*COUNTIF('سجل الإنتاج'!$C$2:$C$501,الطبخات!$A$2:$A$900)),3)) -> 0
A13: كلور خام | B13: كغ | C13: =IF(A13="","",ROUND(SUMIFS(الإدخالات!$D$2:$D$501,الإدخالات!$C$2:$C$501,A13)+SUMIFS('تعديل الجرد'!$F$2:$F$501,'تعديل الجرد'!$C$2:$C$501,A13)-SUMIFS('الصرف المباشر'!$D$2:$D$501,'الصرف المباشر'!$C$2:$C$501,A13)-SUMPRODUCT((الطبخات!$B$2:$B$900=A13)*الطبخات!$C$2:$C$900*COUNTIF('سجل الإنتاج'!$C$2:$C$501,الطبخات!$A$2:$A$900)),3)) -> 272
... A74: عبوات حليبي | B74: عدد | C74: =IF(A74="","",ROUND(SUMIFS(الإدخالات!$D$2:$D$501,الإدخالات!$C$2:$C$501,A74)+SUMIFS('تعديل الجرد'!$F$2:$F$501,'تعديل الجرد'!$C$2:$C$501,A74)-SUMIFS('الصرف المباشر'!$D$2:$D$501,'الصرف المباشر'!$C$2:$C$501,A74)-SUMPRODUCT((الطبخات!$B$2:$B$900=A74)*الطبخات!$C$2:$C$900*COUNTIF('سجل الإنتاج'!$C$2:$C$501,الطبخات!$A$2:$A$900)),3)) -> 93.75
A75: ديتول خام | B75: كغ | C75: =C76
C76: =IF(A76="","",ROUND(SUMIFS(الإدخالات!$D$2:$D$501,الإدخالات!$C$2:$C$501,A76)+SUMIFS('تعديل الجرد'!$F$2:$F$501,'تعديل الجرد'!$C$2:$C$501,A76)-SUMIFS('الصرف المباشر'!$D$2:$D$501,'الصرف المباشر'!$C$2:$C$501,A76)-SUMPRODUCT((الطبخات!$B$2:$B$900=A76)*الطبخات!$C$2:$C$900*COUNTIF('سجل الإنتاج'!$C$2:$C$501,الطبخات!$A$2:$A$900)),3))
C77: =IF(A77="","",ROUND(SUMIFS(الإدخالات!$D$2:$D$501,الإدخالات!$C$2:$C$501,A77)+SUMIFS('تعديل الجرد'!$F$2:$F$501,'تعديل الجرد'!$C$2:$C$501,A77)-SUMIFS('الصرف المباشر'!$D$2:$D$501,'الصرف المباشر'!$C$2:$C$501,A77)-SUMPRODUCT((الطبخات!$B$2:$B$900=A77)*الطبخات!$C$2:$C$900*COUNTIF('سجل الإنتاج'!$C$2:$C$501,الطبخات!$A$2:$A$900)),3))
C78: =IF(A78="","",ROUND(SUMIFS(الإدخالات!$D$2:$D$501,الإدخالات!$C$2:$C$501,A78)+SUMIFS('تعديل الجرد'!$F$2:$F$501,'تعديل الجرد'!$C$2:$C$501,A78)-SUMIFS('الصرف المباشر'!$D$2:$D$501,'الصرف المباشر'!$C$2:$C$501,A78)-SUMPRODUCT((الطبخات!$B$2:$B$900=A78)*الطبخات!$C$2:$C$900*COUNTIF('سجل الإنتاج'!$C$2:$C$501,الطبخات!$A$2:$A$900)),3))
C79: =IF(A79="","",ROUND(SUMIFS(الإدخالات!$D$2:$D$501,الإدخالات!$C$2:$C$501,A79)+SUMIFS('تعديل الجرد'!$F$2:$F$501,'تعديل الجرد'!$C$2:$C$501,A79)-SUMIFS('الصرف المباشر'!$D$2:$D$501,'الصرف المباشر'!$C$2:$C$501,A79)-SUMPRODUCT((الطبخات!$B$2:$B$900=A79)*الطبخات!$C$2:$C$900*COUNTIF('سجل الإنتاج'!$C$2:$C$501,الطبخات!$A$2:$A$900)),3))
C80: =IF(A80="","",ROUND(SUMIFS(الإدخالات!$D$2:$D$501,الإدخالات!$C$2:$C$501,A80)+SUMIFS('تعديل الجرد'!$F$2:$F$501,'تعديل الجرد'!$C$2:$C$501,A80)-SUMIFS('الصرف المباشر'!$D$2:$D$501,'الصرف المباشر'!$C$2:$C$501,A80)-SUMPRODUCT((الطبخات!$B$2:$B$900=A80)*الطبخات!$C$2:$C$900*COUNTIF('سجل الإنتاج'!$C$2:$C$501,الطبخات!$A$2:$A$900)),3))
C81: =IF(A81="","",ROUND(SUMIFS(الإدخالات!$D$2:$D$501,الإدخالات!$C$2:$C$501,A81)+SUMIFS('تعديل الجرد'!$F$2:$F$501,'تعديل الجرد'!$C$2:$C$501,A81)-SUMIFS('الصرف المباشر'!$D$2:$D$501,'الصرف المباشر'!$C$2:$C$501,A81)-SUMPRODUCT((الطبخات!$B$2:$B$900=A81)*الطبخات!$C$2:$C$900*COUNTIF('سجل الإنتاج'!$C$2:$C$501,الطبخات!$A$2:$A$900)),3))
C82: =IF(A82="","",ROUND(SUMIFS(الإدخالات!$D$2:$D$501,الإدخالات!$C$2:$C$501,A82)+SUMIFS('تعديل الجرد'!$F$2:$F$501,'تعديل الجرد'!$C$2:$C$501,A82)-SUMIFS('الصرف المباشر'!$D$2:$D$501,'الصرف المباشر'!$C$2:$C$501,A82)-SUMPRODUCT((الطبخات!$B$2:$B$900=A82)*الطبخات!$C$2:$C$900*COUNTIF('سجل الإنتاج'!$C$2:$C$501,الطبخات!$A$2:$A$900)),3))
C83: =IF(A83="","",ROUND(SUMIFS(الإدخالات!$D$2:$D$501,الإدخالات!$C$2:$C$501,A83)+SUMIFS('تعديل الجرد'!$F$2:$F$501,'تعديل الجرد'!$C$2:$C$501,A83)-SUMIFS('الصرف المباشر'!$D$2:$D$501,'الصرف المباشر'!$C$2:$C$501,A83)-SUMPRODUCT((الطبخات!$B$2:$B$900=A83)*الطبخات!$C$2:$C$900*COUNTIF('سجل الإنتاج'!$C$2:$C$501,الطبخات!$A$2:$A$900)),3))
C84: =IF(A84="","",ROUND(SUMIFS(الإدخالات!$D$2:$D$501,الإدخالات!$C$2:$C$501,A84)+SUMIFS('تعديل الجرد'!$F$2:$F$501,'تعديل الجرد'!$C$2:$C$501,A84)-SUMIFS('الصرف المباشر'!$D$2:$D$501,'الصرف المباشر'!$C$2:$C$501,A84)-SUMPRODUCT((الطبخات!$B$2:$B$900=A84)*الطبخات!$C$2:$C$900*COUNTIF('سجل الإنتاج'!$C$2:$C$501,الطبخات!$A$2:$A$900)),3))
C85: =IF(A85="","",ROUND(SUMIFS(الإدخالات!$D$2:$D$501,الإدخالات!$C$2:$C$501,A85)+SUMIFS('تعديل الجرد'!$F$2:$F$501,'تعديل الجرد'!$C$2:$C$501,A85)-SUMIFS('الصرف المباشر'!$D$2:$D$501,'الصرف المباشر'!$C$2:$C$501,A85)-SUMPRODUCT((الطبخات!$B$2:$B$900=A85)*الطبخات!$C$2:$C$900*COUNTIF('سجل الإنتاج'!$C$2:$C$501,الطبخات!$A$2:$A$900)),3))
C86: =IF(A86="","",ROUND(SUMIFS(الإدخالات!$D$2:$D$501,الإدخالات!$C$2:$C$501,A86)+SUMIFS('تعديل الجرد'!$F$2:$F$501,'تعديل الجرد'!$C$2:$C$501,A86)-SUMIFS('الصرف المباشر'!$D$2:$D$501,'الصرف المباشر'!$C$2:$C$501,A86)-SUMPRODUCT((الطبخات!$B$2:$B$900=A86)*الطبخات!$C$2:$C$900*COUNTIF('سجل الإنتاج'!$C$2:$C$501,الطبخات!$A$2:$A$900)),3))
C87: =IF(A87="","",ROUND(SUMIFS(الإدخالات!$D$2:$D$501,الإدخالات!$C$2:$C$501,A87)+SUMIFS('تعديل الجرد'!$F$2:$F$501,'تعديل الجرد'!$C$2:$C$501,A87)-SUMIFS('الصرف المباشر'!$D$2:$D$501,'الصرف المباشر'!$C$2:$C$501,A87)-SUMPRODUCT((الطبخات!$B$2:$B$900=A87)*الطبخات!$C$2:$C$900*COUNTIF('سجل الإنتاج'!$C$2:$C$501,الطبخات!$A$2:$A$900)),3))
... C320: =IF(A320="","",ROUND(SUMIFS(الإدخالات!$D$2:$D$501,الإدخالات!$C$2:$C$501,A320)+SUMIFS('تعديل الجرد'!$F$2:$F$501,'تعديل الجرد'!$C$2:$C$501,A320)-SUMIFS('الصرف المباشر'!$D$2:$D$501,'الصرف المباشر'!$C$2:$C$501,A320)-SUMPRODUCT((الطبخات!$B$2:$B$900=A320)*الطبخات!$C$2:$C$900*COUNTIF('سجل الإنتاج'!$C$2:$C$501,الطبخات!$A$2:$A$900)),3))

Sheet الطبخات
A1: اسم الطبخة | B1: المادة | C1: الكمية | D1: الوحدة | E1: ملاحظات | F1: أول ظهور (مساعد - لا يُعدَّل) | G1: ترتيب مضغوط (مساعد - لا يُعدَّل)
A2: دوا غسيل بودرا 157 كغ - ببوري | B2: دواء غسيل نصف مصنع | C2: 105 | D2: كغ | F2: =IF(AND($A2<>"",COUNTIF($A$2:A2,$A2)=1),$A2,"") -> دوا غسيل بودرا 157 كغ - ببوري | G2: =IF($F2<>"",SUMPRODUCT(($F$2:F2<>"")*1),"") -> 1
A3: دوا غسيل بودرا 157 كغ - ببوري | B3: ملح | C3: 40 | D3: كغ | F3: =IF(AND($A3<>"",COUNTIF($A$2:A3,$A3)=1),$A3,"") | G3: =IF($F3<>"",SUMPRODUCT(($F$2:F3<>"")*1),"")
A4: دوا غسيل بودرا 157 كغ - ببوري | B4: عطر-ببوري ultimate-mixture - 485797 | C4: 1 | D4: كغ | F4: =IF(AND($A4<>"",COUNTIF($A$2:A4,$A4)=1),$A4,"") | G4: =IF($F4<>"",SUMPRODUCT(($F$2:F4<>"")*1),"")
A5: دوا غسيل بودرا 157 كغ - ببوري | B5: حبيبات ملونة | C5: 11 | D5: =IFERROR(INDEX(المواد!$B$2:$B$320,MATCH(B5,المواد!$A$2:$A$320,0)),"") | F5: =IF(AND($A5<>"",COUNTIF($A$2:A5,$A5)=1),$A5,"") | G5: =IF($F5<>"",SUMPRODUCT(($F$2:F5<>"")*1),"")
A6: دوا غسيل بودرا 157 كغ - ببوري | B6: مانع رغوة سيليكون | C6: 210 | D6: =IFERROR(INDEX(المواد!$B$2:$B$320,MATCH(B6,المواد!$A$2:$A$320,0)),"") -> كغ | F6: =IF(AND($A6<>"",COUNTIF($A$2:A6,$A6)=1),$A6,"") | G6: =IF($F6<>"",SUMPRODUCT(($F$2:F6<>"")*1),"")
A7: دوا غسيل بودرا 45كغ مصنع | B7: دواء غسيل نصف مصنع | C7: 45 | D7: =IFERROR(INDEX(المواد!$B$2:$B$320,MATCH(B7,المواد!$A$2:$A$320,0)),"") -> كغ | F7: =IF(AND($A7<>"",COUNTIF($A$2:A7,$A7)=1),$A7,"") -> دوا غسيل بودرا 45كغ مصنع | G7: =IF($F7<>"",SUMPRODUCT(($F$2:F7<>"")*1),"") -> 2
A8: دوا غسيل بودرا 45كغ مصنع | B8: ملح | C8: 18 | D8: =IFERROR(INDEX(المواد!$B$2:$B$320,MATCH(B8,المواد!$A$2:$A$320,0)),"") -> كغ | F8: =IF(AND($A8<>"",COUNTIF($A$2:A8,$A8)=1),$A8,"") | G8: =IF($F8<>"",SUMPRODUCT(($F$2:F8<>"")*1),"")
A9: دوا غسيل بودرا 45كغ مصنع | B9: عطر-ببوري ultimate-mixture - 485797 | C9: 0.45 | D9: =IFERROR(INDEX(المواد!$B$2:$B$320,MATCH(B9,المواد!$A$2:$A$320,0)),"") -> كغ | F9: =IF(AND($A9<>"",COUNTIF($A$2:A9,$A9)=1),$A9,"") | G9: =IF($F9<>"",SUMPRODUCT(($F$2:F9<>"")*1),"")
A10: دوا غسيل بودرا 45كغ مصنع | B10: حبيبات ملونة | C10: 5 | D10: =IFERROR(INDEX(المواد!$B$2:$B$320,MATCH(B10,المواد!$A$2:$A$320,0)),"") | F10: =IF(AND($A10<>"",COUNTIF($A$2:A10,$A10)=1),$A10,"") | G10: =IF($F10<>"",SUMPRODUCT(($F$2:F10<>"")*1),"")
A11: دوا غسيل بودرا 45كغ مصنع | B11: مانع رغوة سيليكون | C11: 95 | D11: =IFERROR(INDEX(المواد!$B$2:$B$320,MATCH(B11,المواد!$A$2:$A$320,0)),"") -> كغ | F11: =IF(AND($A11<>"",COUNTIF($A$2:A11,$A11)=1),$A11,"") | G11: =IF($F11<>"",SUMPRODUCT(($F$2:F11<>"")*1),"")
A12: دوا غسيل بودرا 60 كغ -عطر ببوري | B12: دواء غسيل نصف مصنع | C12: 60 | D12: =IFERROR(INDEX(المواد!$B$2:$B$320,MATCH(B12,المواد!$A$2:$A$320,0)),"") -> كغ | F12: =IF(AND($A12<>"",COUNTIF($A$2:A12,$A12)=1),$A12,"") -> دوا غسيل بودرا 60 كغ -عطر ببوري | G12: =IF($F12<>"",SUMPRODUCT(($F$2:F12<>"")*1),"") -> 3
A13: دوا غسيل بودرا 60 كغ -عطر ببوري | B13: ملح | C13: 24 | D13: =IFERROR(INDEX(المواد!$B$2:$B$320,MATCH(B13,المواد!$A$2:$A$320,0)),"") -> كغ | F13: =IF(AND($A13<>"",COUNTIF($A$2:A13,$A13)=1),$A13,"") | G13: =IF($F13<>"",SUMPRODUCT(($F$2:F13<>"")*1),"")
A14: دوا غسيل بودرا 60 كغ -عطر ببوري | B14: عطر-ببوري ultimate-mixture - 485797 | C14: 0.6 | D14: =IFERROR(INDEX(المواد!$B$2:$B$320,MATCH(B14,المواد!$A$2:$A$320,0)),"") -> كغ | F14: =IF(AND($A14<>"",COUNTIF($A$2:A14,$A14)=1),$A14,"") | G14: =IF($F14<>"",SUMPRODUCT(($F$2:F14<>"")*1),"")
A15: دوا غسيل بودرا 60 كغ -عطر ببوري | B15: حبيبات ملونة | C15: 6.6 | D15: =IFERROR(INDEX(المواد!$B$2:$B$320,MATCH(B15,المواد!$A$2:$A$320,0)),"") | F15: =IF(AND($A15<>"",COUNTIF($A$2:A15,$A15)=1),$A15,"") | G15: =IF($F15<>"",SUMPRODUCT(($F$2:F15<>"")*1),"")
A16: دوا غسيل بودرا 60 كغ -عطر ببوري | B16: مانع رغوة سيليكون | C16: 126 | D16: =IFERROR(INDEX(المواد!$B$2:$B$320,MATCH(B16,المواد!$A$2:$A$320,0)),"") -> كغ | F16: =IF(AND($A16<>"",COUNTIF($A$2:A16,$A16)=1),$A16,"") | G16: =IF($F16<>"",SUMPRODUCT(($F$2:F16<>"")*1),"")
... A23: صابون سائل رمان - لافندر | B23: عطر-رمان apple grandada - 322730 - لافندر | C23: 2 | D23: =IFERROR(INDEX(المواد!$B$2:$B$320,MATCH(B23,المواد!$A$2:$A$320,0)),"") | F23: =IF(AND($A23<>"",COUNTIF($A$2:A23,$A23)=1),$A23,"") | G23: =IF($F23<>"",SUMPRODUCT(($F$2:F23<>"")*1),"")
A24: صابون سائل رمان - لافندر | B24: صبغة | D24: =IFERROR(INDEX(المواد!$B$2:$B$320,MATCH(B24,المواد!$A$2:$A$320,0)),"") | F24: =IF(AND($A24<>"",COUNTIF($A$2:A24,$A24)=1),$A24,"") | G24: =IF($F24<>"",SUMPRODUCT(($F$2:F24<>"")*1),"")
A25: صابون سائل رمان - لافندر | B25: ماء مقطرة | C25: 800 | D25: =IFERROR(INDEX(المواد!$B$2:$B$320,MATCH(B25,المواد!$A$2:$A$320,0)),"") -> كغ | F25: =IF(AND($A25<>"",COUNTIF($A$2:A25,$A25)=1),$A25,"") | G25: =IF($F25<>"",SUMPRODUCT(($F$2:F25<>"")*1),"")
A26: صابون سائل رمان - لافندر | B26: حمض الليمون | D26: =IFERROR(INDEX(المواد!$B$2:$B$320,MATCH(B26,المواد!$A$2:$A$320,0)),"") -> كغ | F26: =IF(AND($A26<>"",COUNTIF($A$2:A26,$A26)=1),$A26,"") | G26: =IF($F26<>"",SUMPRODUCT(($F$2:F26<>"")*1),"")
A27: صابون سائل عود | B27: تكسبون | C27: 120 | D27: =IFERROR(INDEX(المواد!$B$2:$B$320,MATCH(B27,المواد!$A$2:$A$320,0)),"") -> كغ | F27: =IF(AND($A27<>"",COUNTIF($A$2:A27,$A27)=1),$A27,"") -> صابون سائل عود | G27: =IF($F27<>"",SUMPRODUCT(($F$2:F27<>"")*1),"") -> 5
A28: صابون سائل عود | B28: زفتة | C28: 40 | D28: =IFERROR(INDEX(المواد!$B$2:$B$320,MATCH(B28,المواد!$A$2:$A$320,0)),"") -> كغ | F28: =IF(AND($A28<>"",COUNTIF($A$2:A28,$A28)=1),$A28,"") | G28: =IF($F28<>"",SUMPRODUCT(($F$2:F28<>"")*1),"")
A29: صابون سائل عود | B29: كوستيك-قطرونة | C29: 5 | D29: =IFERROR(INDEX(المواد!$B$2:$B$320,MATCH(B29,المواد!$A$2:$A$320,0)),"") -> كغ | F29: =IF(AND($A29<>"",COUNTIF($A$2:A29,$A29)=1),$A29,"") | G29: =IF($F29<>"",SUMPRODUCT(($F$2:F29<>"")*1),"")
A30: صابون سائل عود | B30: غليسيرين | C30: 5 | D30: =IFERROR(INDEX(المواد!$B$2:$B$320,MATCH(B30,المواد!$A$2:$A$320,0)),"") -> كغ | F30: =IF(AND($A30<>"",COUNTIF($A$2:A30,$A30)=1),$A30,"") | G30: =IF($F30<>"",SUMPRODUCT(($F$2:F30<>"")*1),"")
A31: صابون سائل عود | B31: فورمول ( سم ) | C31: 1.5 | D31: =IFERROR(INDEX(المواد!$B$2:$B$320,MATCH(B31,المواد!$A$2:$A$320,0)),"") -> كغ | F31: =IF(AND($A31<>"",COUNTIF($A$2:A31,$A31)=1),$A31,"") | G31: =IF($F31<>"",SUMPRODUCT(($F$2:F31<>"")*1),"")
A32: صابون سائل عود | B32: بيتائين | C32: 20 | D32: =IFERROR(INDEX(المواد!$B$2:$B$320,MATCH(B32,المواد!$A$2:$A$320,0)),"") -> كغ | F32: =IF(AND($A32<>"",COUNTIF($A$2:A32,$A32)=1),$A32,"") | G32: =IF($F32<>"",SUMPRODUCT(($F$2:F32<>"")*1),"")
A33: صابون سائل عود | B33: عطر عود | C33: 2 | D33: =IFERROR(INDEX(المواد!$B$2:$B$320,MATCH(B33,المواد!$A$2:$A$320,0)),"") | F33: =IF(AND($A33<>"",COUNTIF($A$2:A33,$A33)=1),$A33,"") | G33: =IF($F33<>"",SUMPRODUCT(($F$2:F33<>"")*1),"")
A34: صابون سائل عود | B34: صبغة | D34: =IFERROR(INDEX(المواد!$B$2:$B$320,MATCH(B34,المواد!$A$2:$A$320,0)),"") | F34: =IF(AND($A34<>"",COUNTIF($A$2:A34,$A34)=1),$A34,"") | G34: =IF($F34<>"",SUMPRODUCT(($F$2:F34<>"")*1),"")
A35: صابون سائل عود | B35: ماء مقطرة | C35: 800 | D35: =IFERROR(INDEX(المواد!$B$2:$B$320,MATCH(B35,المواد!$A$2:$A$320,0)),"") -> كغ | F35: =IF(AND($A35<>"",COUNTIF($A$2:A35,$A35)=1),$A35,"") | G35: =IF($F35<>"",SUMPRODUCT(($F$2:F35<>"")*1),"")
A36: صابون سائل عود | B36: حمض الليمون | D36: =IFERROR(INDEX(المواد!$B$2:$B$320,MATCH(B36,المواد!$A$2:$A$320,0)),"") -> كغ | F36: =IF(AND($A36<>"",COUNTIF($A$2:A36,$A36)=1),$A36,"") | G36: =IF($F36<>"",SUMPRODUCT(($F$2:F36<>"")*1),"")
A37: صابون سائل ماء الذهب | B37: تكسبون | C37: 120 | D37: =IFERROR(INDEX(المواد!$B$2:$B$320,MATCH(B37,المواد!$A$2:$A$320,0)),"") -> كغ | F37: =IF(AND($A37<>"",COUNTIF($A$2:A37,$A37)=1),$A37,"") -> صابون سائل ماء الذهب | G37: =IF($F37<>"",SUMPRODUCT(($F$2:F37<>"")*1),"") -> 6
A38: صابون سائل ماء الذهب | B38: زفتة | C38: 40 | D38: =IFERROR(INDEX(المواد!$B$2:$B$320,MATCH(B38,المواد!$A$2:$A$320,0)),"") -> كغ | F38: =IF(AND($A38<>"",COUNTIF($A$2:A38,$A38)=1),$A38,"") | G38: =IF($F38<>"",SUMPRODUCT(($F$2:F38<>"")*1),"")
A39: صابون سائل ماء الذهب | B39: كوستيك-قطرونة | C39: 5 | D39: =IFERROR(INDEX(المواد!$B$2:$B$320,MATCH(B39,المواد!$A$2:$A$320,0)),"") -> كغ | F39: =IF(AND($A39<>"",COUNTIF($A$2:A39,$A39)=1),$A39,"") | G39: =IF($F39<>"",SUMPRODUCT(($F$2:F39<>"")*1),"")
A40: صابون سائل ماء الذهب | B40: غليسيرين | C40: 5 | D40: =IFERROR(INDEX(المواد!$B$2:$B$320,MATCH(B40,المواد!$A$2:$A$320,0)),"") -> كغ | F40: =IF(AND($A40<>"",COUNTIF($A$2:A40,$A40)=1),$A40,"") | G40: =IF($F40<>"",SUMPRODUCT(($F$2:F40<>"")*1),"")
A41: صابون سائل ماء الذهب | B41: فورمول ( سم ) | C41: 1.5 | D41: =IFERROR(INDEX(المواد!$B$2:$B$320,MATCH(B41,المواد!$A$2:$A$320,0)),"") -> كغ | F41: =IF(AND($A41<>"",COUNTIF($A$2:A41,$A41)=1),$A41,"") | G41: =IF($F41<>"",SUMPRODUCT(($F$2:F41<>"")*1),"")
A42: صابون سائل ماء الذهب | B42: بيتائين | C42: 20 | D42: =IFERROR(INDEX(المواد!$B$2:$B$320,MATCH(B42,المواد!$A$2:$A$320,0)),"") -> كغ | F42: =IF(AND($A42<>"",COUNTIF($A$2:A42,$A42)=1),$A42,"") | G42: =IF($F42<>"",SUMPRODUCT(($F$2:F42<>"")*1),"")
A43: صابون سائل ماء الذهب | B43: عطر ماء الذهب | C43: 2 | D43: =IFERROR(INDEX(المواد!$B$2:$B$320,MATCH(B43,المواد!$A$2:$A$320,0)),"") | F43: =IF(AND($A43<>"",COUNTIF($A$2:A43,$A43)=1),$A43,"") | G43: =IF($F43<>"",SUMPRODUCT(($F$2:F43<>"")*1),"")
A44: صابون سائل ماء الذهب | B44: صبغة | D44: =IFERROR(INDEX(المواد!$B$2:$B$320,MATCH(B44,المواد!$A$2:$A$320,0)),"") | F44: =IF(AND($A44<>"",COUNTIF($A$2:A44,$A44)=1),$A44,"") | G44: =IF($F44<>"",SUMPRODUCT(($F$2:F44<>"")*1),"")
A45: صابون سائل ماء الذهب | B45: ماء مقطرة | C45: 800 | D45: =IFERROR(INDEX(المواد!$B$2:$B$320,MATCH(B45,المواد!$A$2:$A$320,0)),"") -> كغ | F45: =IF(AND($A45<>"",COUNTIF($A$2:A45,$A45)=1),$A45,"") | G45: =IF($F45<>"",SUMPRODUCT(($F$2:F45<>"")*1),"")
A46: صابون سائل ماء الذهب | B46: حمض الليمون | D46: =IFERROR(INDEX(المواد!$B$2:$B$320,MATCH(B46,المواد!$A$2:$A$320,0)),"") -> كغ | F46: =IF(AND($A46<>"",COUNTIF($A$2:A46,$A46)=1),$A46,"") | G46: =IF($F46<>"",SUMPRODUCT(($F$2:F46<>"")*1),"")
...

Sheet الإدخالات
A1: رقم العملية | B1: التاريخ | C1: المادة | D1: الكمية | E1: المورد | F1: رقم الفاتورة | G1: ملاحظات
A2: =IF(C2="","",ROW()-1) -> 1 | B2: 46218 | C2: ملح | D2: 138.04 | E2: امين | F2: - | G2: تنزيل البيانات لأول مرة
A3: =IF(C3="","",ROW()-1) -> 2 | B3: 46218 | C3: مقصب | D3: 2 | E3: امين | F3: - | G3: تنزيل البيانات لأول مرة
A4: =IF(C4="","",ROW()-1) -> 3 | B4: 46218 | C4: مجمد | D4: 63.5 | E4: امين | F4: - | G4: تنزيل البيانات لأول مرة
A5: =IF(C5="","",ROW()-1) -> 4 | B5: 46218 | C5: مانع رغوة مائي | D5: 0 | E5: امين | F5: - | G5: تنزيل البيانات لأول مرة
A6: =IF(C6="","",ROW()-1) -> 5 | B6: 46218 | C6: مانع رغوة سيليكون | D6: 0 | E6: امين | F6: - | G6: تنزيل البيانات لأول مرة
A7: =IF(C7="","",ROW()-1) -> 6 | B7: 46218 | C7: ماء مقطرة | D7: 28622 | E7: امين | F7: - | G7: تنزيل البيانات لأول مرة
A8: =IF(C8="","",ROW()-1) -> 7 | B8: 46218 | C8: ماء بلسم | D8: 3 | E8: امين | F8: - | G8: تنزيل البيانات لأول مرة
A9: =IF(C9="","",ROW()-1) -> 8 | B9: 46218 | C9: لانيت 16 ماليزي | D9: 0 | E9: امين | F9: - | G9: تنزيل البيانات لأول مرة
A10: =IF(C10="","",ROW()-1) -> 9 | B10: 46218 | C10: كوستيك-قطرونة | D10: 27.71 | E10: امين | F10: - | G10: تنزيل البيانات لأول مرة
A11: =IF(C11="","",ROW()-1) -> 10 | B11: 46218 | C11: كمبرلان | D11: 0 | E11: امين | F11: - | G11: تنزيل البيانات لأول مرة
A12: =IF(C12="","",ROW()-1) -> 11 | B12: 46218 | C12: كليمازول | D12: 0 | E12: امين | F12: - | G12: تنزيل البيانات لأول مرة
A13: =IF(C13="","",ROW()-1) -> 12 | B13: 46218 | C13: كلور خام | D13: 272 | E13: امين | F13: - | G13: تنزيل البيانات لأول مرة
... A75: =IF(C75="","",ROW()-1) -> 74 | B75: 46218 | C75: ديتول خام | D75: 0 | E75: امين | F75: - | G75: تنزيل البيانات لأول مرة
A76: =IF(C76="","",ROW()-1)
A77: =IF(C77="","",ROW()-1)
A78: =IF(C78="","",ROW()-1)
A79: =IF(C79="","",ROW()-1)
A80: =IF(C80="","",ROW()-1)
A81: =IF(C81="","",ROW()-1)
A82: =IF(C82="","",ROW()-1)
A83: =IF(C83="","",ROW()-1)
A84: =IF(C84="","",ROW()-1)
A85: =IF(C85="","",ROW()-1)
A86: =IF(C86="","",ROW()-1)
A87: =IF(C87="","",ROW()-1)
... A501: =IF(C501="","",ROW()-1)

Sheet سجل الإنتاج
A1: رقم العملية | B1: التاريخ | C1: اسم الطبخة | D1: ملاحظات
A2: =IF(C2="","",ROW()-1) -> 1 | B2: 46211 | C2: لودلين سادة رابع | D2: -
A3: =IF(C3="","",ROW()-1) | B3: 46219
A4: =IF(C4="","",ROW()-1)
A5: =IF(C5="","",ROW()-1)
A6: =IF(C6="","",ROW()-1)
A7: =IF(C7="","",ROW()-1)
A8: =IF(C8="","",ROW()-1)
A9: =IF(C9="","",ROW()-1)
A10: =IF(C10="","",ROW()-1)
A11: =IF(C11="","",ROW()-1)
A12: =IF(C12="","",ROW()-1)
A13: =IF(C13="","",ROW()-1)
A14: =IF(C14="","",ROW()-1)
A15: =IF(C15="","",ROW()-1)
... A501: =IF(C501="","",ROW()-1)

Sheet الصرف المباشر
A1: رقم العملية | B1: التاريخ | C1: المادة | D1: الكمية | E1: الجهة المستفيدة | F1: ملاحظات
A2: =IF(C2="","",ROW()-1) -> 1 | B2: 46211 | C2: تكسبون | D2: 3 | E2: أبو خليل | F2: -
A3: =IF(C3="","",ROW()-1) -> 2 | B3: 46219 | C3: زفتة | D3: 20 | E3: أبو خليل ميسشنتبشب شس | F3: منشان نيسشتبكبي مككيللتكمشسيتب
A4: =IF(C4="","",ROW()-1)
A5: =IF(C5="","",ROW()-1)
A6: =IF(C6="","",ROW()-1)
A7: =IF(C7="","",ROW()-1)
A8: =IF(C8="","",ROW()-1)
A9: =IF(C9="","",ROW()-1)
A10: =IF(C10="","",ROW()-1)
A11: =IF(C11="","",ROW()-1)
A12: =IF(C12="","",ROW()-1)
A13: =IF(C13="","",ROW()-1)
A14: =IF(C14="","",ROW()-1)
A15: =IF(C15="","",ROW()-1)
... A501: =IF(C501="","",ROW()-1)

Sheet تعديل الجرد
A1: رقم العملية | B1: التاريخ | C1: المادة | D1: الرصيد النظامي (قبل هذا التعديل) | E1: الكمية الفعلية (الجرد) | F1: الفرق | G1: سبب التعديل | H1: ملاحظات
A2: =IF(C2="","",ROW()-1) -> 1 | B2: 46211 | C2: زفتة | D2: =IF($C2="","",ROUND(SUMIFS(الإدخالات!$D$2:$D$501,الإدخالات!$C$2:$C$501,$C2)+SUMIFS($F$1:F1,$C$1:C1,$C2)-SUMIFS('الصرف المباشر'!$D$2:$D$501,'الصرف المباشر'!$C$2:$C$501,$C2)-SUMPRODUCT((الطبخات!$B$2:$B$900=$C2)*الطبخات!$C$2:$C$900*COUNTIF('سجل الإنتاج'!$C$2:$C$501,الطبخات!$A$2:$A$900)),3)) -> 496 | E2: 88 | F2: =IF(OR($C2="",$E2=""),"",ROUND($E2-$D2,3)) -> -408 | G2: فقدان | H2: -
A3: =IF(C3="","",ROW()-1) | D3: =IF($C3="","",ROUND(SUMIFS(الإدخالات!$D$2:$D$501,الإدخالات!$C$2:$C$501,$C3)+SUMIFS($F$1:F2,$C$1:C2,$C3)-SUMIFS('الصرف المباشر'!$D$2:$D$501,'الصرف المباشر'!$C$2:$C$501,$C3)-SUMPRODUCT((الطبخات!$B$2:$B$900=$C3)*الطبخات!$C$2:$C$900*COUNTIF('سجل الإنتاج'!$C$2:$C$501,الطبخات!$A$2:$A$900)),3)) | F3: =IF(OR($C3="",$E3=""),"",ROUND($E3-$D3,3))
A4: =IF(C4="","",ROW()-1) | D4: =IF($C4="","",ROUND(SUMIFS(الإدخالات!$D$2:$D$501,الإدخالات!$C$2:$C$501,$C4)+SUMIFS($F$1:F3,$C$1:C3,$C4)-SUMIFS('الصرف المباشر'!$D$2:$D$501,'الصرف المباشر'!$C$2:$C$501,$C4)-SUMPRODUCT((الطبخات!$B$2:$B$900=$C4)*الطبخات!$C$2:$C$900*COUNTIF('سجل الإنتاج'!$C$2:$C$501,الطبخات!$A$2:$A$900)),3)) | F4: =IF(OR($C4="",$E4=""),"",ROUND($E4-$D4,3))
A5: =IF(C5="","",ROW()-1) | D5: =IF($C5="","",ROUND(SUMIFS(الإدخالات!$D$2:$D$501,الإدخالات!$C$2:$C$501,$C5)+SUMIFS($F$1:F4,$C$1:C4,$C5)-SUMIFS('الصرف المباشر'!$D$2:$D$501,'الصرف المباشر'!$C$2:$C$501,$C5)-SUMPRODUCT((الطبخات!$B$2:$B$900=$C5)*الطبخات!$C$2:$C$900*COUNTIF('سجل الإنتاج'!$C$2:$C$501,الطبخات!$A$2:$A$900)),3)) | F5: =IF(OR($C5="",$E5=""),"",ROUND($E5-$D5,3))
A6: =IF(C6="","",ROW()-1) | D6: =IF($C6="","",ROUND(SUMIFS(الإدخالات!$D$2:$D$501,الإدخالات!$C$2:$C$501,$C6)+SUMIFS($F$1:F5,$C$1:C5,$C6)-SUMIFS('الصرف المباشر'!$D$2:$D$501,'الصرف المباشر'!$C$2:$C$501,$C6)-SUMPRODUCT((الطبخات!$B$2:$B$900=$C6)*الطبخات!$C$2:$C$900*COUNTIF('سجل الإنتاج'!$C$2:$C$501,الطبخات!$A$2:$A$900)),3)) | F6: =IF(OR($C6="",$E6=""),"",ROUND($E6-$D6,3))
A7: =IF(C7="","",ROW()-1) | D7: =IF($C7="","",ROUND(SUMIFS(الإدخالات!$D$2:$D$501,الإدخالات!$C$2:$C$501,$C7)+SUMIFS($F$1:F6,$C$1:C6,$C7)-SUMIFS('الصرف المباشر'!$D$2:$D$501,'الصرف المباشر'!$C$2:$C$501,$C7)-SUMPRODUCT((الطبخات!$B$2:$B$900=$C7)*الطبخات!$C$2:$C$900*COUNTIF('سجل الإنتاج'!$C$2:$C$501,الطبخات!$A$2:$A$900)),3)) | F7: =IF(OR($C7="",$E7=""),"",ROUND($E7-$D7,3))
A8: =IF(C8="","",ROW()-1) | D8: =IF($C8="","",ROUND(SUMIFS(الإدخالات!$D$2:$D$501,الإدخالات!$C$2:$C$501,$C8)+SUMIFS($F$1:F7,$C$1:C7,$C8)-SUMIFS('الصرف المباشر'!$D$2:$D$501,'الصرف المباشر'!$C$2:$C$501,$C8)-SUMPRODUCT((الطبخات!$B$2:$B$900=$C8)*الطبخات!$C$2:$C$900*COUNTIF('سجل الإنتاج'!$C$2:$C$501,الطبخات!$A$2:$A$900)),3)) | F8: =IF(OR($C8="",$E8=""),"",ROUND($E8-$D8,3))
A9: =IF(C9="","",ROW()-1) | D9: =IF($C9="","",ROUND(SUMIFS(الإدخالات!$D$2:$D$501,الإدخالات!$C$2:$C$501,$C9)+SUMIFS($F$1:F8,$C$1:C8,$C9)-SUMIFS('الصرف المباشر'!$D$2:$D$501,'الصرف المباشر'!$C$2:$C$501,$C9)-SUMPRODUCT((الطبخات!$B$2:$B$900=$C9)*الطبخات!$C$2:$C$900*COUNTIF('سجل الإنتاج'!$C$2:$C$501,الطبخات!$A$2:$A$900)),3)) | F9: =IF(OR($C9="",$E9=""),"",ROUND($E9-$D9,3))
A10: =IF(C10="","",ROW()-1) | D10: =IF($C10="","",ROUND(SUMIFS(الإدخالات!$D$2:$D$501,الإدخالات!$C$2:$C$501,$C10)+SUMIFS($F$1:F9,$C$1:C9,$C10)-SUMIFS('الصرف المباشر'!$D$2:$D$501,'الصرف المباشر'!$C$2:$C$501,$C10)-SUMPRODUCT((الطبخات!$B$2:$B$900=$C10)*الطبخات!$C$2:$C$900*COUNTIF('سجل الإنتاج'!$C$2:$C$501,الطبخات!$A$2:$A$900)),3)) | F10: =IF(OR($C10="",$E10=""),"",ROUND($E10-$D10,3))
A11: =IF(C11="","",ROW()-1) | D11: =IF($C11="","",ROUND(SUMIFS(الإدخالات!$D$2:$D$501,الإدخالات!$C$2:$C$501,$C11)+SUMIFS($F$1:F10,$C$1:C10,$C11)-SUMIFS('الصرف المباشر'!$D$2:$D$501,'الصرف المباشر'!$C$2:$C$501,$C11)-SUMPRODUCT((الطبخات!$B$2:$B$900=$C11)*الطبخات!$C$2:$C$900*COUNTIF('سجل الإنتاج'!$C$2:$C$501,الطبخات!$A$2:$A$900)),3)) | F11: =IF(OR($C11="",$E11=""),"",ROUND($E11-$D11,3))
A12: =IF(C12="","",ROW()-1) | D12: =IF($C12="","",ROUND(SUMIFS(الإدخالات!$D$2:$D$501,الإدخالات!$C$2:$C$501,$C12)+SUMIFS($F$1:F11,$C$1:C11,$C12)-SUMIFS('الصرف المباشر'!$D$2:$D$501,'الصرف المباشر'!$C$2:$C$501,$C12)-SUMPRODUCT((الطبخات!$B$2:$B$900=$C12)*الطبخات!$C$2:$C$900*COUNTIF('سجل الإنتاج'!$C$2:$C$501,الطبخات!$A$2:$A$900)),3)) | F12: =IF(OR($C12="",$E12=""),"",ROUND($E12-$D12,3))
A13: =IF(C13="","",ROW()-1) | D13: =IF($C13="","",ROUND(SUMIFS(الإدخالات!$D$2:$D$501,الإدخالات!$C$2:$C$501,$C13)+SUMIFS($F$1:F12,$C$1:C12,$C13)-SUMIFS('الصرف المباشر'!$D$2:$D$501,'الصرف المباشر'!$C$2:$C$501,$C13)-SUMPRODUCT((الطبخات!$B$2:$B$900=$C13)*الطبخات!$C$2:$C$900*COUNTIF('سجل الإنتاج'!$C$2:$C$501,الطبخات!$A$2:$A$900)),3)) | F13: =IF(OR($C13="",$E13=""),"",ROUND($E13-$D13,3))
A14: =IF(C14="","",ROW()-1) | D14: =IF($C14="","",ROUND(SUMIFS(الإدخالات!$D$2:$D$501,الإدخالات!$C$2:$C$501,$C14)+SUMIFS($F$1:F13,$C$1:C13,$C14)-SUMIFS('الصرف المباشر'!$D$2:$D$501,'الصرف المباشر'!$C$2:$C$501,$C14)-SUMPRODUCT((الطبخات!$B$2:$B$900=$C14)*الطبخات!$C$2:$C$900*COUNTIF('سجل الإنتاج'!$C$2:$C$501,الطبخات!$A$2:$A$900)),3)) | F14: =IF(OR($C14="",$E14=""),"",ROUND($E14-$D14,3))
... A501: =IF(C501="","",ROW()-1) | D501: =IF($C501="","",ROUND(SUMIFS(الإدخالات!$D$2:$D$501,الإدخالات!$C$2:$C$501,$C501)+SUMIFS($F$1:F500,$C$1:C500,$C501)-SUMIFS('الصرف المباشر'!$D$2:$D$501,'الصرف المباشر'!$C$2:$C$501,$C501)-SUMPRODUCT((الطبخات!$B$2:$B$900=$C501)*الطبخات!$C$2:$C$900*COUNTIF('سجل الإنتاج'!$C$2:$C$501,الطبخات!$A$2:$A$900)),3)) | F501: =IF(OR($C501="",$E501=""),"",ROUND($E501-$D501,3))

Sheet الرصيد الحالي
A1: اسم المادة | B1: الوحدة | C1: الرصيد الحالي | D1: إجمالي الاستهلاك (كل الوقت) | E1: حالة الرصيد | F1: ترتيب مساعد (لا يُعدَّل)
A2: =المواد!A2 -> ملح | B2: =المواد!B2 -> كغ | C2: =IF($A2="","",ROUND(SUMIFS(الإدخالات!$D$2:$D$501,الإدخالات!$C$2:$C$501,$A2)+SUMIFS('تعديل الجرد'!$F$2:$F$501,'تعديل الجرد'!$C$2:$C$501,$A2)-SUMIFS('الصرف المباشر'!$D$2:$D$501,'الصرف المباشر'!$C$2:$C$501,$A2)-SUMPRODUCT((الطبخات!$B$2:$B$900=$A2)*الطبخات!$C$2:$C$900*COUNTIF('سجل الإنتاج'!$C$2:$C$501,الطبخات!$A$2:$A$900)),3)) -> 38.04 | D2: =IF($A2="","",ROUND(SUMIFS('الصرف المباشر'!$D$2:$D$501,'الصرف المباشر'!$C$2:$C$501,$A2)+SUMPRODUCT((الطبخات!$B$2:$B$900=$A2)*الطبخات!$C$2:$C$900*COUNTIF('سجل الإنتاج'!$C$2:$C$501,الطبخات!$A$2:$A$900)),3)) -> 100 | E2: =IF($A2="","",IF($C2<0,"❌ رصيد سالب - يحتاج مراجعة","✔ طبيعي")) -> ✔ طبيعي | F2: =IF(AND($A2<>"",$E2<>"✔ طبيعي"),SUMPRODUCT(('الرصيد الحالي'!$E$2:$E2<>"✔ طبيعي")*('الرصيد الحالي'!$E$2:$E2<>"")*('الرصيد الحالي'!$A$2:$A2<>"")),"")
A3: =المواد!A3 -> مقصب | B3: =المواد!B3 -> كغ | C3: =IF($A3="","",ROUND(SUMIFS(الإدخالات!$D$2:$D$501,الإدخالات!$C$2:$C$501,$A3)+SUMIFS('تعديل الجرد'!$F$2:$F$501,'تعديل الجرد'!$C$2:$C$501,$A3)-SUMIFS('الصرف المباشر'!$D$2:$D$501,'الصرف المباشر'!$C$2:$C$501,$A3)-SUMPRODUCT((الطبخات!$B$2:$B$900=$A3)*الطبخات!$C$2:$C$900*COUNTIF('سجل الإنتاج'!$C$2:$C$501,الطبخات!$A$2:$A$900)),3)) -> 2 | D3: =IF($A3="","",ROUND(SUMIFS('الصرف المباشر'!$D$2:$D$501,'الصرف المباشر'!$C$2:$C$501,$A3)+SUMPRODUCT((الطبخات!$B$2:$B$900=$A3)*الطبخات!$C$2:$C$900*COUNTIF('سجل الإنتاج'!$C$2:$C$501,الطبخات!$A$2:$A$900)),3)) -> 0 | E3: =IF($A3="","",IF($C3<0,"❌ رصيد سالب - يحتاج مراجعة","✔ طبيعي")) -> ✔ طبيعي | F3: =IF(AND($A3<>"",$E3<>"✔ طبيعي"),SUMPRODUCT(('الرصيد الحالي'!$E$2:$E3<>"✔ طبيعي")*('الرصيد الحالي'!$E$2:$E3<>"")*('الرصيد الحالي'!$A$2:$A3<>"")),"")
A4: =المواد!A4 -> مجمد | B4: =المواد!B4 -> كغ | C4: =IF($A4="","",ROUND(SUMIFS(الإدخالات!$D$2:$D$501,الإدخالات!$C$2:$C$501,$A4)+SUMIFS('تعديل الجرد'!$F$2:$F$501,'تعديل الجرد'!$C$2:$C$501,$A4)-SUMIFS('الصرف المباشر'!$D$2:$D$501,'الصرف المباشر'!$C$2:$C$501,$A4)-SUMPRODUCT((الطبخات!$B$2:$B$900=$A4)*الطبخات!$C$2:$C$900*COUNTIF('سجل الإنتاج'!$C$2:$C$501,الطبخات!$A$2:$A$900)),3)) -> 63.5 | D4: =IF($A4="","",ROUND(SUMIFS('الصرف المباشر'!$D$2:$D$501,'الصرف المباشر'!$C$2:$C$501,$A4)+SUMPRODUCT((الطبخات!$B$2:$B$900=$A4)*الطبخات!$C$2:$C$900*COUNTIF('سجل الإنتاج'!$C$2:$C$501,الطبخات!$A$2:$A$900)),3)) -> 0 | E4: =IF($A4="","",IF($C4<0,"❌ رصيد سالب - يحتاج مراجعة","✔ طبيعي")) -> ✔ طبيعي | F4: =IF(AND($A4<>"",$E4<>"✔ طبيعي"),SUMPRODUCT(('الرصيد الحالي'!$E$2:$E4<>"✔ طبيعي")*('الرصيد الحالي'!$E$2:$E4<>"")*('الرصيد الحالي'!$A$2:$A4<>"")),"")
A5: =المواد!A5 -> مانع رغوة مائي | B5: =المواد!B5 -> كغ | C5: =IF($A5="","",ROUND(SUMIFS(الإدخالات!$D$2:$D$501,الإدخالات!$C$2:$C$501,$A5)+SUMIFS('تعديل الجرد'!$F$2:$F$501,'تعديل الجرد'!$C$2:$C$501,$A5)-SUMIFS('الصرف المباشر'!$D$2:$D$501,'الصرف المباشر'!$C$2:$C$501,$A5)-SUMPRODUCT((الطبخات!$B$2:$B$900=$A5)*الطبخات!$C$2:$C$900*COUNTIF('سجل الإنتاج'!$C$2:$C$501,الطبخات!$A$2:$A$900)),3)) -> 0 | D5: =IF($A5="","",ROUND(SUMIFS('الصرف المباشر'!$D$2:$D$501,'الصرف المباشر'!$C$2:$C$501,$A5)+SUMPRODUCT((الطبخات!$B$2:$B$900=$A5)*الطبخات!$C$2:$C$900*COUNTIF('سجل الإنتاج'!$C$2:$C$501,الطبخات!$A$2:$A$900)),3)) -> 0 | E5: =IF($A5="","",IF($C5<0,"❌ رصيد سالب - يحتاج مراجعة","✔ طبيعي")) -> ✔ طبيعي | F5: =IF(AND($A5<>"",$E5<>"✔ طبيعي"),SUMPRODUCT(('الرصيد الحالي'!$E$2:$E5<>"✔ طبيعي")*('الرصيد الحالي'!$E$2:$E5<>"")*('الرصيد الحالي'!$A$2:$A5<>"")),"")
A6: =المواد!A6 -> مانع رغوة سيليكون | B6: =المواد!B6 -> كغ | C6: =IF($A6="","",ROUND(SUMIFS(الإدخالات!$D$2:$D$501,الإدخالات!$C$2:$C$501,$A6)+SUMIFS('تعديل الجرد'!$F$2:$F$501,'تعديل الجرد'!$C$2:$C$501,$A6)-SUMIFS('الصرف المباشر'!$D$2:$D$501,'الصرف المباشر'!$C$2:$C$501,$A6)-SUMPRODUCT((الطبخات!$B$2:$B$900=$A6)*الطبخات!$C$2:$C$900*COUNTIF('سجل الإنتاج'!$C$2:$C$501,الطبخات!$A$2:$A$900)),3)) -> 0 | D6: =IF($A6="","",ROUND(SUMIFS('الصرف المباشر'!$D$2:$D$501,'الصرف المباشر'!$C$2:$C$501,$A6)+SUMPRODUCT((الطبخات!$B$2:$B$900=$A6)*الطبخات!$C$2:$C$900*COUNTIF('سجل الإنتاج'!$C$2:$C$501,الطبخات!$A$2:$A$900)),3)) -> 0 | E6: =IF($A6="","",IF($C6<0,"❌ رصيد سالب - يحتاج مراجعة","✔ طبيعي")) -> ✔ طبيعي | F6: =IF(AND($A6<>"",$E6<>"✔ طبيعي"),SUMPRODUCT(('الرصيد الحالي'!$E$2:$E6<>"✔ طبيعي")*('الرصيد الحالي'!$E$2:$E6<>"")*('الرصيد الحالي'!$A$2:$A6<>"")),"")
A7: =المواد!A7 -> ماء مقطرة | B7: =المواد!B7 -> كغ | C7: =IF($A7="","",ROUND(SUMIFS(الإدخالات!$D$2:$D$501,الإدخالات!$C$2:$C$501,$A7)+SUMIFS('تعديل الجرد'!$F$2:$F$501,'تعديل الجرد'!$C$2:$C$501,$A7)-SUMIFS('الصرف المباشر'!$D$2:$D$501,'الصرف المباشر'!$C$2:$C$501,$A7)-SUMPRODUCT((الطبخات!$B$2:$B$900=$A7)*الطبخات!$C$2:$C$900*COUNTIF('سجل الإنتاج'!$C$2:$C$501,الطبخات!$A$2:$A$900)),3)) -> 27732 | D7: =IF($A7="","",ROUND(SUMIFS('الصرف المباشر'!$D$2:$D$501,'الصرف المباشر'!$C$2:$C$501,$A7)+SUMPRODUCT((الطبخات!$B$2:$B$900=$A7)*الطبخات!$C$2:$C$900*COUNTIF('سجل الإنتاج'!$C$2:$C$501,الطبخات!$A$2:$A$900)),3)) -> 890 | E7: =IF($A7="","",IF($C7<0,"❌ رصيد سالب - يحتاج مراجعة","✔ طبيعي")) -> ✔ طبيعي | F7: =IF(AND($A7<>"",$E7<>"✔ طبيعي"),SUMPRODUCT(('الرصيد الحالي'!$E$2:$E7<>"✔ طبيعي")*('الرصيد الحالي'!$E$2:$E7<>"")*('الرصيد الحالي'!$A$2:$A7<>"")),"")
A8: =المواد!A8 -> ماء بلسم | B8: =المواد!B8 -> كغ | C8: =IF($A8="","",ROUND(SUMIFS(الإدخالات!$D$2:$D$501,الإدخالات!$C$2:$C$501,$A8)+SUMIFS('تعديل الجرد'!$F$2:$F$501,'تعديل الجرد'!$C$2:$C$501,$A8)-SUMIFS('الصرف المباشر'!$D$2:$D$501,'الصرف المباشر'!$C$2:$C$501,$A8)-SUMPRODUCT((الطبخات!$B$2:$B$900=$A8)*الطبخات!$C$2:$C$900*COUNTIF('سجل الإنتاج'!$C$2:$C$501,الطبخات!$A$2:$A$900)),3)) -> 3 | D8: =IF($A8="","",ROUND(SUMIFS('الصرف المباشر'!$D$2:$D$501,'الصرف المباشر'!$C$2:$C$501,$A8)+SUMPRODUCT((الطبخات!$B$2:$B$900=$A8)*الطبخات!$C$2:$C$900*COUNTIF('سجل الإنتاج'!$C$2:$C$501,الطبخات!$A$2:$A$900)),3)) -> 0 | E8: =IF($A8="","",IF($C8<0,"❌ رصيد سالب - يحتاج مراجعة","✔ طبيعي")) -> ✔ طبيعي | F8: =IF(AND($A8<>"",$E8<>"✔ طبيعي"),SUMPRODUCT(('الرصيد الحالي'!$E$2:$E8<>"✔ طبيعي")*('الرصيد الحالي'!$E$2:$E8<>"")*('الرصيد الحالي'!$A$2:$A8<>"")),"")
A9: =المواد!A9 -> لانيت 16 ماليزي | B9: =المواد!B9 -> كغ | C9: =IF($A9="","",ROUND(SUMIFS(الإدخالات!$D$2:$D$501,الإدخالات!$C$2:$C$501,$A9)+SUMIFS('تعديل الجرد'!$F$2:$F$501,'تعديل الجرد'!$C$2:$C$501,$A9)-SUMIFS('الصرف المباشر'!$D$2:$D$501,'الصرف المباشر'!$C$2:$C$501,$A9)-SUMPRODUCT((الطبخات!$B$2:$B$900=$A9)*الطبخات!$C$2:$C$900*COUNTIF('سجل الإنتاج'!$C$2:$C$501,الطبخات!$A$2:$A$900)),3)) -> 0 | D9: =IF($A9="","",ROUND(SUMIFS('الصرف المباشر'!$D$2:$D$501,'الصرف المباشر'!$C$2:$C$501,$A9)+SUMPRODUCT((الطبخات!$B$2:$B$900=$A9)*الطبخات!$C$2:$C$900*COUNTIF('سجل الإنتاج'!$C$2:$C$501,الطبخات!$A$2:$A$900)),3)) -> 0 | E9: =IF($A9="","",IF($C9<0,"❌ رصيد سالب - يحتاج مراجعة","✔ طبيعي")) -> ✔ طبيعي | F9: =IF(AND($A9<>"",$E9<>"✔ طبيعي"),SUMPRODUCT(('الرصيد الحالي'!$E$2:$E9<>"✔ طبيعي")*('الرصيد الحالي'!$E$2:$E9<>"")*('الرصيد الحالي'!$A$2:$A9<>"")),"")
A10: =المواد!A10 -> كوستيك-قطرونة | B10: =المواد!B10 -> كغ | C10: =IF($A10="","",ROUND(SUMIFS(الإدخالات!$D$2:$D$501,الإدخالات!$C$2:$C$501,$A10)+SUMIFS('تعديل الجرد'!$F$2:$F$501,'تعديل الجرد'!$C$2:$C$501,$A10)-SUMIFS('الصرف المباشر'!$D$2:$D$501,'الصرف المباشر'!$C$2:$C$501,$A10)-SUMPRODUCT((الطبخات!$B$2:$B$900=$A10)*الطبخات!$C$2:$C$900*COUNTIF('سجل الإنتاج'!$C$2:$C$501,الطبخات!$A$2:$A$900)),3)) -> 27.71 | D10: =IF($A10="","",ROUND(SUMIFS('الصرف المباشر'!$D$2:$D$501,'الصرف المباشر'!$C$2:$C$501,$A10)+SUMPRODUCT((الطبخات!$B$2:$B$900=$A10)*الطبخات!$C$2:$C$900*COUNTIF('سجل الإنتاج'!$C$2:$C$501,الطبخات!$A$2:$A$900)),3)) -> 0 | E10: =IF($A10="","",IF($C10<0,"❌ رصيد سالب - يحتاج مراجعة","✔ طبيعي")) -> ✔ طبيعي | F10: =IF(AND($A10<>"",$E10<>"✔ طبيعي"),SUMPRODUCT(('الرصيد الحالي'!$E$2:$E10<>"✔ طبيعي")*('الرصيد الحالي'!$E$2:$E10<>"")*('الرصيد الحالي'!$A$2:$A10<>"")),"")
A11: =المواد!A11 -> كمبرلان | B11: =المواد!B11 -> كغ | C11: =IF($A11="","",ROUND(SUMIFS(الإدخالات!$D$2:$D$501,الإدخالات!$C$2:$C$501,$A11)+SUMIFS('تعديل الجرد'!$F$2:$F$501,'تعديل الجرد'!$C$2:$C$501,$A11)-SUMIFS('الصرف المباشر'!$D$2:$D$501,'الصرف المباشر'!$C$2:$C$501,$A11)-SUMPRODUCT((الطبخات!$B$2:$B$900=$A11)*الطبخات!$C$2:$C$900*COUNTIF('سجل الإنتاج'!$C$2:$C$501,الطبخات!$A$2:$A$900)),3)) -> 0 | D11: =IF($A11="","",ROUND(SUMIFS('الصرف المباشر'!$D$2:$D$501,'الصرف المباشر'!$C$2:$C$501,$A11)+SUMPRODUCT((الطبخات!$B$2:$B$900=$A11)*الطبخات!$C$2:$C$900*COUNTIF('سجل الإنتاج'!$C$2:$C$501,الطبخات!$A$2:$A$900)),3)) -> 0 | E11: =IF($A11="","",IF($C11<0,"❌ رصيد سالب - يحتاج مراجعة","✔ طبيعي")) -> ✔ طبيعي | F11: =IF(AND($A11<>"",$E11<>"✔ طبيعي"),SUMPRODUCT(('الرصيد الحالي'!$E$2:$E11<>"✔ طبيعي")*('الرصيد الحالي'!$E$2:$E11<>"")*('الرصيد الحالي'!$A$2:$A11<>"")),"")
A12: =المواد!A12 -> كليمازول | B12: =المواد!B12 -> كغ | C12: =IF($A12="","",ROUND(SUMIFS(الإدخالات!$D$2:$D$501,الإدخالات!$C$2:$C$501,$A12)+SUMIFS('تعديل الجرد'!$F$2:$F$501,'تعديل الجرد'!$C$2:$C$501,$A12)-SUMIFS('الصرف المباشر'!$D$2:$D$501,'الصرف المباشر'!$C$2:$C$501,$A12)-SUMPRODUCT((الطبخات!$B$2:$B$900=$A12)*الطبخات!$C$2:$C$900*COUNTIF('سجل الإنتاج'!$C$2:$C$501,الطبخات!$A$2:$A$900)),3)) -> 0 | D12: =IF($A12="","",ROUND(SUMIFS('الصرف المباشر'!$D$2:$D$501,'الصرف المباشر'!$C$2:$C$501,$A12)+SUMPRODUCT((الطبخات!$B$2:$B$900=$A12)*الطبخات!$C$2:$C$900*COUNTIF('سجل الإنتاج'!$C$2:$C$501,الطبخات!$A$2:$A$900)),3)) -> 0 | E12: =IF($A12="","",IF($C12<0,"❌ رصيد سالب - يحتاج مراجعة","✔ طبيعي")) -> ✔ طبيعي | F12: =IF(AND($A12<>"",$E12<>"✔ طبيعي"),SUMPRODUCT(('الرصيد الحالي'!$E$2:$E12<>"✔ طبيعي")*('الرصيد الحالي'!$E$2:$E12<>"")*('الرصيد الحالي'!$A$2:$A12<>"")),"")
A13: =المواد!A13 -> كلور خام | B13: =المواد!B13 -> كغ | C13: =IF($A13="","",ROUND(SUMIFS(الإدخالات!$D$2:$D$501,الإدخالات!$C$2:$C$501,$A13)+SUMIFS('تعديل الجرد'!$F$2:$F$501,'تعديل الجرد'!$C$2:$C$501,$A13)-SUMIFS('الصرف المباشر'!$D$2:$D$501,'الصرف المباشر'!$C$2:$C$501,$A13)-SUMPRODUCT((الطبخات!$B$2:$B$900=$A13)*الطبخات!$C$2:$C$900*COUNTIF('سجل الإنتاج'!$C$2:$C$501,الطبخات!$A$2:$A$900)),3)) -> 272 | D13: =IF($A13="","",ROUND(SUMIFS('الصرف المباشر'!$D$2:$D$501,'الصرف المباشر'!$C$2:$C$501,$A13)+SUMPRODUCT((الطبخات!$B$2:$B$900=$A13)*الطبخات!$C$2:$C$900*COUNTIF('سجل الإنتاج'!$C$2:$C$501,الطبخات!$A$2:$A$900)),3)) -> 0 | E13: =IF($A13="","",IF($C13<0,"❌ رصيد سالب - يحتاج مراجعة","✔ طبيعي")) -> ✔ طبيعي | F13: =IF(AND($A13<>"",$E13<>"✔ طبيعي"),SUMPRODUCT(('الرصيد الحالي'!$E$2:$E13<>"✔ طبيعي")*('الرصيد الحالي'!$E$2:$E13<>"")*('الرصيد الحالي'!$A$2:$A13<>"")),"")
... A320: =المواد!A320 -> 0 | B320: =المواد!B320 -> 0 | C320: =IF($A320="","",ROUND(SUMIFS(الإدخالات!$D$2:$D$501,الإدخالات!$C$2:$C$501,$A320)+SUMIFS('تعديل الجرد'!$F$2:$F$501,'تعديل الجرد'!$C$2:$C$501,$A320)-SUMIFS('الصرف المباشر'!$D$2:$D$501,'الصرف المباشر'!$C$2:$C$501,$A320)-SUMPRODUCT((الطبخات!$B$2:$B$900=$A320)*الطبخات!$C$2:$C$900*COUNTIF('سجل الإنتاج'!$C$2:$C$501,الطبخات!$A$2:$A$900)),3)) -> 0 | D320: =IF($A320="","",ROUND(SUMIFS('الصرف المباشر'!$D$2:$D$501,'الصرف المباشر'!$C$2:$C$501,$A320)+SUMPRODUCT((الطبخات!$B$2:$B$900=$A320)*الطبخات!$C$2:$C$900*COUNTIF('سجل الإنتاج'!$C$2:$C$501,الطبخات!$A$2:$A$900)),3)) -> 0 | E320: =IF($A320="","",IF($C320<0,"❌ رصيد سالب - يحتاج مراجعة","✔ طبيعي")) -> ✔ طبيعي | F320: =IF(AND($A320<>"",$E320<>"✔ طبيعي"),SUMPRODUCT(('الرصيد الحالي'!$E$2:$E320<>"✔ طبيعي")*('الرصيد الحالي'!$E$2:$E320<>"")*('الرصيد الحالي'!$A$2:$A320<>"")),"")

Sheet سجل الحركات
A1: التاريخ | B1: نوع الحركة | C1: المرجع (طبخة/مورد/جهة/سبب) | D1: المادة | E1: الكمية (+ إدخال / - إخراج) | F1: ملاحظات | H1: ملاحظة: هذه الصفحة مضغوطة تلقائياً (بدون فراغات) وتعرض العمليات الأربع كلها - شراء، ثم صرف مباشر، ثم إنتاج، ثم تعديل جرد - كل نوع بترتيب إدخاله. للعرض حسب التاريخ فقط استخدم عامل التصفية/الفرز على عمود "التاريخ".
A2: =IFERROR(INDEX('بيانات الحركات'!A:A,MATCH(1,'بيانات الحركات'!$G:$G,0)),"") -> 46218 | B2: =IFERROR(INDEX('بيانات الحركات'!B:B,MATCH(1,'بيانات الحركات'!$G:$G,0)),"") -> شراء | C2: =IFERROR(INDEX('بيانات الحركات'!C:C,MATCH(1,'بيانات الحركات'!$G:$G,0)),"") -> امين | D2: =IFERROR(INDEX('بيانات الحركات'!D:D,MATCH(1,'بيانات الحركات'!$G:$G,0)),"") -> ملح | E2: =IF($B2="إنتاج طبخة","",IFERROR(INDEX('بيانات الحركات'!E:E,MATCH(1,'بيانات الحركات'!$G:$G,0)),"")) -> 138.04 | F2: =IFERROR(INDEX('بيانات الحركات'!F:F,MATCH(1,'بيانات الحركات'!$G:$G,0)),"") -> تنزيل البيانات لأول مرة
A3: =IFERROR(INDEX('بيانات الحركات'!A:A,MATCH(2,'بيانات الحركات'!$G:$G,0)),"") -> 46218 | B3: =IFERROR(INDEX('بيانات الحركات'!B:B,MATCH(2,'بيانات الحركات'!$G:$G,0)),"") -> شراء | C3: =IFERROR(INDEX('بيانات الحركات'!C:C,MATCH(2,'بيانات الحركات'!$G:$G,0)),"") -> امين | D3: =IFERROR(INDEX('بيانات الحركات'!D:D,MATCH(2,'بيانات الحركات'!$G:$G,0)),"") -> مقصب | E3: =IF($B3="إنتاج طبخة","",IFERROR(INDEX('بيانات الحركات'!E:E,MATCH(2,'بيانات الحركات'!$G:$G,0)),"")) -> 2 | F3: =IFERROR(INDEX('بيانات الحركات'!F:F,MATCH(2,'بيانات الحركات'!$G:$G,0)),"") -> تنزيل البيانات لأول مرة
A4: =IFERROR(INDEX('بيانات الحركات'!A:A,MATCH(3,'بيانات الحركات'!$G:$G,0)),"") -> 46218 | B4: =IFERROR(INDEX('بيانات الحركات'!B:B,MATCH(3,'بيانات الحركات'!$G:$G,0)),"") -> شراء | C4: =IFERROR(INDEX('بيانات الحركات'!C:C,MATCH(3,'بيانات الحركات'!$G:$G,0)),"") -> امين | D4: =IFERROR(INDEX('بيانات الحركات'!D:D,MATCH(3,'بيانات الحركات'!$G:$G,0)),"") -> مجمد | E4: =IF($B4="إنتاج طبخة","",IFERROR(INDEX('بيانات الحركات'!E:E,MATCH(3,'بيانات الحركات'!$G:$G,0)),"")) -> 63.5 | F4: =IFERROR(INDEX('بيانات الحركات'!F:F,MATCH(3,'بيانات الحركات'!$G:$G,0)),"") -> تنزيل البيانات لأول مرة
A5: =IFERROR(INDEX('بيانات الحركات'!A:A,MATCH(4,'بيانات الحركات'!$G:$G,0)),"") -> 46218 | B5: =IFERROR(INDEX('بيانات الحركات'!B:B,MATCH(4,'بيانات الحركات'!$G:$G,0)),"") -> شراء | C5: =IFERROR(INDEX('بيانات الحركات'!C:C,MATCH(4,'بيانات الحركات'!$G:$G,0)),"") -> امين | D5: =IFERROR(INDEX('بيانات الحركات'!D:D,MATCH(4,'بيانات الحركات'!$G:$G,0)),"") -> مانع رغوة مائي | E5: =IF($B5="إنتاج طبخة","",IFERROR(INDEX('بيانات الحركات'!E:E,MATCH(4,'بيانات الحركات'!$G:$G,0)),"")) -> 0 | F5: =IFERROR(INDEX('بيانات الحركات'!F:F,MATCH(4,'بيانات الحركات'!$G:$G,0)),"") -> تنزيل البيانات لأول مرة
A6: =IFERROR(INDEX('بيانات الحركات'!A:A,MATCH(5,'بيانات الحركات'!$G:$G,0)),"") -> 46218 | B6: =IFERROR(INDEX('بيانات الحركات'!B:B,MATCH(5,'بيانات الحركات'!$G:$G,0)),"") -> شراء | C6: =IFERROR(INDEX('بيانات الحركات'!C:C,MATCH(5,'بيانات الحركات'!$G:$G,0)),"") -> امين | D6: =IFERROR(INDEX('بيانات الحركات'!D:D,MATCH(5,'بيانات الحركات'!$G:$G,0)),"") -> مانع رغوة سيليكون | E6: =IF($B6="إنتاج طبخة","",IFERROR(INDEX('بيانات الحركات'!E:E,MATCH(5,'بيانات الحركات'!$G:$G,0)),"")) -> 0 | F6: =IFERROR(INDEX('بيانات الحركات'!F:F,MATCH(5,'بيانات الحركات'!$G:$G,0)),"") -> تنزيل البيانات لأول مرة
A7: =IFERROR(INDEX('بيانات الحركات'!A:A,MATCH(6,'بيانات الحركات'!$G:$G,0)),"") -> 46218 | B7: =IFERROR(INDEX('بيانات الحركات'!B:B,MATCH(6,'بيانات الحركات'!$G:$G,0)),"") -> شراء | C7: =IFERROR(INDEX('بيانات الحركات'!C:C,MATCH(6,'بيانات الحركات'!$G:$G,0)),"") -> امين | D7: =IFERROR(INDEX('بيانات الحركات'!D:D,MATCH(6,'بيانات الحركات'!$G:$G,0)),"") -> ماء مقطرة | E7: =IF($B7="إنتاج طبخة","",IFERROR(INDEX('بيانات الحركات'!E:E,MATCH(6,'بيانات الحركات'!$G:$G,0)),"")) -> 28622 | F7: =IFERROR(INDEX('بيانات الحركات'!F:F,MATCH(6,'بيانات الحركات'!$G:$G,0)),"") -> تنزيل البيانات لأول مرة
A8: =IFERROR(INDEX('بيانات الحركات'!A:A,MATCH(7,'بيانات الحركات'!$G:$G,0)),"") -> 46218 | B8: =IFERROR(INDEX('بيانات الحركات'!B:B,MATCH(7,'بيانات الحركات'!$G:$G,0)),"") -> شراء | C8: =IFERROR(INDEX('بيانات الحركات'!C:C,MATCH(7,'بيانات الحركات'!$G:$G,0)),"") -> امين | D8: =IFERROR(INDEX('بيانات الحركات'!D:D,MATCH(7,'بيانات الحركات'!$G:$G,0)),"") -> ماء بلسم | E8: =IF($B8="إنتاج طبخة","",IFERROR(INDEX('بيانات الحركات'!E:E,MATCH(7,'بيانات الحركات'!$G:$G,0)),"")) -> 3 | F8: =IFERROR(INDEX('بيانات الحركات'!F:F,MATCH(7,'بيانات الحركات'!$G:$G,0)),"") -> تنزيل البيانات لأول مرة
A9: =IFERROR(INDEX('بيانات الحركات'!A:A,MATCH(8,'بيانات الحركات'!$G:$G,0)),"") -> 46218 | B9: =IFERROR(INDEX('بيانات الحركات'!B:B,MATCH(8,'بيانات الحركات'!$G:$G,0)),"") -> شراء | C9: =IFERROR(INDEX('بيانات الحركات'!C:C,MATCH(8,'بيانات الحركات'!$G:$G,0)),"") -> امين | D9: =IFERROR(INDEX('بيانات الحركات'!D:D,MATCH(8,'بيانات الحركات'!$G:$G,0)),"") -> لانيت 16 ماليزي | E9: =IF($B9="إنتاج طبخة","",IFERROR(INDEX('بيانات الحركات'!E:E,MATCH(8,'بيانات الحركات'!$G:$G,0)),"")) -> 0 | F9: =IFERROR(INDEX('بيانات الحركات'!F:F,MATCH(8,'بيانات الحركات'!$G:$G,0)),"") -> تنزيل البيانات لأول مرة
A10: =IFERROR(INDEX('بيانات الحركات'!A:A,MATCH(9,'بيانات الحركات'!$G:$G,0)),"") -> 46218 | B10: =IFERROR(INDEX('بيانات الحركات'!B:B,MATCH(9,'بيانات الحركات'!$G:$G,0)),"") -> شراء | C10: =IFERROR(INDEX('بيانات الحركات'!C:C,MATCH(9,'بيانات الحركات'!$G:$G,0)),"") -> امين | D10: =IFERROR(INDEX('بيانات الحركات'!D:D,MATCH(9,'بيانات الحركات'!$G:$G,0)),"") -> كوستيك-قطرونة | E10: =IF($B10="إنتاج طبخة","",IFERROR(INDEX('بيانات الحركات'!E:E,MATCH(9,'بيانات الحركات'!$G:$G,0)),"")) -> 27.71 | F10: =IFERROR(INDEX('بيانات الحركات'!F:F,MATCH(9,'بيانات الحركات'!$G:$G,0)),"") -> تنزيل البيانات لأول مرة
A11: =IFERROR(INDEX('بيانات الحركات'!A:A,MATCH(10,'بيانات الحركات'!$G:$G,0)),"") -> 46218 | B11: =IFERROR(INDEX('بيانات الحركات'!B:B,MATCH(10,'بيانات الحركات'!$G:$G,0)),"") -> شراء | C11: =IFERROR(INDEX('بيانات الحركات'!C:C,MATCH(10,'بيانات الحركات'!$G:$G,0)),"") -> امين | D11: =IFERROR(INDEX('بيانات الحركات'!D:D,MATCH(10,'بيانات الحركات'!$G:$G,0)),"") -> كمبرلان | E11: =IF($B11="إنتاج طبخة","",IFERROR(INDEX('بيانات الحركات'!E:E,MATCH(10,'بيانات الحركات'!$G:$G,0)),"")) -> 0 | F11: =IFERROR(INDEX('بيانات الحركات'!F:F,MATCH(10,'بيانات الحركات'!$G:$G,0)),"") -> تنزيل البيانات لأول مرة
A12: =IFERROR(INDEX('بيانات الحركات'!A:A,MATCH(11,'بيانات الحركات'!$G:$G,0)),"") -> 46218 | B12: =IFERROR(INDEX('بيانات الحركات'!B:B,MATCH(11,'بيانات الحركات'!$G:$G,0)),"") -> شراء | C12: =IFERROR(INDEX('بيانات الحركات'!C:C,MATCH(11,'بيانات الحركات'!$G:$G,0)),"") -> امين | D12: =IFERROR(INDEX('بيانات الحركات'!D:D,MATCH(11,'بيانات الحركات'!$G:$G,0)),"") -> كليمازول | E12: =IF($B12="إنتاج طبخة","",IFERROR(INDEX('بيانات الحركات'!E:E,MATCH(11,'بيانات الحركات'!$G:$G,0)),"")) -> 0 | F12: =IFERROR(INDEX('بيانات الحركات'!F:F,MATCH(11,'بيانات الحركات'!$G:$G,0)),"") -> تنزيل البيانات لأول مرة
A13: =IFERROR(INDEX('بيانات الحركات'!A:A,MATCH(12,'بيانات الحركات'!$G:$G,0)),"") -> 46218 | B13: =IFERROR(INDEX('بيانات الحركات'!B:B,MATCH(12,'بيانات الحركات'!$G:$G,0)),"") -> شراء | C13: =IFERROR(INDEX('بيانات الحركات'!C:C,MATCH(12,'بيانات الحركات'!$G:$G,0)),"") -> امين | D13: =IFERROR(INDEX('بيانات الحركات'!D:D,MATCH(12,'بيانات الحركات'!$G:$G,0)),"") -> كلور خام | E13: =IF($B13="إنتاج طبخة","",IFERROR(INDEX('بيانات الحركات'!E:E,MATCH(12,'بيانات الحركات'!$G:$G,0)),"")) -> 272 | F13: =IFERROR(INDEX('بيانات الحركات'!F:F,MATCH(12,'بيانات الحركات'!$G:$G,0)),"") -> تنزيل البيانات لأول مرة
