Workbook

Sheet لوحة التحكم
A1: لوحة التحكم — الأرباح الحقيقية بالدولار 2026
B2: الخلايا الصفراء بخط أزرق = خلايا إدخال، وكل ما عداها معادلات. كل المبالغ في التقارير بالدولار الأمريكي.
B4: الإعدادات | J4: رقم الشهر المعروض | K4: =IF($C$5="آخر شهر متوفر",MAX(1,MAX(المقارنة!$B$40:$M$40)),MATCH($C$5,المقارنة!$B$5:$M$5,0)) -> 9
B5: الشهر المعروض في الملخص | C5: آخر شهر متوفر | D5: اتركه «آخر شهر متوفر» ليتبع آخر شهر أُدخلت مبيعاته، أو اختر شهرًا بعينه
B6: أول شهر لبيانات المستودع (رقم) | C6: 6 | D6: 6 = حزيران؛ قبله لا تُطلب بيانات مستودع ولا يُحسب ربح حقيقي
B8: سعر الصرف الشهري (ل.س مقابل 1$) وحالة كل شهر — أدخل سعر كل شهر
B9: الشهر | C9: سعر الصرف | D9: حالة الشهر | E9: تنبيهات | F9: المبيعات $ | G9: الربح الحقيقي $ | H9: هامش الربح
B10: يناير | C10: 11500 | D10: ='01-يناير'!$H$6 -> ℹ ربح تقديري فقط | E10: =IF('01-يناير'!$H$13>0,'01-يناير'!$H$13,"") | F10: =المقارنة!B11 -> 10341.391 | G10: =المقارنة!B19 | H10: =المقارنة!B20
B11: فبراير | C11: 12000 | D11: ='02-فبراير'!$H$6 -> ℹ ربح تقديري فقط | E11: =IF('02-فبراير'!$H$13>0,'02-فبراير'!$H$13,"") | F11: =المقارنة!C11 -> 7321.5833 | G11: =المقارنة!C19 | H11: =المقارنة!C20
B12: مارس | C12: 12000 | D12: ='03-مارس'!$H$6 -> ℹ ربح تقديري فقط | E12: =IF('03-مارس'!$H$13>0,'03-مارس'!$H$13,"") | F12: =المقارنة!D11 -> 8786.9167 | G12: =المقارنة!D19 | H12: =المقارنة!D20
B13: أبريل | C13: 12500 | D13: ='04-أبريل'!$H$6 -> ℹ ربح تقديري فقط | E13: =IF('04-أبريل'!$H$13>0,'04-أبريل'!$H$13,"") | F13: =المقارنة!E11 -> 13335.28 | G13: =المقارنة!E19 | H13: =المقارنة!E20
B14: مايو | C14: 12500 | D14: ='05-مايو'!$H$6 -> ℹ ربح تقديري فقط | E14: =IF('05-مايو'!$H$13>0,'05-مايو'!$H$13,"") | F14: =المقارنة!F11 -> 13066.72 | G14: =المقارنة!F19 | H14: =المقارنة!F20
B15: يونيو | C15: 13200 | D15: ='06-يونيو'!$H$6 -> ℹ ربح تقديري فقط | E15: =IF('06-يونيو'!$H$13>0,'06-يونيو'!$H$13,"") | F15: =المقارنة!G11 -> 14956.364 | G15: =المقارنة!G19 | H15: =المقارنة!G20
B16: يوليو | C16: 13300 | D16: ='07-يوليو'!$H$6 -> ✅ جاهز — ربح حقيقي | E16: =IF('07-يوليو'!$H$13>0,'07-يوليو'!$H$13,"") | F16: =المقارنة!H11 -> 14364.06 | G16: =المقارنة!H19 -> 5462.4143 | H16: =المقارنة!H20 -> 0.38028345
B17: أغسطس | C17: 13200 | D17: ='08-أغسطس'!$H$6 -> ✅ جاهز — ربح حقيقي | E17: =IF('08-أغسطس'!$H$13>0,'08-أغسطس'!$H$13,"") | F17: =المقارنة!I11 -> 17236.97 | G17: =المقارنة!I19 -> 8239.9551 | H17: =المقارنة!I20 -> 0.47803966
B18: سبتمبر | C18: 13800 | D18: ='09-سبتمبر'!$H$6 -> ✅ جاهز — ربح حقيقي | E18: =IF('09-سبتمبر'!$H$13>0,'09-سبتمبر'!$H$13,"") | F18: =المقارنة!J11 -> 12412.101 | G18: =المقارنة!J19 -> 1709.2248 | H18: =المقارنة!J20 -> 0.13770632
B19: أكتوبر | C19: 14200 | D19: ='10-أكتوبر'!$H$6 -> لا بيانات | E19: =IF('10-أكتوبر'!$H$13>0,'10-أكتوبر'!$H$13,"") | F19: =المقارنة!K11 | G19: =المقارنة!K19 | H19: =المقارنة!K20
B20: نوفمبر | D20: ='11-نوفمبر'!$H$6 -> لا بيانات | E20: =IF('11-نوفمبر'!$H$13>0,'11-نوفمبر'!$H$13,"") | F20: =المقارنة!L11 | G20: =المقارنة!L19 | H20: =المقارنة!L20
B21: ديسمبر | D21: ='12-ديسمبر'!$H$6 -> لا بيانات | E21: =IF('12-ديسمبر'!$H$13>0,'12-ديسمبر'!$H$13,"") | F21: =المقارنة!M11 | G21: =المقارنة!M19 | H21: =المقارنة!M20
B22: =IF(IF(N('01-يناير'!$H$13)>0," • يناير ("&'01-يناير'!$H$13&")","")&IF(N('02-فبراير'!$H$13)>0," • فبراير ("&'02-فبراير'!$H$13&")","")&IF(N('03-مارس'!$H$13)>0," • مارس ("&'03-مارس'!$H$13&")","")&IF(N('04-أبريل'!$H$13)>0," • أبريل ("&'04-أبريل'!$H$13&")","")&IF(N('05-مايو'!$H$13)>0," • مايو ("&'05-مايو'!$H$13&")","")&IF(N('06-يونيو'!$H$13)>0," • يونيو ("&'06-يونيو'!$H$13&")","")&IF(N('07-يوليو'!$H$13)>0," • يوليو ("&'07-يوليو'!$H$13&")","")&IF(N('08-أغسطس'!$H$13)>0," • أغسطس ("&'08-أغسطس'!$H$13&")","")&IF(N('09-سبتمبر'!$H$13)>0," • سبتمبر ("&'09-سبتمبر'!$H$13&")","")&IF(N('10-أكتوبر'!$H$13)>0," • أكتوبر ("&'10-أكتوبر'!$H$13&")","")&IF(N('11-نوفمبر'!$H$13)>0," • نوفمبر ("&'11-نوفمبر'!$H$13&")","")&IF(N('12-ديسمبر'!$H$13)>0," • ديسمبر ("&'12-ديسمبر'!$H$13&")","")="","✅ لا توجد تنبيهات في أي شهر","⚠ أشهر فيها تنبيهات (عددها بين القوسين):"&IF(N('01-يناير'!$H$13)>0," • يناير ("&'01-يناير'!$H$13&")","")&IF(N('02-فبراير'!$H$13)>0," • فبراير ("&'02-فبراير'!$H$13&")","")&IF(N('03-مارس'!$H$13)>0," • مارس ("&'03-مارس'!$H$13&")","")&IF(N('04-أبريل'!$H$13)>0," • أبريل ("&'04-أبريل'!$H$13&")","")&IF(N('05-مايو'!$H$13)>0," • مايو ("&'05-مايو'!$H$13&")","")&IF(N('06-يونيو'!$H$13)>0," • يونيو ("&'06-يونيو'!$H$13&")","")&IF(N('07-يوليو'!$H$13)>0," • يوليو ("&'07-يوليو'!$H$13&")","")&IF(N('08-أغسطس'!$H$13)>0," • أغسطس ("&'08-أغسطس'!$H$13&")","")&IF(N('09-سبتمبر'!$H$13)>0," • سبتمبر ("&'09-سبتمبر'!$H$13&")","")&IF(N('10-أكتوبر'!$H$13)>0," • أكتوبر ("&'10-أكتوبر'!$H$13&")","")&IF(N('11-نوفمبر'!$H$13)>0," • نوفمبر ("&'11-نوفمبر'!$H$13&")","")&IF(N('12-ديسمبر'!$H$13)>0," • ديسمبر ("&'12-ديسمبر'!$H$13&")","")&" — افتح صفحة الشهر لرؤية التفاصيل") -> ✅ لا توجد تنبيهات في أي شهر
B24: ملخص الشهر المعروض
B25: ="الشهر: "&INDEX(المقارنة!$B$5:$M$5,$K$4)&" 2026 | "&INDEX(المقارنة!$B$37:$M$37,$K$4) -> الشهر: سبتمبر 2026 | ✅ جاهز — ربح حقيقي
B26: المبيعات | D26: الربح الحقيقي التشغيلي | F26: هامش الربح الحقيقي
B27: =IF(ISNUMBER(INDEX(المقارنة!$B$11:$M$11,$K$4)),INDEX(المقارنة!$B$11:$M$11,$K$4),"—") -> 12412.101 | D27: =IF(ISNUMBER(INDEX(المقارنة!$B$19:$M$19,$K$4)),INDEX(المقارنة!$B$19:$M$19,$K$4),"—") -> 1709.2248 | F27: =IF(ISNUMBER(INDEX(المقارنة!$B$20:$M$20,$K$4)),INDEX(المقارنة!$B$20:$M$20,$K$4),"—") -> 0.13770632
B28: =IF(AND($K$4>1,ISNUMBER(INDEX(المقارنة!$B$11:$M$11,$K$4)),ISNUMBER(INDEX(المقارنة!$B$11:$M$11,$K$4-1))),IF(INDEX(المقارنة!$B$11:$M$11,$K$4-1)<>0,IF(INDEX(المقارنة!$B$11:$M$11,$K$4)>=INDEX(المقارنة!$B$11:$M$11,$K$4-1),"▲ ","▼ ")&TEXT(ABS((INDEX(المقارنة!$B$11:$M$11,$K$4)-INDEX(المقارنة!$B$11:$M$11,$K$4-1))/ABS(INDEX(المقارنة!$B$11:$M$11,$K$4-1))),"0.0%")&" عن الشهر السابق","—"),"—") -> ▼ 28.0% عن الشهر السابق | D28: =IF(AND($K$4>1,ISNUMBER(INDEX(المقارنة!$B$19:$M$19,$K$4)),ISNUMBER(INDEX(المقارنة!$B$19:$M$19,$K$4-1))),IF(INDEX(المقارنة!$B$19:$M$19,$K$4-1)<>0,IF(INDEX(المقارنة!$B$19:$M$19,$K$4)>=INDEX(المقارنة!$B$19:$M$19,$K$4-1),"▲ ","▼ ")&TEXT(ABS((INDEX(المقارنة!$B$19:$M$19,$K$4)-INDEX(المقارنة!$B$19:$M$19,$K$4-1))/ABS(INDEX(المقارنة!$B$19:$M$19,$K$4-1))),"0.0%")&" عن الشهر السابق","—"),"—") -> ▼ 79.3% عن الشهر السابق | F28: =IF(AND($K$4>1,ISNUMBER(INDEX(المقارنة!$B$20:$M$20,$K$4)),ISNUMBER(INDEX(المقارنة!$B$20:$M$20,$K$4-1))),IF(INDEX(المقارنة!$B$20:$M$20,$K$4)>=INDEX(المقارنة!$B$20:$M$20,$K$4-1),"▲ ","▼ ")&TEXT(ABS(INDEX(المقارنة!$B$20:$M$20,$K$4)-INDEX(المقارنة!$B$20:$M$20,$K$4-1))*100,"0.0")&" نقطة عن الشهر السابق","—") -> ▼ 34.0 نقطة عن الشهر السابق
B30: المصاريف | D30: قيمة المخزون | F30: صافي المركز المالي
B31: =IF(ISNUMBER(INDEX(المقارنة!$B$13:$M$13,$K$4)),INDEX(المقارنة!$B$13:$M$13,$K$4),"—") -> 3175.942 | D31: =IF(ISNUMBER(INDEX(المقارنة!$B$24:$M$24,$K$4)),INDEX(المقارنة!$B$24:$M$24,$K$4),"—") -> 44900.765 | F31: =IF(ISNUMBER(INDEX(المقارنة!$B$28:$M$28,$K$4)),INDEX(المقارنة!$B$28:$M$28,$K$4),"—") -> -42454.29
B32: =IF(AND($K$4>1,ISNUMBER(INDEX(المقارنة!$B$13:$M$13,$K$4)),ISNUMBER(INDEX(المقارنة!$B$13:$M$13,$K$4-1))),IF(INDEX(المقارنة!$B$13:$M$13,$K$4-1)<>0,IF(INDEX(المقارنة!$B$13:$M$13,$K$4)>=INDEX(المقارنة!$B$13:$M$13,$K$4-1),"▲ ","▼ ")&TEXT(ABS((INDEX(المقارنة!$B$13:$M$13,$K$4)-INDEX(المقارنة!$B$13:$M$13,$K$4-1))/ABS(INDEX(المقارنة!$B$13:$M$13,$K$4-1))),"0.0%")&" عن الشهر السابق","—"),"—") -> ▲ 30.2% عن الشهر السابق | D32: =IF(AND($K$4>1,ISNUMBER(INDEX(المقارنة!$B$24:$M$24,$K$4)),ISNUMBER(INDEX(المقارنة!$B$24:$M$24,$K$4-1))),IF(INDEX(المقارنة!$B$24:$M$24,$K$4-1)<>0,IF(INDEX(المقارنة!$B$24:$M$24,$K$4)>=INDEX(المقارنة!$B$24:$M$24,$K$4-1),"▲ ","▼ ")&TEXT(ABS((INDEX(المقارنة!$B$24:$M$24,$K$4)-INDEX(المقارنة!$B$24:$M$24,$K$4-1))/ABS(INDEX(المقارنة!$B$24:$M$24,$K$4-1))),"0.0%")&" عن الشهر السابق","—"),"—") -> ▼ 6.3% عن الشهر السابق | F32: =IF(AND($K$4>1,ISNUMBER(INDEX(المقارنة!$B$28:$M$28,$K$4)),ISNUMBER(INDEX(المقارنة!$B$28:$M$28,$K$4-1))),IF(INDEX(المقارنة!$B$28:$M$28,$K$4-1)<>0,IF(INDEX(المقارنة!$B$28:$M$28,$K$4)>=INDEX(المقارنة!$B$28:$M$28,$K$4-1),"▲ ","▼ ")&TEXT(ABS((INDEX(المقارنة!$B$28:$M$28,$K$4)-INDEX(المقارنة!$B$28:$M$28,$K$4-1))/ABS(INDEX(المقارنة!$B$28:$M$28,$K$4-1))),"0.0%")&" عن الشهر السابق","—"),"—") -> ▼ 293.3% عن الشهر السابق
B34: الربح الحقيقي التشغيلي = المبيعات − تكلفة المبيعات − المصاريف، وتكلفة المبيعات = مخزون أول الشهر + المشتريات − مخزون آخر الشهر (من ملف المستودع). أثر تغير الصرف على مخزون الليرة يظهر في سطر مستقل داخل صفحة كل شهر وفي المقارنة.

Sheet 01-يناير
A1: تقرير شهر يناير 2026 — الأرباح الحقيقية بالدولار الأمريكي | G1: خلايا مساعدة (خارج الطباعة)
A2: سعر الصرف المعتمد (ل.س مقابل 1$) — من لوحة التحكم | B2: =IF(ISNUMBER('لوحة التحكم'!$C$10),'لوحة التحكم'!$C$10,0) -> 11500 | C2: حالة الشهر | D2: =$H$6 -> ℹ ربح تقديري فقط | G2: سعر صرف الشهر السابق | H2: =0 -> 0
A3: =IF($H$5=0,"لا توجد بيانات لهذا الشهر بعد — أدخل المدخلات أدناه",IF($H$13>0,(IF($H$7=1,"⚠ سعر الصرف غير مُدخل في لوحة التحكم. ","")&IF($H$8=1,"⚠ أكمل المبيعات والمشتريات والمصاريف. ","")&IF($H$9=1,"⚠ الصق بيانات المستودع في فقرة «بيانات المستودع». ","")&IF($H$10=1,"⚠ الصف الملصوق يخص شهرًا آخر. ","")&IF($H$11=1,"⚠ سعر صرف المستودع ("&$B$21&") يختلف عن سعر لوحة التحكم ("&$B$2&"). ","")&IF($H$12=1,"⚠ ملف المستودع فيه أصناف بها أخطاء (العدد: "&$E$21&") — صحّحها ثم أعد التصدير.","")),IF($H$3=1,"✅ البيانات مكتملة — الربح الحقيقي محسوب","ℹ الربح الحقيقي غير متاح (يلزم مخزون هذا الشهر والشهر السابق وسعر صرف الشهرين) — المعروض ربح تقديري فقط"))) -> ℹ الربح الحقيقي غير متاح (يلزم مخزون هذا الشهر والشهر السابق وسعر صرف الشهرين) — المعروض ربح تقديري فقط | G3: الربح الحقيقي جاهز؟ (1/0) | H3: =0 -> 0
A4: مدخلات الشهر (أدخل بالليرة السورية من برنامج المحاسبة) — الخلايا الصفراء | G4: أثر الصرف على مخزون الليرة ($) | H4: =0 -> 0
A5: البيان | B5: المبلغ (ل.س) | C5: المعادل ($) | D5: ملاحظة | G5: فيه بيانات؟ (1/0) | H5: =IF(COUNTA(B6:B8,B13:C15,A21:E21)>0,1,0) -> 1
A6: المبيعات | B6: 118926000 | C6: =IF(AND(ISNUMBER(B6),$B$2>0),B6/$B$2,"") -> 10341.391 | D6: إجمالي مبيعات الشهر | G6: حالة الشهر | H6: =IF(H5=0,"لا بيانات",IF(H3=1,IF(H13=0,"✅ جاهز — ربح حقيقي","⚠ ربح حقيقي مع تنبيهات"),IF(H13>0,"⚠ تنبيهات — راجع الصفحة",IF(COUNT(B6:B8)=3,"ℹ ربح تقديري فقط","⚠ بيانات ناقصة")))) -> ℹ ربح تقديري فقط
A7: المشتريات | B7: 74709000 | C7: =IF(AND(ISNUMBER(B7),$B$2>0),B7/$B$2,"") -> 6496.4348 | D7: مشتريات الشهر (مواد وبضاعة) | G7: تنبيه: سعر الصرف ناقص | H7: =IF(AND(H5=1,$B$2<=0),1,0) -> 0
A8: المصاريف | B8: 38000000 | C8: =IF(AND(ISNUMBER(B8),$B$2>0),B8/$B$2,"") -> 3304.3478 | D8: مصاريف التشغيل والرواتب... | G8: تنبيه: مدخلات ناقصة | H8: =IF(AND(H5=1,COUNT(B6:B8)<3),1,0) -> 0
A9: الربح التقديري (مبيعات − مشتريات − مصاريف) | B9: =IF(COUNT(B6:B8)=3,B6-B7-B8,"") -> 6217000 | C9: =IF(AND(ISNUMBER(B9),$B$2>0),B9/$B$2,"") -> 540.6087 | D9: للمرجع فقط — لا يأخذ المخزون بالحسبان | G9: تنبيه: بيانات المستودع ناقصة | H9: =IF(AND(H5=1,H15>=H14,NOT(AND(ISNUMBER(C21),ISNUMBER(D21)))),1,0) -> 0
G10: تنبيه: صف شهر آخر | H10: =IF(AND(ISNUMBER(A21),A21<>H15),1,0) -> 0
A11: الصندوق والديون بالعملتين | G11: تنبيه: سعر صرف مختلف | H11: =IF(AND(ISNUMBER(B21),$B$2>0,ABS(B21-$B$2)>0.5),1,0) -> 0
A12: البيان | B12: ليرة سورية | C12: دولار أمريكي | D12: الإجمالي ($) | G12: تنبيه: أخطاء بالمستودع | H12: =IF(N(E21)>0,1,0) -> 0
A13: الصندوق (كاش فعلي) | B13: 1000000 | C13: 0 | D13: =IF(AND(ISNUMBER(B13),ISNUMBER(C13),$B$2>0),B13/$B$2+C13,"") -> 86.956522 | G13: مجموع التنبيهات | H13: =SUM(H7:H12) -> 0
A14: ديون لنا (مستحقة لنا) | B14: 70767000 | C14: 6080 | D14: =IF(AND(ISNUMBER(B14),ISNUMBER(C14),$B$2>0),B14/$B$2+C14,"") -> 12233.652 | G14: أول شهر لبيانات المستودع | H14: ='لوحة التحكم'!$C$6 -> 6
A15: ديون علينا | B15: 4123000 | C15: 14534 | D15: =IF(AND(ISNUMBER(B15),ISNUMBER(C15),$B$2>0),B15/$B$2+C15,"") -> 14892.522 | G15: رقم هذا الشهر | H15: 1
A16: صافي الدين (لنا − علينا) | B16: =IF(AND(ISNUMBER(B14),ISNUMBER(B15)),B14-B15,"") -> 66644000 | C16: =IF(AND(ISNUMBER(C14),ISNUMBER(C15)),C14-C15,"") -> -8454 | D16: =IF(AND(ISNUMBER(D14),ISNUMBER(D15)),D14-D15,"") -> -2658.8696
A17: صافي المركز المالي (صندوق + ديون لنا − ديون علينا) | D17: =IF(AND(ISNUMBER(D13),ISNUMBER(D16)),D13+D16,"") -> -2571.913
A19: بيانات المستودع — الصق صفًّا واحدًا كـ «قيم» من ورقة «تصدير للتقارير» في ملف المستودع
A20: رقم الشهر | B20: سعر صرف المستودع | C20: مخزون مسعّر بالدولار ($) | D20: مخزون مسعّر بالليرة (ل.س) | E20: أصناف بها أخطاء
A22: قيمة المخزون الكلية بالدولار (بسعر الشراء وسعر صرف الشهر) | C22: =IF(AND(ISNUMBER(C21),ISNUMBER(D21),$B$2>0),C21+D21/$B$2,"") | D22: المسعّر بالدولار + (المسعّر بالليرة ÷ سعر الصرف)
A24: التقرير الشهري بالدولار الأمريكي
A25: البيان | B25: هذا الشهر ($) | C25: الشهر السابق ($) | D25: التغير ($) | E25: التغير %
A26: المبيعات | B26: =IF(ISNUMBER(C6),C6,"") -> 10341.391 | C26: ="" | D26: =IF(AND(ISNUMBER(B26),ISNUMBER(C26)),B26-C26,"") | E26: =IF(AND(ISNUMBER(B26),ISNUMBER(C26)),IF(C26<>0,(B26-C26)/ABS(C26),""),"")
A27: مخزون أول الشهر (= مخزون آخر الشهر السابق) | B27: ="" | C27: ="" | D27: =IF(AND(ISNUMBER(B27),ISNUMBER(C27)),B27-C27,"") | E27: =IF(AND(ISNUMBER(B27),ISNUMBER(C27)),IF(C27<>0,(B27-C27)/ABS(C27),""),"")
A28: (+) المشتريات | B28: =IF(ISNUMBER(C7),C7,"") -> 6496.4348 | C28: ="" | D28: =IF(AND(ISNUMBER(B28),ISNUMBER(C28)),B28-C28,"") | E28: =IF(AND(ISNUMBER(B28),ISNUMBER(C28)),IF(C28<>0,(B28-C28)/ABS(C28),""),"")
A29: (−) مخزون آخر الشهر (بعد عزل أثر الصرف) | B29: =IF($H$3=1,C22-$H$4,"") | C29: ="" | D29: =IF(AND(ISNUMBER(B29),ISNUMBER(C29)),B29-C29,"") | E29: =IF(AND(ISNUMBER(B29),ISNUMBER(C29)),IF(C29<>0,(B29-C29)/ABS(C29),""),"")
A30: (=) تكلفة المبيعات | B30: =IF($H$3=1,B27+B28-B29,"") | C30: ="" | D30: =IF(AND(ISNUMBER(B30),ISNUMBER(C30)),B30-C30,"") | E30: =IF(AND(ISNUMBER(B30),ISNUMBER(C30)),IF(C30<>0,(B30-C30)/ABS(C30),""),"")
A31: مجمل الربح (المبيعات − التكلفة) | B31: =IF($H$3=1,B26-B30,"") | C31: ="" | D31: =IF(AND(ISNUMBER(B31),ISNUMBER(C31)),B31-C31,"") | E31: =IF(AND(ISNUMBER(B31),ISNUMBER(C31)),IF(C31<>0,(B31-C31)/ABS(C31),""),"")
A32: (−) المصاريف | B32: =IF(ISNUMBER(C8),C8,"") -> 3304.3478 | C32: ="" | D32: =IF(AND(ISNUMBER(B32),ISNUMBER(C32)),B32-C32,"") | E32: =IF(AND(ISNUMBER(B32),ISNUMBER(C32)),IF(C32<>0,(B32-C32)/ABS(C32),""),"")
A33: (=) الربح الحقيقي التشغيلي | B33: =IF($H$3=1,B31-B32,"") | C33: ="" | D33: =IF(AND(ISNUMBER(B33),ISNUMBER(C33)),B33-C33,"") | E33: =IF(AND(ISNUMBER(B33),ISNUMBER(C33)),IF(C33<>0,(B33-C33)/ABS(C33),""),"")
A34: هامش الربح الحقيقي % | B34: =IF(AND($H$3=1,N(B26)>0),B33/B26,"") | C34: ="" | D34: =IF(AND(ISNUMBER(B34),ISNUMBER(C34)),B34-C34,"")
A35: أثر تغير الصرف على مخزون الليرة | B35: =IF($H$3=1,$H$4,"") | C35: ="" | D35: =IF(AND(ISNUMBER(B35),ISNUMBER(C35)),B35-C35,"") | E35: =IF(AND(ISNUMBER(B35),ISNUMBER(C35)),IF(C35<>0,(B35-C35)/ABS(C35),""),"")
A36: صافي الربح بعد أثر الصرف | B36: =IF($H$3=1,B33+B35,"") | C36: ="" | D36: =IF(AND(ISNUMBER(B36),ISNUMBER(C36)),B36-C36,"") | E36: =IF(AND(ISNUMBER(B36),ISNUMBER(C36)),IF(C36<>0,(B36-C36)/ABS(C36),""),"")
A37: للمرجع: الربح التقديري (مبيعات − مشتريات − مصاريف) | B37: =IF(ISNUMBER(C9),C9,"") -> 540.6087 | C37: ="" | D37: =IF(AND(ISNUMBER(B37),ISNUMBER(C37)),B37-C37,"") | E37: =IF(AND(ISNUMBER(B37),ISNUMBER(C37)),IF(C37<>0,(B37-C37)/ABS(C37),""),"")
A39: مؤشرات إضافية
A40: المؤشر | B40: هذا الشهر | C40: الشهر السابق | D40: التغير | E40: التغير %
A41: نسبة المصاريف من المبيعات % | B41: =IF(AND(ISNUMBER(B32),N(B26)>0),B32/B26,"") -> 0.31952643 | C41: ="" | D41: =IF(AND(ISNUMBER(B41),ISNUMBER(C41)),B41-C41,"")
A42: نسبة تكلفة المبيعات من المبيعات % | B42: =IF(AND(ISNUMBER(B30),N(B26)>0),B30/B26,"") | C42: ="" | D42: =IF(AND(ISNUMBER(B42),ISNUMBER(C42)),B42-C42,"")
A43: قيمة المخزون الكلية ($) | B43: =IF(ISNUMBER(C22),C22,"") | C43: ="" | D43: =IF(AND(ISNUMBER(B43),ISNUMBER(C43)),B43-C43,"") | E43: =IF(AND(ISNUMBER(B43),ISNUMBER(C43)),IF(C43<>0,(B43-C43)/ABS(C43),""),"")
A44: نسبة المخزون المسعّر بالليرة % | B44: =IF(AND(ISNUMBER(C22),$B$2>0),IF(C22>0,(D21/$B$2)/C22,""),"") | C44: ="" | D44: =IF(AND(ISNUMBER(B44),ISNUMBER(C44)),B44-C44,"")
...

Sheet 02-فبراير
A1: تقرير شهر فبراير 2026 — الأرباح الحقيقية بالدولار الأمريكي | G1: خلايا مساعدة (خارج الطباعة)
A2: سعر الصرف المعتمد (ل.س مقابل 1$) — من لوحة التحكم | B2: =IF(ISNUMBER('لوحة التحكم'!$C$11),'لوحة التحكم'!$C$11,0) -> 12000 | C2: حالة الشهر | D2: =$H$6 -> ℹ ربح تقديري فقط | G2: سعر صرف الشهر السابق | H2: ='01-يناير'!$B$2 -> 11500
A3: =IF($H$5=0,"لا توجد بيانات لهذا الشهر بعد — أدخل المدخلات أدناه",IF($H$13>0,(IF($H$7=1,"⚠ سعر الصرف غير مُدخل في لوحة التحكم. ","")&IF($H$8=1,"⚠ أكمل المبيعات والمشتريات والمصاريف. ","")&IF($H$9=1,"⚠ الصق بيانات المستودع في فقرة «بيانات المستودع». ","")&IF($H$10=1,"⚠ الصف الملصوق يخص شهرًا آخر. ","")&IF($H$11=1,"⚠ سعر صرف المستودع ("&$B$21&") يختلف عن سعر لوحة التحكم ("&$B$2&"). ","")&IF($H$12=1,"⚠ ملف المستودع فيه أصناف بها أخطاء (العدد: "&$E$21&") — صحّحها ثم أعد التصدير.","")),IF($H$3=1,"✅ البيانات مكتملة — الربح الحقيقي محسوب","ℹ الربح الحقيقي غير متاح (يلزم مخزون هذا الشهر والشهر السابق وسعر صرف الشهرين) — المعروض ربح تقديري فقط"))) -> ℹ الربح الحقيقي غير متاح (يلزم مخزون هذا الشهر والشهر السابق وسعر صرف الشهرين) — المعروض ربح تقديري فقط | G3: الربح الحقيقي جاهز؟ (1/0) | H3: =IF(AND($B$2>0,H2>0,COUNT(B6:B8)=3,ISNUMBER(C22),ISNUMBER('01-يناير'!$C$22),ISNUMBER('01-يناير'!$D$21)),1,0) -> 0
A4: مدخلات الشهر (أدخل بالليرة السورية من برنامج المحاسبة) — الخلايا الصفراء | G4: أثر الصرف على مخزون الليرة ($) | H4: =IF(H3=1,'01-يناير'!$D$21*(1/$B$2-1/H2),0) -> 0
A5: البيان | B5: المبلغ (ل.س) | C5: المعادل ($) | D5: ملاحظة | G5: فيه بيانات؟ (1/0) | H5: =IF(COUNTA(B6:B8,B13:C15,A21:E21)>0,1,0) -> 1
A6: المبيعات | B6: 87859000 | C6: =IF(AND(ISNUMBER(B6),$B$2>0),B6/$B$2,"") -> 7321.5833 | D6: إجمالي مبيعات الشهر | G6: حالة الشهر | H6: =IF(H5=0,"لا بيانات",IF(H3=1,IF(H13=0,"✅ جاهز — ربح حقيقي","⚠ ربح حقيقي مع تنبيهات"),IF(H13>0,"⚠ تنبيهات — راجع الصفحة",IF(COUNT(B6:B8)=3,"ℹ ربح تقديري فقط","⚠ بيانات ناقصة")))) -> ℹ ربح تقديري فقط
A7: المشتريات | B7: 41296000 | C7: =IF(AND(ISNUMBER(B7),$B$2>0),B7/$B$2,"") -> 3441.3333 | D7: مشتريات الشهر (مواد وبضاعة) | G7: تنبيه: سعر الصرف ناقص | H7: =IF(AND(H5=1,$B$2<=0),1,0) -> 0
A8: المصاريف | B8: 36215000 | C8: =IF(AND(ISNUMBER(B8),$B$2>0),B8/$B$2,"") -> 3017.9167 | D8: مصاريف التشغيل والرواتب... | G8: تنبيه: مدخلات ناقصة | H8: =IF(AND(H5=1,COUNT(B6:B8)<3),1,0) -> 0
A9: الربح التقديري (مبيعات − مشتريات − مصاريف) | B9: =IF(COUNT(B6:B8)=3,B6-B7-B8,"") -> 10348000 | C9: =IF(AND(ISNUMBER(B9),$B$2>0),B9/$B$2,"") -> 862.33333 | D9: للمرجع فقط — لا يأخذ المخزون بالحسبان | G9: تنبيه: بيانات المستودع ناقصة | H9: =IF(AND(H5=1,H15>=H14,NOT(AND(ISNUMBER(C21),ISNUMBER(D21)))),1,0) -> 0
G10: تنبيه: صف شهر آخر | H10: =IF(AND(ISNUMBER(A21),A21<>H15),1,0) -> 0
A11: الصندوق والديون بالعملتين | G11: تنبيه: سعر صرف مختلف | H11: =IF(AND(ISNUMBER(B21),$B$2>0,ABS(B21-$B$2)>0.5),1,0) -> 0
A12: البيان | B12: ليرة سورية | C12: دولار أمريكي | D12: الإجمالي ($) | G12: تنبيه: أخطاء بالمستودع | H12: =IF(N(E21)>0,1,0) -> 0
A13: الصندوق (كاش فعلي) | B13: 2489000 | C13: 325 | D13: =IF(AND(ISNUMBER(B13),ISNUMBER(C13),$B$2>0),B13/$B$2+C13,"") -> 532.41667 | G13: مجموع التنبيهات | H13: =SUM(H7:H12) -> 0
A14: ديون لنا (مستحقة لنا) | B14: 58684000 | C14: 5052 | D14: =IF(AND(ISNUMBER(B14),ISNUMBER(C14),$B$2>0),B14/$B$2+C14,"") -> 9942.3333 | G14: أول شهر لبيانات المستودع | H14: ='لوحة التحكم'!$C$6 -> 6
A15: ديون علينا | B15: 3838000 | C15: 12974 | D15: =IF(AND(ISNUMBER(B15),ISNUMBER(C15),$B$2>0),B15/$B$2+C15,"") -> 13293.833 | G15: رقم هذا الشهر | H15: 2
A16: صافي الدين (لنا − علينا) | B16: =IF(AND(ISNUMBER(B14),ISNUMBER(B15)),B14-B15,"") -> 54846000 | C16: =IF(AND(ISNUMBER(C14),ISNUMBER(C15)),C14-C15,"") -> -7922 | D16: =IF(AND(ISNUMBER(D14),ISNUMBER(D15)),D14-D15,"") -> -3351.5
A17: صافي المركز المالي (صندوق + ديون لنا − ديون علينا) | D17: =IF(AND(ISNUMBER(D13),ISNUMBER(D16)),D13+D16,"") -> -2819.0833
A19: بيانات المستودع — الصق صفًّا واحدًا كـ «قيم» من ورقة «تصدير للتقارير» في ملف المستودع
A20: رقم الشهر | B20: سعر صرف المستودع | C20: مخزون مسعّر بالدولار ($) | D20: مخزون مسعّر بالليرة (ل.س) | E20: أصناف بها أخطاء
A22: قيمة المخزون الكلية بالدولار (بسعر الشراء وسعر صرف الشهر) | C22: =IF(AND(ISNUMBER(C21),ISNUMBER(D21),$B$2>0),C21+D21/$B$2,"") | D22: المسعّر بالدولار + (المسعّر بالليرة ÷ سعر الصرف)
A24: التقرير الشهري بالدولار الأمريكي
A25: البيان | B25: هذا الشهر ($) | C25: الشهر السابق ($) | D25: التغير ($) | E25: التغير %
A26: المبيعات | B26: =IF(ISNUMBER(C6),C6,"") -> 7321.5833 | C26: =IF('01-يناير'!$B$26="","",'01-يناير'!$B$26) -> 10341.391 | D26: =IF(AND(ISNUMBER(B26),ISNUMBER(C26)),B26-C26,"") -> -3019.808 | E26: =IF(AND(ISNUMBER(B26),ISNUMBER(C26)),IF(C26<>0,(B26-C26)/ABS(C26),""),"") -> -0.29201177
A27: مخزون أول الشهر (= مخزون آخر الشهر السابق) | B27: =IF($H$3=1,'01-يناير'!$C$22,"") | C27: =IF('01-يناير'!$B$27="","",'01-يناير'!$B$27) | D27: =IF(AND(ISNUMBER(B27),ISNUMBER(C27)),B27-C27,"") | E27: =IF(AND(ISNUMBER(B27),ISNUMBER(C27)),IF(C27<>0,(B27-C27)/ABS(C27),""),"")
A28: (+) المشتريات | B28: =IF(ISNUMBER(C7),C7,"") -> 3441.3333 | C28: =IF('01-يناير'!$B$28="","",'01-يناير'!$B$28) -> 6496.4348 | D28: =IF(AND(ISNUMBER(B28),ISNUMBER(C28)),B28-C28,"") -> -3055.1014 | E28: =IF(AND(ISNUMBER(B28),ISNUMBER(C28)),IF(C28<>0,(B28-C28)/ABS(C28),""),"") -> -0.47027355
A29: (−) مخزون آخر الشهر (بعد عزل أثر الصرف) | B29: =IF($H$3=1,C22-$H$4,"") | C29: =IF('01-يناير'!$B$29="","",'01-يناير'!$B$29) | D29: =IF(AND(ISNUMBER(B29),ISNUMBER(C29)),B29-C29,"") | E29: =IF(AND(ISNUMBER(B29),ISNUMBER(C29)),IF(C29<>0,(B29-C29)/ABS(C29),""),"")
A30: (=) تكلفة المبيعات | B30: =IF($H$3=1,B27+B28-B29,"") | C30: =IF('01-يناير'!$B$30="","",'01-يناير'!$B$30) | D30: =IF(AND(ISNUMBER(B30),ISNUMBER(C30)),B30-C30,"") | E30: =IF(AND(ISNUMBER(B30),ISNUMBER(C30)),IF(C30<>0,(B30-C30)/ABS(C30),""),"")
A31: مجمل الربح (المبيعات − التكلفة) | B31: =IF($H$3=1,B26-B30,"") | C31: =IF('01-يناير'!$B$31="","",'01-يناير'!$B$31) | D31: =IF(AND(ISNUMBER(B31),ISNUMBER(C31)),B31-C31,"") | E31: =IF(AND(ISNUMBER(B31),ISNUMBER(C31)),IF(C31<>0,(B31-C31)/ABS(C31),""),"")
A32: (−) المصاريف | B32: =IF(ISNUMBER(C8),C8,"") -> 3017.9167 | C32: =IF('01-يناير'!$B$32="","",'01-يناير'!$B$32) -> 3304.3478 | D32: =IF(AND(ISNUMBER(B32),ISNUMBER(C32)),B32-C32,"") -> -286.43116 | E32: =IF(AND(ISNUMBER(B32),ISNUMBER(C32)),IF(C32<>0,(B32-C32)/ABS(C32),""),"") -> -0.086683114
A33: (=) الربح الحقيقي التشغيلي | B33: =IF($H$3=1,B31-B32,"") | C33: =IF('01-يناير'!$B$33="","",'01-يناير'!$B$33) | D33: =IF(AND(ISNUMBER(B33),ISNUMBER(C33)),B33-C33,"") | E33: =IF(AND(ISNUMBER(B33),ISNUMBER(C33)),IF(C33<>0,(B33-C33)/ABS(C33),""),"")
A34: هامش الربح الحقيقي % | B34: =IF(AND($H$3=1,N(B26)>0),B33/B26,"") | C34: =IF('01-يناير'!$B$34="","",'01-يناير'!$B$34) | D34: =IF(AND(ISNUMBER(B34),ISNUMBER(C34)),B34-C34,"")
A35: أثر تغير الصرف على مخزون الليرة | B35: =IF($H$3=1,$H$4,"") | C35: =IF('01-يناير'!$B$35="","",'01-يناير'!$B$35) | D35: =IF(AND(ISNUMBER(B35),ISNUMBER(C35)),B35-C35,"") | E35: =IF(AND(ISNUMBER(B35),ISNUMBER(C35)),IF(C35<>0,(B35-C35)/ABS(C35),""),"")
A36: صافي الربح بعد أثر الصرف | B36: =IF($H$3=1,B33+B35,"") | C36: =IF('01-يناير'!$B$36="","",'01-يناير'!$B$36) | D36: =IF(AND(ISNUMBER(B36),ISNUMBER(C36)),B36-C36,"") | E36: =IF(AND(ISNUMBER(B36),ISNUMBER(C36)),IF(C36<>0,(B36-C36)/ABS(C36),""),"")
A37: للمرجع: الربح التقديري (مبيعات − مشتريات − مصاريف) | B37: =IF(ISNUMBER(C9),C9,"") -> 862.33333 | C37: =IF('01-يناير'!$B$37="","",'01-يناير'!$B$37) -> 540.6087 | D37: =IF(AND(ISNUMBER(B37),ISNUMBER(C37)),B37-C37,"") -> 321.72464 | E37: =IF(AND(ISNUMBER(B37),ISNUMBER(C37)),IF(C37<>0,(B37-C37)/ABS(C37),""),"") -> 0.59511554
A39: مؤشرات إضافية
A40: المؤشر | B40: هذا الشهر | C40: الشهر السابق | D40: التغير | E40: التغير %
A41: نسبة المصاريف من المبيعات % | B41: =IF(AND(ISNUMBER(B32),N(B26)>0),B32/B26,"") -> 0.41219454 | C41: =IF('01-يناير'!$B$41="","",'01-يناير'!$B$41) -> 0.31952643 | D41: =IF(AND(ISNUMBER(B41),ISNUMBER(C41)),B41-C41,"") -> 0.092668111
A42: نسبة تكلفة المبيعات من المبيعات % | B42: =IF(AND(ISNUMBER(B30),N(B26)>0),B30/B26,"") | C42: =IF('01-يناير'!$B$42="","",'01-يناير'!$B$42) | D42: =IF(AND(ISNUMBER(B42),ISNUMBER(C42)),B42-C42,"")
A43: قيمة المخزون الكلية ($) | B43: =IF(ISNUMBER(C22),C22,"") | C43: =IF('01-يناير'!$B$43="","",'01-يناير'!$B$43) | D43: =IF(AND(ISNUMBER(B43),ISNUMBER(C43)),B43-C43,"") | E43: =IF(AND(ISNUMBER(B43),ISNUMBER(C43)),IF(C43<>0,(B43-C43)/ABS(C43),""),"")
A44: نسبة المخزون المسعّر بالليرة % | B44: =IF(AND(ISNUMBER(C22),$B$2>0),IF(C22>0,(D21/$B$2)/C22,""),"") | C44: =IF('01-يناير'!$B$44="","",'01-يناير'!$B$44) | D44: =IF(AND(ISNUMBER(B44),ISNUMBER(C44)),B44-C44,"")
...

Sheet 03-مارس
A1: تقرير شهر مارس 2026 — الأرباح الحقيقية بالدولار الأمريكي | G1: خلايا مساعدة (خارج الطباعة)
A2: سعر الصرف المعتمد (ل.س مقابل 1$) — من لوحة التحكم | B2: =IF(ISNUMBER('لوحة التحكم'!$C$12),'لوحة التحكم'!$C$12,0) -> 12000 | C2: حالة الشهر | D2: =$H$6 -> ℹ ربح تقديري فقط | G2: سعر صرف الشهر السابق | H2: ='02-فبراير'!$B$2 -> 12000
A3: =IF($H$5=0,"لا توجد بيانات لهذا الشهر بعد — أدخل المدخلات أدناه",IF($H$13>0,(IF($H$7=1,"⚠ سعر الصرف غير مُدخل في لوحة التحكم. ","")&IF($H$8=1,"⚠ أكمل المبيعات والمشتريات والمصاريف. ","")&IF($H$9=1,"⚠ الصق بيانات المستودع في فقرة «بيانات المستودع». ","")&IF($H$10=1,"⚠ الصف الملصوق يخص شهرًا آخر. ","")&IF($H$11=1,"⚠ سعر صرف المستودع ("&$B$21&") يختلف عن سعر لوحة التحكم ("&$B$2&"). ","")&IF($H$12=1,"⚠ ملف المستودع فيه أصناف بها أخطاء (العدد: "&$E$21&") — صحّحها ثم أعد التصدير.","")),IF($H$3=1,"✅ البيانات مكتملة — الربح الحقيقي محسوب","ℹ الربح الحقيقي غير متاح (يلزم مخزون هذا الشهر والشهر السابق وسعر صرف الشهرين) — المعروض ربح تقديري فقط"))) -> ℹ الربح الحقيقي غير متاح (يلزم مخزون هذا الشهر والشهر السابق وسعر صرف الشهرين) — المعروض ربح تقديري فقط | G3: الربح الحقيقي جاهز؟ (1/0) | H3: =IF(AND($B$2>0,H2>0,COUNT(B6:B8)=3,ISNUMBER(C22),ISNUMBER('02-فبراير'!$C$22),ISNUMBER('02-فبراير'!$D$21)),1,0) -> 0
A4: مدخلات الشهر (أدخل بالليرة السورية من برنامج المحاسبة) — الخلايا الصفراء | G4: أثر الصرف على مخزون الليرة ($) | H4: =IF(H3=1,'02-فبراير'!$D$21*(1/$B$2-1/H2),0) -> 0
A5: البيان | B5: المبلغ (ل.س) | C5: المعادل ($) | D5: ملاحظة | G5: فيه بيانات؟ (1/0) | H5: =IF(COUNTA(B6:B8,B13:C15,A21:E21)>0,1,0) -> 1
A6: المبيعات | B6: 105443000 | C6: =IF(AND(ISNUMBER(B6),$B$2>0),B6/$B$2,"") -> 8786.9167 | D6: إجمالي مبيعات الشهر | G6: حالة الشهر | H6: =IF(H5=0,"لا بيانات",IF(H3=1,IF(H13=0,"✅ جاهز — ربح حقيقي","⚠ ربح حقيقي مع تنبيهات"),IF(H13>0,"⚠ تنبيهات — راجع الصفحة",IF(COUNT(B6:B8)=3,"ℹ ربح تقديري فقط","⚠ بيانات ناقصة")))) -> ℹ ربح تقديري فقط
A7: المشتريات | B7: 45155000 | C7: =IF(AND(ISNUMBER(B7),$B$2>0),B7/$B$2,"") -> 3762.9167 | D7: مشتريات الشهر (مواد وبضاعة) | G7: تنبيه: سعر الصرف ناقص | H7: =IF(AND(H5=1,$B$2<=0),1,0) -> 0
A8: المصاريف | B8: 37203000 | C8: =IF(AND(ISNUMBER(B8),$B$2>0),B8/$B$2,"") -> 3100.25 | D8: مصاريف التشغيل والرواتب... | G8: تنبيه: مدخلات ناقصة | H8: =IF(AND(H5=1,COUNT(B6:B8)<3),1,0) -> 0
A9: الربح التقديري (مبيعات − مشتريات − مصاريف) | B9: =IF(COUNT(B6:B8)=3,B6-B7-B8,"") -> 23085000 | C9: =IF(AND(ISNUMBER(B9),$B$2>0),B9/$B$2,"") -> 1923.75 | D9: للمرجع فقط — لا يأخذ المخزون بالحسبان | G9: تنبيه: بيانات المستودع ناقصة | H9: =IF(AND(H5=1,H15>=H14,NOT(AND(ISNUMBER(C21),ISNUMBER(D21)))),1,0) -> 0
G10: تنبيه: صف شهر آخر | H10: =IF(AND(ISNUMBER(A21),A21<>H15),1,0) -> 0
A11: الصندوق والديون بالعملتين | G11: تنبيه: سعر صرف مختلف | H11: =IF(AND(ISNUMBER(B21),$B$2>0,ABS(B21-$B$2)>0.5),1,0) -> 0
A12: البيان | B12: ليرة سورية | C12: دولار أمريكي | D12: الإجمالي ($) | G12: تنبيه: أخطاء بالمستودع | H12: =IF(N(E21)>0,1,0) -> 0
A13: الصندوق (كاش فعلي) | B13: 1684000 | C13: 270 | D13: =IF(AND(ISNUMBER(B13),ISNUMBER(C13),$B$2>0),B13/$B$2+C13,"") -> 410.33333 | G13: مجموع التنبيهات | H13: =SUM(H7:H12) -> 0
A14: ديون لنا (مستحقة لنا) | B14: 66327000 | C14: 5156 | D14: =IF(AND(ISNUMBER(B14),ISNUMBER(C14),$B$2>0),B14/$B$2+C14,"") -> 10683.25 | G14: أول شهر لبيانات المستودع | H14: ='لوحة التحكم'!$C$6 -> 6
A15: ديون علينا | B15: 4536000 | C15: 12826 | D15: =IF(AND(ISNUMBER(B15),ISNUMBER(C15),$B$2>0),B15/$B$2+C15,"") -> 13204 | G15: رقم هذا الشهر | H15: 3
A16: صافي الدين (لنا − علينا) | B16: =IF(AND(ISNUMBER(B14),ISNUMBER(B15)),B14-B15,"") -> 61791000 | C16: =IF(AND(ISNUMBER(C14),ISNUMBER(C15)),C14-C15,"") -> -7670 | D16: =IF(AND(ISNUMBER(D14),ISNUMBER(D15)),D14-D15,"") -> -2520.75
A17: صافي المركز المالي (صندوق + ديون لنا − ديون علينا) | D17: =IF(AND(ISNUMBER(D13),ISNUMBER(D16)),D13+D16,"") -> -2110.4167
A19: بيانات المستودع — الصق صفًّا واحدًا كـ «قيم» من ورقة «تصدير للتقارير» في ملف المستودع
A20: رقم الشهر | B20: سعر صرف المستودع | C20: مخزون مسعّر بالدولار ($) | D20: مخزون مسعّر بالليرة (ل.س) | E20: أصناف بها أخطاء
A22: قيمة المخزون الكلية بالدولار (بسعر الشراء وسعر صرف الشهر) | C22: =IF(AND(ISNUMBER(C21),ISNUMBER(D21),$B$2>0),C21+D21/$B$2,"") | D22: المسعّر بالدولار + (المسعّر بالليرة ÷ سعر الصرف)
A24: التقرير الشهري بالدولار الأمريكي
A25: البيان | B25: هذا الشهر ($) | C25: الشهر السابق ($) | D25: التغير ($) | E25: التغير %
A26: المبيعات | B26: =IF(ISNUMBER(C6),C6,"") -> 8786.9167 | C26: =IF('02-فبراير'!$B$26="","",'02-فبراير'!$B$26) -> 7321.5833 | D26: =IF(AND(ISNUMBER(B26),ISNUMBER(C26)),B26-C26,"") -> 1465.3333 | E26: =IF(AND(ISNUMBER(B26),ISNUMBER(C26)),IF(C26<>0,(B26-C26)/ABS(C26),""),"") -> 0.20013886
A27: مخزون أول الشهر (= مخزون آخر الشهر السابق) | B27: =IF($H$3=1,'02-فبراير'!$C$22,"") | C27: =IF('02-فبراير'!$B$27="","",'02-فبراير'!$B$27) | D27: =IF(AND(ISNUMBER(B27),ISNUMBER(C27)),B27-C27,"") | E27: =IF(AND(ISNUMBER(B27),ISNUMBER(C27)),IF(C27<>0,(B27-C27)/ABS(C27),""),"")
A28: (+) المشتريات | B28: =IF(ISNUMBER(C7),C7,"") -> 3762.9167 | C28: =IF('02-فبراير'!$B$28="","",'02-فبراير'!$B$28) -> 3441.3333 | D28: =IF(AND(ISNUMBER(B28),ISNUMBER(C28)),B28-C28,"") -> 321.58333 | E28: =IF(AND(ISNUMBER(B28),ISNUMBER(C28)),IF(C28<>0,(B28-C28)/ABS(C28),""),"") -> 0.093447307
A29: (−) مخزون آخر الشهر (بعد عزل أثر الصرف) | B29: =IF($H$3=1,C22-$H$4,"") | C29: =IF('02-فبراير'!$B$29="","",'02-فبراير'!$B$29) | D29: =IF(AND(ISNUMBER(B29),ISNUMBER(C29)),B29-C29,"") | E29: =IF(AND(ISNUMBER(B29),ISNUMBER(C29)),IF(C29<>0,(B29-C29)/ABS(C29),""),"")
A30: (=) تكلفة المبيعات | B30: =IF($H$3=1,B27+B28-B29,"") | C30: =IF('02-فبراير'!$B$30="","",'02-فبراير'!$B$30) | D30: =IF(AND(ISNUMBER(B30),ISNUMBER(C30)),B30-C30,"") | E30: =IF(AND(ISNUMBER(B30),ISNUMBER(C30)),IF(C30<>0,(B30-C30)/ABS(C30),""),"")
A31: مجمل الربح (المبيعات − التكلفة) | B31: =IF($H$3=1,B26-B30,"") | C31: =IF('02-فبراير'!$B$31="","",'02-فبراير'!$B$31) | D31: =IF(AND(ISNUMBER(B31),ISNUMBER(C31)),B31-C31,"") | E31: =IF(AND(ISNUMBER(B31),ISNUMBER(C31)),IF(C31<>0,(B31-C31)/ABS(C31),""),"")
A32: (−) المصاريف | B32: =IF(ISNUMBER(C8),C8,"") -> 3100.25 | C32: =IF('02-فبراير'!$B$32="","",'02-فبراير'!$B$32) -> 3017.9167 | D32: =IF(AND(ISNUMBER(B32),ISNUMBER(C32)),B32-C32,"") -> 82.333333 | E32: =IF(AND(ISNUMBER(B32),ISNUMBER(C32)),IF(C32<>0,(B32-C32)/ABS(C32),""),"") -> 0.027281513
A33: (=) الربح الحقيقي التشغيلي | B33: =IF($H$3=1,B31-B32,"") | C33: =IF('02-فبراير'!$B$33="","",'02-فبراير'!$B$33) | D33: =IF(AND(ISNUMBER(B33),ISNUMBER(C33)),B33-C33,"") | E33: =IF(AND(ISNUMBER(B33),ISNUMBER(C33)),IF(C33<>0,(B33-C33)/ABS(C33),""),"")
A34: هامش الربح الحقيقي % | B34: =IF(AND($H$3=1,N(B26)>0),B33/B26,"") | C34: =IF('02-فبراير'!$B$34="","",'02-فبراير'!$B$34) | D34: =IF(AND(ISNUMBER(B34),ISNUMBER(C34)),B34-C34,"")
A35: أثر تغير الصرف على مخزون الليرة | B35: =IF($H$3=1,$H$4,"") | C35: =IF('02-فبراير'!$B$35="","",'02-فبراير'!$B$35) | D35: =IF(AND(ISNUMBER(B35),ISNUMBER(C35)),B35-C35,"") | E35: =IF(AND(ISNUMBER(B35),ISNUMBER(C35)),IF(C35<>0,(B35-C35)/ABS(C35),""),"")
A36: صافي الربح بعد أثر الصرف | B36: =IF($H$3=1,B33+B35,"") | C36: =IF('02-فبراير'!$B$36="","",'02-فبراير'!$B$36) | D36: =IF(AND(ISNUMBER(B36),ISNUMBER(C36)),B36-C36,"") | E36: =IF(AND(ISNUMBER(B36),ISNUMBER(C36)),IF(C36<>0,(B36-C36)/ABS(C36),""),"")
A37: للمرجع: الربح التقديري (مبيعات − مشتريات − مصاريف) | B37: =IF(ISNUMBER(C9),C9,"") -> 1923.75 | C37: =IF('02-فبراير'!$B$37="","",'02-فبراير'!$B$37) -> 862.33333 | D37: =IF(AND(ISNUMBER(B37),ISNUMBER(C37)),B37-C37,"") -> 1061.4167 | E37: =IF(AND(ISNUMBER(B37),ISNUMBER(C37)),IF(C37<>0,(B37-C37)/ABS(C37),""),"") -> 1.2308659
A39: مؤشرات إضافية
A40: المؤشر | B40: هذا الشهر | C40: الشهر السابق | D40: التغير | E40: التغير %
A41: نسبة المصاريف من المبيعات % | B41: =IF(AND(ISNUMBER(B32),N(B26)>0),B32/B26,"") -> 0.3528257 | C41: =IF('02-فبراير'!$B$41="","",'02-فبراير'!$B$41) -> 0.41219454 | D41: =IF(AND(ISNUMBER(B41),ISNUMBER(C41)),B41-C41,"") -> -0.059368842
A42: نسبة تكلفة المبيعات من المبيعات % | B42: =IF(AND(ISNUMBER(B30),N(B26)>0),B30/B26,"") | C42: =IF('02-فبراير'!$B$42="","",'02-فبراير'!$B$42) | D42: =IF(AND(ISNUMBER(B42),ISNUMBER(C42)),B42-C42,"")
A43: قيمة المخزون الكلية ($) | B43: =IF(ISNUMBER(C22),C22,"") | C43: =IF('02-فبراير'!$B$43="","",'02-فبراير'!$B$43) | D43: =IF(AND(ISNUMBER(B43),ISNUMBER(C43)),B43-C43,"") | E43: =IF(AND(ISNUMBER(B43),ISNUMBER(C43)),IF(C43<>0,(B43-C43)/ABS(C43),""),"")
A44: نسبة المخزون المسعّر بالليرة % | B44: =IF(AND(ISNUMBER(C22),$B$2>0),IF(C22>0,(D21/$B$2)/C22,""),"") | C44: =IF('02-فبراير'!$B$44="","",'02-فبراير'!$B$44) | D44: =IF(AND(ISNUMBER(B44),ISNUMBER(C44)),B44-C44,"")
...

Sheet 04-أبريل
A1: تقرير شهر أبريل 2026 — الأرباح الحقيقية بالدولار الأمريكي | G1: خلايا مساعدة (خارج الطباعة)
A2: سعر الصرف المعتمد (ل.س مقابل 1$) — من لوحة التحكم | B2: =IF(ISNUMBER('لوحة التحكم'!$C$13),'لوحة التحكم'!$C$13,0) -> 12500 | C2: حالة الشهر | D2: =$H$6 -> ℹ ربح تقديري فقط | G2: سعر صرف الشهر السابق | H2: ='03-مارس'!$B$2 -> 12000
A3: =IF($H$5=0,"لا توجد بيانات لهذا الشهر بعد — أدخل المدخلات أدناه",IF($H$13>0,(IF($H$7=1,"⚠ سعر الصرف غير مُدخل في لوحة التحكم. ","")&IF($H$8=1,"⚠ أكمل المبيعات والمشتريات والمصاريف. ","")&IF($H$9=1,"⚠ الصق بيانات المستودع في فقرة «بيانات المستودع». ","")&IF($H$10=1,"⚠ الصف الملصوق يخص شهرًا آخر. ","")&IF($H$11=1,"⚠ سعر صرف المستودع ("&$B$21&") يختلف عن سعر لوحة التحكم ("&$B$2&"). ","")&IF($H$12=1,"⚠ ملف المستودع فيه أصناف بها أخطاء (العدد: "&$E$21&") — صحّحها ثم أعد التصدير.","")),IF($H$3=1,"✅ البيانات مكتملة — الربح الحقيقي محسوب","ℹ الربح الحقيقي غير متاح (يلزم مخزون هذا الشهر والشهر السابق وسعر صرف الشهرين) — المعروض ربح تقديري فقط"))) -> ℹ الربح الحقيقي غير متاح (يلزم مخزون هذا الشهر والشهر السابق وسعر صرف الشهرين) — المعروض ربح تقديري فقط | G3: الربح الحقيقي جاهز؟ (1/0) | H3: =IF(AND($B$2>0,H2>0,COUNT(B6:B8)=3,ISNUMBER(C22),ISNUMBER('03-مارس'!$C$22),ISNUMBER('03-مارس'!$D$21)),1,0) -> 0
A4: مدخلات الشهر (أدخل بالليرة السورية من برنامج المحاسبة) — الخلايا الصفراء | G4: أثر الصرف على مخزون الليرة ($) | H4: =IF(H3=1,'03-مارس'!$D$21*(1/$B$2-1/H2),0) -> 0
A5: البيان | B5: المبلغ (ل.س) | C5: المعادل ($) | D5: ملاحظة | G5: فيه بيانات؟ (1/0) | H5: =IF(COUNTA(B6:B8,B13:C15,A21:E21)>0,1,0) -> 1
A6: المبيعات | B6: 166691000 | C6: =IF(AND(ISNUMBER(B6),$B$2>0),B6/$B$2,"") -> 13335.28 | D6: إجمالي مبيعات الشهر | G6: حالة الشهر | H6: =IF(H5=0,"لا بيانات",IF(H3=1,IF(H13=0,"✅ جاهز — ربح حقيقي","⚠ ربح حقيقي مع تنبيهات"),IF(H13>0,"⚠ تنبيهات — راجع الصفحة",IF(COUNT(B6:B8)=3,"ℹ ربح تقديري فقط","⚠ بيانات ناقصة")))) -> ℹ ربح تقديري فقط
A7: المشتريات | B7: 91555000 | C7: =IF(AND(ISNUMBER(B7),$B$2>0),B7/$B$2,"") -> 7324.4 | D7: مشتريات الشهر (مواد وبضاعة) | G7: تنبيه: سعر الصرف ناقص | H7: =IF(AND(H5=1,$B$2<=0),1,0) -> 0
A8: المصاريف | B8: 38371000 | C8: =IF(AND(ISNUMBER(B8),$B$2>0),B8/$B$2,"") -> 3069.68 | D8: مصاريف التشغيل والرواتب... | G8: تنبيه: مدخلات ناقصة | H8: =IF(AND(H5=1,COUNT(B6:B8)<3),1,0) -> 0
A9: الربح التقديري (مبيعات − مشتريات − مصاريف) | B9: =IF(COUNT(B6:B8)=3,B6-B7-B8,"") -> 36765000 | C9: =IF(AND(ISNUMBER(B9),$B$2>0),B9/$B$2,"") -> 2941.2 | D9: للمرجع فقط — لا يأخذ المخزون بالحسبان | G9: تنبيه: بيانات المستودع ناقصة | H9: =IF(AND(H5=1,H15>=H14,NOT(AND(ISNUMBER(C21),ISNUMBER(D21)))),1,0) -> 0
G10: تنبيه: صف شهر آخر | H10: =IF(AND(ISNUMBER(A21),A21<>H15),1,0) -> 0
A11: الصندوق والديون بالعملتين | G11: تنبيه: سعر صرف مختلف | H11: =IF(AND(ISNUMBER(B21),$B$2>0,ABS(B21-$B$2)>0.5),1,0) -> 0
A12: البيان | B12: ليرة سورية | C12: دولار أمريكي | D12: الإجمالي ($) | G12: تنبيه: أخطاء بالمستودع | H12: =IF(N(E21)>0,1,0) -> 0
A13: الصندوق (كاش فعلي) | B13: 1436000 | C13: 295 | D13: =IF(AND(ISNUMBER(B13),ISNUMBER(C13),$B$2>0),B13/$B$2+C13,"") -> 409.88 | G13: مجموع التنبيهات | H13: =SUM(H7:H12) -> 0
A14: ديون لنا (مستحقة لنا) | B14: 70574000 | C14: 7360 | D14: =IF(AND(ISNUMBER(B14),ISNUMBER(C14),$B$2>0),B14/$B$2+C14,"") -> 13005.92 | G14: أول شهر لبيانات المستودع | H14: ='لوحة التحكم'!$C$6 -> 6
A15: ديون علينا | B15: 5924000 | C15: 11459 | D15: =IF(AND(ISNUMBER(B15),ISNUMBER(C15),$B$2>0),B15/$B$2+C15,"") -> 11932.92 | G15: رقم هذا الشهر | H15: 4
A16: صافي الدين (لنا − علينا) | B16: =IF(AND(ISNUMBER(B14),ISNUMBER(B15)),B14-B15,"") -> 64650000 | C16: =IF(AND(ISNUMBER(C14),ISNUMBER(C15)),C14-C15,"") -> -4099 | D16: =IF(AND(ISNUMBER(D14),ISNUMBER(D15)),D14-D15,"") -> 1073
A17: صافي المركز المالي (صندوق + ديون لنا − ديون علينا) | D17: =IF(AND(ISNUMBER(D13),ISNUMBER(D16)),D13+D16,"") -> 1482.88
A19: بيانات المستودع — الصق صفًّا واحدًا كـ «قيم» من ورقة «تصدير للتقارير» في ملف المستودع
A20: رقم الشهر | B20: سعر صرف المستودع | C20: مخزون مسعّر بالدولار ($) | D20: مخزون مسعّر بالليرة (ل.س) | E20: أصناف بها أخطاء
A22: قيمة المخزون الكلية بالدولار (بسعر الشراء وسعر صرف الشهر) | C22: =IF(AND(ISNUMBER(C21),ISNUMBER(D21),$B$2>0),C21+D21/$B$2,"") | D22: المسعّر بالدولار + (المسعّر بالليرة ÷ سعر الصرف)
A24: التقرير الشهري بالدولار الأمريكي
A25: البيان | B25: هذا الشهر ($) | C25: الشهر السابق ($) | D25: التغير ($) | E25: التغير %
A26: المبيعات | B26: =IF(ISNUMBER(C6),C6,"") -> 13335.28 | C26: =IF('03-مارس'!$B$26="","",'03-مارس'!$B$26) -> 8786.9167 | D26: =IF(AND(ISNUMBER(B26),ISNUMBER(C26)),B26-C26,"") -> 4548.3633 | E26: =IF(AND(ISNUMBER(B26),ISNUMBER(C26)),IF(C26<>0,(B26-C26)/ABS(C26),""),"") -> 0.51762905
A27: مخزون أول الشهر (= مخزون آخر الشهر السابق) | B27: =IF($H$3=1,'03-مارس'!$C$22,"") | C27: =IF('03-مارس'!$B$27="","",'03-مارس'!$B$27) | D27: =IF(AND(ISNUMBER(B27),ISNUMBER(C27)),B27-C27,"") | E27: =IF(AND(ISNUMBER(B27),ISNUMBER(C27)),IF(C27<>0,(B27-C27)/ABS(C27),""),"")
A28: (+) المشتريات | B28: =IF(ISNUMBER(C7),C7,"") -> 7324.4 | C28: =IF('03-مارس'!$B$28="","",'03-مارس'!$B$28) -> 3762.9167 | D28: =IF(AND(ISNUMBER(B28),ISNUMBER(C28)),B28-C28,"") -> 3561.4833 | E28: =IF(AND(ISNUMBER(B28),ISNUMBER(C28)),IF(C28<>0,(B28-C28)/ABS(C28),""),"") -> 0.94646883
A29: (−) مخزون آخر الشهر (بعد عزل أثر الصرف) | B29: =IF($H$3=1,C22-$H$4,"") | C29: =IF('03-مارس'!$B$29="","",'03-مارس'!$B$29) | D29: =IF(AND(ISNUMBER(B29),ISNUMBER(C29)),B29-C29,"") | E29: =IF(AND(ISNUMBER(B29),ISNUMBER(C29)),IF(C29<>0,(B29-C29)/ABS(C29),""),"")
A30: (=) تكلفة المبيعات | B30: =IF($H$3=1,B27+B28-B29,"") | C30: =IF('03-مارس'!$B$30="","",'03-مارس'!$B$30) | D30: =IF(AND(ISNUMBER(B30),ISNUMBER(C30)),B30-C30,"") | E30: =IF(AND(ISNUMBER(B30),ISNUMBER(C30)),IF(C30<>0,(B30-C30)/ABS(C30),""),"")
A31: مجمل الربح (المبيعات − التكلفة) | B31: =IF($H$3=1,B26-B30,"") | C31: =IF('03-مارس'!$B$31="","",'03-مارس'!$B$31) | D31: =IF(AND(ISNUMBER(B31),ISNUMBER(C31)),B31-C31,"") | E31: =IF(AND(ISNUMBER(B31),ISNUMBER(C31)),IF(C31<>0,(B31-C31)/ABS(C31),""),"")
A32: (−) المصاريف | B32: =IF(ISNUMBER(C8),C8,"") -> 3069.68 | C32: =IF('03-مارس'!$B$32="","",'03-مارس'!$B$32) -> 3100.25 | D32: =IF(AND(ISNUMBER(B32),ISNUMBER(C32)),B32-C32,"") -> -30.57 | E32: =IF(AND(ISNUMBER(B32),ISNUMBER(C32)),IF(C32<>0,(B32-C32)/ABS(C32),""),"") -> -0.0098604951
A33: (=) الربح الحقيقي التشغيلي | B33: =IF($H$3=1,B31-B32,"") | C33: =IF('03-مارس'!$B$33="","",'03-مارس'!$B$33) | D33: =IF(AND(ISNUMBER(B33),ISNUMBER(C33)),B33-C33,"") | E33: =IF(AND(ISNUMBER(B33),ISNUMBER(C33)),IF(C33<>0,(B33-C33)/ABS(C33),""),"")
A34: هامش الربح الحقيقي % | B34: =IF(AND($H$3=1,N(B26)>0),B33/B26,"") | C34: =IF('03-مارس'!$B$34="","",'03-مارس'!$B$34) | D34: =IF(AND(ISNUMBER(B34),ISNUMBER(C34)),B34-C34,"")
A35: أثر تغير الصرف على مخزون الليرة | B35: =IF($H$3=1,$H$4,"") | C35: =IF('03-مارس'!$B$35="","",'03-مارس'!$B$35) | D35: =IF(AND(ISNUMBER(B35),ISNUMBER(C35)),B35-C35,"") | E35: =IF(AND(ISNUMBER(B35),ISNUMBER(C35)),IF(C35<>0,(B35-C35)/ABS(C35),""),"")
A36: صافي الربح بعد أثر الصرف | B36: =IF($H$3=1,B33+B35,"") | C36: =IF('03-مارس'!$B$36="","",'03-مارس'!$B$36) | D36: =IF(AND(ISNUMBER(B36),ISNUMBER(C36)),B36-C36,"") | E36: =IF(AND(ISNUMBER(B36),ISNUMBER(C36)),IF(C36<>0,(B36-C36)/ABS(C36),""),"")
A37: للمرجع: الربح التقديري (مبيعات − مشتريات − مصاريف) | B37: =IF(ISNUMBER(C9),C9,"") -> 2941.2 | C37: =IF('03-مارس'!$B$37="","",'03-مارس'!$B$37) -> 1923.75 | D37: =IF(AND(ISNUMBER(B37),ISNUMBER(C37)),B37-C37,"") -> 1017.45 | E37: =IF(AND(ISNUMBER(B37),ISNUMBER(C37)),IF(C37<>0,(B37-C37)/ABS(C37),""),"") -> 0.52888889
A39: مؤشرات إضافية
A40: المؤشر | B40: هذا الشهر | C40: الشهر السابق | D40: التغير | E40: التغير %
A41: نسبة المصاريف من المبيعات % | B41: =IF(AND(ISNUMBER(B32),N(B26)>0),B32/B26,"") -> 0.23019239 | C41: =IF('03-مارس'!$B$41="","",'03-مارس'!$B$41) -> 0.3528257 | D41: =IF(AND(ISNUMBER(B41),ISNUMBER(C41)),B41-C41,"") -> -0.12263331
A42: نسبة تكلفة المبيعات من المبيعات % | B42: =IF(AND(ISNUMBER(B30),N(B26)>0),B30/B26,"") | C42: =IF('03-مارس'!$B$42="","",'03-مارس'!$B$42) | D42: =IF(AND(ISNUMBER(B42),ISNUMBER(C42)),B42-C42,"")
A43: قيمة المخزون الكلية ($) | B43: =IF(ISNUMBER(C22),C22,"") | C43: =IF('03-مارس'!$B$43="","",'03-مارس'!$B$43) | D43: =IF(AND(ISNUMBER(B43),ISNUMBER(C43)),B43-C43,"") | E43: =IF(AND(ISNUMBER(B43),ISNUMBER(C43)),IF(C43<>0,(B43-C43)/ABS(C43),""),"")
A44: نسبة المخزون المسعّر بالليرة % | B44: =IF(AND(ISNUMBER(C22),$B$2>0),IF(C22>0,(D21/$B$2)/C22,""),"") | C44: =IF('03-مارس'!$B$44="","",'03-مارس'!$B$44) | D44: =IF(AND(ISNUMBER(B44),ISNUMBER(C44)),B44-C44,"")
...

Sheet 05-مايو
A1: تقرير شهر مايو 2026 — الأرباح الحقيقية بالدولار الأمريكي | G1: خلايا مساعدة (خارج الطباعة)
A2: سعر الصرف المعتمد (ل.س مقابل 1$) — من لوحة التحكم | B2: =IF(ISNUMBER('لوحة التحكم'!$C$14),'لوحة التحكم'!$C$14,0) -> 12500 | C2: حالة الشهر | D2: =$H$6 -> ℹ ربح تقديري فقط | G2: سعر صرف الشهر السابق | H2: ='04-أبريل'!$B$2 -> 12500
A3: =IF($H$5=0,"لا توجد بيانات لهذا الشهر بعد — أدخل المدخلات أدناه",IF($H$13>0,(IF($H$7=1,"⚠ سعر الصرف غير مُدخل في لوحة التحكم. ","")&IF($H$8=1,"⚠ أكمل المبيعات والمشتريات والمصاريف. ","")&IF($H$9=1,"⚠ الصق بيانات المستودع في فقرة «بيانات المستودع». ","")&IF($H$10=1,"⚠ الصف الملصوق يخص شهرًا آخر. ","")&IF($H$11=1,"⚠ سعر صرف المستودع ("&$B$21&") يختلف عن سعر لوحة التحكم ("&$B$2&"). ","")&IF($H$12=1,"⚠ ملف المستودع فيه أصناف بها أخطاء (العدد: "&$E$21&") — صحّحها ثم أعد التصدير.","")),IF($H$3=1,"✅ البيانات مكتملة — الربح الحقيقي محسوب","ℹ الربح الحقيقي غير متاح (يلزم مخزون هذا الشهر والشهر السابق وسعر صرف الشهرين) — المعروض ربح تقديري فقط"))) -> ℹ الربح الحقيقي غير متاح (يلزم مخزون هذا الشهر والشهر السابق وسعر صرف الشهرين) — المعروض ربح تقديري فقط | G3: الربح الحقيقي جاهز؟ (1/0) | H3: =IF(AND($B$2>0,H2>0,COUNT(B6:B8)=3,ISNUMBER(C22),ISNUMBER('04-أبريل'!$C$22),ISNUMBER('04-أبريل'!$D$21)),1,0) -> 0
A4: مدخلات الشهر (أدخل بالليرة السورية من برنامج المحاسبة) — الخلايا الصفراء | G4: أثر الصرف على مخزون الليرة ($) | H4: =IF(H3=1,'04-أبريل'!$D$21*(1/$B$2-1/H2),0) -> 0
A5: البيان | B5: المبلغ (ل.س) | C5: المعادل ($) | D5: ملاحظة | G5: فيه بيانات؟ (1/0) | H5: =IF(COUNTA(B6:B8,B13:C15,A21:E21)>0,1,0) -> 1
A6: المبيعات | B6: 163334000 | C6: =IF(AND(ISNUMBER(B6),$B$2>0),B6/$B$2,"") -> 13066.72 | D6: إجمالي مبيعات الشهر | G6: حالة الشهر | H6: =IF(H5=0,"لا بيانات",IF(H3=1,IF(H13=0,"✅ جاهز — ربح حقيقي","⚠ ربح حقيقي مع تنبيهات"),IF(H13>0,"⚠ تنبيهات — راجع الصفحة",IF(COUNT(B6:B8)=3,"ℹ ربح تقديري فقط","⚠ بيانات ناقصة")))) -> ℹ ربح تقديري فقط
A7: المشتريات | B7: 91196000 | C7: =IF(AND(ISNUMBER(B7),$B$2>0),B7/$B$2,"") -> 7295.68 | D7: مشتريات الشهر (مواد وبضاعة) | G7: تنبيه: سعر الصرف ناقص | H7: =IF(AND(H5=1,$B$2<=0),1,0) -> 0
A8: المصاريف | B8: 26000000 | C8: =IF(AND(ISNUMBER(B8),$B$2>0),B8/$B$2,"") -> 2080 | D8: مصاريف التشغيل والرواتب... | G8: تنبيه: مدخلات ناقصة | H8: =IF(AND(H5=1,COUNT(B6:B8)<3),1,0) -> 0
A9: الربح التقديري (مبيعات − مشتريات − مصاريف) | B9: =IF(COUNT(B6:B8)=3,B6-B7-B8,"") -> 46138000 | C9: =IF(AND(ISNUMBER(B9),$B$2>0),B9/$B$2,"") -> 3691.04 | D9: للمرجع فقط — لا يأخذ المخزون بالحسبان | G9: تنبيه: بيانات المستودع ناقصة | H9: =IF(AND(H5=1,H15>=H14,NOT(AND(ISNUMBER(C21),ISNUMBER(D21)))),1,0) -> 0
G10: تنبيه: صف شهر آخر | H10: =IF(AND(ISNUMBER(A21),A21<>H15),1,0) -> 0
A11: الصندوق والديون بالعملتين | G11: تنبيه: سعر صرف مختلف | H11: =IF(AND(ISNUMBER(B21),$B$2>0,ABS(B21-$B$2)>0.5),1,0) -> 0
A12: البيان | B12: ليرة سورية | C12: دولار أمريكي | D12: الإجمالي ($) | G12: تنبيه: أخطاء بالمستودع | H12: =IF(N(E21)>0,1,0) -> 0
A13: الصندوق (كاش فعلي) | B13: 1500000 | C13: 50 | D13: =IF(AND(ISNUMBER(B13),ISNUMBER(C13),$B$2>0),B13/$B$2+C13,"") -> 170 | G13: مجموع التنبيهات | H13: =SUM(H7:H12) -> 0
A14: ديون لنا (مستحقة لنا) | B14: 35913000 | C14: 6270 | D14: =IF(AND(ISNUMBER(B14),ISNUMBER(C14),$B$2>0),B14/$B$2+C14,"") -> 9143.04 | G14: أول شهر لبيانات المستودع | H14: ='لوحة التحكم'!$C$6 -> 6
A15: ديون علينا | B15: 8730000 | C15: 5679 | D15: =IF(AND(ISNUMBER(B15),ISNUMBER(C15),$B$2>0),B15/$B$2+C15,"") -> 6377.4 | G15: رقم هذا الشهر | H15: 5
A16: صافي الدين (لنا − علينا) | B16: =IF(AND(ISNUMBER(B14),ISNUMBER(B15)),B14-B15,"") -> 27183000 | C16: =IF(AND(ISNUMBER(C14),ISNUMBER(C15)),C14-C15,"") -> 591 | D16: =IF(AND(ISNUMBER(D14),ISNUMBER(D15)),D14-D15,"") -> 2765.64
A17: صافي المركز المالي (صندوق + ديون لنا − ديون علينا) | D17: =IF(AND(ISNUMBER(D13),ISNUMBER(D16)),D13+D16,"") -> 2935.64
A19: بيانات المستودع — الصق صفًّا واحدًا كـ «قيم» من ورقة «تصدير للتقارير» في ملف المستودع
A20: رقم الشهر | B20: سعر صرف المستودع | C20: مخزون مسعّر بالدولار ($) | D20: مخزون مسعّر بالليرة (ل.س) | E20: أصناف بها أخطاء
A22: قيمة المخزون الكلية بالدولار (بسعر الشراء وسعر صرف الشهر) | C22: =IF(AND(ISNUMBER(C21),ISNUMBER(D21),$B$2>0),C21+D21/$B$2,"") | D22: المسعّر بالدولار + (المسعّر بالليرة ÷ سعر الصرف)
A24: التقرير الشهري بالدولار الأمريكي
A25: البيان | B25: هذا الشهر ($) | C25: الشهر السابق ($) | D25: التغير ($) | E25: التغير %
A26: المبيعات | B26: =IF(ISNUMBER(C6),C6,"") -> 13066.72 | C26: =IF('04-أبريل'!$B$26="","",'04-أبريل'!$B$26) -> 13335.28 | D26: =IF(AND(ISNUMBER(B26),ISNUMBER(C26)),B26-C26,"") -> -268.56 | E26: =IF(AND(ISNUMBER(B26),ISNUMBER(C26)),IF(C26<>0,(B26-C26)/ABS(C26),""),"") -> -0.02013906
A27: مخزون أول الشهر (= مخزون آخر الشهر السابق) | B27: =IF($H$3=1,'04-أبريل'!$C$22,"") | C27: =IF('04-أبريل'!$B$27="","",'04-أبريل'!$B$27) | D27: =IF(AND(ISNUMBER(B27),ISNUMBER(C27)),B27-C27,"") | E27: =IF(AND(ISNUMBER(B27),ISNUMBER(C27)),IF(C27<>0,(B27-C27)/ABS(C27),""),"")
A28: (+) المشتريات | B28: =IF(ISNUMBER(C7),C7,"") -> 7295.68 | C28: =IF('04-أبريل'!$B$28="","",'04-أبريل'!$B$28) -> 7324.4 | D28: =IF(AND(ISNUMBER(B28),ISNUMBER(C28)),B28-C28,"") -> -28.72 | E28: =IF(AND(ISNUMBER(B28),ISNUMBER(C28)),IF(C28<>0,(B28-C28)/ABS(C28),""),"") -> -0.0039211403
A29: (−) مخزون آخر الشهر (بعد عزل أثر الصرف) | B29: =IF($H$3=1,C22-$H$4,"") | C29: =IF('04-أبريل'!$B$29="","",'04-أبريل'!$B$29) | D29: =IF(AND(ISNUMBER(B29),ISNUMBER(C29)),B29-C29,"") | E29: =IF(AND(ISNUMBER(B29),ISNUMBER(C29)),IF(C29<>0,(B29-C29)/ABS(C29),""),"")
A30: (=) تكلفة المبيعات | B30: =IF($H$3=1,B27+B28-B29,"") | C30: =IF('04-أبريل'!$B$30="","",'04-أبريل'!$B$30) | D30: =IF(AND(ISNUMBER(B30),ISNUMBER(C30)),B30-C30,"") | E30: =IF(AND(ISNUMBER(B30),ISNUMBER(C30)),IF(C30<>0,(B30-C30)/ABS(C30),""),"")
A31: مجمل الربح (المبيعات − التكلفة) | B31: =IF($H$3=1,B26-B30,"") | C31: =IF('04-أبريل'!$B$31="","",'04-أبريل'!$B$31) | D31: =IF(AND(ISNUMBER(B31),ISNUMBER(C31)),B31-C31,"") | E31: =IF(AND(ISNUMBER(B31),ISNUMBER(C31)),IF(C31<>0,(B31-C31)/ABS(C31),""),"")
A32: (−) المصاريف | B32: =IF(ISNUMBER(C8),C8,"") -> 2080 | C32: =IF('04-أبريل'!$B$32="","",'04-أبريل'!$B$32) -> 3069.68 | D32: =IF(AND(ISNUMBER(B32),ISNUMBER(C32)),B32-C32,"") -> -989.68 | E32: =IF(AND(ISNUMBER(B32),ISNUMBER(C32)),IF(C32<>0,(B32-C32)/ABS(C32),""),"") -> -0.32240494
A33: (=) الربح الحقيقي التشغيلي | B33: =IF($H$3=1,B31-B32,"") | C33: =IF('04-أبريل'!$B$33="","",'04-أبريل'!$B$33) | D33: =IF(AND(ISNUMBER(B33),ISNUMBER(C33)),B33-C33,"") | E33: =IF(AND(ISNUMBER(B33),ISNUMBER(C33)),IF(C33<>0,(B33-C33)/ABS(C33),""),"")
A34: هامش الربح الحقيقي % | B34: =IF(AND($H$3=1,N(B26)>0),B33/B26,"") | C34: =IF('04-أبريل'!$B$34="","",'04-أبريل'!$B$34) | D34: =IF(AND(ISNUMBER(B34),ISNUMBER(C34)),B34-C34,"")
A35: أثر تغير الصرف على مخزون الليرة | B35: =IF($H$3=1,$H$4,"") | C35: =IF('04-أبريل'!$B$35="","",'04-أبريل'!$B$35) | D35: =IF(AND(ISNUMBER(B35),ISNUMBER(C35)),B35-C35,"") | E35: =IF(AND(ISNUMBER(B35),ISNUMBER(C35)),IF(C35<>0,(B35-C35)/ABS(C35),""),"")
A36: صافي الربح بعد أثر الصرف | B36: =IF($H$3=1,B33+B35,"") | C36: =IF('04-أبريل'!$B$36="","",'04-أبريل'!$B$36) | D36: =IF(AND(ISNUMBER(B36),ISNUMBER(C36)),B36-C36,"") | E36: =IF(AND(ISNUMBER(B36),ISNUMBER(C36)),IF(C36<>0,(B36-C36)/ABS(C36),""),"")
A37: للمرجع: الربح التقديري (مبيعات − مشتريات − مصاريف) | B37: =IF(ISNUMBER(C9),C9,"") -> 3691.04 | C37: =IF('04-أبريل'!$B$37="","",'04-أبريل'!$B$37) -> 2941.2 | D37: =IF(AND(ISNUMBER(B37),ISNUMBER(C37)),B37-C37,"") -> 749.84 | E37: =IF(AND(ISNUMBER(B37),ISNUMBER(C37)),IF(C37<>0,(B37-C37)/ABS(C37),""),"") -> 0.25494356
A39: مؤشرات إضافية
A40: المؤشر | B40: هذا الشهر | C40: الشهر السابق | D40: التغير | E40: التغير %
A41: نسبة المصاريف من المبيعات % | B41: =IF(AND(ISNUMBER(B32),N(B26)>0),B32/B26,"") -> 0.15918302 | C41: =IF('04-أبريل'!$B$41="","",'04-أبريل'!$B$41) -> 0.23019239 | D41: =IF(AND(ISNUMBER(B41),ISNUMBER(C41)),B41-C41,"") -> -0.071009368
A42: نسبة تكلفة المبيعات من المبيعات % | B42: =IF(AND(ISNUMBER(B30),N(B26)>0),B30/B26,"") | C42: =IF('04-أبريل'!$B$42="","",'04-أبريل'!$B$42) | D42: =IF(AND(ISNUMBER(B42),ISNUMBER(C42)),B42-C42,"")
A43: قيمة المخزون الكلية ($) | B43: =IF(ISNUMBER(C22),C22,"") | C43: =IF('04-أبريل'!$B$43="","",'04-أبريل'!$B$43) | D43: =IF(AND(ISNUMBER(B43),ISNUMBER(C43)),B43-C43,"") | E43: =IF(AND(ISNUMBER(B43),ISNUMBER(C43)),IF(C43<>0,(B43-C43)/ABS(C43),""),"")
A44: نسبة المخزون المسعّر بالليرة % | B44: =IF(AND(ISNUMBER(C22),$B$2>0),IF(C22>0,(D21/$B$2)/C22,""),"") | C44: =IF('04-أبريل'!$B$44="","",'04-أبريل'!$B$44) | D44: =IF(AND(ISNUMBER(B44),ISNUMBER(C44)),B44-C44,"")
...

Sheet 06-يونيو
A1: تقرير شهر يونيو 2026 — الأرباح الحقيقية بالدولار الأمريكي | G1: خلايا مساعدة (خارج الطباعة)
A2: سعر الصرف المعتمد (ل.س مقابل 1$) — من لوحة التحكم | B2: =IF(ISNUMBER('لوحة التحكم'!$C$15),'لوحة التحكم'!$C$15,0) -> 13200 | C2: حالة الشهر | D2: =$H$6 -> ℹ ربح تقديري فقط | G2: سعر صرف الشهر السابق | H2: ='05-مايو'!$B$2 -> 12500
A3: =IF($H$5=0,"لا توجد بيانات لهذا الشهر بعد — أدخل المدخلات أدناه",IF($H$13>0,(IF($H$7=1,"⚠ سعر الصرف غير مُدخل في لوحة التحكم. ","")&IF($H$8=1,"⚠ أكمل المبيعات والمشتريات والمصاريف. ","")&IF($H$9=1,"⚠ الصق بيانات المستودع في فقرة «بيانات المستودع». ","")&IF($H$10=1,"⚠ الصف الملصوق يخص شهرًا آخر. ","")&IF($H$11=1,"⚠ سعر صرف المستودع ("&$B$21&") يختلف عن سعر لوحة التحكم ("&$B$2&"). ","")&IF($H$12=1,"⚠ ملف المستودع فيه أصناف بها أخطاء (العدد: "&$E$21&") — صحّحها ثم أعد التصدير.","")),IF($H$3=1,"✅ البيانات مكتملة — الربح الحقيقي محسوب","ℹ الربح الحقيقي غير متاح (يلزم مخزون هذا الشهر والشهر السابق وسعر صرف الشهرين) — المعروض ربح تقديري فقط"))) -> ℹ الربح الحقيقي غير متاح (يلزم مخزون هذا الشهر والشهر السابق وسعر صرف الشهرين) — المعروض ربح تقديري فقط | G3: الربح الحقيقي جاهز؟ (1/0) | H3: =IF(AND($B$2>0,H2>0,COUNT(B6:B8)=3,ISNUMBER(C22),ISNUMBER('05-مايو'!$C$22),ISNUMBER('05-مايو'!$D$21)),1,0) -> 0
A4: مدخلات الشهر (أدخل بالليرة السورية من برنامج المحاسبة) — الخلايا الصفراء | G4: أثر الصرف على مخزون الليرة ($) | H4: =IF(H3=1,'05-مايو'!$D$21*(1/$B$2-1/H2),0) -> 0
A5: البيان | B5: المبلغ (ل.س) | C5: المعادل ($) | D5: ملاحظة | G5: فيه بيانات؟ (1/0) | H5: =IF(COUNTA(B6:B8,B13:C15,A21:E21)>0,1,0) -> 1
A6: المبيعات | B6: 197424000 | C6: =IF(AND(ISNUMBER(B6),$B$2>0),B6/$B$2,"") -> 14956.364 | D6: إجمالي مبيعات الشهر | G6: حالة الشهر | H6: =IF(H5=0,"لا بيانات",IF(H3=1,IF(H13=0,"✅ جاهز — ربح حقيقي","⚠ ربح حقيقي مع تنبيهات"),IF(H13>0,"⚠ تنبيهات — راجع الصفحة",IF(COUNT(B6:B8)=3,"ℹ ربح تقديري فقط","⚠ بيانات ناقصة")))) -> ℹ ربح تقديري فقط
A7: المشتريات | B7: 61619000 | C7: =IF(AND(ISNUMBER(B7),$B$2>0),B7/$B$2,"") -> 4668.1061 | D7: مشتريات الشهر (مواد وبضاعة) | G7: تنبيه: سعر الصرف ناقص | H7: =IF(AND(H5=1,$B$2<=0),1,0) -> 0
A8: المصاريف | B8: 32391000 | C8: =IF(AND(ISNUMBER(B8),$B$2>0),B8/$B$2,"") -> 2453.8636 | D8: مصاريف التشغيل والرواتب... | G8: تنبيه: مدخلات ناقصة | H8: =IF(AND(H5=1,COUNT(B6:B8)<3),1,0) -> 0
A9: الربح التقديري (مبيعات − مشتريات − مصاريف) | B9: =IF(COUNT(B6:B8)=3,B6-B7-B8,"") -> 103414000 | C9: =IF(AND(ISNUMBER(B9),$B$2>0),B9/$B$2,"") -> 7834.3939 | D9: للمرجع فقط — لا يأخذ المخزون بالحسبان | G9: تنبيه: بيانات المستودع ناقصة | H9: =IF(AND(H5=1,H15>=H14,NOT(AND(ISNUMBER(C21),ISNUMBER(D21)))),1,0) -> 0
G10: تنبيه: صف شهر آخر | H10: =IF(AND(ISNUMBER(A21),A21<>H15),1,0) -> 0
A11: الصندوق والديون بالعملتين | G11: تنبيه: سعر صرف مختلف | H11: =IF(AND(ISNUMBER(B21),$B$2>0,ABS(B21-$B$2)>0.5),1,0) -> 0
A12: البيان | B12: ليرة سورية | C12: دولار أمريكي | D12: الإجمالي ($) | G12: تنبيه: أخطاء بالمستودع | H12: =IF(N(E21)>0,1,0) -> 0
A13: الصندوق (كاش فعلي) | B13: 584000 | C13: 686 | D13: =IF(AND(ISNUMBER(B13),ISNUMBER(C13),$B$2>0),B13/$B$2+C13,"") -> 730.24242 | G13: مجموع التنبيهات | H13: =SUM(H7:H12) -> 0
A14: ديون لنا (مستحقة لنا) | B14: 35652000 | C14: 11283 | D14: =IF(AND(ISNUMBER(B14),ISNUMBER(C14),$B$2>0),B14/$B$2+C14,"") -> 13983.909 | G14: أول شهر لبيانات المستودع | H14: ='لوحة التحكم'!$C$6 -> 6
A15: ديون علينا | B15: 6647000 | C15: 5101 | D15: =IF(AND(ISNUMBER(B15),ISNUMBER(C15),$B$2>0),B15/$B$2+C15,"") -> 5604.5606 | G15: رقم هذا الشهر | H15: 6
A16: صافي الدين (لنا − علينا) | B16: =IF(AND(ISNUMBER(B14),ISNUMBER(B15)),B14-B15,"") -> 29005000 | C16: =IF(AND(ISNUMBER(C14),ISNUMBER(C15)),C14-C15,"") -> 6182 | D16: =IF(AND(ISNUMBER(D14),ISNUMBER(D15)),D14-D15,"") -> 8379.3485
A17: صافي المركز المالي (صندوق + ديون لنا − ديون علينا) | D17: =IF(AND(ISNUMBER(D13),ISNUMBER(D16)),D13+D16,"") -> 9109.5909
A19: بيانات المستودع — الصق صفًّا واحدًا كـ «قيم» من ورقة «تصدير للتقارير» في ملف المستودع
A20: رقم الشهر | B20: سعر صرف المستودع | C20: مخزون مسعّر بالدولار ($) | D20: مخزون مسعّر بالليرة (ل.س) | E20: أصناف بها أخطاء
A21: 6 | B21: 13200 | C21: 29259.8 | D21: 204304214 | E21: 0
A22: قيمة المخزون الكلية بالدولار (بسعر الشراء وسعر صرف الشهر) | C22: =IF(AND(ISNUMBER(C21),ISNUMBER(D21),$B$2>0),C21+D21/$B$2,"") -> 44737.392 | D22: المسعّر بالدولار + (المسعّر بالليرة ÷ سعر الصرف)
A24: التقرير الشهري بالدولار الأمريكي
A25: البيان | B25: هذا الشهر ($) | C25: الشهر السابق ($) | D25: التغير ($) | E25: التغير %
A26: المبيعات | B26: =IF(ISNUMBER(C6),C6,"") -> 14956.364 | C26: =IF('05-مايو'!$B$26="","",'05-مايو'!$B$26) -> 13066.72 | D26: =IF(AND(ISNUMBER(B26),ISNUMBER(C26)),B26-C26,"") -> 1889.6436 | E26: =IF(AND(ISNUMBER(B26),ISNUMBER(C26)),IF(C26<>0,(B26-C26)/ABS(C26),""),"") -> 0.14461499
A27: مخزون أول الشهر (= مخزون آخر الشهر السابق) | B27: =IF($H$3=1,'05-مايو'!$C$22,"") | C27: =IF('05-مايو'!$B$27="","",'05-مايو'!$B$27) | D27: =IF(AND(ISNUMBER(B27),ISNUMBER(C27)),B27-C27,"") | E27: =IF(AND(ISNUMBER(B27),ISNUMBER(C27)),IF(C27<>0,(B27-C27)/ABS(C27),""),"")
A28: (+) المشتريات | B28: =IF(ISNUMBER(C7),C7,"") -> 4668.1061 | C28: =IF('05-مايو'!$B$28="","",'05-مايو'!$B$28) -> 7295.68 | D28: =IF(AND(ISNUMBER(B28),ISNUMBER(C28)),B28-C28,"") -> -2627.5739 | E28: =IF(AND(ISNUMBER(B28),ISNUMBER(C28)),IF(C28<>0,(B28-C28)/ABS(C28),""),"") -> -0.36015477
A29: (−) مخزون آخر الشهر (بعد عزل أثر الصرف) | B29: =IF($H$3=1,C22-$H$4,"") | C29: =IF('05-مايو'!$B$29="","",'05-مايو'!$B$29) | D29: =IF(AND(ISNUMBER(B29),ISNUMBER(C29)),B29-C29,"") | E29: =IF(AND(ISNUMBER(B29),ISNUMBER(C29)),IF(C29<>0,(B29-C29)/ABS(C29),""),"")
A30: (=) تكلفة المبيعات | B30: =IF($H$3=1,B27+B28-B29,"") | C30: =IF('05-مايو'!$B$30="","",'05-مايو'!$B$30) | D30: =IF(AND(ISNUMBER(B30),ISNUMBER(C30)),B30-C30,"") | E30: =IF(AND(ISNUMBER(B30),ISNUMBER(C30)),IF(C30<>0,(B30-C30)/ABS(C30),""),"")
A31: مجمل الربح (المبيعات − التكلفة) | B31: =IF($H$3=1,B26-B30,"") | C31: =IF('05-مايو'!$B$31="","",'05-مايو'!$B$31) | D31: =IF(AND(ISNUMBER(B31),ISNUMBER(C31)),B31-C31,"") | E31: =IF(AND(ISNUMBER(B31),ISNUMBER(C31)),IF(C31<>0,(B31-C31)/ABS(C31),""),"")
A32: (−) المصاريف | B32: =IF(ISNUMBER(C8),C8,"") -> 2453.8636 | C32: =IF('05-مايو'!$B$32="","",'05-مايو'!$B$32) -> 2080 | D32: =IF(AND(ISNUMBER(B32),ISNUMBER(C32)),B32-C32,"") -> 373.86364 | E32: =IF(AND(ISNUMBER(B32),ISNUMBER(C32)),IF(C32<>0,(B32-C32)/ABS(C32),""),"") -> 0.17974213
A33: (=) الربح الحقيقي التشغيلي | B33: =IF($H$3=1,B31-B32,"") | C33: =IF('05-مايو'!$B$33="","",'05-مايو'!$B$33) | D33: =IF(AND(ISNUMBER(B33),ISNUMBER(C33)),B33-C33,"") | E33: =IF(AND(ISNUMBER(B33),ISNUMBER(C33)),IF(C33<>0,(B33-C33)/ABS(C33),""),"")
A34: هامش الربح الحقيقي % | B34: =IF(AND($H$3=1,N(B26)>0),B33/B26,"") | C34: =IF('05-مايو'!$B$34="","",'05-مايو'!$B$34) | D34: =IF(AND(ISNUMBER(B34),ISNUMBER(C34)),B34-C34,"")
A35: أثر تغير الصرف على مخزون الليرة | B35: =IF($H$3=1,$H$4,"") | C35: =IF('05-مايو'!$B$35="","",'05-مايو'!$B$35) | D35: =IF(AND(ISNUMBER(B35),ISNUMBER(C35)),B35-C35,"") | E35: =IF(AND(ISNUMBER(B35),ISNUMBER(C35)),IF(C35<>0,(B35-C35)/ABS(C35),""),"")
A36: صافي الربح بعد أثر الصرف | B36: =IF($H$3=1,B33+B35,"") | C36: =IF('05-مايو'!$B$36="","",'05-مايو'!$B$36) | D36: =IF(AND(ISNUMBER(B36),ISNUMBER(C36)),B36-C36,"") | E36: =IF(AND(ISNUMBER(B36),ISNUMBER(C36)),IF(C36<>0,(B36-C36)/ABS(C36),""),"")
A37: للمرجع: الربح التقديري (مبيعات − مشتريات − مصاريف) | B37: =IF(ISNUMBER(C9),C9,"") -> 7834.3939 | C37: =IF('05-مايو'!$B$37="","",'05-مايو'!$B$37) -> 3691.04 | D37: =IF(AND(ISNUMBER(B37),ISNUMBER(C37)),B37-C37,"") -> 4143.3539 | E37: =IF(AND(ISNUMBER(B37),ISNUMBER(C37)),IF(C37<>0,(B37-C37)/ABS(C37),""),"") -> 1.1225438
A39: مؤشرات إضافية
A40: المؤشر | B40: هذا الشهر | C40: الشهر السابق | D40: التغير | E40: التغير %
A41: نسبة المصاريف من المبيعات % | B41: =IF(AND(ISNUMBER(B32),N(B26)>0),B32/B26,"") -> 0.1640682 | C41: =IF('05-مايو'!$B$41="","",'05-مايو'!$B$41) -> 0.15918302 | D41: =IF(AND(ISNUMBER(B41),ISNUMBER(C41)),B41-C41,"") -> 0.0048851747
A42: نسبة تكلفة المبيعات من المبيعات % | B42: =IF(AND(ISNUMBER(B30),N(B26)>0),B30/B26,"") | C42: =IF('05-مايو'!$B$42="","",'05-مايو'!$B$42) | D42: =IF(AND(ISNUMBER(B42),ISNUMBER(C42)),B42-C42,"")
A43: قيمة المخزون الكلية ($) | B43: =IF(ISNUMBER(C22),C22,"") -> 44737.392 | C43: =IF('05-مايو'!$B$43="","",'05-مايو'!$B$43) | D43: =IF(AND(ISNUMBER(B43),ISNUMBER(C43)),B43-C43,"") | E43: =IF(AND(ISNUMBER(B43),ISNUMBER(C43)),IF(C43<>0,(B43-C43)/ABS(C43),""),"")
...

Sheet 07-يوليو
A1: تقرير شهر يوليو 2026 — الأرباح الحقيقية بالدولار الأمريكي | G1: خلايا مساعدة (خارج الطباعة)
A2: سعر الصرف المعتمد (ل.س مقابل 1$) — من لوحة التحكم | B2: =IF(ISNUMBER('لوحة التحكم'!$C$16),'لوحة التحكم'!$C$16,0) -> 13300 | C2: حالة الشهر | D2: =$H$6 -> ✅ جاهز — ربح حقيقي | G2: سعر صرف الشهر السابق | H2: ='06-يونيو'!$B$2 -> 13200
A3: =IF($H$5=0,"لا توجد بيانات لهذا الشهر بعد — أدخل المدخلات أدناه",IF($H$13>0,(IF($H$7=1,"⚠ سعر الصرف غير مُدخل في لوحة التحكم. ","")&IF($H$8=1,"⚠ أكمل المبيعات والمشتريات والمصاريف. ","")&IF($H$9=1,"⚠ الصق بيانات المستودع في فقرة «بيانات المستودع». ","")&IF($H$10=1,"⚠ الصف الملصوق يخص شهرًا آخر. ","")&IF($H$11=1,"⚠ سعر صرف المستودع ("&$B$21&") يختلف عن سعر لوحة التحكم ("&$B$2&"). ","")&IF($H$12=1,"⚠ ملف المستودع فيه أصناف بها أخطاء (العدد: "&$E$21&") — صحّحها ثم أعد التصدير.","")),IF($H$3=1,"✅ البيانات مكتملة — الربح الحقيقي محسوب","ℹ الربح الحقيقي غير متاح (يلزم مخزون هذا الشهر والشهر السابق وسعر صرف الشهرين) — المعروض ربح تقديري فقط"))) -> ✅ البيانات مكتملة — الربح الحقيقي محسوب | G3: الربح الحقيقي جاهز؟ (1/0) | H3: =IF(AND($B$2>0,H2>0,COUNT(B6:B8)=3,ISNUMBER(C22),ISNUMBER('06-يونيو'!$C$22),ISNUMBER('06-يونيو'!$D$21)),1,0) -> 1
A4: مدخلات الشهر (أدخل بالليرة السورية من برنامج المحاسبة) — الخلايا الصفراء | G4: أثر الصرف على مخزون الليرة ($) | H4: =IF(H3=1,'06-يونيو'!$D$21*(1/$B$2-1/H2),0) -> -116.37287
A5: البيان | B5: المبلغ (ل.س) | C5: المعادل ($) | D5: ملاحظة | G5: فيه بيانات؟ (1/0) | H5: =IF(COUNTA(B6:B8,B13:C15,A21:E21)>0,1,0) -> 1
A6: المبيعات | B6: 191042000 | C6: =IF(AND(ISNUMBER(B6),$B$2>0),B6/$B$2,"") -> 14364.06 | D6: إجمالي مبيعات الشهر | G6: حالة الشهر | H6: =IF(H5=0,"لا بيانات",IF(H3=1,IF(H13=0,"✅ جاهز — ربح حقيقي","⚠ ربح حقيقي مع تنبيهات"),IF(H13>0,"⚠ تنبيهات — راجع الصفحة",IF(COUNT(B6:B8)=3,"ℹ ربح تقديري فقط","⚠ بيانات ناقصة")))) -> ✅ جاهز — ربح حقيقي
