Workbook

Sheet لوحة التحكم
B1: لوحة تحكم المستودع — 2026
B2: كل المبالغ بالدولار الأمريكي (USD) · الخلايا الصفراء بخط أزرق = خلايا الإدخال · غيرها معادلات
B3: =IF($K$10="جاهز","✓ بيانات شهر "&INDEX($B$16:$B$27,$D$6)&" جاهزة · كل المبالغ بالدولار",IF($K$10="لا بيانات","⚠ لا توجد بيانات في ورقة "&INDEX($B$16:$B$27,$D$6)&" — الصق الجدول في الخلية A1 من ورقة الشهر",IF($K$10="أدخل سعر الصرف","⚠ أدخل سعر صرف شهر "&INDEX($B$16:$B$27,$D$6)&" في الخلية الصفراء بجدول أسعار الصرف أدناه","⚠ الملف تجاوز 500 صنفًا — راجع التعليمات في ورقة اقرأني"))) -> ✓ بيانات شهر أيلول جاهزة · كل المبالغ بالدولار
B4: =IF(IF(N('الملخص الشهري'!B45)>0," • كانون الثاني ("&'الملخص الشهري'!B45&" صنف)","")&IF(N('الملخص الشهري'!C45)>0," • شباط ("&'الملخص الشهري'!C45&" صنف)","")&IF(N('الملخص الشهري'!D45)>0," • آذار ("&'الملخص الشهري'!D45&" صنف)","")&IF(N('الملخص الشهري'!E45)>0," • نيسان ("&'الملخص الشهري'!E45&" صنف)","")&IF(N('الملخص الشهري'!F45)>0," • أيار ("&'الملخص الشهري'!F45&" صنف)","")&IF(N('الملخص الشهري'!G45)>0," • حزيران ("&'الملخص الشهري'!G45&" صنف)","")&IF(N('الملخص الشهري'!H45)>0," • تموز ("&'الملخص الشهري'!H45&" صنف)","")&IF(N('الملخص الشهري'!I45)>0," • آب ("&'الملخص الشهري'!I45&" صنف)","")&IF(N('الملخص الشهري'!J45)>0," • أيلول ("&'الملخص الشهري'!J45&" صنف)","")&IF(N('الملخص الشهري'!K45)>0," • تشرين الأول ("&'الملخص الشهري'!K45&" صنف)","")&IF(N('الملخص الشهري'!L45)>0," • تشرين الثاني ("&'الملخص الشهري'!L45&" صنف)","")&IF(N('الملخص الشهري'!M45)>0," • كانون الأول ("&'الملخص الشهري'!M45&" صنف)","")="","✓ لا أخطاء في بيانات أي شهر","⚠ أخطاء في بيانات:"&IF(N('الملخص الشهري'!B45)>0," • كانون الثاني ("&'الملخص الشهري'!B45&" صنف)","")&IF(N('الملخص الشهري'!C45)>0," • شباط ("&'الملخص الشهري'!C45&" صنف)","")&IF(N('الملخص الشهري'!D45)>0," • آذار ("&'الملخص الشهري'!D45&" صنف)","")&IF(N('الملخص الشهري'!E45)>0," • نيسان ("&'الملخص الشهري'!E45&" صنف)","")&IF(N('الملخص الشهري'!F45)>0," • أيار ("&'الملخص الشهري'!F45&" صنف)","")&IF(N('الملخص الشهري'!G45)>0," • حزيران ("&'الملخص الشهري'!G45&" صنف)","")&IF(N('الملخص الشهري'!H45)>0," • تموز ("&'الملخص الشهري'!H45&" صنف)","")&IF(N('الملخص الشهري'!I45)>0," • آب ("&'الملخص الشهري'!I45&" صنف)","")&IF(N('الملخص الشهري'!J45)>0," • أيلول ("&'الملخص الشهري'!J45&" صنف)","")&IF(N('الملخص الشهري'!K45)>0," • تشرين الأول ("&'الملخص الشهري'!K45&" صنف)","")&IF(N('الملخص الشهري'!L45)>0," • تشرين الثاني ("&'الملخص الشهري'!L45&" صنف)","")&IF(N('الملخص الشهري'!M45)>0," • كانون الأول ("&'الملخص الشهري'!M45&" صنف)","")&" — التفاصيل في ورقة فحص الأخطاء وفي عمود الملاحظات بورقة الشهر") -> ✓ لا أخطاء في بيانات أي شهر
B5: ⚙ الإعدادات | K5: ورقة الشهر المعروض
B6: الشهر المعروض | C6: آخر شهر متوفر | D6: =IFERROR(IF($C$6="آخر شهر متوفر",MAX(1,SUMPRODUCT(MAX(($D$16:$D$27>0)*$G$16:$G$27))),MATCH($C$6,$B$16:$B$27,0)),1) -> 9 | E6: يتحكم بالمقارنة وفحص الأخطاء وبقية اللوحة (اتركه «آخر شهر متوفر» ليتبع آخر شهر فيه بيانات) | K6: =INDEX($F$16:$F$27,$D$6) -> 09-أيلول
B7: سعر البيع المعتمد لحساب الربح | C7: سعر الجملة | D7: =IF($C$7="القطاعي",2,IF($C$7="جملة الجملة",3,1)) -> 1 | E7: الاختيارات: سعر الجملة / القطاعي / جملة الجملة | K7: جاهز؟
B8: الفئة الفرعية المتوقع لها سعر بيع | C8: مواد جاهزة للبيع | E8: الأصناف في هذه الفئة بكمية وسعر بيع صفر تُسجَّل كخطأ؛ المواد الخام والطبخات لا يُتوقع لها سعر بيع | K8: =INDEX('الملخص الشهري'!$B$8:$M$8,$D$6) -> 1
B9: حد الشك بأسعار الليرة (أقل من) | C9: 50 | E9: صنف عملته ليرة وسعره أقل من هذا الرقم غالبًا أُدخل بالدولار خطأ | K9: الحالة
B10: حد الشك بأسعار الدولار (أكبر من) | C10: 5000 | E10: صنف عملته دولار وسعره أكبر من هذا الرقم غالبًا أُدخل بالليرة خطأ | K10: =INDEX('الملخص الشهري'!$B$7:$M$7,$D$6) -> جاهز
B11: أعلى نسبة مقبولة بين أسعار البيع | C11: 1.5 | E11: إذا كان أعلى سعر بيع أكبر من الأدنى بأكثر من هذه النسبة يُسجَّل «تباين» | K11: فيه بيانات؟
B12: نسبة تغير سعر الشراء المهمة | C12: 0.1 | E12: تُستخدم لعدّ الأصناف التي ارتفع/انخفض سعر شرائها مقارنة بالشهر السابق | K12: =IF(AND(INDEX('الملخص الشهري'!$B$5:$M$5,$D$6)>0,INDEX('الملخص الشهري'!$B$5:$M$5,$D$6)<=500),1,0) -> 1
K13: فهرس أعلى قيمة | L13: فهرس أعلى ربح
B14: 💱 أسعار الصرف الشهرية (ليرة سورية مقابل 1 دولار) — أدخل سعر كل شهر
B15: الشهر | C15: سعر الصرف | D15: عدد الأصناف الملصوقة | E15: الحالة | F15: اسم الورقة | G15: رقم الشهر | H15: أصناف بها أخطاء
B16: كانون الثاني | D16: ='الملخص الشهري'!B5 -> 0 | E16: ='الملخص الشهري'!B7 -> لا بيانات | F16: 01-كانون الثاني | G16: 1 | H16: =IF(N('الملخص الشهري'!B45)>0,'الملخص الشهري'!B45,"")
B17: شباط | D17: ='الملخص الشهري'!C5 -> 0 | E17: ='الملخص الشهري'!C7 -> لا بيانات | F17: 02-شباط | G17: 2 | H17: =IF(N('الملخص الشهري'!C45)>0,'الملخص الشهري'!C45,"")
B18: آذار | D18: ='الملخص الشهري'!D5 -> 0 | E18: ='الملخص الشهري'!D7 -> لا بيانات | F18: 03-آذار | G18: 3 | H18: =IF(N('الملخص الشهري'!D45)>0,'الملخص الشهري'!D45,"")
B19: نيسان | D19: ='الملخص الشهري'!E5 -> 0 | E19: ='الملخص الشهري'!E7 -> لا بيانات | F19: 04-نيسان | G19: 4 | H19: =IF(N('الملخص الشهري'!E45)>0,'الملخص الشهري'!E45,"")
B20: أيار | D20: ='الملخص الشهري'!F5 -> 0 | E20: ='الملخص الشهري'!F7 -> لا بيانات | F20: 05-أيار | G20: 5 | H20: =IF(N('الملخص الشهري'!F45)>0,'الملخص الشهري'!F45,"")
B21: حزيران | C21: 13200 | D21: ='الملخص الشهري'!G5 -> 236 | E21: ='الملخص الشهري'!G7 -> جاهز | F21: 06-حزيران | G21: 6 | H21: =IF(N('الملخص الشهري'!G45)>0,'الملخص الشهري'!G45,"")
B22: تموز | C22: 13300 | D22: ='الملخص الشهري'!H5 -> 239 | E22: ='الملخص الشهري'!H7 -> جاهز | F22: 07-تموز | G22: 7 | H22: =IF(N('الملخص الشهري'!H45)>0,'الملخص الشهري'!H45,"")
B23: آب | C23: 13200 | D23: ='الملخص الشهري'!I5 -> 261 | E23: ='الملخص الشهري'!I7 -> جاهز | F23: 08-آب | G23: 8 | H23: =IF(N('الملخص الشهري'!I45)>0,'الملخص الشهري'!I45,"")
B24: أيلول | C24: 13800 | D24: ='الملخص الشهري'!J5 -> 268 | E24: ='الملخص الشهري'!J7 -> جاهز | F24: 09-أيلول | G24: 9 | H24: =IF(N('الملخص الشهري'!J45)>0,'الملخص الشهري'!J45,"")
B25: تشرين الأول | D25: ='الملخص الشهري'!K5 -> 0 | E25: ='الملخص الشهري'!K7 -> لا بيانات | F25: 10-تشرين الأول | G25: 10 | H25: =IF(N('الملخص الشهري'!K45)>0,'الملخص الشهري'!K45,"")
B26: تشرين الثاني | D26: ='الملخص الشهري'!L5 -> 0 | E26: ='الملخص الشهري'!L7 -> لا بيانات | F26: 11-تشرين الثاني | G26: 11 | H26: =IF(N('الملخص الشهري'!L45)>0,'الملخص الشهري'!L45,"")
B27: كانون الأول | D27: ='الملخص الشهري'!M5 -> 0 | E27: ='الملخص الشهري'!M7 -> لا بيانات | F27: 12-كانون الأول | G27: 12 | H27: =IF(N('الملخص الشهري'!M45)>0,'الملخص الشهري'!M45,"")
B29: 📊 ملخص الشهر المعروض
B30: ="الشهر: "&INDEX($B$16:$B$27,$D$6)&" 2026" -> الشهر: أيلول 2026
B31: قيمة المستودع (بسعر الشراء) | D31: القيمة البيعية المتوقعة | F31: الربح المتوقع | H31: هامش الربح من المبيع
B32: =IFERROR(INDEX('الملخص الشهري'!$B$11:$M$11,$D$6),"") -> 44900.767 | D32: =IFERROR(INDEX('الملخص الشهري'!$B$12:$M$12,$D$6),"") -> 18699.77 | F32: =IFERROR(INDEX('الملخص الشهري'!$B$14:$M$14,$D$6),"") -> 7284.6252 | H32: =IFERROR(INDEX('الملخص الشهري'!$B$15:$M$15,$D$6),"") -> 0.38955693
B33: =IF(ISNUMBER(IFERROR(INDEX('الملخص الشهري'!$B$28:$M$28,$D$6),"")),IF(IFERROR(INDEX('الملخص الشهري'!$B$28:$M$28,$D$6),"")>=0,"▲ ","▼ ")&TEXT(ABS(IFERROR(INDEX('الملخص الشهري'!$B$28:$M$28,$D$6),"")),"0.0%")&" عن الشهر السابق","—") -> ▼ 6.3% عن الشهر السابق | D33: =IF(ISNUMBER(IFERROR(INDEX('الملخص الشهري'!$B$18:$M$18,$D$6),"")),"+ "&TEXT(IFERROR(INDEX('الملخص الشهري'!$B$18:$M$18,$D$6),""),"#,##0")&"$ أصناف بلا سعر شراء","—") -> + 0$ أصناف بلا سعر شراء | F33: =IF(ISNUMBER(IFERROR(INDEX('الملخص الشهري'!$B$29:$M$29,$D$6),"")),IF(IFERROR(INDEX('الملخص الشهري'!$B$29:$M$29,$D$6),"")>=0,"▲ ","▼ ")&TEXT(ABS(IFERROR(INDEX('الملخص الشهري'!$B$29:$M$29,$D$6),"")),"#,##0")&"$ عن الشهر السابق","—") -> ▼ 1,859$ عن الشهر السابق | H33: =IF(ISNUMBER(IFERROR(INDEX('الملخص الشهري'!$B$16:$M$16,$D$6),"")),"نسبة الربح على التكلفة: "&TEXT(IFERROR(INDEX('الملخص الشهري'!$B$16:$M$16,$D$6),""),"0.0%"),"—") -> نسبة الربح على التكلفة: 63.8%
B35: التوزيع حسب الفئة الفرعية والعملة
B36: الفئة الفرعية | C36: قيمة المخزون $ | D36: % من الإجمالي | E36: الربح المتوقع $ | F36: العملة | G36: قيمة المخزون $ | H36: % من المخزون
B37: ='الملخص الشهري'!A47 -> مواد جاهزة للبيع | C37: =IFERROR(INDEX('الملخص الشهري'!$B$47:$M$47,$D$6),"") -> 9961.3769 | D37: =IF(AND(ISNUMBER(C37),N($B$32)>0),C37/$B$32,"") -> 0.22185316 | E37: =IFERROR(INDEX('الملخص الشهري'!$B$53:$M$53,$D$6),"") -> 6503.0826 | F37: مسعّر بالليرة | G37: =IFERROR(INDEX('الملخص الشهري'!$B$23:$M$23,$D$6),"") -> 10157.255 | H37: =IFERROR(INDEX('الملخص الشهري'!$B$25:$M$25,$D$6),"") -> 0.22621563
B38: ='الملخص الشهري'!A48 -> مواد خام | C38: =IFERROR(INDEX('الملخص الشهري'!$B$48:$M$48,$D$6),"") -> 34922.59 | D38: =IF(AND(ISNUMBER(C38),N($B$32)>0),C38/$B$32,"") -> 0.77777268 | E38: =IFERROR(INDEX('الملخص الشهري'!$B$54:$M$54,$D$6),"") -> 781.54255 | F38: مسعّر بالدولار | G38: =IFERROR(INDEX('الملخص الشهري'!$B$24:$M$24,$D$6),"") -> 34743.512 | H38: =IF(ISNUMBER(H37),1-H37,"") -> 0.77378437
B39: ='الملخص الشهري'!A49 -> الطبخات | C39: =IFERROR(INDEX('الملخص الشهري'!$B$49:$M$49,$D$6),"") -> 16.8 | D39: =IF(AND(ISNUMBER(C39),N($B$32)>0),C39/$B$32,"") -> 0.00037415842 | E39: =IFERROR(INDEX('الملخص الشهري'!$B$55:$M$55,$D$6),"") -> 0
B40: ='الملخص الشهري'!A50 -> All | C40: =IFERROR(INDEX('الملخص الشهري'!$B$50:$M$50,$D$6),"") -> 0 | D40: =IF(AND(ISNUMBER(C40),N($B$32)>0),C40/$B$32,"") -> 0 | E40: =IFERROR(INDEX('الملخص الشهري'!$B$56:$M$56,$D$6),"") -> 0 | F40: نسبة الليرة العالية تعني أن جزءًا كبيرًا من قيمة المخزون بالدولار يتأثر بتغير سعر الصرف.
B41: ='الملخص الشهري'!A51 -> أخرى / غير مدرجة | C41: =IFERROR(INDEX('الملخص الشهري'!$B$51:$M$51,$D$6),"") -> -7.2759576e-12 | D41: =IF(AND(ISNUMBER(C41),N($B$32)>0),C41/$B$32,"") -> -1.6204529e-16 | E41: =IFERROR(INDEX('الملخص الشهري'!$B$57:$M$57,$D$6),"") -> -5.4569682e-12
B43: المقارنة بالشهر السابق | جودة البيانات (تفاصيلها في ورقة فحص الأخطاء)
...

Sheet اقرأني
B1: دليل الاستخدام
B3: الإجراء الشهري (5 خطوات)
B4: 1) من برنامج المحاسبة صدّر ملف الأصناف كما هو (نفس الأعمدة التسعة وبنفس الترتيب).
B5: 2) افتح ورقة الشهر (مثل «08-آب»)، حدد A2:I501 ثم اضغط Delete لمسح اللصق القديم إن وُجد.
B6: 3) انسخ الجدول كاملًا مع صف العناوين والصقه في الخلية A1. لا تلمس الأعمدة من K فما بعد: هي معادلات جاهزة.
B7: 4) انظر إلى الخلية الأولى في عمود «تنبيه» (K1): أخضر ✓ = لا ملاحظات، أحمر ⚠ = يوجد أصناف بها أخطاء (تظهر بخلفية حمراء مع وصف الخطأ في عمود «ملاحظات / أخطاء»).
B8: 5) في «لوحة التحكم» أدخل سعر صرف ذلك الشهر في الخلية الصفراء، ثم راجع اللوحة و«المقارنة» و«فحص الأخطاء».
B9: كيف يُنبَّه إلى الأخطاء؟
B10: • أعلى «لوحة التحكم»: شريط يذكر الأشهر التي فيها أخطاء وعدد الأصناف في كل منها، وشريط آخر يخبرك إن كان ينقصك سعر الصرف أو البيانات.
B11: • جدول أسعار الصرف في اللوحة: عمود «أصناف بها أخطاء» لكل شهر.
B12: • كل ورقة شهر: خلية تنبيه ملونة في K1 + علامة ⚠ وخلفية حمراء على كل صنف به خطأ (يمكنك التصفية بعمود الملاحظات).
B13: • «فحص الأخطاء»: قائمة الأصناف المعيبة للشهر المعروض مع شرح كل نوع وطريقة المعالجة.
... B40: • الصف يحمل: سعر صرف هذا الملف، المخزون المسعّر بالدولار، المخزون المسعّر بالليرة (بالليرة نفسها)، وعدد الأصناف التي بها أخطاء.

Sheet الملخص الشهري
A1: الملخص الشهري — كل المبالغ بالدولار الأمريكي
A2: كل الخلايا هنا معادلات تُحسب تلقائيًا من أوراق الأشهر. لا تُدخل شيئًا في هذه الورقة (عدا أسماء الفئات الفرعية باللون الأزرق).
A4: المؤشر | B4: كانون الثاني | C4: شباط | D4: آذار | E4: نيسان | F4: أيار | G4: حزيران | H4: تموز | I4: آب | J4: أيلول | K4: تشرين الأول | L4: تشرين الثاني | M4: كانون الأول
A5: عدد الأصناف الملصوقة | B5: =COUNTA('01-كانون الثاني'!$A$2:$A$5000) -> 0 | C5: =COUNTA('02-شباط'!$A$2:$A$5000) -> 0 | D5: =COUNTA('03-آذار'!$A$2:$A$5000) -> 0 | E5: =COUNTA('04-نيسان'!$A$2:$A$5000) -> 0 | F5: =COUNTA('05-أيار'!$A$2:$A$5000) -> 0 | G5: =COUNTA('06-حزيران'!$A$2:$A$4998) -> 236 | H5: =COUNTA('07-تموز'!$A$2:$A$4999) -> 239 | I5: =COUNTA('08-آب'!$A$2:$A$5000) -> 261 | J5: =COUNTA('09-أيلول'!$A$2:$A$4999) -> 268 | K5: =COUNTA('10-تشرين الأول'!$A$2:$A$5000) -> 0 | L5: =COUNTA('11-تشرين الثاني'!$A$2:$A$5000) -> 0 | M5: =COUNTA('12-كانون الأول'!$A$2:$A$5000) -> 0
A6: سعر الصرف (ل.س لكل 1$) | B6: =IF('لوحة التحكم'!$C$16="","",'لوحة التحكم'!$C$16) | C6: =IF('لوحة التحكم'!$C$17="","",'لوحة التحكم'!$C$17) | D6: =IF('لوحة التحكم'!$C$18="","",'لوحة التحكم'!$C$18) | E6: =IF('لوحة التحكم'!$C$19="","",'لوحة التحكم'!$C$19) | F6: =IF('لوحة التحكم'!$C$20="","",'لوحة التحكم'!$C$20) | G6: =IF('لوحة التحكم'!$C$21="","",'لوحة التحكم'!$C$21) -> 13200 | H6: =IF('لوحة التحكم'!$C$22="","",'لوحة التحكم'!$C$22) -> 13300 | I6: =IF('لوحة التحكم'!$C$23="","",'لوحة التحكم'!$C$23) -> 13200 | J6: =IF('لوحة التحكم'!$C$24="","",'لوحة التحكم'!$C$24) -> 13800 | K6: =IF('لوحة التحكم'!$C$25="","",'لوحة التحكم'!$C$25) | L6: =IF('لوحة التحكم'!$C$26="","",'لوحة التحكم'!$C$26) | M6: =IF('لوحة التحكم'!$C$27="","",'لوحة التحكم'!$C$27)
A7: حالة الشهر | B7: =IF(B5=0,"لا بيانات",IF(B5>500,"تجاوز السعة",IF(AND(COUNTIF('01-كانون الثاني'!$F$2:$F$501,"*ليرة*")>0,N(B6)<=0),"أدخل سعر الصرف","جاهز"))) -> لا بيانات | C7: =IF(C5=0,"لا بيانات",IF(C5>500,"تجاوز السعة",IF(AND(COUNTIF('02-شباط'!$F$2:$F$501,"*ليرة*")>0,N(C6)<=0),"أدخل سعر الصرف","جاهز"))) -> لا بيانات | D7: =IF(D5=0,"لا بيانات",IF(D5>500,"تجاوز السعة",IF(AND(COUNTIF('03-آذار'!$F$2:$F$501,"*ليرة*")>0,N(D6)<=0),"أدخل سعر الصرف","جاهز"))) -> لا بيانات | E7: =IF(E5=0,"لا بيانات",IF(E5>500,"تجاوز السعة",IF(AND(COUNTIF('04-نيسان'!$F$2:$F$501,"*ليرة*")>0,N(E6)<=0),"أدخل سعر الصرف","جاهز"))) -> لا بيانات | F7: =IF(F5=0,"لا بيانات",IF(F5>500,"تجاوز السعة",IF(AND(COUNTIF('05-أيار'!$F$2:$F$501,"*ليرة*")>0,N(F6)<=0),"أدخل سعر الصرف","جاهز"))) -> لا بيانات | G7: =IF(G5=0,"لا بيانات",IF(G5>500,"تجاوز السعة",IF(AND(COUNTIF('06-حزيران'!$F$2:$F$499,"*ليرة*")>0,N(G6)<=0),"أدخل سعر الصرف","جاهز"))) -> جاهز | H7: =IF(H5=0,"لا بيانات",IF(H5>500,"تجاوز السعة",IF(AND(COUNTIF('07-تموز'!$F$2:$F$500,"*ليرة*")>0,N(H6)<=0),"أدخل سعر الصرف","جاهز"))) -> جاهز | I7: =IF(I5=0,"لا بيانات",IF(I5>500,"تجاوز السعة",IF(AND(COUNTIF('08-آب'!$F$2:$F$501,"*ليرة*")>0,N(I6)<=0),"أدخل سعر الصرف","جاهز"))) -> جاهز | J7: =IF(J5=0,"لا بيانات",IF(J5>500,"تجاوز السعة",IF(AND(COUNTIF('09-أيلول'!$F$2:$F$500,"*ليرة*")>0,N(J6)<=0),"أدخل سعر الصرف","جاهز"))) -> جاهز | K7: =IF(K5=0,"لا بيانات",IF(K5>500,"تجاوز السعة",IF(AND(COUNTIF('10-تشرين الأول'!$F$2:$F$501,"*ليرة*")>0,N(K6)<=0),"أدخل سعر الصرف","جاهز"))) -> لا بيانات | L7: =IF(L5=0,"لا بيانات",IF(L5>500,"تجاوز السعة",IF(AND(COUNTIF('11-تشرين الثاني'!$F$2:$F$501,"*ليرة*")>0,N(L6)<=0),"أدخل سعر الصرف","جاهز"))) -> لا بيانات | M7: =IF(M5=0,"لا بيانات",IF(M5>500,"تجاوز السعة",IF(AND(COUNTIF('12-كانون الأول'!$F$2:$F$501,"*ليرة*")>0,N(M6)<=0),"أدخل سعر الصرف","جاهز"))) -> لا بيانات
A8: جاهز للحساب (1/0) | B8: =IF(B7="جاهز",1,0) -> 0 | C8: =IF(C7="جاهز",1,0) -> 0 | D8: =IF(D7="جاهز",1,0) -> 0 | E8: =IF(E7="جاهز",1,0) -> 0 | F8: =IF(F7="جاهز",1,0) -> 0 | G8: =IF(G7="جاهز",1,0) -> 1 | H8: =IF(H7="جاهز",1,0) -> 1 | I8: =IF(I7="جاهز",1,0) -> 1 | ... M8: =IF(M7="جاهز",1,0) -> 0
A9: المخزون والربحية
A10: أصناف كميتها موجبة | B10: =IF(B$8=1,COUNTIF('01-كانون الثاني'!$P$2:$P$501,">0"),"") | C10: =IF(C$8=1,COUNTIF('02-شباط'!$P$2:$P$501,">0"),"") | D10: =IF(D$8=1,COUNTIF('03-آذار'!$P$2:$P$501,">0"),"") | E10: =IF(E$8=1,COUNTIF('04-نيسان'!$P$2:$P$501,">0"),"") | F10: =IF(F$8=1,COUNTIF('05-أيار'!$P$2:$P$501,">0"),"") | G10: =IF(G$8=1,COUNTIF('06-حزيران'!$P$2:$P$499,">0"),"") -> 107 | H10: =IF(H$8=1,COUNTIF('07-تموز'!$P$2:$P$500,">0"),"") -> 113 | I10: =IF(I$8=1,COUNTIF('08-آب'!$P$2:$P$501,">0"),"") -> 136 | J10: =IF(J$8=1,COUNTIF('09-أيلول'!$P$2:$P$500,">0"),"") -> 134 | K10: =IF(K$8=1,COUNTIF('10-تشرين الأول'!$P$2:$P$501,">0"),"") | L10: =IF(L$8=1,COUNTIF('11-تشرين الثاني'!$P$2:$P$501,">0"),"") | M10: =IF(M$8=1,COUNTIF('12-كانون الأول'!$P$2:$P$501,">0"),"")
A11: قيمة المستودع بسعر الشراء | B11: =IF(B$8=1,SUM('01-كانون الثاني'!$Q$2:$Q$501),"") | C11: =IF(C$8=1,SUM('02-شباط'!$Q$2:$Q$501),"") | D11: =IF(D$8=1,SUM('03-آذار'!$Q$2:$Q$501),"") | E11: =IF(E$8=1,SUM('04-نيسان'!$Q$2:$Q$501),"") | F11: =IF(F$8=1,SUM('05-أيار'!$Q$2:$Q$501),"") | G11: =IF(G$8=1,SUM('06-حزيران'!$Q$2:$Q$499),"") -> 44737.39 | H11: =IF(H$8=1,SUM('07-تموز'!$Q$2:$Q$500),"") -> 48491.032 | I11: =IF(I$8=1,SUM('08-آب'!$Q$2:$Q$501),"") -> 47944.021 | J11: =IF(J$8=1,SUM('09-أيلول'!$Q$2:$Q$500),"") -> 44900.767 | K11: =IF(K$8=1,SUM('10-تشرين الأول'!$Q$2:$Q$501),"") | L11: =IF(L$8=1,SUM('11-تشرين الثاني'!$Q$2:$Q$501),"") | M11: =IF(M$8=1,SUM('12-كانون الأول'!$Q$2:$Q$501),"")
A12: القيمة البيعية المتوقعة (للأصناف مكتملة التسعير) | B12: =IF(B$8=1,SUMIFS('01-كانون الثاني'!$R$2:$R$501,'01-كانون الثاني'!$S$2:$S$501,1),"") | C12: =IF(C$8=1,SUMIFS('02-شباط'!$R$2:$R$501,'02-شباط'!$S$2:$S$501,1),"") | D12: =IF(D$8=1,SUMIFS('03-آذار'!$R$2:$R$501,'03-آذار'!$S$2:$S$501,1),"") | E12: =IF(E$8=1,SUMIFS('04-نيسان'!$R$2:$R$501,'04-نيسان'!$S$2:$S$501,1),"") | F12: =IF(F$8=1,SUMIFS('05-أيار'!$R$2:$R$501,'05-أيار'!$S$2:$S$501,1),"") | G12: =IF(G$8=1,SUMIFS('06-حزيران'!$R$2:$R$499,'06-حزيران'!$S$2:$S$499,1),"") -> 25034.172 | H12: =IF(H$8=1,SUMIFS('07-تموز'!$R$2:$R$500,'07-تموز'!$S$2:$S$500,1),"") -> 22961.061 | I12: =IF(I$8=1,SUMIFS('08-آب'!$R$2:$R$501,'08-آب'!$S$2:$S$501,1),"") -> 23866.931 | J12: =IF(J$8=1,SUMIFS('09-أيلول'!$R$2:$R$500,'09-أيلول'!$S$2:$S$500,1),"") -> 18699.77 | K12: =IF(K$8=1,SUMIFS('10-تشرين الأول'!$R$2:$R$501,'10-تشرين الأول'!$S$2:$S$501,1),"") | L12: =IF(L$8=1,SUMIFS('11-تشرين الثاني'!$R$2:$R$501,'11-تشرين الثاني'!$S$2:$S$501,1),"") | M12: =IF(M$8=1,SUMIFS('12-كانون الأول'!$R$2:$R$501,'12-كانون الأول'!$S$2:$S$501,1),"")
A13: تكلفة الأصناف مكتملة التسعير | B13: =IF(B$8=1,SUMIFS('01-كانون الثاني'!$Q$2:$Q$501,'01-كانون الثاني'!$S$2:$S$501,1),"") | C13: =IF(C$8=1,SUMIFS('02-شباط'!$Q$2:$Q$501,'02-شباط'!$S$2:$S$501,1),"") | D13: =IF(D$8=1,SUMIFS('03-آذار'!$Q$2:$Q$501,'03-آذار'!$S$2:$S$501,1),"") | E13: =IF(E$8=1,SUMIFS('04-نيسان'!$Q$2:$Q$501,'04-نيسان'!$S$2:$S$501,1),"") | F13: =IF(F$8=1,SUMIFS('05-أيار'!$Q$2:$Q$501,'05-أيار'!$S$2:$S$501,1),"") | G13: =IF(G$8=1,SUMIFS('06-حزيران'!$Q$2:$Q$499,'06-حزيران'!$S$2:$S$499,1),"") -> 15682.554 | H13: =IF(H$8=1,SUMIFS('07-تموز'!$Q$2:$Q$500,'07-تموز'!$S$2:$S$500,1),"") -> 14150.609 | I13: =IF(I$8=1,SUMIFS('08-آب'!$Q$2:$Q$501,'08-آب'!$S$2:$S$501,1),"") -> 14723.314 | J13: =IF(J$8=1,SUMIFS('09-أيلول'!$Q$2:$Q$500,'09-أيلول'!$S$2:$S$500,1),"") -> 11415.145 | K13: =IF(K$8=1,SUMIFS('10-تشرين الأول'!$Q$2:$Q$501,'10-تشرين الأول'!$S$2:$S$501,1),"") | L13: =IF(L$8=1,SUMIFS('11-تشرين الثاني'!$Q$2:$Q$501,'11-تشرين الثاني'!$S$2:$S$501,1),"") | M13: =IF(M$8=1,SUMIFS('12-كانون الأول'!$Q$2:$Q$501,'12-كانون الأول'!$S$2:$S$501,1),"")
A14: الربح المتوقع | B14: =IF(B$8=1,B12-B13,"") | C14: =IF(C$8=1,C12-C13,"") | D14: =IF(D$8=1,D12-D13,"") | E14: =IF(E$8=1,E12-E13,"") | F14: =IF(F$8=1,F12-F13,"") | G14: =IF(G$8=1,G12-G13,"") -> 9351.6176 | H14: =IF(H$8=1,H12-H13,"") -> 8810.4512 | I14: =IF(I$8=1,I12-I13,"") -> 9143.6171 | ... M14: =IF(M$8=1,M12-M13,"")
A15: هامش الربح من المبيع % | B15: =IF(B$8=1,IF(B12>0,B14/B12,0),"") | C15: =IF(C$8=1,IF(C12>0,C14/C12,0),"") | D15: =IF(D$8=1,IF(D12>0,D14/D12,0),"") | E15: =IF(E$8=1,IF(E12>0,E14/E12,0),"") | F15: =IF(F$8=1,IF(F12>0,F14/F12,0),"") | G15: =IF(G$8=1,IF(G12>0,G14/G12,0),"") -> 0.3735541 | H15: =IF(H$8=1,IF(H12>0,H14/H12,0),"") -> 0.38371273 | I15: =IF(I$8=1,IF(I12>0,I14/I12,0),"") -> 0.3831082 | ... M15: =IF(M$8=1,IF(M12>0,M14/M12,0),"")
A16: نسبة الربح على التكلفة % | B16: =IF(B$8=1,IF(B13>0,B14/B13,0),"") | C16: =IF(C$8=1,IF(C13>0,C14/C13,0),"") | D16: =IF(D$8=1,IF(D13>0,D14/D13,0),"") | E16: =IF(E$8=1,IF(E13>0,E14/E13,0),"") | F16: =IF(F$8=1,IF(F13>0,F14/F13,0),"") | G16: =IF(G$8=1,IF(G13>0,G14/G13,0),"") -> 0.59630704 | H16: =IF(H$8=1,IF(H13>0,H14/H13,0),"") -> 0.62261992 | I16: =IF(I$8=1,IF(I13>0,I14/I13,0),"") -> 0.62102981 | ... M16: =IF(M$8=1,IF(M13>0,M14/M13,0),"")
A17: قيمة مخزون غير مُسعَّر للبيع (مواد خام/طبخات/ناقص تسعير) | B17: =IF(B$8=1,B11-B13,"") | C17: =IF(C$8=1,C11-C13,"") | D17: =IF(D$8=1,D11-D13,"") | E17: =IF(E$8=1,E11-E13,"") | F17: =IF(F$8=1,F11-F13,"") | G17: =IF(G$8=1,G11-G13,"") -> 29054.836 | H17: =IF(H$8=1,H11-H13,"") -> 34340.423 | I17: =IF(I$8=1,I11-I13,"") -> 33220.707 | ... M17: =IF(M$8=1,M11-M13,"")
A18: قيمة بيع أصناف بلا سعر شراء مسجل (تكلفتها مجهولة) | B18: =IF(B$8=1,SUMIFS('01-كانون الثاني'!$R$2:$R$501,'01-كانون الثاني'!$P$2:$P$501,">0",'01-كانون الثاني'!$N$2:$N$501,0,'01-كانون الثاني'!$O$2:$O$501,">0"),"") | C18: =IF(C$8=1,SUMIFS('02-شباط'!$R$2:$R$501,'02-شباط'!$P$2:$P$501,">0",'02-شباط'!$N$2:$N$501,0,'02-شباط'!$O$2:$O$501,">0"),"") | D18: =IF(D$8=1,SUMIFS('03-آذار'!$R$2:$R$501,'03-آذار'!$P$2:$P$501,">0",'03-آذار'!$N$2:$N$501,0,'03-آذار'!$O$2:$O$501,">0"),"") | E18: =IF(E$8=1,SUMIFS('04-نيسان'!$R$2:$R$501,'04-نيسان'!$P$2:$P$501,">0",'04-نيسان'!$N$2:$N$501,0,'04-نيسان'!$O$2:$O$501,">0"),"") | F18: =IF(F$8=1,SUMIFS('05-أيار'!$R$2:$R$501,'05-أيار'!$P$2:$P$501,">0",'05-أيار'!$N$2:$N$501,0,'05-أيار'!$O$2:$O$501,">0"),"") | G18: =IF(G$8=1,SUMIFS('06-حزيران'!$R$2:$R$499,'06-حزيران'!$P$2:$P$499,">0",'06-حزيران'!$N$2:$N$499,0,'06-حزيران'!$O$2:$O$499,">0"),"") -> 0 | H18: =IF(H$8=1,SUMIFS('07-تموز'!$R$2:$R$500,'07-تموز'!$P$2:$P$500,">0",'07-تموز'!$N$2:$N$500,0,'07-تموز'!$O$2:$O$500,">0"),"") -> 0 | I18: =IF(I$8=1,SUMIFS('08-آب'!$R$2:$R$501,'08-آب'!$P$2:$P$501,">0",'08-آب'!$N$2:$N$501,0,'08-آب'!$O$2:$O$501,">0"),"") -> 0 | J18: =IF(J$8=1,SUMIFS('09-أيلول'!$R$2:$R$500,'09-أيلول'!$P$2:$P$500,">0",'09-أيلول'!$N$2:$N$500,0,'09-أيلول'!$O$2:$O$500,">0"),"") -> 0 | K18: =IF(K$8=1,SUMIFS('10-تشرين الأول'!$R$2:$R$501,'10-تشرين الأول'!$P$2:$P$501,">0",'10-تشرين الأول'!$N$2:$N$501,0,'10-تشرين الأول'!$O$2:$O$501,">0"),"") | L18: =IF(L$8=1,SUMIFS('11-تشرين الثاني'!$R$2:$R$501,'11-تشرين الثاني'!$P$2:$P$501,">0",'11-تشرين الثاني'!$N$2:$N$501,0,'11-تشرين الثاني'!$O$2:$O$501,">0"),"") | M18: =IF(M$8=1,SUMIFS('12-كانون الأول'!$R$2:$R$501,'12-كانون الأول'!$P$2:$P$501,">0",'12-كانون الأول'!$N$2:$N$501,0,'12-كانون الأول'!$O$2:$O$501,">0"),"")
A19: الربح المتوقع لو البيع بسعر الجملة | B19: =IF(B$8=1,SUM('01-كانون الثاني'!$AH$2:$AH$501),"") | C19: =IF(C$8=1,SUM('02-شباط'!$AH$2:$AH$501),"") | D19: =IF(D$8=1,SUM('03-آذار'!$AH$2:$AH$501),"") | E19: =IF(E$8=1,SUM('04-نيسان'!$AH$2:$AH$501),"") | F19: =IF(F$8=1,SUM('05-أيار'!$AH$2:$AH$501),"") | G19: =IF(G$8=1,SUM('06-حزيران'!$AH$2:$AH$499),"") -> 9351.6176 | H19: =IF(H$8=1,SUM('07-تموز'!$AH$2:$AH$500),"") -> 8810.4512 | I19: =IF(I$8=1,SUM('08-آب'!$AH$2:$AH$501),"") -> 9143.6171 | J19: =IF(J$8=1,SUM('09-أيلول'!$AH$2:$AH$500),"") -> 7284.6252 | K19: =IF(K$8=1,SUM('10-تشرين الأول'!$AH$2:$AH$501),"") | L19: =IF(L$8=1,SUM('11-تشرين الثاني'!$AH$2:$AH$501),"") | M19: =IF(M$8=1,SUM('12-كانون الأول'!$AH$2:$AH$501),"")
A20: الربح المتوقع لو البيع بسعر القطاعي | B20: =IF(B$8=1,SUM('01-كانون الثاني'!$AI$2:$AI$501),"") | C20: =IF(C$8=1,SUM('02-شباط'!$AI$2:$AI$501),"") | D20: =IF(D$8=1,SUM('03-آذار'!$AI$2:$AI$501),"") | E20: =IF(E$8=1,SUM('04-نيسان'!$AI$2:$AI$501),"") | F20: =IF(F$8=1,SUM('05-أيار'!$AI$2:$AI$501),"") | G20: =IF(G$8=1,SUM('06-حزيران'!$AI$2:$AI$499),"") -> 9351.6176 | H20: =IF(H$8=1,SUM('07-تموز'!$AI$2:$AI$500),"") -> 8810.4512 | I20: =IF(I$8=1,SUM('08-آب'!$AI$2:$AI$501),"") -> 9143.6171 | J20: =IF(J$8=1,SUM('09-أيلول'!$AI$2:$AI$500),"") -> 7284.6252 | K20: =IF(K$8=1,SUM('10-تشرين الأول'!$AI$2:$AI$501),"") | L20: =IF(L$8=1,SUM('11-تشرين الثاني'!$AI$2:$AI$501),"") | M20: =IF(M$8=1,SUM('12-كانون الأول'!$AI$2:$AI$501),"")
A21: الربح المتوقع لو البيع بسعر جملة الجملة | B21: =IF(B$8=1,SUM('01-كانون الثاني'!$AJ$2:$AJ$501),"") | C21: =IF(C$8=1,SUM('02-شباط'!$AJ$2:$AJ$501),"") | D21: =IF(D$8=1,SUM('03-آذار'!$AJ$2:$AJ$501),"") | E21: =IF(E$8=1,SUM('04-نيسان'!$AJ$2:$AJ$501),"") | F21: =IF(F$8=1,SUM('05-أيار'!$AJ$2:$AJ$501),"") | G21: =IF(G$8=1,SUM('06-حزيران'!$AJ$2:$AJ$499),"") -> 9351.6176 | H21: =IF(H$8=1,SUM('07-تموز'!$AJ$2:$AJ$500),"") -> 8810.4512 | I21: =IF(I$8=1,SUM('08-آب'!$AJ$2:$AJ$501),"") -> 9143.6171 | J21: =IF(J$8=1,SUM('09-أيلول'!$AJ$2:$AJ$500),"") -> 7284.6252 | K21: =IF(K$8=1,SUM('10-تشرين الأول'!$AJ$2:$AJ$501),"") | L21: =IF(L$8=1,SUM('11-تشرين الثاني'!$AJ$2:$AJ$501),"") | M21: =IF(M$8=1,SUM('12-كانون الأول'!$AJ$2:$AJ$501),"")
A22: التعرض لتقلب سعر الصرف
A23: قيمة المخزون المسعّر بالليرة (بالدولار) | B23: =IF(B$8=1,SUMIFS('01-كانون الثاني'!$Q$2:$Q$501,'01-كانون الثاني'!$F$2:$F$501,"*ليرة*"),"") | C23: =IF(C$8=1,SUMIFS('02-شباط'!$Q$2:$Q$501,'02-شباط'!$F$2:$F$501,"*ليرة*"),"") | D23: =IF(D$8=1,SUMIFS('03-آذار'!$Q$2:$Q$501,'03-آذار'!$F$2:$F$501,"*ليرة*"),"") | E23: =IF(E$8=1,SUMIFS('04-نيسان'!$Q$2:$Q$501,'04-نيسان'!$F$2:$F$501,"*ليرة*"),"") | F23: =IF(F$8=1,SUMIFS('05-أيار'!$Q$2:$Q$501,'05-أيار'!$F$2:$F$501,"*ليرة*"),"") | G23: =IF(G$8=1,SUMIFS('06-حزيران'!$Q$2:$Q$499,'06-حزيران'!$F$2:$F$499,"*ليرة*"),"") -> 15477.592 | H23: =IF(H$8=1,SUMIFS('07-تموز'!$Q$2:$Q$500,'07-تموز'!$F$2:$F$500,"*ليرة*"),"") -> 13511.107 | I23: =IF(I$8=1,SUMIFS('08-آب'!$Q$2:$Q$501,'08-آب'!$F$2:$F$501,"*ليرة*"),"") -> 14028.721 | J23: =IF(J$8=1,SUMIFS('09-أيلول'!$Q$2:$Q$500,'09-أيلول'!$F$2:$F$500,"*ليرة*"),"") -> 10157.255 | K23: =IF(K$8=1,SUMIFS('10-تشرين الأول'!$Q$2:$Q$501,'10-تشرين الأول'!$F$2:$F$501,"*ليرة*"),"") | L23: =IF(L$8=1,SUMIFS('11-تشرين الثاني'!$Q$2:$Q$501,'11-تشرين الثاني'!$F$2:$F$501,"*ليرة*"),"") | M23: =IF(M$8=1,SUMIFS('12-كانون الأول'!$Q$2:$Q$501,'12-كانون الأول'!$F$2:$F$501,"*ليرة*"),"")
A24: قيمة المخزون المسعّر بالدولار | B24: =IF(B$8=1,SUMIFS('01-كانون الثاني'!$Q$2:$Q$501,'01-كانون الثاني'!$F$2:$F$501,"*دولار*"),"") | C24: =IF(C$8=1,SUMIFS('02-شباط'!$Q$2:$Q$501,'02-شباط'!$F$2:$F$501,"*دولار*"),"") | D24: =IF(D$8=1,SUMIFS('03-آذار'!$Q$2:$Q$501,'03-آذار'!$F$2:$F$501,"*دولار*"),"") | E24: =IF(E$8=1,SUMIFS('04-نيسان'!$Q$2:$Q$501,'04-نيسان'!$F$2:$F$501,"*دولار*"),"") | F24: =IF(F$8=1,SUMIFS('05-أيار'!$Q$2:$Q$501,'05-أيار'!$F$2:$F$501,"*دولار*"),"") | G24: =IF(G$8=1,SUMIFS('06-حزيران'!$Q$2:$Q$499,'06-حزيران'!$F$2:$F$499,"*دولار*"),"") -> 29259.799 | H24: =IF(H$8=1,SUMIFS('07-تموز'!$Q$2:$Q$500,'07-تموز'!$F$2:$F$500,"*دولار*"),"") -> 34979.925 | I24: =IF(I$8=1,SUMIFS('08-آب'!$Q$2:$Q$501,'08-آب'!$F$2:$F$501,"*دولار*"),"") -> 33915.3 | J24: =IF(J$8=1,SUMIFS('09-أيلول'!$Q$2:$Q$500,'09-أيلول'!$F$2:$F$500,"*دولار*"),"") -> 34743.512 | K24: =IF(K$8=1,SUMIFS('10-تشرين الأول'!$Q$2:$Q$501,'10-تشرين الأول'!$F$2:$F$501,"*دولار*"),"") | L24: =IF(L$8=1,SUMIFS('11-تشرين الثاني'!$Q$2:$Q$501,'11-تشرين الثاني'!$F$2:$F$501,"*دولار*"),"") | M24: =IF(M$8=1,SUMIFS('12-كانون الأول'!$Q$2:$Q$501,'12-كانون الأول'!$F$2:$F$501,"*دولار*"),"")
A25: نسبة المخزون المسعّر بالليرة % (تعرّض لتقلب الصرف) | B25: =IF(B$8=1,IF(B11>0,B23/B11,0),"") | C25: =IF(C$8=1,IF(C11>0,C23/C11,0),"") | D25: =IF(D$8=1,IF(D11>0,D23/D11,0),"") | E25: =IF(E$8=1,IF(E11>0,E23/E11,0),"") | F25: =IF(F$8=1,IF(F11>0,F23/F11,0),"") | G25: =IF(G$8=1,IF(G11>0,G23/G11,0),"") -> 0.34596546 | H25: =IF(H$8=1,IF(H11>0,H23/H11,0),"") -> 0.27863105 | I25: =IF(I$8=1,IF(I11>0,I23/I11,0),"") -> 0.29260627 | ... M25: =IF(M$8=1,IF(M11>0,M23/M11,0),"")
A26: المقارنة بالشهر السابق
A27: تغير قيمة المستودع عن الشهر السابق | B27: — | C27: =IF(AND(C$8=1,B$8=1),C11-B11,"") | D27: =IF(AND(D$8=1,C$8=1),D11-C11,"") | E27: =IF(AND(E$8=1,D$8=1),E11-D11,"") | F27: =IF(AND(F$8=1,E$8=1),F11-E11,"") | G27: =IF(AND(G$8=1,F$8=1),G11-F11,"") | H27: =IF(AND(H$8=1,G$8=1),H11-G11,"") -> 3753.6416 | I27: =IF(AND(I$8=1,H$8=1),I11-H11,"") -> -547.01091 | J27: =IF(AND(J$8=1,I$8=1),J11-I11,"") -> -3043.2541 | ... M27: =IF(AND(M$8=1,L$8=1),M11-L11,"")
A28: تغير قيمة المستودع % | B28: — | C28: =IF(AND(C$8=1,B$8=1),IF(B11>0,(C11-B11)/B11,0),"") | D28: =IF(AND(D$8=1,C$8=1),IF(C11>0,(D11-C11)/C11,0),"") | E28: =IF(AND(E$8=1,D$8=1),IF(D11>0,(E11-D11)/D11,0),"") | F28: =IF(AND(F$8=1,E$8=1),IF(E11>0,(F11-E11)/E11,0),"") | G28: =IF(AND(G$8=1,F$8=1),IF(F11>0,(G11-F11)/F11,0),"") | H28: =IF(AND(H$8=1,G$8=1),IF(G11>0,(H11-G11)/G11,0),"") -> 0.083903901 | I28: =IF(AND(I$8=1,H$8=1),IF(H11>0,(I11-H11)/H11,0),"") -> -0.011280661 | J28: =IF(AND(J$8=1,I$8=1),IF(I11>0,(J11-I11)/I11,0),"") -> -0.063475153 | ... M28: =IF(AND(M$8=1,L$8=1),IF(L11>0,(M11-L11)/L11,0),"")
A29: تغير الربح المتوقع عن الشهر السابق | B29: — | C29: =IF(AND(C$8=1,B$8=1),C14-B14,"") | D29: =IF(AND(D$8=1,C$8=1),D14-C14,"") | E29: =IF(AND(E$8=1,D$8=1),E14-D14,"") | F29: =IF(AND(F$8=1,E$8=1),F14-E14,"") | G29: =IF(AND(G$8=1,F$8=1),G14-F14,"") | H29: =IF(AND(H$8=1,G$8=1),H14-G14,"") -> -541.16637 | I29: =IF(AND(I$8=1,H$8=1),I14-H14,"") -> 333.1659 | J29: =IF(AND(J$8=1,I$8=1),J14-I14,"") -> -1858.9919 | ... M29: =IF(AND(M$8=1,L$8=1),M14-L14,"")
A30: أصناف جديدة | B30: — | C30: =IF(AND(AND(C5>0,C5<=500),AND(B5>0,B5<=500)),COUNTIF('02-شباط'!$W$2:$W$501,"جديد"),"") | D30: =IF(AND(AND(D5>0,D5<=500),AND(C5>0,C5<=500)),COUNTIF('03-آذار'!$W$2:$W$501,"جديد"),"") | E30: =IF(AND(AND(E5>0,E5<=500),AND(D5>0,D5<=500)),COUNTIF('04-نيسان'!$W$2:$W$501,"جديد"),"") | F30: =IF(AND(AND(F5>0,F5<=500),AND(E5>0,E5<=500)),COUNTIF('05-أيار'!$W$2:$W$501,"جديد"),"") | G30: =IF(AND(AND(G5>0,G5<=500),AND(F5>0,F5<=500)),COUNTIF('06-حزيران'!$W$2:$W$499,"جديد"),"") | H30: =IF(AND(AND(H5>0,H5<=500),AND(G5>0,G5<=500)),COUNTIF('07-تموز'!$W$2:$W$500,"جديد"),"") -> 3 | I30: =IF(AND(AND(I5>0,I5<=500),AND(H5>0,H5<=500)),COUNTIF('08-آب'!$W$2:$W$501,"جديد"),"") -> 22 | J30: =IF(AND(AND(J5>0,J5<=500),AND(I5>0,I5<=500)),COUNTIF('09-أيلول'!$W$2:$W$500,"جديد"),"") -> 8 | K30: =IF(AND(AND(K5>0,K5<=500),AND(J5>0,J5<=500)),COUNTIF('10-تشرين الأول'!$W$2:$W$501,"جديد"),"") | L30: =IF(AND(AND(L5>0,L5<=500),AND(K5>0,K5<=500)),COUNTIF('11-تشرين الثاني'!$W$2:$W$501,"جديد"),"") | M30: =IF(AND(AND(M5>0,M5<=500),AND(L5>0,L5<=500)),COUNTIF('12-كانون الأول'!$W$2:$W$501,"جديد"),"")
A31: أصناف محذوفة | B31: — | C31: =IF(AND(AND(C5>0,C5<=500),AND(B5>0,B5<=500)),COUNTIF('01-كانون الثاني'!$AC$2:$AC$501,"محذوف لاحقاً"),"") | D31: =IF(AND(AND(D5>0,D5<=500),AND(C5>0,C5<=500)),COUNTIF('02-شباط'!$AC$2:$AC$501,"محذوف لاحقاً"),"") | E31: =IF(AND(AND(E5>0,E5<=500),AND(D5>0,D5<=500)),COUNTIF('03-آذار'!$AC$2:$AC$501,"محذوف لاحقاً"),"") | F31: =IF(AND(AND(F5>0,F5<=500),AND(E5>0,E5<=500)),COUNTIF('04-نيسان'!$AC$2:$AC$501,"محذوف لاحقاً"),"") | G31: =IF(AND(AND(G5>0,G5<=500),AND(F5>0,F5<=500)),COUNTIF('05-أيار'!$AC$2:$AC$501,"محذوف لاحقاً"),"") | H31: =IF(AND(AND(H5>0,H5<=500),AND(G5>0,G5<=500)),COUNTIF('06-حزيران'!$AC$2:$AC$499,"محذوف لاحقاً"),"") -> 0 | I31: =IF(AND(AND(I5>0,I5<=500),AND(H5>0,H5<=500)),COUNTIF('07-تموز'!$AC$2:$AC$500,"محذوف لاحقاً"),"") -> 0 | J31: =IF(AND(AND(J5>0,J5<=500),AND(I5>0,I5<=500)),COUNTIF('08-آب'!$AC$2:$AC$501,"محذوف لاحقاً"),"") -> 1 | K31: =IF(AND(AND(K5>0,K5<=500),AND(J5>0,J5<=500)),COUNTIF('09-أيلول'!$AC$2:$AC$500,"محذوف لاحقاً"),"") | L31: =IF(AND(AND(L5>0,L5<=500),AND(K5>0,K5<=500)),COUNTIF('10-تشرين الأول'!$AC$2:$AC$501,"محذوف لاحقاً"),"") | M31: =IF(AND(AND(M5>0,M5<=500),AND(L5>0,L5<=500)),COUNTIF('11-تشرين الثاني'!$AC$2:$AC$501,"محذوف لاحقاً"),"")
A32: أصناف زادت كميتها (غير الجديدة) | B32: — | C32: =IF(AND(AND(C5>0,C5<=500),AND(B5>0,B5<=500)),COUNTIFS('02-شباط'!$Y$2:$Y$501,">0",'02-شباط'!$W$2:$W$501,"<>جديد"),"") | D32: =IF(AND(AND(D5>0,D5<=500),AND(C5>0,C5<=500)),COUNTIFS('03-آذار'!$Y$2:$Y$501,">0",'03-آذار'!$W$2:$W$501,"<>جديد"),"") | E32: =IF(AND(AND(E5>0,E5<=500),AND(D5>0,D5<=500)),COUNTIFS('04-نيسان'!$Y$2:$Y$501,">0",'04-نيسان'!$W$2:$W$501,"<>جديد"),"") | F32: =IF(AND(AND(F5>0,F5<=500),AND(E5>0,E5<=500)),COUNTIFS('05-أيار'!$Y$2:$Y$501,">0",'05-أيار'!$W$2:$W$501,"<>جديد"),"") | G32: =IF(AND(AND(G5>0,G5<=500),AND(F5>0,F5<=500)),COUNTIFS('06-حزيران'!$Y$2:$Y$499,">0",'06-حزيران'!$W$2:$W$499,"<>جديد"),"") | H32: =IF(AND(AND(H5>0,H5<=500),AND(G5>0,G5<=500)),COUNTIFS('07-تموز'!$Y$2:$Y$500,">0",'07-تموز'!$W$2:$W$500,"<>جديد"),"") -> 30 | I32: =IF(AND(AND(I5>0,I5<=500),AND(H5>0,H5<=500)),COUNTIFS('08-آب'!$Y$2:$Y$501,">0",'08-آب'!$W$2:$W$501,"<>جديد"),"") -> 32 | J32: =IF(AND(AND(J5>0,J5<=500),AND(I5>0,I5<=500)),COUNTIFS('09-أيلول'!$Y$2:$Y$500,">0",'09-أيلول'!$W$2:$W$500,"<>جديد"),"") -> 19 | K32: =IF(AND(AND(K5>0,K5<=500),AND(J5>0,J5<=500)),COUNTIFS('10-تشرين الأول'!$Y$2:$Y$501,">0",'10-تشرين الأول'!$W$2:$W$501,"<>جديد"),"") | L32: =IF(AND(AND(L5>0,L5<=500),AND(K5>0,K5<=500)),COUNTIFS('11-تشرين الثاني'!$Y$2:$Y$501,">0",'11-تشرين الثاني'!$W$2:$W$501,"<>جديد"),"") | M32: =IF(AND(AND(M5>0,M5<=500),AND(L5>0,L5<=500)),COUNTIFS('12-كانون الأول'!$Y$2:$Y$501,">0",'12-كانون الأول'!$W$2:$W$501,"<>جديد"),"")
A33: أصناف نقصت كميتها | B33: — | C33: =IF(AND(AND(C5>0,C5<=500),AND(B5>0,B5<=500)),COUNTIFS('02-شباط'!$Y$2:$Y$501,"<0",'02-شباط'!$W$2:$W$501,"<>جديد"),"") | D33: =IF(AND(AND(D5>0,D5<=500),AND(C5>0,C5<=500)),COUNTIFS('03-آذار'!$Y$2:$Y$501,"<0",'03-آذار'!$W$2:$W$501,"<>جديد"),"") | E33: =IF(AND(AND(E5>0,E5<=500),AND(D5>0,D5<=500)),COUNTIFS('04-نيسان'!$Y$2:$Y$501,"<0",'04-نيسان'!$W$2:$W$501,"<>جديد"),"") | F33: =IF(AND(AND(F5>0,F5<=500),AND(E5>0,E5<=500)),COUNTIFS('05-أيار'!$Y$2:$Y$501,"<0",'05-أيار'!$W$2:$W$501,"<>جديد"),"") | G33: =IF(AND(AND(G5>0,G5<=500),AND(F5>0,F5<=500)),COUNTIFS('06-حزيران'!$Y$2:$Y$499,"<0",'06-حزيران'!$W$2:$W$499,"<>جديد"),"") | H33: =IF(AND(AND(H5>0,H5<=500),AND(G5>0,G5<=500)),COUNTIFS('07-تموز'!$Y$2:$Y$500,"<0",'07-تموز'!$W$2:$W$500,"<>جديد"),"") -> 40 | I33: =IF(AND(AND(I5>0,I5<=500),AND(H5>0,H5<=500)),COUNTIFS('08-آب'!$Y$2:$Y$501,"<0",'08-آب'!$W$2:$W$501,"<>جديد"),"") -> 49 | J33: =IF(AND(AND(J5>0,J5<=500),AND(I5>0,I5<=500)),COUNTIFS('09-أيلول'!$Y$2:$Y$500,"<0",'09-أيلول'!$W$2:$W$500,"<>جديد"),"") -> 68 | K33: =IF(AND(AND(K5>0,K5<=500),AND(J5>0,J5<=500)),COUNTIFS('10-تشرين الأول'!$Y$2:$Y$501,"<0",'10-تشرين الأول'!$W$2:$W$501,"<>جديد"),"") | L33: =IF(AND(AND(L5>0,L5<=500),AND(K5>0,K5<=500)),COUNTIFS('11-تشرين الثاني'!$Y$2:$Y$501,"<0",'11-تشرين الثاني'!$W$2:$W$501,"<>جديد"),"") | M33: =IF(AND(AND(M5>0,M5<=500),AND(L5>0,L5<=500)),COUNTIFS('12-كانون الأول'!$Y$2:$Y$501,"<0",'12-كانون الأول'!$W$2:$W$501,"<>جديد"),"")
A34: أصناف ارتفع سعر شرائها بأكثر من النسبة المحددة | B34: — | C34: =IF(AND(AND(C5>0,C5<=500),AND(B5>0,B5<=500)),COUNTIF('02-شباط'!$AB$2:$AB$501,">"&'لوحة التحكم'!$C$12),"") | D34: =IF(AND(AND(D5>0,D5<=500),AND(C5>0,C5<=500)),COUNTIF('03-آذار'!$AB$2:$AB$501,">"&'لوحة التحكم'!$C$12),"") | E34: =IF(AND(AND(E5>0,E5<=500),AND(D5>0,D5<=500)),COUNTIF('04-نيسان'!$AB$2:$AB$501,">"&'لوحة التحكم'!$C$12),"") | F34: =IF(AND(AND(F5>0,F5<=500),AND(E5>0,E5<=500)),COUNTIF('05-أيار'!$AB$2:$AB$501,">"&'لوحة التحكم'!$C$12),"") | G34: =IF(AND(AND(G5>0,G5<=500),AND(F5>0,F5<=500)),COUNTIF('06-حزيران'!$AB$2:$AB$499,">"&'لوحة التحكم'!$C$12),"") | H34: =IF(AND(AND(H5>0,H5<=500),AND(G5>0,G5<=500)),COUNTIF('07-تموز'!$AB$2:$AB$500,">"&'لوحة التحكم'!$C$12),"") -> 1 | I34: =IF(AND(AND(I5>0,I5<=500),AND(H5>0,H5<=500)),COUNTIF('08-آب'!$AB$2:$AB$501,">"&'لوحة التحكم'!$C$12),"") -> 0 | J34: =IF(AND(AND(J5>0,J5<=500),AND(I5>0,I5<=500)),COUNTIF('09-أيلول'!$AB$2:$AB$500,">"&'لوحة التحكم'!$C$12),"") -> 0 | K34: =IF(AND(AND(K5>0,K5<=500),AND(J5>0,J5<=500)),COUNTIF('10-تشرين الأول'!$AB$2:$AB$501,">"&'لوحة التحكم'!$C$12),"") | L34: =IF(AND(AND(L5>0,L5<=500),AND(K5>0,K5<=500)),COUNTIF('11-تشرين الثاني'!$AB$2:$AB$501,">"&'لوحة التحكم'!$C$12),"") | M34: =IF(AND(AND(M5>0,M5<=500),AND(L5>0,L5<=500)),COUNTIF('12-كانون الأول'!$AB$2:$AB$501,">"&'لوحة التحكم'!$C$12),"")
A35: أصناف انخفض سعر شرائها بأكثر من النسبة المحددة | B35: — | C35: =IF(AND(AND(C5>0,C5<=500),AND(B5>0,B5<=500)),COUNTIF('02-شباط'!$AB$2:$AB$501,"<"&-'لوحة التحكم'!$C$12),"") | D35: =IF(AND(AND(D5>0,D5<=500),AND(C5>0,C5<=500)),COUNTIF('03-آذار'!$AB$2:$AB$501,"<"&-'لوحة التحكم'!$C$12),"") | E35: =IF(AND(AND(E5>0,E5<=500),AND(D5>0,D5<=500)),COUNTIF('04-نيسان'!$AB$2:$AB$501,"<"&-'لوحة التحكم'!$C$12),"") | F35: =IF(AND(AND(F5>0,F5<=500),AND(E5>0,E5<=500)),COUNTIF('05-أيار'!$AB$2:$AB$501,"<"&-'لوحة التحكم'!$C$12),"") | G35: =IF(AND(AND(G5>0,G5<=500),AND(F5>0,F5<=500)),COUNTIF('06-حزيران'!$AB$2:$AB$499,"<"&-'لوحة التحكم'!$C$12),"") | H35: =IF(AND(AND(H5>0,H5<=500),AND(G5>0,G5<=500)),COUNTIF('07-تموز'!$AB$2:$AB$500,"<"&-'لوحة التحكم'!$C$12),"") -> 0 | I35: =IF(AND(AND(I5>0,I5<=500),AND(H5>0,H5<=500)),COUNTIF('08-آب'!$AB$2:$AB$501,"<"&-'لوحة التحكم'!$C$12),"") -> 0 | J35: =IF(AND(AND(J5>0,J5<=500),AND(I5>0,I5<=500)),COUNTIF('09-أيلول'!$AB$2:$AB$500,"<"&-'لوحة التحكم'!$C$12),"") -> 1 | K35: =IF(AND(AND(K5>0,K5<=500),AND(J5>0,J5<=500)),COUNTIF('10-تشرين الأول'!$AB$2:$AB$501,"<"&-'لوحة التحكم'!$C$12),"") | L35: =IF(AND(AND(L5>0,L5<=500),AND(K5>0,K5<=500)),COUNTIF('11-تشرين الثاني'!$AB$2:$AB$501,"<"&-'لوحة التحكم'!$C$12),"") | M35: =IF(AND(AND(M5>0,M5<=500),AND(L5>0,L5<=500)),COUNTIF('12-كانون الأول'!$AB$2:$AB$501,"<"&-'لوحة التحكم'!$C$12),"")
A36: جودة البيانات (عدد الأصناف)
A37: كمية سالبة | B37: =IF(AND(B5>0,B5<=500),COUNTIF('01-كانون الثاني'!$U$2:$U$501,"*كمية سالبة*"),"") | C37: =IF(AND(C5>0,C5<=500),COUNTIF('02-شباط'!$U$2:$U$501,"*كمية سالبة*"),"") | D37: =IF(AND(D5>0,D5<=500),COUNTIF('03-آذار'!$U$2:$U$501,"*كمية سالبة*"),"") | E37: =IF(AND(E5>0,E5<=500),COUNTIF('04-نيسان'!$U$2:$U$501,"*كمية سالبة*"),"") | F37: =IF(AND(F5>0,F5<=500),COUNTIF('05-أيار'!$U$2:$U$501,"*كمية سالبة*"),"") | G37: =IF(AND(G5>0,G5<=500),COUNTIF('06-حزيران'!$U$2:$U$499,"*كمية سالبة*"),"") -> 0 | H37: =IF(AND(H5>0,H5<=500),COUNTIF('07-تموز'!$U$2:$U$500,"*كمية سالبة*"),"") -> 0 | I37: =IF(AND(I5>0,I5<=500),COUNTIF('08-آب'!$U$2:$U$501,"*كمية سالبة*"),"") -> 0 | J37: =IF(AND(J5>0,J5<=500),COUNTIF('09-أيلول'!$U$2:$U$500,"*كمية سالبة*"),"") -> 0 | K37: =IF(AND(K5>0,K5<=500),COUNTIF('10-تشرين الأول'!$U$2:$U$501,"*كمية سالبة*"),"") | L37: =IF(AND(L5>0,L5<=500),COUNTIF('11-تشرين الثاني'!$U$2:$U$501,"*كمية سالبة*"),"") | M37: =IF(AND(M5>0,M5<=500),COUNTIF('12-كانون الأول'!$U$2:$U$501,"*كمية سالبة*"),"")
A38: كمية موجبة وسعر شراء صفر | B38: =IF(AND(B5>0,B5<=500),COUNTIF('01-كانون الثاني'!$U$2:$U$501,"*شراء صفر*"),"") | C38: =IF(AND(C5>0,C5<=500),COUNTIF('02-شباط'!$U$2:$U$501,"*شراء صفر*"),"") | D38: =IF(AND(D5>0,D5<=500),COUNTIF('03-آذار'!$U$2:$U$501,"*شراء صفر*"),"") | E38: =IF(AND(E5>0,E5<=500),COUNTIF('04-نيسان'!$U$2:$U$501,"*شراء صفر*"),"") | F38: =IF(AND(F5>0,F5<=500),COUNTIF('05-أيار'!$U$2:$U$501,"*شراء صفر*"),"") | G38: =IF(AND(G5>0,G5<=500),COUNTIF('06-حزيران'!$U$2:$U$499,"*شراء صفر*"),"") -> 0 | H38: =IF(AND(H5>0,H5<=500),COUNTIF('07-تموز'!$U$2:$U$500,"*شراء صفر*"),"") -> 0 | I38: =IF(AND(I5>0,I5<=500),COUNTIF('08-آب'!$U$2:$U$501,"*شراء صفر*"),"") -> 0 | J38: =IF(AND(J5>0,J5<=500),COUNTIF('09-أيلول'!$U$2:$U$500,"*شراء صفر*"),"") -> 0 | K38: =IF(AND(K5>0,K5<=500),COUNTIF('10-تشرين الأول'!$U$2:$U$501,"*شراء صفر*"),"") | L38: =IF(AND(L5>0,L5<=500),COUNTIF('11-تشرين الثاني'!$U$2:$U$501,"*شراء صفر*"),"") | M38: =IF(AND(M5>0,M5<=500),COUNTIF('12-كانون الأول'!$U$2:$U$501,"*شراء صفر*"),"")
A39: صنف للبيع بكمية وسعر بيع صفر | B39: =IF(AND(B5>0,B5<=500),COUNTIF('01-كانون الثاني'!$U$2:$U$501,"*بيع صفر*"),"") | C39: =IF(AND(C5>0,C5<=500),COUNTIF('02-شباط'!$U$2:$U$501,"*بيع صفر*"),"") | D39: =IF(AND(D5>0,D5<=500),COUNTIF('03-آذار'!$U$2:$U$501,"*بيع صفر*"),"") | E39: =IF(AND(E5>0,E5<=500),COUNTIF('04-نيسان'!$U$2:$U$501,"*بيع صفر*"),"") | F39: =IF(AND(F5>0,F5<=500),COUNTIF('05-أيار'!$U$2:$U$501,"*بيع صفر*"),"") | G39: =IF(AND(G5>0,G5<=500),COUNTIF('06-حزيران'!$U$2:$U$499,"*بيع صفر*"),"") -> 0 | H39: =IF(AND(H5>0,H5<=500),COUNTIF('07-تموز'!$U$2:$U$500,"*بيع صفر*"),"") -> 0 | I39: =IF(AND(I5>0,I5<=500),COUNTIF('08-آب'!$U$2:$U$501,"*بيع صفر*"),"") -> 0 | J39: =IF(AND(J5>0,J5<=500),COUNTIF('09-أيلول'!$U$2:$U$500,"*بيع صفر*"),"") -> 0 | K39: =IF(AND(K5>0,K5<=500),COUNTIF('10-تشرين الأول'!$U$2:$U$501,"*بيع صفر*"),"") | L39: =IF(AND(L5>0,L5<=500),COUNTIF('11-تشرين الثاني'!$U$2:$U$501,"*بيع صفر*"),"") | M39: =IF(AND(M5>0,M5<=500),COUNTIF('12-كانون الأول'!$U$2:$U$501,"*بيع صفر*"),"")
A40: سعر البيع أقل من سعر الشراء | B40: =IF(AND(B5>0,B5<=500),COUNTIF('01-كانون الثاني'!$U$2:$U$501,"*بيع أقل من الشراء*"),"") | C40: =IF(AND(C5>0,C5<=500),COUNTIF('02-شباط'!$U$2:$U$501,"*بيع أقل من الشراء*"),"") | D40: =IF(AND(D5>0,D5<=500),COUNTIF('03-آذار'!$U$2:$U$501,"*بيع أقل من الشراء*"),"") | E40: =IF(AND(E5>0,E5<=500),COUNTIF('04-نيسان'!$U$2:$U$501,"*بيع أقل من الشراء*"),"") | F40: =IF(AND(F5>0,F5<=500),COUNTIF('05-أيار'!$U$2:$U$501,"*بيع أقل من الشراء*"),"") | G40: =IF(AND(G5>0,G5<=500),COUNTIF('06-حزيران'!$U$2:$U$499,"*بيع أقل من الشراء*"),"") -> 0 | H40: =IF(AND(H5>0,H5<=500),COUNTIF('07-تموز'!$U$2:$U$500,"*بيع أقل من الشراء*"),"") -> 0 | I40: =IF(AND(I5>0,I5<=500),COUNTIF('08-آب'!$U$2:$U$501,"*بيع أقل من الشراء*"),"") -> 0 | J40: =IF(AND(J5>0,J5<=500),COUNTIF('09-أيلول'!$U$2:$U$500,"*بيع أقل من الشراء*"),"") -> 0 | K40: =IF(AND(K5>0,K5<=500),COUNTIF('10-تشرين الأول'!$U$2:$U$501,"*بيع أقل من الشراء*"),"") | L40: =IF(AND(L5>0,L5<=500),COUNTIF('11-تشرين الثاني'!$U$2:$U$501,"*بيع أقل من الشراء*"),"") | M40: =IF(AND(M5>0,M5<=500),COUNTIF('12-كانون الأول'!$U$2:$U$501,"*بيع أقل من الشراء*"),"")
A41: عملة/سعر مشكوك | B41: =IF(AND(B5>0,B5<=500),COUNTIF('01-كانون الثاني'!$U$2:$U$501,"*مشكوك*"),"") | C41: =IF(AND(C5>0,C5<=500),COUNTIF('02-شباط'!$U$2:$U$501,"*مشكوك*"),"") | D41: =IF(AND(D5>0,D5<=500),COUNTIF('03-آذار'!$U$2:$U$501,"*مشكوك*"),"") | E41: =IF(AND(E5>0,E5<=500),COUNTIF('04-نيسان'!$U$2:$U$501,"*مشكوك*"),"") | F41: =IF(AND(F5>0,F5<=500),COUNTIF('05-أيار'!$U$2:$U$501,"*مشكوك*"),"") | G41: =IF(AND(G5>0,G5<=500),COUNTIF('06-حزيران'!$U$2:$U$499,"*مشكوك*"),"") -> 0 | H41: =IF(AND(H5>0,H5<=500),COUNTIF('07-تموز'!$U$2:$U$500,"*مشكوك*"),"") -> 0 | I41: =IF(AND(I5>0,I5<=500),COUNTIF('08-آب'!$U$2:$U$501,"*مشكوك*"),"") -> 0 | J41: =IF(AND(J5>0,J5<=500),COUNTIF('09-أيلول'!$U$2:$U$500,"*مشكوك*"),"") -> 0 | K41: =IF(AND(K5>0,K5<=500),COUNTIF('10-تشرين الأول'!$U$2:$U$501,"*مشكوك*"),"") | L41: =IF(AND(L5>0,L5<=500),COUNTIF('11-تشرين الثاني'!$U$2:$U$501,"*مشكوك*"),"") | M41: =IF(AND(M5>0,M5<=500),COUNTIF('12-كانون الأول'!$U$2:$U$501,"*مشكوك*"),"")
...

Sheet تصدير للتقارير
A1: تصدير للتقارير — الأرقام التي تُنقل شهريًا إلى ملف التقارير
A2: انسخ الخلايا A:E من صف الشهر (بعد أن يصبح نظيفًا) والصقها في ملف التقارير داخل A21:E21 من صفحة ذلك الشهر «كقيم فقط» (Ctrl+Alt+V ثم V). العمود F للمعلومة ولا يُنسخ.
A4: رقم الشهر | B4: سعر الصرف المستخدم | C4: مخزون مسعّر بالدولار ($) | D4: مخزون مسعّر بالليرة (ل.س) | E4: أصناف بها أخطاء | F4: الحالة (لا يُنسخ)
A5: 1 | B5: =IF('الملخص الشهري'!B8=1,'الملخص الشهري'!B6,"") | C5: =IF('الملخص الشهري'!B8=1,ROUND('الملخص الشهري'!B24,2),"") | D5: =IF('الملخص الشهري'!B8=1,ROUND('الملخص الشهري'!B23*'الملخص الشهري'!B6,0),"") | E5: =IF('الملخص الشهري'!B8=1,'الملخص الشهري'!B45,"") | F5: =IF('الملخص الشهري'!B8=1,IF('الملخص الشهري'!B45=0,"✅ جاهز للنسخ","⚠ فيه "&'الملخص الشهري'!B45&" صنف بأخطاء — صحّح ثم أعد التصدير"),'الملخص الشهري'!B7) -> لا بيانات
A6: 2 | B6: =IF('الملخص الشهري'!C8=1,'الملخص الشهري'!C6,"") | C6: =IF('الملخص الشهري'!C8=1,ROUND('الملخص الشهري'!C24,2),"") | D6: =IF('الملخص الشهري'!C8=1,ROUND('الملخص الشهري'!C23*'الملخص الشهري'!C6,0),"") | E6: =IF('الملخص الشهري'!C8=1,'الملخص الشهري'!C45,"") | F6: =IF('الملخص الشهري'!C8=1,IF('الملخص الشهري'!C45=0,"✅ جاهز للنسخ","⚠ فيه "&'الملخص الشهري'!C45&" صنف بأخطاء — صحّح ثم أعد التصدير"),'الملخص الشهري'!C7) -> لا بيانات
A7: 3 | B7: =IF('الملخص الشهري'!D8=1,'الملخص الشهري'!D6,"") | C7: =IF('الملخص الشهري'!D8=1,ROUND('الملخص الشهري'!D24,2),"") | D7: =IF('الملخص الشهري'!D8=1,ROUND('الملخص الشهري'!D23*'الملخص الشهري'!D6,0),"") | E7: =IF('الملخص الشهري'!D8=1,'الملخص الشهري'!D45,"") | F7: =IF('الملخص الشهري'!D8=1,IF('الملخص الشهري'!D45=0,"✅ جاهز للنسخ","⚠ فيه "&'الملخص الشهري'!D45&" صنف بأخطاء — صحّح ثم أعد التصدير"),'الملخص الشهري'!D7) -> لا بيانات
A8: 4 | B8: =IF('الملخص الشهري'!E8=1,'الملخص الشهري'!E6,"") | C8: =IF('الملخص الشهري'!E8=1,ROUND('الملخص الشهري'!E24,2),"") | D8: =IF('الملخص الشهري'!E8=1,ROUND('الملخص الشهري'!E23*'الملخص الشهري'!E6,0),"") | E8: =IF('الملخص الشهري'!E8=1,'الملخص الشهري'!E45,"") | F8: =IF('الملخص الشهري'!E8=1,IF('الملخص الشهري'!E45=0,"✅ جاهز للنسخ","⚠ فيه "&'الملخص الشهري'!E45&" صنف بأخطاء — صحّح ثم أعد التصدير"),'الملخص الشهري'!E7) -> لا بيانات
A9: 5 | B9: =IF('الملخص الشهري'!F8=1,'الملخص الشهري'!F6,"") | C9: =IF('الملخص الشهري'!F8=1,ROUND('الملخص الشهري'!F24,2),"") | D9: =IF('الملخص الشهري'!F8=1,ROUND('الملخص الشهري'!F23*'الملخص الشهري'!F6,0),"") | E9: =IF('الملخص الشهري'!F8=1,'الملخص الشهري'!F45,"") | F9: =IF('الملخص الشهري'!F8=1,IF('الملخص الشهري'!F45=0,"✅ جاهز للنسخ","⚠ فيه "&'الملخص الشهري'!F45&" صنف بأخطاء — صحّح ثم أعد التصدير"),'الملخص الشهري'!F7) -> لا بيانات
A10: 6 | B10: =IF('الملخص الشهري'!G8=1,'الملخص الشهري'!G6,"") -> 13200 | C10: =IF('الملخص الشهري'!G8=1,ROUND('الملخص الشهري'!G24,2),"") -> 29259.8 | D10: =IF('الملخص الشهري'!G8=1,ROUND('الملخص الشهري'!G23*'الملخص الشهري'!G6,0),"") -> 204304214 | E10: =IF('الملخص الشهري'!G8=1,'الملخص الشهري'!G45,"") -> 0 | F10: =IF('الملخص الشهري'!G8=1,IF('الملخص الشهري'!G45=0,"✅ جاهز للنسخ","⚠ فيه "&'الملخص الشهري'!G45&" صنف بأخطاء — صحّح ثم أعد التصدير"),'الملخص الشهري'!G7) -> ✅ جاهز للنسخ
A11: 7 | B11: =IF('الملخص الشهري'!H8=1,'الملخص الشهري'!H6,"") -> 13300 | C11: =IF('الملخص الشهري'!H8=1,ROUND('الملخص الشهري'!H24,2),"") -> 34979.92 | D11: =IF('الملخص الشهري'!H8=1,ROUND('الملخص الشهري'!H23*'الملخص الشهري'!H6,0),"") -> 179697728 | E11: =IF('الملخص الشهري'!H8=1,'الملخص الشهري'!H45,"") -> 0 | F11: =IF('الملخص الشهري'!H8=1,IF('الملخص الشهري'!H45=0,"✅ جاهز للنسخ","⚠ فيه "&'الملخص الشهري'!H45&" صنف بأخطاء — صحّح ثم أعد التصدير"),'الملخص الشهري'!H7) -> ✅ جاهز للنسخ
A12: 8 | B12: =IF('الملخص الشهري'!I8=1,'الملخص الشهري'!I6,"") -> 13200 | C12: =IF('الملخص الشهري'!I8=1,ROUND('الملخص الشهري'!I24,2),"") -> 33915.3 | D12: =IF('الملخص الشهري'!I8=1,ROUND('الملخص الشهري'!I23*'الملخص الشهري'!I6,0),"") -> 185179118 | E12: =IF('الملخص الشهري'!I8=1,'الملخص الشهري'!I45,"") -> 0 | F12: =IF('الملخص الشهري'!I8=1,IF('الملخص الشهري'!I45=0,"✅ جاهز للنسخ","⚠ فيه "&'الملخص الشهري'!I45&" صنف بأخطاء — صحّح ثم أعد التصدير"),'الملخص الشهري'!I7) -> ✅ جاهز للنسخ
A13: 9 | B13: =IF('الملخص الشهري'!J8=1,'الملخص الشهري'!J6,"") -> 13800 | C13: =IF('الملخص الشهري'!J8=1,ROUND('الملخص الشهري'!J24,2),"") -> 34743.51 | D13: =IF('الملخص الشهري'!J8=1,ROUND('الملخص الشهري'!J23*'الملخص الشهري'!J6,0),"") -> 140170124 | E13: =IF('الملخص الشهري'!J8=1,'الملخص الشهري'!J45,"") -> 0 | F13: =IF('الملخص الشهري'!J8=1,IF('الملخص الشهري'!J45=0,"✅ جاهز للنسخ","⚠ فيه "&'الملخص الشهري'!J45&" صنف بأخطاء — صحّح ثم أعد التصدير"),'الملخص الشهري'!J7) -> ✅ جاهز للنسخ
A14: 10 | B14: =IF('الملخص الشهري'!K8=1,'الملخص الشهري'!K6,"") | C14: =IF('الملخص الشهري'!K8=1,ROUND('الملخص الشهري'!K24,2),"") | D14: =IF('الملخص الشهري'!K8=1,ROUND('الملخص الشهري'!K23*'الملخص الشهري'!K6,0),"") | E14: =IF('الملخص الشهري'!K8=1,'الملخص الشهري'!K45,"") | F14: =IF('الملخص الشهري'!K8=1,IF('الملخص الشهري'!K45=0,"✅ جاهز للنسخ","⚠ فيه "&'الملخص الشهري'!K45&" صنف بأخطاء — صحّح ثم أعد التصدير"),'الملخص الشهري'!K7) -> لا بيانات
A15: 11 | B15: =IF('الملخص الشهري'!L8=1,'الملخص الشهري'!L6,"") | C15: =IF('الملخص الشهري'!L8=1,ROUND('الملخص الشهري'!L24,2),"") | D15: =IF('الملخص الشهري'!L8=1,ROUND('الملخص الشهري'!L23*'الملخص الشهري'!L6,0),"") | E15: =IF('الملخص الشهري'!L8=1,'الملخص الشهري'!L45,"") | F15: =IF('الملخص الشهري'!L8=1,IF('الملخص الشهري'!L45=0,"✅ جاهز للنسخ","⚠ فيه "&'الملخص الشهري'!L45&" صنف بأخطاء — صحّح ثم أعد التصدير"),'الملخص الشهري'!L7) -> لا بيانات
A16: 12 | B16: =IF('الملخص الشهري'!M8=1,'الملخص الشهري'!M6,"") | C16: =IF('الملخص الشهري'!M8=1,ROUND('الملخص الشهري'!M24,2),"") | D16: =IF('الملخص الشهري'!M8=1,ROUND('الملخص الشهري'!M23*'الملخص الشهري'!M6,0),"") | E16: =IF('الملخص الشهري'!M8=1,'الملخص الشهري'!M45,"") | F16: =IF('الملخص الشهري'!M8=1,IF('الملخص الشهري'!M45=0,"✅ جاهز للنسخ","⚠ فيه "&'الملخص الشهري'!M45&" صنف بأخطاء — صحّح ثم أعد التصدير"),'الملخص الشهري'!M7) -> لا بيانات

Sheet المقارنة
B1: مقارنة الشهر المعروض بالشهر السابق | H1: ورقة الحالي | I1: ='لوحة التحكم'!$K$6 -> 09-أيلول
B2: الشهر الحالي | C2: =INDEX('لوحة التحكم'!$B$16:$B$27,'لوحة التحكم'!$D$6) -> أيلول | D2: الشهر السابق | E2: =IF('لوحة التحكم'!$D$6>1,INDEX('لوحة التحكم'!$B$16:$B$27,'لوحة التحكم'!$D$6-1),"—") -> آب | H2: ورقة السابق | I2: =IF('لوحة التحكم'!$D$6>1,INDEX('لوحة التحكم'!$F$16:$F$27,'لوحة التحكم'!$D$6-1),"") -> 08-آب
B3: =IF($I$5=1,"✓ المقارنة متاحة","⚠ المقارنة غير متاحة: يلزم أن يكون الشهران فيهما بيانات وسعر صرف (راجع لوحة التحكم)") -> ✓ المقارنة متاحة | H3: الحالي جاهز؟ | I3: ='لوحة التحكم'!$K$8 -> 1
H4: السابق جاهز؟ | I4: =IF('لوحة التحكم'!$D$6>1,INDEX('الملخص الشهري'!$B$8:$M$8,'لوحة التحكم'!$D$6-1),0) -> 1
B5: المقارنة الإجمالية | H5: كلاهما جاهز؟ | I5: =IF(AND(I3=1,I4=1),1,0) -> 1
B6: المؤشر | C6: الحالي | D6: السابق | E6: التغير | F6: التغير %
B7: قيمة المستودع بسعر الشراء $ | C7: =IF($I$5=1,INDEX('الملخص الشهري'!$B$11:$M$11,'لوحة التحكم'!$D$6),"") -> 44900.767 | D7: =IF($I$5=1,INDEX('الملخص الشهري'!$B$11:$M$11,'لوحة التحكم'!$D$6-1),"") -> 47944.021 | E7: =IF($I$5=1,C7-D7,"") -> -3043.2541 | F7: =IF($I$5=1,IF(D7<>0,(C7-D7)/ABS(D7),0),"") -> -0.063475153
B8: القيمة البيعية المتوقعة $ | C8: =IF($I$5=1,INDEX('الملخص الشهري'!$B$12:$M$12,'لوحة التحكم'!$D$6),"") -> 18699.77 | D8: =IF($I$5=1,INDEX('الملخص الشهري'!$B$12:$M$12,'لوحة التحكم'!$D$6-1),"") -> 23866.931 | E8: =IF($I$5=1,C8-D8,"") -> -5167.161 | F8: =IF($I$5=1,IF(D8<>0,(C8-D8)/ABS(D8),0),"") -> -0.21649876
B9: الربح المتوقع $ | C9: =IF($I$5=1,INDEX('الملخص الشهري'!$B$14:$M$14,'لوحة التحكم'!$D$6),"") -> 7284.6252 | D9: =IF($I$5=1,INDEX('الملخص الشهري'!$B$14:$M$14,'لوحة التحكم'!$D$6-1),"") -> 9143.6171 | E9: =IF($I$5=1,C9-D9,"") -> -1858.9919 | F9: =IF($I$5=1,IF(D9<>0,(C9-D9)/ABS(D9),0),"") -> -0.20331034
B10: هامش الربح % | C10: =IF($I$5=1,INDEX('الملخص الشهري'!$B$15:$M$15,'لوحة التحكم'!$D$6),"") -> 0.38955693 | D10: =IF($I$5=1,INDEX('الملخص الشهري'!$B$15:$M$15,'لوحة التحكم'!$D$6-1),"") -> 0.3831082 | E10: =IF($I$5=1,C10-D10,"") -> 0.0064487318
B11: أصناف كميتها موجبة | C11: =IF($I$5=1,INDEX('الملخص الشهري'!$B$10:$M$10,'لوحة التحكم'!$D$6),"") -> 134 | D11: =IF($I$5=1,INDEX('الملخص الشهري'!$B$10:$M$10,'لوحة التحكم'!$D$6-1),"") -> 136 | E11: =IF($I$5=1,C11-D11,"") -> -2 | F11: =IF($I$5=1,IF(D11<>0,(C11-D11)/ABS(D11),0),"") -> -0.014705882
B12: عدد الأصناف الملصوقة | C12: =IF($I$5=1,INDEX('الملخص الشهري'!$B$5:$M$5,'لوحة التحكم'!$D$6),"") -> 268 | D12: =IF($I$5=1,INDEX('الملخص الشهري'!$B$5:$M$5,'لوحة التحكم'!$D$6-1),"") -> 261 | E12: =IF($I$5=1,C12-D12,"") -> 7 | F12: =IF($I$5=1,IF(D12<>0,(C12-D12)/ABS(D12),0),"") -> 0.026819923
B13: نسبة المخزون المسعّر بالليرة % | C13: =IF($I$5=1,INDEX('الملخص الشهري'!$B$25:$M$25,'لوحة التحكم'!$D$6),"") -> 0.22621563 | D13: =IF($I$5=1,INDEX('الملخص الشهري'!$B$25:$M$25,'لوحة التحكم'!$D$6-1),"") -> 0.29260627 | E13: =IF($I$5=1,C13-D13,"") -> -0.066390635
B15: أصناف جديدة (ظهرت هذا الشهر ولم تكن في الشهر السابق)
B16: الصنف | C16: الكمية | D16: قيمة المخزون $ | E16: الفئة الفرعية | K16: فهرس
B17: =IF(K17="","",INDEX(INDIRECT("'"&$I$1&"'!$A$2:$A$501"),K17)) -> منتول كريستال | C17: =IF(K17="","",INDEX(INDIRECT("'"&$I$1&"'!$P$2:$P$501"),K17)) -> 0 | D17: =IF(K17="","",INDEX(INDIRECT("'"&$I$1&"'!$Q$2:$Q$501"),K17)) -> 0 | E17: =IF(K17="","",INDEX(INDIRECT("'"&$I$1&"'!$H$2:$H$501"),K17)) -> مواد خام | K17: =IF($I$5=1,IFERROR(MATCH(1,INDIRECT("'"&$I$1&"'!$AD$2:$AD$501"),0),""),"") -> 5
B18: =IF(K18="","",INDEX(INDIRECT("'"&$I$1&"'!$A$2:$A$501"),K18)) -> فوط | C18: =IF(K18="","",INDEX(INDIRECT("'"&$I$1&"'!$P$2:$P$501"),K18)) -> 0 | D18: =IF(K18="","",INDEX(INDIRECT("'"&$I$1&"'!$Q$2:$Q$501"),K18)) -> 0 | E18: =IF(K18="","",INDEX(INDIRECT("'"&$I$1&"'!$H$2:$H$501"),K18)) -> مواد جاهزة للبيع | K18: =IF($I$5=1,IFERROR(MATCH(2,INDIRECT("'"&$I$1&"'!$AD$2:$AD$501"),0),""),"") -> 83
B19: =IF(K19="","",INDEX(INDIRECT("'"&$I$1&"'!$A$2:$A$501"),K19)) -> عطر ورد-جوري | C19: =IF(K19="","",INDEX(INDIRECT("'"&$I$1&"'!$P$2:$P$501"),K19)) -> 0.4 | D19: =IF(K19="","",INDEX(INDIRECT("'"&$I$1&"'!$Q$2:$Q$501"),K19)) -> 6.6 | E19: =IF(K19="","",INDEX(INDIRECT("'"&$I$1&"'!$H$2:$H$501"),K19)) -> مواد خام | K19: =IF($I$5=1,IFERROR(MATCH(3,INDIRECT("'"&$I$1&"'!$AD$2:$AD$501"),0),""),"") -> 111
B20: =IF(K20="","",INDEX(INDIRECT("'"&$I$1&"'!$A$2:$A$501"),K20)) -> عطر هيد اند شولدرز | C20: =IF(K20="","",INDEX(INDIRECT("'"&$I$1&"'!$P$2:$P$501"),K20)) -> 0 | D20: =IF(K20="","",INDEX(INDIRECT("'"&$I$1&"'!$Q$2:$Q$501"),K20)) -> 0 | E20: =IF(K20="","",INDEX(INDIRECT("'"&$I$1&"'!$H$2:$H$501"),K20)) -> مواد خام | K20: =IF($I$5=1,IFERROR(MATCH(4,INDIRECT("'"&$I$1&"'!$AD$2:$AD$501"),0),""),"") -> 112
B21: =IF(K21="","",INDEX(INDIRECT("'"&$I$1&"'!$A$2:$A$501"),K21)) -> عطر بلو كابس | C21: =IF(K21="","",INDEX(INDIRECT("'"&$I$1&"'!$P$2:$P$501"),K21)) -> 0.5 | D21: =IF(K21="","",INDEX(INDIRECT("'"&$I$1&"'!$Q$2:$Q$501"),K21)) -> 9.75 | E21: =IF(K21="","",INDEX(INDIRECT("'"&$I$1&"'!$H$2:$H$501"),K21)) -> مواد خام | K21: =IF($I$5=1,IFERROR(MATCH(5,INDIRECT("'"&$I$1&"'!$AD$2:$AD$501"),0),""),"") -> 124
B22: =IF(K22="","",INDEX(INDIRECT("'"&$I$1&"'!$A$2:$A$501"),K22)) -> عبوة كلور 800 ميلي | C22: =IF(K22="","",INDEX(INDIRECT("'"&$I$1&"'!$P$2:$P$501"),K22)) -> 4466 | D22: =IF(K22="","",INDEX(INDIRECT("'"&$I$1&"'!$Q$2:$Q$501"),K22)) -> 602.91 | E22: =IF(K22="","",INDEX(INDIRECT("'"&$I$1&"'!$H$2:$H$501"),K22)) -> مواد خام | K22: =IF($I$5=1,IFERROR(MATCH(6,INDIRECT("'"&$I$1&"'!$AD$2:$AD$501"),0),""),"") -> 135
B23: =IF(K23="","",INDEX(INDIRECT("'"&$I$1&"'!$A$2:$A$501"),K23)) -> شامبو 120 كغ خام | C23: =IF(K23="","",INDEX(INDIRECT("'"&$I$1&"'!$P$2:$P$501"),K23)) -> 0 | D23: =IF(K23="","",INDEX(INDIRECT("'"&$I$1&"'!$Q$2:$Q$501"),K23)) -> 0 | E23: =IF(K23="","",INDEX(INDIRECT("'"&$I$1&"'!$H$2:$H$501"),K23)) -> الطبخات | K23: =IF($I$5=1,IFERROR(MATCH(7,INDIRECT("'"&$I$1&"'!$AD$2:$AD$501"),0),""),"") -> 161
B24: =IF(K24="","",INDEX(INDIRECT("'"&$I$1&"'!$A$2:$A$501"),K24)) -> سيتول | C24: =IF(K24="","",INDEX(INDIRECT("'"&$I$1&"'!$P$2:$P$501"),K24)) -> 0 | D24: =IF(K24="","",INDEX(INDIRECT("'"&$I$1&"'!$Q$2:$Q$501"),K24)) -> 0 | E24: =IF(K24="","",INDEX(INDIRECT("'"&$I$1&"'!$H$2:$H$501"),K24)) -> مواد خام | K24: =IF($I$5=1,IFERROR(MATCH(8,INDIRECT("'"&$I$1&"'!$AD$2:$AD$501"),0),""),"") -> 170
B25: =IF(K25="","",INDEX(INDIRECT("'"&$I$1&"'!$A$2:$A$501"),K25)) | C25: =IF(K25="","",INDEX(INDIRECT("'"&$I$1&"'!$P$2:$P$501"),K25)) | D25: =IF(K25="","",INDEX(INDIRECT("'"&$I$1&"'!$Q$2:$Q$501"),K25)) | E25: =IF(K25="","",INDEX(INDIRECT("'"&$I$1&"'!$H$2:$H$501"),K25)) | K25: =IF($I$5=1,IFERROR(MATCH(9,INDIRECT("'"&$I$1&"'!$AD$2:$AD$501"),0),""),"")
B26: =IF(K26="","",INDEX(INDIRECT("'"&$I$1&"'!$A$2:$A$501"),K26)) | C26: =IF(K26="","",INDEX(INDIRECT("'"&$I$1&"'!$P$2:$P$501"),K26)) | D26: =IF(K26="","",INDEX(INDIRECT("'"&$I$1&"'!$Q$2:$Q$501"),K26)) | E26: =IF(K26="","",INDEX(INDIRECT("'"&$I$1&"'!$H$2:$H$501"),K26)) | K26: =IF($I$5=1,IFERROR(MATCH(10,INDIRECT("'"&$I$1&"'!$AD$2:$AD$501"),0),""),"")
B27: =IF(K27="","",INDEX(INDIRECT("'"&$I$1&"'!$A$2:$A$501"),K27)) | C27: =IF(K27="","",INDEX(INDIRECT("'"&$I$1&"'!$P$2:$P$501"),K27)) | D27: =IF(K27="","",INDEX(INDIRECT("'"&$I$1&"'!$Q$2:$Q$501"),K27)) | E27: =IF(K27="","",INDEX(INDIRECT("'"&$I$1&"'!$H$2:$H$501"),K27)) | K27: =IF($I$5=1,IFERROR(MATCH(11,INDIRECT("'"&$I$1&"'!$AD$2:$AD$501"),0),""),"")
B28: =IF(K28="","",INDEX(INDIRECT("'"&$I$1&"'!$A$2:$A$501"),K28)) | C28: =IF(K28="","",INDEX(INDIRECT("'"&$I$1&"'!$P$2:$P$501"),K28)) | D28: =IF(K28="","",INDEX(INDIRECT("'"&$I$1&"'!$Q$2:$Q$501"),K28)) | E28: =IF(K28="","",INDEX(INDIRECT("'"&$I$1&"'!$H$2:$H$501"),K28)) | K28: =IF($I$5=1,IFERROR(MATCH(12,INDIRECT("'"&$I$1&"'!$AD$2:$AD$501"),0),""),"")
B29: =IF(K29="","",INDEX(INDIRECT("'"&$I$1&"'!$A$2:$A$501"),K29)) | C29: =IF(K29="","",INDEX(INDIRECT("'"&$I$1&"'!$P$2:$P$501"),K29)) | D29: =IF(K29="","",INDEX(INDIRECT("'"&$I$1&"'!$Q$2:$Q$501"),K29)) | E29: =IF(K29="","",INDEX(INDIRECT("'"&$I$1&"'!$H$2:$H$501"),K29)) | K29: =IF($I$5=1,IFERROR(MATCH(13,INDIRECT("'"&$I$1&"'!$AD$2:$AD$501"),0),""),"")
B30: =IF(K30="","",INDEX(INDIRECT("'"&$I$1&"'!$A$2:$A$501"),K30)) | C30: =IF(K30="","",INDEX(INDIRECT("'"&$I$1&"'!$P$2:$P$501"),K30)) | D30: =IF(K30="","",INDEX(INDIRECT("'"&$I$1&"'!$Q$2:$Q$501"),K30)) | E30: =IF(K30="","",INDEX(INDIRECT("'"&$I$1&"'!$H$2:$H$501"),K30)) | K30: =IF($I$5=1,IFERROR(MATCH(14,INDIRECT("'"&$I$1&"'!$AD$2:$AD$501"),0),""),"")
B31: =IF(K31="","",INDEX(INDIRECT("'"&$I$1&"'!$A$2:$A$501"),K31)) | C31: =IF(K31="","",INDEX(INDIRECT("'"&$I$1&"'!$P$2:$P$501"),K31)) | D31: =IF(K31="","",INDEX(INDIRECT("'"&$I$1&"'!$Q$2:$Q$501"),K31)) | E31: =IF(K31="","",INDEX(INDIRECT("'"&$I$1&"'!$H$2:$H$501"),K31)) | K31: =IF($I$5=1,IFERROR(MATCH(15,INDIRECT("'"&$I$1&"'!$AD$2:$AD$501"),0),""),"")
B32: =IF(K32="","",INDEX(INDIRECT("'"&$I$1&"'!$A$2:$A$501"),K32)) | C32: =IF(K32="","",INDEX(INDIRECT("'"&$I$1&"'!$P$2:$P$501"),K32)) | D32: =IF(K32="","",INDEX(INDIRECT("'"&$I$1&"'!$Q$2:$Q$501"),K32)) | E32: =IF(K32="","",INDEX(INDIRECT("'"&$I$1&"'!$H$2:$H$501"),K32)) | K32: =IF($I$5=1,IFERROR(MATCH(16,INDIRECT("'"&$I$1&"'!$AD$2:$AD$501"),0),""),"")
B33: =IF(K33="","",INDEX(INDIRECT("'"&$I$1&"'!$A$2:$A$501"),K33)) | C33: =IF(K33="","",INDEX(INDIRECT("'"&$I$1&"'!$P$2:$P$501"),K33)) | D33: =IF(K33="","",INDEX(INDIRECT("'"&$I$1&"'!$Q$2:$Q$501"),K33)) | E33: =IF(K33="","",INDEX(INDIRECT("'"&$I$1&"'!$H$2:$H$501"),K33)) | K33: =IF($I$5=1,IFERROR(MATCH(17,INDIRECT("'"&$I$1&"'!$AD$2:$AD$501"),0),""),"")
B34: =IF(K34="","",INDEX(INDIRECT("'"&$I$1&"'!$A$2:$A$501"),K34)) | C34: =IF(K34="","",INDEX(INDIRECT("'"&$I$1&"'!$P$2:$P$501"),K34)) | D34: =IF(K34="","",INDEX(INDIRECT("'"&$I$1&"'!$Q$2:$Q$501"),K34)) | E34: =IF(K34="","",INDEX(INDIRECT("'"&$I$1&"'!$H$2:$H$501"),K34)) | K34: =IF($I$5=1,IFERROR(MATCH(18,INDIRECT("'"&$I$1&"'!$AD$2:$AD$501"),0),""),"")
B35: =IF(K35="","",INDEX(INDIRECT("'"&$I$1&"'!$A$2:$A$501"),K35)) | C35: =IF(K35="","",INDEX(INDIRECT("'"&$I$1&"'!$P$2:$P$501"),K35)) | D35: =IF(K35="","",INDEX(INDIRECT("'"&$I$1&"'!$Q$2:$Q$501"),K35)) | E35: =IF(K35="","",INDEX(INDIRECT("'"&$I$1&"'!$H$2:$H$501"),K35)) | K35: =IF($I$5=1,IFERROR(MATCH(19,INDIRECT("'"&$I$1&"'!$AD$2:$AD$501"),0),""),"")
B36: =IF(K36="","",INDEX(INDIRECT("'"&$I$1&"'!$A$2:$A$501"),K36)) | C36: =IF(K36="","",INDEX(INDIRECT("'"&$I$1&"'!$P$2:$P$501"),K36)) | D36: =IF(K36="","",INDEX(INDIRECT("'"&$I$1&"'!$Q$2:$Q$501"),K36)) | E36: =IF(K36="","",INDEX(INDIRECT("'"&$I$1&"'!$H$2:$H$501"),K36)) | K36: =IF($I$5=1,IFERROR(MATCH(20,INDIRECT("'"&$I$1&"'!$AD$2:$AD$501"),0),""),"")
B37: =IF(K37="","",INDEX(INDIRECT("'"&$I$1&"'!$A$2:$A$501"),K37)) | C37: =IF(K37="","",INDEX(INDIRECT("'"&$I$1&"'!$P$2:$P$501"),K37)) | D37: =IF(K37="","",INDEX(INDIRECT("'"&$I$1&"'!$Q$2:$Q$501"),K37)) | E37: =IF(K37="","",INDEX(INDIRECT("'"&$I$1&"'!$H$2:$H$501"),K37)) | K37: =IF($I$5=1,IFERROR(MATCH(21,INDIRECT("'"&$I$1&"'!$AD$2:$AD$501"),0),""),"")
B38: =IF(K38="","",INDEX(INDIRECT("'"&$I$1&"'!$A$2:$A$501"),K38)) | C38: =IF(K38="","",INDEX(INDIRECT("'"&$I$1&"'!$P$2:$P$501"),K38)) | D38: =IF(K38="","",INDEX(INDIRECT("'"&$I$1&"'!$Q$2:$Q$501"),K38)) | E38: =IF(K38="","",INDEX(INDIRECT("'"&$I$1&"'!$H$2:$H$501"),K38)) | K38: =IF($I$5=1,IFERROR(MATCH(22,INDIRECT("'"&$I$1&"'!$AD$2:$AD$501"),0),""),"")
B39: =IF(K39="","",INDEX(INDIRECT("'"&$I$1&"'!$A$2:$A$501"),K39)) | C39: =IF(K39="","",INDEX(INDIRECT("'"&$I$1&"'!$P$2:$P$501"),K39)) | D39: =IF(K39="","",INDEX(INDIRECT("'"&$I$1&"'!$Q$2:$Q$501"),K39)) | E39: =IF(K39="","",INDEX(INDIRECT("'"&$I$1&"'!$H$2:$H$501"),K39)) | K39: =IF($I$5=1,IFERROR(MATCH(23,INDIRECT("'"&$I$1&"'!$AD$2:$AD$501"),0),""),"")
B40: =IF(K40="","",INDEX(INDIRECT("'"&$I$1&"'!$A$2:$A$501"),K40)) | C40: =IF(K40="","",INDEX(INDIRECT("'"&$I$1&"'!$P$2:$P$501"),K40)) | D40: =IF(K40="","",INDEX(INDIRECT("'"&$I$1&"'!$Q$2:$Q$501"),K40)) | E40: =IF(K40="","",INDEX(INDIRECT("'"&$I$1&"'!$H$2:$H$501"),K40)) | K40: =IF($I$5=1,IFERROR(MATCH(24,INDIRECT("'"&$I$1&"'!$AD$2:$AD$501"),0),""),"")
B41: =IF(K41="","",INDEX(INDIRECT("'"&$I$1&"'!$A$2:$A$501"),K41)) | C41: =IF(K41="","",INDEX(INDIRECT("'"&$I$1&"'!$P$2:$P$501"),K41)) | D41: =IF(K41="","",INDEX(INDIRECT("'"&$I$1&"'!$Q$2:$Q$501"),K41)) | E41: =IF(K41="","",INDEX(INDIRECT("'"&$I$1&"'!$H$2:$H$501"),K41)) | K41: =IF($I$5=1,IFERROR(MATCH(25,INDIRECT("'"&$I$1&"'!$AD$2:$AD$501"),0),""),"")
...

Sheet فحص الأخطاء
B1: فحص الأخطاء — الشهر المعروض
B2: ="الشهر: "&INDEX('لوحة التحكم'!$B$16:$B$27,'لوحة التحكم'!$D$6)&" · "&IF('لوحة التحكم'!$K$12=1,IF(INDEX('الملخص الشهري'!$B$45:$M$45,'لوحة التحكم'!$D$6)=0,"✓ لا توجد أخطاء","⚠ يوجد "&INDEX('الملخص الشهري'!$B$45:$M$45,'لوحة التحكم'!$D$6)&" صنف به ملاحظات — صحّحها في البرنامج المحاسبي ثم أعد التصدير واللصق"),"لا توجد بيانات صالحة للفحص") -> الشهر: أيلول · ✓ لا توجد أخطاء
B4: أنواع الملاحظات وطريقة معالجتها
B5: النوع | C5: العدد | D5: ماذا يعني وكيف تعالجه
B6: كمية سالبة | C6: =IFERROR(INDEX('الملخص الشهري'!$B$37:$M$37,'لوحة التحكم'!$D$6),"") -> 0 | D6: رصيد أقل من الصفر (غالبًا بيع قبل إدخال الشراء أو تصنيع بلا مدخلات). تُعتبر صفرًا في قيمة المستودع. صحّح الحركات أو أدخل الجرد.
